Workbook

Sheet Dashboard
B2: =C3&" – Dashboard" -> Project Bana – Dashboard
C3: Project Bana
C4: 50 MVA onshore wind, Ács Katódgyár – sale at COD vs hold to maturity
C5: Version | E5: v2
C6: Model date | E6: 46309
C7: Key-assumption set | E7: =Scenario_Name -> Base: Raiffeisen
C8: Master check | E8: =IF(Master_Check=0,"OK","CHECK") -> OK
C9: Item | D9: Unit | E9: European turbine | F9: Chinese turbine | X9: Key assumptions | Y9: Unit | Z9: Live
A11: x | C11: The bid: commitments and points | E11: European turbine | F11: Chinese turbine | H11: Offerable range | I11: Points EU | J11: Points CN | X11: Key-assumption set
C12: Municipal one-off (ÖSZ-1) | D12: EUR k/MW | E12: 50 | F12: 50 | H12: 0 or 10–50 | I12: =Calc_1!$F$34 -> 20 | J12: =Calc_2!$F$34 -> 20 | X12: Key-assumption set | Y12: text | Z12: Base: Raiffeisen
C13: Community contribution (ÖSZ-2) | D13: EUR/MWh | E13: 3 | F13: 3 | H13: 0 or 2–3 | I13: =Calc_1!$F$35 -> 15 | J13: =Calc_2!$F$35 -> 15
C14: Overbuild committed (ÖSZ-3) | D14: % | E14: 0.2 | F14: 0.2 | H14: ≥ 0 % | I14: =Calc_1!$F$36 -> 5 | J14: =Calc_2!$F$36 -> 5 | X14: Key assumptions (live)
C15: BESS power, share of MVA (ÖSZ-4) | D15: % | E15: 0.2 | F15: 0.2 | H15: ≤ wind MW | I15: =Calc_1!$F$37 -> 7.5 | J15: =Calc_2!$F$37 -> 7.5 | X15: Purchase price | Y15: EUR k | Z15: =In_Purchase_Price -> 4500
C16: BESS duration | D16: h | E16: 4 | F16: 4 | H16: ≥ 4 h | X16: COD | Y16: date | Z16: =In_COD -> 47756
C17: Performance security multiple (ÖSZ-6) | D17: x | E17: 1 | F17: 1 | H17: ≥ 1.0 | I17: =Calc_1!$F$39 -> 0 | J17: =Calc_2!$F$39 -> 0 | X17: Overbuild built | Y17: % | Z17: =In_Overbuild_Built -> 0.1
C18: Partial award accepted (ÖSZ-5) | D18: flag | E18: 0 | F18: 0 | H18: 0 / 1 | I18: =Calc_1!$F$38 -> 0 | J18: =Calc_2!$F$38 -> 0 | X18: Sanction regime (1 pro rata, 2 full) | Y18: flag | Z18: =In_Sanction_Regime -> 1
C19: Shared connection (ÖSZ-8) | D19: flag | E19: 0 | F19: 0 | H19: 0 / 1 | I19: =Calc_1!$F$40 -> 0 | J19: =Calc_2!$F$40 -> 0 | X19: COD price, EU | Y19: EUR k/MW | Z19: =In_COD_Price -> 2450
C20: EU turbines ≥ 80 % (ÖSZ-9), sets the route | D20: flag | E20: 1 | F20: 0 | H20: 0 / 1 | I20: =Calc_1!$F$41 -> 12 | J20: =Calc_2!$F$41 -> 0 | X20: COD price, CN | Y20: EUR k/MW | Z20: =In_COD_Price_CN -> 2100
C21: EU transformers ≥ 80 % (ÖSZ-9) | D21: flag | E21: 0 | F21: 0 | H21: 0 / 1 | I21: =Calc_1!$F$42 -> 0 | J21: =Calc_2!$F$42 -> 0 | X21: Turbine price, EU | Y21: EUR k/MW | Z21: =In_Turbine -> 950
C22: Points total | D22: points | E22: =Calc_1!$E43 -> 59.5 | F22: =Calc_2!$E43 -> 47.5 | X22: Turbine price, CN | Y22: EUR k/MW | Z22: =In_Turbine_CN -> 500
C23: Commitments within the offerable range | D23: flag | E23: =IF(Calc_1!$E45+Calc_1!$F45=0,"OK","CHECK") -> OK | F23: =IF(Calc_2!$E45+Calc_2!$F45=0,"OK","CHECK") -> OK | X23: Net P50 hours | Y23: h/yr | Z23: =In_P50_Hours -> 2600
X24: PPA price at COD, whole life | Y24: EUR/MWh | Z24: =In_PPA_Price -> 90
A25: x | C25: Capacity: committed vs built | E25: European turbine | F25: Chinese turbine | X25: Debt rate | Y25: % | Z25: =In_Debt_Rate -> 0.05
C26: Wind committed in the bid | D26: MW | E26: =Calc_1!$E25 -> 60 | F26: =Calc_2!$E25 -> 60 | X26: Target DSCR | Y26: x | Z26: =In_DSCR -> 1.2
C27: Wind built | D27: MW | E27: =Calc_1!$F25 -> 55 | F27: =Calc_2!$F25 -> 55 | X27: Tenor from COD | Y27: years | Z27: =In_Debt_Tenor -> 15
C28: BESS committed | D28: MW | E28: =Calc_1!$E27 -> 10 | F28: =Calc_2!$E27 -> 10 | X28: Debt share cap | Y28: % | Z28: =In_Gearing -> 0.7
C29: BESS energy committed | D29: MWh | E29: =Calc_1!$E28 -> 40 | F29: =Calc_2!$E28 -> 40 | X29: CIT | Y29: % | Z29: =In_CIT -> 0.15
C30: BESS built | D30: MW | E30: =Calc_1!$F27 -> 10 | F30: =Calc_2!$F27 -> 10 | X30: Robin Hood tax on (1 = yes) | Y30: flag | Z30: =In_RH_On -> 0
C31: Wind build shortfall vs commitment | D31: % | E31: =Calc_1!$E30 -> 0.083333333 | F31: =Calc_2!$E30 -> 0.083333333 | X31: Discount rate | Y31: % | Z31: =In_Discount_Rate -> 0.08
C32: Memo: connection right lost pro rata | D32: MVA | E32: =Calc_1!$E31 -> 0 | F32: =Calc_2!$E31 -> 0 | X32: FX | Y32: HUF/EUR | Z32: =In_FX -> 365
C33: Grid-bottleneck energy loss | D33: % | E33: =Calc_1!$E29 -> 0.0045454545 | F33: =Calc_2!$E29 -> 0.0045454545
C34: PB call if the pro-rata rule applies (GYIK 28/30) | D34: EUR m | E34: =Calc_1!$E61/Thousand -> 0 | F34: =Calc_2!$E61/Thousand -> 0
C35: PB call if the full-call rule applies (GYIK 72) | D35: EUR m | E35: =Calc_1!$F61/Thousand -> 2.2164384 | F35: =Calc_2!$F61/Thousand -> 2.2164384
C36: PB call paid, selected regime | D36: EUR m | E36: =(-Calc_1!$I62)/Thousand -> 0 | F36: =(-Calc_2!$I62)/Thousand -> 0
A38: x | C38: Returns at a glance | E38: European turbine | F38: Chinese turbine
C39: FEP profit – sale at COD | D39: EUR m | E39: =Calc_1!$I139/Thousand -> 20.88859 | F39: =Calc_2!$I139/Thousand -> 28.953814
C40: FEP IRR – sale at COD | D40: % | E40: =Calc_1!$E140 -> 0.2480759 | F40: =Calc_2!$E140 -> 0.43059013
C41: FEP MOIC – sale at COD | D41: x | E41: =Calc_1!$E141 -> 1.3302601 | F41: =Calc_2!$E141 -> 1.8037996
C42: FEP NPV – sale at COD | D42: EUR m | E42: =Calc_1!$E142/Thousand -> 11.024428 | F42: =Calc_2!$E142/Thousand -> 18.540429
C43: FEP profit – hold to maturity | D43: EUR m | E43: =Calc_1!$I152/Thousand -> 137.25447 | F43: =Calc_2!$I152/Thousand -> 160.39804
...

Sheet Inputs
B2: =Dashboard!$C$3&" – Inputs and scenarios" -> Project Bana – Inputs and scenarios
B4: Scenario selected | D4: Set on the Dashboard | F4: =Scenario_Name -> Base: Raiffeisen
B5: Scenario number | F5: =MATCH(Scenario_Name,Scenario_Names,0) -> 1
B7: Input | C7: Unit | D7: Source / note | F7: Live | H7: Base: Raiffeisen | I7: Base: UniCredit | J7: COD price −10% | K7: COD price +10% | L7: Turbine +10% | M7: Yield −10% | N7: PPA +10% | O7: Full PB call | P7: Rate +1 pp | Q7: Tenor 10 years | R7: Robin Hood 31% | S7: CIT 9% | T7: BESS 100 MWh | U7: Promise all, deliver nothing | V7: Full cash sweep
A10: x | C10: Constants
B11: Thousand | C11: # | D11: Scale | F11: 1000
B12: Million | C12: # | D12: Scale | F12: 1000000
B13: Days In Year | C13: days | D13: Day count for year fractions and XIRR | F13: 365
B14: Months In Year | C14: months | F14: 12
B15: Months Per Period | C15: months | D15: Timeline periodicity (quarterly) | F15: 3
B16: Tolerance | C16: # | D16: Check and solver tolerance | F16: 1e-06
A18: x | C18: Timing
B19: Model start date | C19: date | D19: Timeline start | F19: =IF(INDEX($H19:$W19,1,Scenario_Selected)="",$H19,INDEX($H19:$W19,1,Scenario_Selected)) -> 46296 | H19: 46296
B20: Sensitivity step for the turbine and yield sets | C20: % | D20: User 13-Oct-26 | F20: 0.1
B21: Bid submission: fee paid, bid security posted, DD | C21: date | D21: Kiírás VI.5 | F21: =IF(INDEX($H21:$W21,1,Scenario_Selected)="",$H21,INDEX($H21:$W21,1,Scenario_Selected)) -> 46325 | H21: 46325
B22: Award decision | C22: date | D22: Bana v3 Inputs E96 | F22: =IF(INDEX($H22:$W22,1,Scenario_Selected)="",$H22,INDEX($H22:$W22,1,Scenario_Selected)) -> 46369 | H22: 46369
B23: Award decision received | C23: date | D23: GYIK Q68 | F23: =IF(INDEX($H23:$W23,1,Scenario_Selected)="",$H23,INDEX($H23:$W23,1,Scenario_Selected)) -> 46418 | H23: 46418
B24: PB posted, TSO security paid after the decision | C24: days | D24: Kiírás XII.5, XIII.6 | F24: =IF(INDEX($H24:$W24,1,Scenario_Selected)="",$H24,INDEX($H24:$W24,1,Scenario_Selected)) -> 15 | H24: 15
B25: Closing of the rights transfer: price paid | C25: date | D25: Bana deck p2: closing after the award | F25: =IF(INDEX($H25:$W25,1,Scenario_Selected)="",$H25,INDEX($H25:$W25,1,Scenario_Selected)) -> 46387 | H25: 46387
B26: Notice to proceed | C26: date | D26: Bana v3 Inputs E154 | F26: =IF(INDEX($H26:$W26,1,Scenario_Selected)="",$H26,INDEX($H26:$W26,1,Scenario_Selected)) -> 47026 | H26: 47026
B27: Connection agreement (HCSSZ): fees paid | C27: date | D27: Bana v3 Inputs E99 | F27: =IF(INDEX($H27:$W27,1,Scenario_Selected)="",$H27,INDEX($H27:$W27,1,Scenario_Selected)) -> 47126 | H27: 47126
B28: Commercial operation date | C28: date | D28: Bana v3 Inputs E155, E237 | F28: =IF(INDEX($H28:$W28,1,Scenario_Selected)="",$H28,INDEX($H28:$W28,1,Scenario_Selected)) -> 47756 | H28: 47756
B29: Operating life | C29: years | D29: Bana v3 Inputs E157 | F29: =IF(INDEX($H29:$W29,1,Scenario_Selected)="",$H29,INDEX($H29:$W29,1,Scenario_Selected)) -> 30 | H29: 30
B30: Performance security released (hold route) | C30: date | D30: Kiírás XII.8 (COD deadline + 6 m) | F30: =IF(INDEX($H30:$W30,1,Scenario_Selected)="",$H30,INDEX($H30:$W30,1,Scenario_Selected)) -> 48669 | H30: 48669
A32: x | C32: Acquisition, exit and tax
B33: FX rate | C33: HUF/EUR | D33: Bana v3 Inputs E11 | F33: =IF(INDEX($H33:$W33,1,Scenario_Selected)="",$H33,INDEX($H33:$W33,1,Scenario_Selected)) -> 365 | H33: 365
B34: Purchase price to GEI | C34: EUR k | D34: Bana v3 Inputs E283 | F34: =IF(INDEX($H34:$W34,1,Scenario_Selected)="",$H34,INDEX($H34:$W34,1,Scenario_Selected)) -> 4500 | H34: 4500
B35: Transaction and DD costs | C35: EUR k | D35: Bana v3 Inputs E25 | F35: =IF(INDEX($H35:$W35,1,Scenario_Selected)="",$H35,INDEX($H35:$W35,1,Scenario_Selected)) -> 150 | H35: 150
B36: Devex to NTP incl. contingency | C36: EUR k | D36: Bana v3 Inputs E292 | F36: =IF(INDEX($H36:$W36,1,Scenario_Selected)="",$H36,INDEX($H36:$W36,1,Scenario_Selected)) -> 500 | H36: 500
B37: Sale price at COD per MW, EU turbines | C37: EUR k/MW | D37: Bana v3 Inputs M230 | F37: =IF(INDEX($H37:$W37,1,Scenario_Selected)="",$H37,INDEX($H37:$W37,1,Scenario_Selected)) -> 2450 | H37: 2450 | J37: =H37*(1-Sens_Step) -> 2205 | K37: =H37*(1+Sens_Step) -> 2695
B38: Sale price at COD per MW, CN turbines | C38: EUR k/MW | D38: Bana v3 Inputs N230 | F38: =IF(INDEX($H38:$W38,1,Scenario_Selected)="",$H38,INDEX($H38:$W38,1,Scenario_Selected)) -> 2100 | H38: 2100 | J38: =H38*(1-Sens_Step) -> 1890 | K38: =H38*(1+Sens_Step) -> 2310
B39: Sale costs at COD | C39: EUR k | D39: Bana v3 Inputs E26 | F39: =IF(INDEX($H39:$W39,1,Scenario_Selected)="",$H39,INDEX($H39:$W39,1,Scenario_Selected)) -> 500 | H39: 500
B40: FEP discount rate (NPV) | C40: % | D40: Bana v3 Inputs E253 | F40: =IF(INDEX($H40:$W40,1,Scenario_Selected)="",$H40,INDEX($H40:$W40,1,Scenario_Selected)) -> 0.08 | H40: 0.08
B41: Corporate income tax: 9 % + possible Pillar Two top-up (proxy) | C41: % | D41: User 14-Oct-26; set 12: Tao. 19. § | F41: =IF(INDEX($H41:$W41,1,Scenario_Selected)="",$H41,INDEX($H41:$W41,1,Scenario_Selected)) -> 0.15 | H41: 0.15 | S41: 0.09
B42: Robin Hood tax applies (1 = yes) | C42: flag | D42: User 14-Oct-26: sensitivity only (Thtv.) | F42: =IF(INDEX($H42:$W42,1,Scenario_Selected)="",$H42,INDEX($H42:$W42,1,Scenario_Selected)) -> 0 | H42: 0 | R42: 1
B43: Robin Hood tax on positive pre-tax profit | C43: % | D43: Thtv.; 41 % to 2025, 31 % from 2026 | F43: =IF(INDEX($H43:$W43,1,Scenario_Selected)="",$H43,INDEX($H43:$W43,1,Scenario_Selected)) -> 0.31 | H43: 0.31
B44: Gain on the COD share sale taxed (0 = exempt) | C44: flag | D44: Bana v3 E231; participation exemption | F44: =IF(INDEX($H44:$W44,1,Scenario_Selected)="",$H44,INDEX($H44:$W44,1,Scenario_Selected)) -> 0 | H44: 0
B45: Tax depreciation period | C45: years | D45: Bana v3 Inputs E213 (to confirm) | F45: =IF(INDEX($H45:$W45,1,Scenario_Selected)="",$H45,INDEX($H45:$W45,1,Scenario_Selected)) -> 20 | H45: 20
B46: Tax losses usable, share of the tax base | C46: % | D46: Tao. 17. § (2); Bana v3 E214 | F46: =IF(INDEX($H46:$W46,1,Scenario_Selected)="",$H46,INDEX($H46:$W46,1,Scenario_Selected)) -> 0.5 | H46: 0.5
B47: Tax losses usable within | C47: years | D47: Tao. 17. § (1) | F47: =IF(INDEX($H47:$W47,1,Scenario_Selected)="",$H47,INDEX($H47:$W47,1,Scenario_Selected)) -> 5 | H47: 5
...

Sheet Curves
B2: =Dashboard!$C$3&" – Time-series inputs" -> Project Bana – Time-series inputs
A5: x | C5: Tender scoring bands | E5: Kiírás Annex 3-4
E6: Weight / min | F6: Max | J6: Bands →
C7: ÖSZ-1 municipal one-off – lower bound | D7: EUR k/MW | E7: 10 | F7: 50 | J7: 10 | K7: 15 | L7: 20 | M7: 25 | N7: 30 | O7: 35 | P7: 40 | Q7: 45 | R7: 50
C8: ÖSZ-1 municipal one-off – lower bound included | D8: flag | J8: 0 | K8: 0 | L8: 0 | M8: 0 | N8: 0 | O8: 0 | P8: 0 | Q8: 0 | R8: 1
C9: ÖSZ-1 municipal one-off – inner points (below, bands) | D9: points | E9: 0.2 | J9: 0 | K9: 10 | L9: 20 | M9: 30 | N9: 40 | O9: 55 | P9: 70 | Q9: 80 | R9: 90 | S9: 100
C10: ÖSZ-2 community contribution – lower bound | D10: EUR/MWh | E10: 2 | F10: 3 | J10: 2 | K10: 2.1 | L10: 2.2 | M10: 2.3 | N10: 2.4 | O10: 2.5 | P10: 2.6 | Q10: 2.7 | R10: 2.8 | S10: 2.9 | T10: 3
C11: ÖSZ-2 community contribution – lower bound included | D11: flag | J11: 0 | K11: 0 | L11: 0 | M11: 0 | N11: 0 | O11: 0 | P11: 0 | Q11: 0 | R11: 0 | S11: 0 | T11: 1
C12: ÖSZ-2 community contribution – inner points (below, bands) | D12: points | E12: 0.15 | J12: 0 | K12: 5 | L12: 10 | M12: 20 | N12: 30 | O12: 40 | P12: 50 | Q12: 60 | R12: 70 | S12: 80 | T12: 90 | U12: 100
C13: ÖSZ-4 BESS ratio – lower bound | D13: % | E13: 0.05 | J13: 0.02 | K13: 0.05 | L13: 0.1 | M13: 0.15 | N13: 0.2 | O13: 0.25 | P13: 0.3 | Q13: 0.35 | R13: 0.4 | S13: 0.5
C14: ÖSZ-4 BESS ratio – lower bound included | D14: flag | J14: 0 | K14: 1 | L14: 1 | M14: 1 | N14: 1 | O14: 1 | P14: 1 | Q14: 1 | R14: 1 | S14: 0
C15: ÖSZ-4 BESS ratio – inner points (below, bands) | D15: points | E15: 0.15 | J15: 0 | K15: 10 | L15: 20 | M15: 30 | N15: 40 | O15: 50 | P15: 60 | Q15: 70 | R15: 80 | S15: 90 | T15: 100
C16: ÖSZ-3 overbuild – lower bound | D16: % | J16: 0.02 | K16: 0.05 | L16: 0.1 | M16: 0.15 | N16: 0.2 | O16: 0.25 | P16: 0.3 | Q16: 0.35 | R16: 0.4 | S16: 0.5
C17: ÖSZ-3 overbuild – lower bound included | D17: flag | J17: 0 | K17: 1 | L17: 1 | M17: 1 | N17: 1 | O17: 1 | P17: 1 | Q17: 1 | R17: 1 | S17: 0
C18: ÖSZ-3 overbuild – inner points (below, bands) | D18: points | E18: 0.1 | J18: 0 | K18: 10 | L18: 20 | M18: 30 | N18: 40 | O18: 50 | P18: 60 | Q18: 70 | R18: 80 | S18: 90 | T18: 100
C19: ÖSZ-6 performance security multiple – lower bound | D19: x | J19: 1 | K19: 1.2 | L19: 1.3 | M19: 1.4 | N19: 1.5 | O19: 1.6 | P19: 1.7 | Q19: 1.8 | R19: 1.9 | S19: 2
C20: ÖSZ-6 performance security multiple – lower bound included | D20: flag | J20: 0 | K20: 1 | L20: 1 | M20: 1 | N20: 1 | O20: 1 | P20: 1 | Q20: 1 | R20: 1 | S20: 1
C21: ÖSZ-6 performance security multiple – inner points (below, bands) | D21: points | E21: 0.05 | J21: 0 | K21: 10 | L21: 20 | M21: 30 | N21: 40 | O21: 50 | P21: 60 | Q21: 70 | R21: 80 | S21: 90 | T21: 100
C22: ÖSZ-5 partial award – inner points | D22: points | E22: 0.05 | J22: 100
C23: ÖSZ-8 shared connection – inner points | D23: points | E23: 0.05 | J23: 100
C24: ÖSZ-9 EU turbines – inner points | D24: points | E24: 0.15 | J24: 80
C25: ÖSZ-9 EU transformers – inner points | D25: points | J25: 20
C27: ***END***

Sheet Calc_1
A1: 1 | C1: Bid number
B2: =Dashboard!$C$3&" – Calculations – "&INDEX(Bid_Labels,1,$A$1) -> Project Bana – Calculations – European turbine
C3: Period start | D3: date | J3: =I$4+1 -> 46296 | K3: =J$4+1 -> 46388 | L3: =K$4+1 -> 46478 | M3: =L$4+1 -> 46569 | N3: =M$4+1 -> 46661 | O3: =N$4+1 -> 46753 | P3: =O$4+1 -> 46844 | Q3: =P$4+1 -> 46935 | ... EO3: =EN$4+1 -> 58623
C4: Period end | D4: date | I4: =In_Model_Start-1 -> 46295 | J4: =EOMONTH(J$3,Months_Per_Period-1) -> 46387 | K4: =EOMONTH(K$3,Months_Per_Period-1) -> 46477 | L4: =EOMONTH(L$3,Months_Per_Period-1) -> 46568 | M4: =EOMONTH(M$3,Months_Per_Period-1) -> 46660 | N4: =EOMONTH(N$3,Months_Per_Period-1) -> 46752 | O4: =EOMONTH(O$3,Months_Per_Period-1) -> 46843 | P4: =EOMONTH(P$3,Months_Per_Period-1) -> 46934 | Q4: =EOMONTH(Q$3,Months_Per_Period-1) -> 47026 | ... EO4: =EOMONTH(EO$3,Months_Per_Period-1) -> 58714
C5: Days in period | D5: days | J5: =J$4-J$3+1 -> 92 | K5: =K$4-K$3+1 -> 90 | L5: =L$4-L$3+1 -> 91 | M5: =M$4-M$3+1 -> 92 | N5: =N$4-N$3+1 -> 92 | O5: =O$4-O$3+1 -> 91 | P5: =P$4-P$3+1 -> 91 | Q5: =Q$4-Q$3+1 -> 92 | ... EO5: =EO$4-EO$3+1 -> 92
C6: Year fraction | D6: factor | J6: =J$5/Days_In_Year -> 0.25205479 | K6: =K$5/Days_In_Year -> 0.24657534 | L6: =L$5/Days_In_Year -> 0.24931507 | M6: =M$5/Days_In_Year -> 0.25205479 | N6: =N$5/Days_In_Year -> 0.25205479 | O6: =O$5/Days_In_Year -> 0.24931507 | P6: =P$5/Days_In_Year -> 0.24931507 | Q6: =Q$5/Days_In_Year -> 0.25205479 | ... EO6: =EO$5/Days_In_Year -> 0.25205479
C7: Year | D7: year | J7: =YEAR(J$4) -> 2026 | K7: =YEAR(K$4) -> 2027 | L7: =YEAR(L$4) -> 2027 | M7: =YEAR(M$4) -> 2027 | N7: =YEAR(N$4) -> 2027 | O7: =YEAR(O$4) -> 2028 | P7: =YEAR(P$4) -> 2028 | Q7: =YEAR(Q$4) -> 2028 | ... EO7: =YEAR(EO$4) -> 2060
C8: Period counter | D8: # | J8: =I$8+1 -> 1 | K8: =J$8+1 -> 2 | L8: =K$8+1 -> 3 | M8: =L$8+1 -> 4 | N8: =M$8+1 -> 5 | O8: =N$8+1 -> 6 | P8: =O$8+1 -> 7 | Q8: =P$8+1 -> 8 | ... EO8: =EN$8+1 -> 136
A11: x | C11: Timing and flags
C12: Construction share (NTP → COD) | D12: factor | E12: =In_NTP+1 -> 47027 | F12: =In_COD -> 47756 | I12: =SUM(J12:EO12) -> 1 | J12: =MAX(0,MIN($F12,J$4)-MAX($E12,J$3)+1)/($F12-$E12+1) -> 0 | K12: =MAX(0,MIN($F12,K$4)-MAX($E12,K$3)+1)/($F12-$E12+1) -> 0 | L12: =MAX(0,MIN($F12,L$4)-MAX($E12,L$3)+1)/($F12-$E12+1) -> 0 | M12: =MAX(0,MIN($F12,M$4)-MAX($E12,M$3)+1)/($F12-$E12+1) -> 0 | N12: =MAX(0,MIN($F12,N$4)-MAX($E12,N$3)+1)/($F12-$E12+1) -> 0 | O12: =MAX(0,MIN($F12,O$4)-MAX($E12,O$3)+1)/($F12-$E12+1) -> 0 | P12: =MAX(0,MIN($F12,P$4)-MAX($E12,P$3)+1)/($F12-$E12+1) -> 0 | Q12: =MAX(0,MIN($F12,Q$4)-MAX($E12,Q$3)+1)/($F12-$E12+1) -> 0 | ... EO12: =MAX(0,MIN($F12,EO$4)-MAX($E12,EO$3)+1)/($F12-$E12+1) -> 0
C13: Devex share (closing → NTP) | D13: factor | E13: =In_Closing+1 -> 46388 | F13: =In_NTP -> 47026 | I13: =SUM(J13:EO13) -> 1 | J13: =MAX(0,MIN($F13,J$4)-MAX($E13,J$3)+1)/($F13-$E13+1) -> 0 | K13: =MAX(0,MIN($F13,K$4)-MAX($E13,K$3)+1)/($F13-$E13+1) -> 0.14084507 | L13: =MAX(0,MIN($F13,L$4)-MAX($E13,L$3)+1)/($F13-$E13+1) -> 0.14241002 | M13: =MAX(0,MIN($F13,M$4)-MAX($E13,M$3)+1)/($F13-$E13+1) -> 0.14397496 | N13: =MAX(0,MIN($F13,N$4)-MAX($E13,N$3)+1)/($F13-$E13+1) -> 0.14397496 | O13: =MAX(0,MIN($F13,O$4)-MAX($E13,O$3)+1)/($F13-$E13+1) -> 0.14241002 | P13: =MAX(0,MIN($F13,P$4)-MAX($E13,P$3)+1)/($F13-$E13+1) -> 0.14241002 | Q13: =MAX(0,MIN($F13,Q$4)-MAX($E13,Q$3)+1)/($F13-$E13+1) -> 0.14397496 | ... EO13: =MAX(0,MIN($F13,EO$4)-MAX($E13,EO$3)+1)/($F13-$E13+1) -> 0
C14: COD | D14: flag | E14: =In_COD -> 47756 | I14: =SUM(J14:EO14) -> 1 | J14: =N(AND(J$3<=$E14,J$4>=$E14)) -> 0 | K14: =N(AND(K$3<=$E14,K$4>=$E14)) -> 0 | L14: =N(AND(L$3<=$E14,L$4>=$E14)) -> 0 | M14: =N(AND(M$3<=$E14,M$4>=$E14)) -> 0 | N14: =N(AND(N$3<=$E14,N$4>=$E14)) -> 0 | O14: =N(AND(O$3<=$E14,O$4>=$E14)) -> 0 | P14: =N(AND(P$3<=$E14,P$4>=$E14)) -> 0 | Q14: =N(AND(Q$3<=$E14,Q$4>=$E14)) -> 0 | ... EO14: =N(AND(EO$3<=$E14,EO$4>=$E14)) -> 0
C15: COD column on the timeline (buyer IRR start) | D15: # | E15: =MATCH(In_COD,$J$4:$EO$4,0) -> 16
C16: Operations | D16: flag | E16: =In_COD+1 -> 47757 | F16: =EDATE(In_COD,In_Life*Months_In_Year) -> 58714 | J16: =MAX(0,(MIN($F16,J$4)-MAX($E16,J$3)+1)/J$5) -> 0 | K16: =MAX(0,(MIN($F16,K$4)-MAX($E16,K$3)+1)/K$5) -> 0 | L16: =MAX(0,(MIN($F16,L$4)-MAX($E16,L$3)+1)/L$5) -> 0 | M16: =MAX(0,(MIN($F16,M$4)-MAX($E16,M$3)+1)/M$5) -> 0 | N16: =MAX(0,(MIN($F16,N$4)-MAX($E16,N$3)+1)/N$5) -> 0 | O16: =MAX(0,(MIN($F16,O$4)-MAX($E16,O$3)+1)/O$5) -> 0 | P16: =MAX(0,(MIN($F16,P$4)-MAX($E16,P$3)+1)/P$5) -> 0 | Q16: =MAX(0,(MIN($F16,Q$4)-MAX($E16,Q$3)+1)/Q$5) -> 0 | ... EO16: =MAX(0,(MIN($F16,EO$4)-MAX($E16,EO$3)+1)/EO$5) -> 1
C17: Land lease period (NTP → end of life) | D17: flag | E17: =In_NTP+1 -> 47027 | F17: =EDATE(In_COD,In_Life*Months_In_Year) -> 58714 | J17: =MAX(0,(MIN($F17,J$4)-MAX($E17,J$3)+1)/J$5) -> 0 | K17: =MAX(0,(MIN($F17,K$4)-MAX($E17,K$3)+1)/K$5) -> 0 | L17: =MAX(0,(MIN($F17,L$4)-MAX($E17,L$3)+1)/L$5) -> 0 | M17: =MAX(0,(MIN($F17,M$4)-MAX($E17,M$3)+1)/M$5) -> 0 | N17: =MAX(0,(MIN($F17,N$4)-MAX($E17,N$3)+1)/N$5) -> 0 | O17: =MAX(0,(MIN($F17,O$4)-MAX($E17,O$3)+1)/O$5) -> 0 | P17: =MAX(0,(MIN($F17,P$4)-MAX($E17,P$3)+1)/P$5) -> 0 | Q17: =MAX(0,(MIN($F17,Q$4)-MAX($E17,Q$3)+1)/Q$5) -> 0 | ... EO17: =MAX(0,(MIN($F17,EO$4)-MAX($E17,EO$3)+1)/EO$5) -> 1
C18: Debt repayment period | D18: flag | E18: =In_COD+1 -> 47757 | F18: =EDATE(In_COD,In_Debt_Tenor*Months_In_Year) -> 53235 | J18: =MAX(0,(MIN($F18,J$4)-MAX($E18,J$3)+1)/J$5) -> 0 | K18: =MAX(0,(MIN($F18,K$4)-MAX($E18,K$3)+1)/K$5) -> 0 | L18: =MAX(0,(MIN($F18,L$4)-MAX($E18,L$3)+1)/L$5) -> 0 | M18: =MAX(0,(MIN($F18,M$4)-MAX($E18,M$3)+1)/M$5) -> 0 | N18: =MAX(0,(MIN($F18,N$4)-MAX($E18,N$3)+1)/N$5) -> 0 | O18: =MAX(0,(MIN($F18,O$4)-MAX($E18,O$3)+1)/O$5) -> 0 | P18: =MAX(0,(MIN($F18,P$4)-MAX($E18,P$3)+1)/P$5) -> 0 | Q18: =MAX(0,(MIN($F18,Q$4)-MAX($E18,Q$3)+1)/Q$5) -> 0 | ... EO18: =MAX(0,(MIN($F18,EO$4)-MAX($E18,EO$3)+1)/EO$5) -> 0
C19: Last debt repayment | D19: flag | E19: =EDATE(In_COD,In_Debt_Tenor*Months_In_Year) -> 53235 | I19: =SUM(J19:EO19) -> 1 | J19: =N(AND(J$3<=$E19,J$4>=$E19)) -> 0 | K19: =N(AND(K$3<=$E19,K$4>=$E19)) -> 0 | L19: =N(AND(L$3<=$E19,L$4>=$E19)) -> 0 | M19: =N(AND(M$3<=$E19,M$4>=$E19)) -> 0 | N19: =N(AND(N$3<=$E19,N$4>=$E19)) -> 0 | O19: =N(AND(O$3<=$E19,O$4>=$E19)) -> 0 | P19: =N(AND(P$3<=$E19,P$4>=$E19)) -> 0 | Q19: =N(AND(Q$3<=$E19,Q$4>=$E19)) -> 0 | ... EO19: =N(AND(EO$3<=$E19,EO$4>=$E19)) -> 0
C20: Tax depreciation share | D20: factor | E20: =In_COD+1 -> 47757 | F20: =EDATE(In_COD,In_Dep_Years*Months_In_Year) -> 55061 | I20: =SUM(J20:EO20) -> 1 | J20: =MAX(0,MIN($F20,J$4)-MAX($E20,J$3)+1)/($F20-$E20+1) -> 0 | K20: =MAX(0,MIN($F20,K$4)-MAX($E20,K$3)+1)/($F20-$E20+1) -> 0 | L20: =MAX(0,MIN($F20,L$4)-MAX($E20,L$3)+1)/($F20-$E20+1) -> 0 | M20: =MAX(0,MIN($F20,M$4)-MAX($E20,M$3)+1)/($F20-$E20+1) -> 0 | N20: =MAX(0,MIN($F20,N$4)-MAX($E20,N$3)+1)/($F20-$E20+1) -> 0 | O20: =MAX(0,MIN($F20,O$4)-MAX($E20,O$3)+1)/($F20-$E20+1) -> 0 | P20: =MAX(0,MIN($F20,P$4)-MAX($E20,P$3)+1)/($F20-$E20+1) -> 0 | Q20: =MAX(0,MIN($F20,Q$4)-MAX($E20,Q$3)+1)/($F20-$E20+1) -> 0 | ... EO20: =MAX(0,MIN($F20,EO$4)-MAX($E20,EO$3)+1)/($F20-$E20+1) -> 0
C21: Operating year | D21: # | J21: =ROUNDUP(YEARFRAC(In_COD,J$4),0)*(J$4>In_COD) -> 0 | K21: =ROUNDUP(YEARFRAC(In_COD,K$4),0)*(K$4>In_COD) -> 0 | L21: =ROUNDUP(YEARFRAC(In_COD,L$4),0)*(L$4>In_COD) -> 0 | M21: =ROUNDUP(YEARFRAC(In_COD,M$4),0)*(M$4>In_COD) -> 0 | N21: =ROUNDUP(YEARFRAC(In_COD,N$4),0)*(N$4>In_COD) -> 0 | O21: =ROUNDUP(YEARFRAC(In_COD,O$4),0)*(O$4>In_COD) -> 0 | P21: =ROUNDUP(YEARFRAC(In_COD,P$4),0)*(P$4>In_COD) -> 0 | Q21: =ROUNDUP(YEARFRAC(In_COD,Q$4),0)*(Q$4>In_COD) -> 0 | ... EO21: =ROUNDUP(YEARFRAC(In_COD,EO$4),0)*(EO$4>In_COD) -> 30
C22: Debt compounding index (E: at COD, F: rate per period) | D22: factor | E22: =SUMIF($J$4:$EO$4,In_COD,$J22:$EO22) -> 1.2198895 | F22: =In_Debt_Rate*Months_Per_Period/Months_In_Year -> 0.0125 | J22: =(1+$F22)^J$8 -> 1.0125 | K22: =(1+$F22)^K$8 -> 1.0251562 | L22: =(1+$F22)^L$8 -> 1.0379707 | M22: =(1+$F22)^M$8 -> 1.0509453 | N22: =(1+$F22)^N$8 -> 1.0640822 | O22: =(1+$F22)^O$8 -> 1.0773832 | P22: =(1+$F22)^P$8 -> 1.0908505 | Q22: =(1+$F22)^Q$8 -> 1.1044861 | ... EO22: =(1+$F22)^EO$8 -> 5.4165697
A24: x | C24: Capacity (E: committed in the bid, F: built)
C25: Wind | D25: MW | E25: =In_MVA*(1+INDEX(Dash_Overbuild,1,$A$1)) -> 60 | F25: =In_MVA*(1+In_Overbuild_Built) -> 55
C26: BESS power, share of MVA (bid, or the set's commitment) | D26: % | E26: =IF(In_BESS_Set>0,In_BESS_Set,INDEX(Dash_BESS,1,$A$1)) -> 0.2
C27: BESS power | D27: MW | E27: =$E26*In_MVA -> 10 | F27: =$E27*In_BESS_Built -> 10
C28: BESS energy | D28: MWh | E28: =$E27*INDEX(Dash_BESS_Hours,1,$A$1) -> 40
C29: Grid-bottleneck loss on built wind | D29: % | E29: =($F25-In_MVA)/$F25*In_Bottleneck_Loss -> 0.0045454545
C30: Build shortfall vs commitment (E: wind, F: BESS) | D30: % | E30: =MAX(0,1-$F25/$E25) -> 0.083333333 | F30: =(1-In_BESS_Built)*($E27>0) -> 0
C31: Memo: connection right lost pro rata (GYIK 28/30) | D31: MVA | E31: =($E30>In_Tolerance_Cap)*$E30*In_MVA*(In_Sanction_Regime=1) -> 0
A33: x | C33: Tender points (E: commitment, F: weighted points)
C34: ÖSZ-1 municipal one-off | D34: EUR k/MW | E34: =INDEX(Dash_Municipal,1,$A$1) -> 50 | F34: =INDEX(Osz1_Pts,1+SUMPRODUCT((Osz1_LB<$E34)+(Osz1_LB=$E34)*Osz1_Incl))*Osz1_W -> 20
C35: ÖSZ-2 community contribution | D35: EUR/MWh | E35: =INDEX(Dash_Community,1,$A$1) -> 3 | F35: =INDEX(Osz2_Pts,1+SUMPRODUCT((Osz2_LB<$E35)+(Osz2_LB=$E35)*Osz2_Incl))*Osz2_W -> 15
C36: ÖSZ-3 overbuild | D36: % | E36: =INDEX(Dash_Overbuild,1,$A$1) -> 0.2 | F36: =INDEX(Osz3_Pts,1+SUMPRODUCT((Osz3_LB<$E36)+(Osz3_LB=$E36)*Osz3_Incl))*Osz3_W -> 5
C37: ÖSZ-4 BESS power, share of MVA | D37: % | E37: =$E26 -> 0.2 | F37: =INDEX(Osz4_Pts,1+SUMPRODUCT((Osz4_LB<$E37)+(Osz4_LB=$E37)*Osz4_Incl))*Osz4_W*($E37>=Osz4_Min) -> 7.5
C38: ÖSZ-5 partial award | D38: flag | E38: =INDEX(Dash_Partial,1,$A$1) -> 0 | F38: =$E38*Osz5_Pts*Osz5_W -> 0
C39: ÖSZ-6 performance security multiple | D39: x | E39: =INDEX(Dash_PB_Mult,1,$A$1) -> 1 | F39: =INDEX(Osz6_Pts,1+SUMPRODUCT((Osz6_LB<$E39)+(Osz6_LB=$E39)*Osz6_Incl))*Osz6_W -> 0
C40: ÖSZ-8 shared connection | D40: flag | E40: =INDEX(Dash_Shared,1,$A$1) -> 0 | F40: =$E40*Osz8_Pts*Osz8_W -> 0
C41: ÖSZ-9 EU turbines (1 = European turbine route) | D41: flag | E41: =INDEX(Dash_EU_Turbine,1,$A$1) -> 1 | F41: =$E41*Osz9a_Pts*Osz9_W -> 12
C42: ÖSZ-9 EU transformers | D42: flag | E42: =INDEX(Dash_EU_Transformer,1,$A$1) -> 0 | F42: =$E42*Osz9b_Pts*Osz9_W -> 0
C43: Points total | D43: points | E43: =ROUND(SUM($F34:$F42),Points_Decimals) -> 59.5
C44: European turbines installed (bid and delivered) | D44: flag | E44: =$E41*In_Deliver -> 1
...

Sheet Calc_2
A1: 2 | C1: Bid number
B2: =Dashboard!$C$3&" – Calculations – "&INDEX(Bid_Labels,1,$A$1) -> Project Bana – Calculations – Chinese turbine
C3: Period start | D3: date | J3: =I$4+1 -> 46296 | K3: =J$4+1 -> 46388 | L3: =K$4+1 -> 46478 | M3: =L$4+1 -> 46569 | N3: =M$4+1 -> 46661 | O3: =N$4+1 -> 46753 | P3: =O$4+1 -> 46844 | Q3: =P$4+1 -> 46935 | ... EO3: =EN$4+1 -> 58623
C4: Period end | D4: date | I4: =In_Model_Start-1 -> 46295 | J4: =EOMONTH(J$3,Months_Per_Period-1) -> 46387 | K4: =EOMONTH(K$3,Months_Per_Period-1) -> 46477 | L4: =EOMONTH(L$3,Months_Per_Period-1) -> 46568 | M4: =EOMONTH(M$3,Months_Per_Period-1) -> 46660 | N4: =EOMONTH(N$3,Months_Per_Period-1) -> 46752 | O4: =EOMONTH(O$3,Months_Per_Period-1) -> 46843 | P4: =EOMONTH(P$3,Months_Per_Period-1) -> 46934 | Q4: =EOMONTH(Q$3,Months_Per_Period-1) -> 47026 | ... EO4: =EOMONTH(EO$3,Months_Per_Period-1) -> 58714
C5: Days in period | D5: days | J5: =J$4-J$3+1 -> 92 | K5: =K$4-K$3+1 -> 90 | L5: =L$4-L$3+1 -> 91 | M5: =M$4-M$3+1 -> 92 | N5: =N$4-N$3+1 -> 92 | O5: =O$4-O$3+1 -> 91 | P5: =P$4-P$3+1 -> 91 | Q5: =Q$4-Q$3+1 -> 92 | ... EO5: =EO$4-EO$3+1 -> 92
C6: Year fraction | D6: factor | J6: =J$5/Days_In_Year -> 0.25205479 | K6: =K$5/Days_In_Year -> 0.24657534 | L6: =L$5/Days_In_Year -> 0.24931507 | M6: =M$5/Days_In_Year -> 0.25205479 | N6: =N$5/Days_In_Year -> 0.25205479 | O6: =O$5/Days_In_Year -> 0.24931507 | P6: =P$5/Days_In_Year -> 0.24931507 | Q6: =Q$5/Days_In_Year -> 0.25205479 | ... EO6: =EO$5/Days_In_Year -> 0.25205479
C7: Year | D7: year | J7: =YEAR(J$4) -> 2026 | K7: =YEAR(K$4) -> 2027 | L7: =YEAR(L$4) -> 2027 | M7: =YEAR(M$4) -> 2027 | N7: =YEAR(N$4) -> 2027 | O7: =YEAR(O$4) -> 2028 | P7: =YEAR(P$4) -> 2028 | Q7: =YEAR(Q$4) -> 2028 | ... EO7: =YEAR(EO$4) -> 2060
C8: Period counter | D8: # | J8: =I$8+1 -> 1 | K8: =J$8+1 -> 2 | L8: =K$8+1 -> 3 | M8: =L$8+1 -> 4 | N8: =M$8+1 -> 5 | O8: =N$8+1 -> 6 | P8: =O$8+1 -> 7 | Q8: =P$8+1 -> 8 | ... EO8: =EN$8+1 -> 136
A11: x | C11: Timing and flags
C12: Construction share (NTP → COD) | D12: factor | E12: =In_NTP+1 -> 47027 | F12: =In_COD -> 47756 | I12: =SUM(J12:EO12) -> 1 | J12: =MAX(0,MIN($F12,J$4)-MAX($E12,J$3)+1)/($F12-$E12+1) -> 0 | K12: =MAX(0,MIN($F12,K$4)-MAX($E12,K$3)+1)/($F12-$E12+1) -> 0 | L12: =MAX(0,MIN($F12,L$4)-MAX($E12,L$3)+1)/($F12-$E12+1) -> 0 | M12: =MAX(0,MIN($F12,M$4)-MAX($E12,M$3)+1)/($F12-$E12+1) -> 0 | N12: =MAX(0,MIN($F12,N$4)-MAX($E12,N$3)+1)/($F12-$E12+1) -> 0 | O12: =MAX(0,MIN($F12,O$4)-MAX($E12,O$3)+1)/($F12-$E12+1) -> 0 | P12: =MAX(0,MIN($F12,P$4)-MAX($E12,P$3)+1)/($F12-$E12+1) -> 0 | Q12: =MAX(0,MIN($F12,Q$4)-MAX($E12,Q$3)+1)/($F12-$E12+1) -> 0 | ... EO12: =MAX(0,MIN($F12,EO$4)-MAX($E12,EO$3)+1)/($F12-$E12+1) -> 0
C13: Devex share (closing → NTP) | D13: factor | E13: =In_Closing+1 -> 46388 | F13: =In_NTP -> 47026 | I13: =SUM(J13:EO13) -> 1 | J13: =MAX(0,MIN($F13,J$4)-MAX($E13,J$3)+1)/($F13-$E13+1) -> 0 | K13: =MAX(0,MIN($F13,K$4)-MAX($E13,K$3)+1)/($F13-$E13+1) -> 0.14084507 | L13: =MAX(0,MIN($F13,L$4)-MAX($E13,L$3)+1)/($F13-$E13+1) -> 0.14241002 | M13: =MAX(0,MIN($F13,M$4)-MAX($E13,M$3)+1)/($F13-$E13+1) -> 0.14397496 | N13: =MAX(0,MIN($F13,N$4)-MAX($E13,N$3)+1)/($F13-$E13+1) -> 0.14397496 | O13: =MAX(0,MIN($F13,O$4)-MAX($E13,O$3)+1)/($F13-$E13+1) -> 0.14241002 | P13: =MAX(0,MIN($F13,P$4)-MAX($E13,P$3)+1)/($F13-$E13+1) -> 0.14241002 | Q13: =MAX(0,MIN($F13,Q$4)-MAX($E13,Q$3)+1)/($F13-$E13+1) -> 0.14397496 | ... EO13: =MAX(0,MIN($F13,EO$4)-MAX($E13,EO$3)+1)/($F13-$E13+1) -> 0
C14: COD | D14: flag | E14: =In_COD -> 47756 | I14: =SUM(J14:EO14) -> 1 | J14: =N(AND(J$3<=$E14,J$4>=$E14)) -> 0 | K14: =N(AND(K$3<=$E14,K$4>=$E14)) -> 0 | L14: =N(AND(L$3<=$E14,L$4>=$E14)) -> 0 | M14: =N(AND(M$3<=$E14,M$4>=$E14)) -> 0 | N14: =N(AND(N$3<=$E14,N$4>=$E14)) -> 0 | O14: =N(AND(O$3<=$E14,O$4>=$E14)) -> 0 | P14: =N(AND(P$3<=$E14,P$4>=$E14)) -> 0 | Q14: =N(AND(Q$3<=$E14,Q$4>=$E14)) -> 0 | ... EO14: =N(AND(EO$3<=$E14,EO$4>=$E14)) -> 0
C15: COD column on the timeline (buyer IRR start) | D15: # | E15: =MATCH(In_COD,$J$4:$EO$4,0) -> 16
C16: Operations | D16: flag | E16: =In_COD+1 -> 47757 | F16: =EDATE(In_COD,In_Life*Months_In_Year) -> 58714 | J16: =MAX(0,(MIN($F16,J$4)-MAX($E16,J$3)+1)/J$5) -> 0 | K16: =MAX(0,(MIN($F16,K$4)-MAX($E16,K$3)+1)/K$5) -> 0 | L16: =MAX(0,(MIN($F16,L$4)-MAX($E16,L$3)+1)/L$5) -> 0 | M16: =MAX(0,(MIN($F16,M$4)-MAX($E16,M$3)+1)/M$5) -> 0 | N16: =MAX(0,(MIN($F16,N$4)-MAX($E16,N$3)+1)/N$5) -> 0 | O16: =MAX(0,(MIN($F16,O$4)-MAX($E16,O$3)+1)/O$5) -> 0 | P16: =MAX(0,(MIN($F16,P$4)-MAX($E16,P$3)+1)/P$5) -> 0 | Q16: =MAX(0,(MIN($F16,Q$4)-MAX($E16,Q$3)+1)/Q$5) -> 0 | ... EO16: =MAX(0,(MIN($F16,EO$4)-MAX($E16,EO$3)+1)/EO$5) -> 1
C17: Land lease period (NTP → end of life) | D17: flag | E17: =In_NTP+1 -> 47027 | F17: =EDATE(In_COD,In_Life*Months_In_Year) -> 58714 | J17: =MAX(0,(MIN($F17,J$4)-MAX($E17,J$3)+1)/J$5) -> 0 | K17: =MAX(0,(MIN($F17,K$4)-MAX($E17,K$3)+1)/K$5) -> 0 | L17: =MAX(0,(MIN($F17,L$4)-MAX($E17,L$3)+1)/L$5) -> 0 | M17: =MAX(0,(MIN($F17,M$4)-MAX($E17,M$3)+1)/M$5) -> 0 | N17: =MAX(0,(MIN($F17,N$4)-MAX($E17,N$3)+1)/N$5) -> 0 | O17: =MAX(0,(MIN($F17,O$4)-MAX($E17,O$3)+1)/O$5) -> 0 | P17: =MAX(0,(MIN($F17,P$4)-MAX($E17,P$3)+1)/P$5) -> 0 | Q17: =MAX(0,(MIN($F17,Q$4)-MAX($E17,Q$3)+1)/Q$5) -> 0 | ... EO17: =MAX(0,(MIN($F17,EO$4)-MAX($E17,EO$3)+1)/EO$5) -> 1
C18: Debt repayment period | D18: flag | E18: =In_COD+1 -> 47757 | F18: =EDATE(In_COD,In_Debt_Tenor*Months_In_Year) -> 53235 | J18: =MAX(0,(MIN($F18,J$4)-MAX($E18,J$3)+1)/J$5) -> 0 | K18: =MAX(0,(MIN($F18,K$4)-MAX($E18,K$3)+1)/K$5) -> 0 | L18: =MAX(0,(MIN($F18,L$4)-MAX($E18,L$3)+1)/L$5) -> 0 | M18: =MAX(0,(MIN($F18,M$4)-MAX($E18,M$3)+1)/M$5) -> 0 | N18: =MAX(0,(MIN($F18,N$4)-MAX($E18,N$3)+1)/N$5) -> 0 | O18: =MAX(0,(MIN($F18,O$4)-MAX($E18,O$3)+1)/O$5) -> 0 | P18: =MAX(0,(MIN($F18,P$4)-MAX($E18,P$3)+1)/P$5) -> 0 | Q18: =MAX(0,(MIN($F18,Q$4)-MAX($E18,Q$3)+1)/Q$5) -> 0 | ... EO18: =MAX(0,(MIN($F18,EO$4)-MAX($E18,EO$3)+1)/EO$5) -> 0
C19: Last debt repayment | D19: flag | E19: =EDATE(In_COD,In_Debt_Tenor*Months_In_Year) -> 53235 | I19: =SUM(J19:EO19) -> 1 | J19: =N(AND(J$3<=$E19,J$4>=$E19)) -> 0 | K19: =N(AND(K$3<=$E19,K$4>=$E19)) -> 0 | L19: =N(AND(L$3<=$E19,L$4>=$E19)) -> 0 | M19: =N(AND(M$3<=$E19,M$4>=$E19)) -> 0 | N19: =N(AND(N$3<=$E19,N$4>=$E19)) -> 0 | O19: =N(AND(O$3<=$E19,O$4>=$E19)) -> 0 | P19: =N(AND(P$3<=$E19,P$4>=$E19)) -> 0 | Q19: =N(AND(Q$3<=$E19,Q$4>=$E19)) -> 0 | ... EO19: =N(AND(EO$3<=$E19,EO$4>=$E19)) -> 0
C20: Tax depreciation share | D20: factor | E20: =In_COD+1 -> 47757 | F20: =EDATE(In_COD,In_Dep_Years*Months_In_Year) -> 55061 | I20: =SUM(J20:EO20) -> 1 | J20: =MAX(0,MIN($F20,J$4)-MAX($E20,J$3)+1)/($F20-$E20+1) -> 0 | K20: =MAX(0,MIN($F20,K$4)-MAX($E20,K$3)+1)/($F20-$E20+1) -> 0 | L20: =MAX(0,MIN($F20,L$4)-MAX($E20,L$3)+1)/($F20-$E20+1) -> 0 | M20: =MAX(0,MIN($F20,M$4)-MAX($E20,M$3)+1)/($F20-$E20+1) -> 0 | N20: =MAX(0,MIN($F20,N$4)-MAX($E20,N$3)+1)/($F20-$E20+1) -> 0 | O20: =MAX(0,MIN($F20,O$4)-MAX($E20,O$3)+1)/($F20-$E20+1) -> 0 | P20: =MAX(0,MIN($F20,P$4)-MAX($E20,P$3)+1)/($F20-$E20+1) -> 0 | Q20: =MAX(0,MIN($F20,Q$4)-MAX($E20,Q$3)+1)/($F20-$E20+1) -> 0 | ... EO20: =MAX(0,MIN($F20,EO$4)-MAX($E20,EO$3)+1)/($F20-$E20+1) -> 0
C21: Operating year | D21: # | J21: =ROUNDUP(YEARFRAC(In_COD,J$4),0)*(J$4>In_COD) -> 0 | K21: =ROUNDUP(YEARFRAC(In_COD,K$4),0)*(K$4>In_COD) -> 0 | L21: =ROUNDUP(YEARFRAC(In_COD,L$4),0)*(L$4>In_COD) -> 0 | M21: =ROUNDUP(YEARFRAC(In_COD,M$4),0)*(M$4>In_COD) -> 0 | N21: =ROUNDUP(YEARFRAC(In_COD,N$4),0)*(N$4>In_COD) -> 0 | O21: =ROUNDUP(YEARFRAC(In_COD,O$4),0)*(O$4>In_COD) -> 0 | P21: =ROUNDUP(YEARFRAC(In_COD,P$4),0)*(P$4>In_COD) -> 0 | Q21: =ROUNDUP(YEARFRAC(In_COD,Q$4),0)*(Q$4>In_COD) -> 0 | ... EO21: =ROUNDUP(YEARFRAC(In_COD,EO$4),0)*(EO$4>In_COD) -> 30
C22: Debt compounding index (E: at COD, F: rate per period) | D22: factor | E22: =SUMIF($J$4:$EO$4,In_COD,$J22:$EO22) -> 1.2198895 | F22: =In_Debt_Rate*Months_Per_Period/Months_In_Year -> 0.0125 | J22: =(1+$F22)^J$8 -> 1.0125 | K22: =(1+$F22)^K$8 -> 1.0251562 | L22: =(1+$F22)^L$8 -> 1.0379707 | M22: =(1+$F22)^M$8 -> 1.0509453 | N22: =(1+$F22)^N$8 -> 1.0640822 | O22: =(1+$F22)^O$8 -> 1.0773832 | P22: =(1+$F22)^P$8 -> 1.0908505 | Q22: =(1+$F22)^Q$8 -> 1.1044861 | ... EO22: =(1+$F22)^EO$8 -> 5.4165697
A24: x | C24: Capacity (E: committed in the bid, F: built)
C25: Wind | D25: MW | E25: =In_MVA*(1+INDEX(Dash_Overbuild,1,$A$1)) -> 60 | F25: =In_MVA*(1+In_Overbuild_Built) -> 55
C26: BESS power, share of MVA (bid, or the set's commitment) | D26: % | E26: =IF(In_BESS_Set>0,In_BESS_Set,INDEX(Dash_BESS,1,$A$1)) -> 0.2
C27: BESS power | D27: MW | E27: =$E26*In_MVA -> 10 | F27: =$E27*In_BESS_Built -> 10
C28: BESS energy | D28: MWh | E28: =$E27*INDEX(Dash_BESS_Hours,1,$A$1) -> 40
C29: Grid-bottleneck loss on built wind | D29: % | E29: =($F25-In_MVA)/$F25*In_Bottleneck_Loss -> 0.0045454545
C30: Build shortfall vs commitment (E: wind, F: BESS) | D30: % | E30: =MAX(0,1-$F25/$E25) -> 0.083333333 | F30: =(1-In_BESS_Built)*($E27>0) -> 0
C31: Memo: connection right lost pro rata (GYIK 28/30) | D31: MVA | E31: =($E30>In_Tolerance_Cap)*$E30*In_MVA*(In_Sanction_Regime=1) -> 0
A33: x | C33: Tender points (E: commitment, F: weighted points)
C34: ÖSZ-1 municipal one-off | D34: EUR k/MW | E34: =INDEX(Dash_Municipal,1,$A$1) -> 50 | F34: =INDEX(Osz1_Pts,1+SUMPRODUCT((Osz1_LB<$E34)+(Osz1_LB=$E34)*Osz1_Incl))*Osz1_W -> 20
C35: ÖSZ-2 community contribution | D35: EUR/MWh | E35: =INDEX(Dash_Community,1,$A$1) -> 3 | F35: =INDEX(Osz2_Pts,1+SUMPRODUCT((Osz2_LB<$E35)+(Osz2_LB=$E35)*Osz2_Incl))*Osz2_W -> 15
C36: ÖSZ-3 overbuild | D36: % | E36: =INDEX(Dash_Overbuild,1,$A$1) -> 0.2 | F36: =INDEX(Osz3_Pts,1+SUMPRODUCT((Osz3_LB<$E36)+(Osz3_LB=$E36)*Osz3_Incl))*Osz3_W -> 5
C37: ÖSZ-4 BESS power, share of MVA | D37: % | E37: =$E26 -> 0.2 | F37: =INDEX(Osz4_Pts,1+SUMPRODUCT((Osz4_LB<$E37)+(Osz4_LB=$E37)*Osz4_Incl))*Osz4_W*($E37>=Osz4_Min) -> 7.5
C38: ÖSZ-5 partial award | D38: flag | E38: =INDEX(Dash_Partial,1,$A$1) -> 0 | F38: =$E38*Osz5_Pts*Osz5_W -> 0
C39: ÖSZ-6 performance security multiple | D39: x | E39: =INDEX(Dash_PB_Mult,1,$A$1) -> 1 | F39: =INDEX(Osz6_Pts,1+SUMPRODUCT((Osz6_LB<$E39)+(Osz6_LB=$E39)*Osz6_Incl))*Osz6_W -> 0
C40: ÖSZ-8 shared connection | D40: flag | E40: =INDEX(Dash_Shared,1,$A$1) -> 0 | F40: =$E40*Osz8_Pts*Osz8_W -> 0
C41: ÖSZ-9 EU turbines (1 = European turbine route) | D41: flag | E41: =INDEX(Dash_EU_Turbine,1,$A$1) -> 0 | F41: =$E41*Osz9a_Pts*Osz9_W -> 0
C42: ÖSZ-9 EU transformers | D42: flag | E42: =INDEX(Dash_EU_Transformer,1,$A$1) -> 0 | F42: =$E42*Osz9b_Pts*Osz9_W -> 0
C43: Points total | D43: points | E43: =ROUND(SUM($F34:$F42),Points_Decimals) -> 47.5
C44: European turbines installed (bid and delivered) | D44: flag | E44: =$E41*In_Deliver -> 0
...

Sheet Checks
B2: =Dashboard!$C$3&" – Checks" -> Project Bana – Checks
C4: Period end | J4: =Calc_1!J$4 -> 46387 | K4: =Calc_1!K$4 -> 46477 | L4: =Calc_1!L$4 -> 46568 | M4: =Calc_1!M$4 -> 46660 | N4: =Calc_1!N$4 -> 46752 | O4: =Calc_1!O$4 -> 46843 | P4: =Calc_1!P$4 -> 46934 | Q4: =Calc_1!Q$4 -> 47026 | ... EO4: =Calc_1!EO$4 -> 58714
E9: Status | F9: Fails
A11: x | C11: Checks (0 = OK)
C12: Solver Tax_1: delta = 0 | D12: flag | E12: =IF(F12=0,"OK","CHECK") -> OK | F12: =N(Tax_1_Delta>Tolerance) -> 0
C13: Solver Tax_2: delta = 0 | D13: flag | E13: =IF(F13=0,"OK","CHECK") -> OK | F13: =N(Tax_2_Delta>Tolerance) -> 0
C14: Levers within the tender rules – Calc_1 | D14: flag | E14: =IF(F14=0,"OK","CHECK") -> OK | F14: =N(Calc_1!$E45+Calc_1!$F45>0) -> 0
C15: Levers within the tender rules – Calc_2 | D15: flag | E15: =IF(F15=0,"OK","CHECK") -> OK | F15: =N(Calc_2!$E45+Calc_2!$F45>0) -> 0
C16: COD falls on a quarter end – Calc_1 | D16: flag | E16: =IF(F16=0,"OK","CHECK") -> OK | F16: =N(COUNTIF(Calc_1!$J$4:$EO$4,In_COD)=0) -> 0
C17: COD falls on a quarter end – Calc_2 | D17: flag | E17: =IF(F17=0,"OK","CHECK") -> OK | F17: =N(COUNTIF(Calc_2!$J$4:$EO$4,In_COD)=0) -> 0
C18: Debt at COD within the DSCR capacity – Calc_1 | D18: flag | E18: =IF(F18=0,"OK","CHECK") -> OK | F18: =N(Calc_1!$F90>1+Tolerance) -> 0
C19: Debt at COD within the DSCR capacity – Calc_2 | D19: flag | E19: =IF(F19=0,"OK","CHECK") -> OK | F19: =N(Calc_2!$F90>1+Tolerance) -> 0
C20: Debt repaid by the end of the tenor – Calc_1 | D20: flag | E20: =IF(F20=0,"OK","CHECK") -> OK | F20: =SUM(J20:EO20) -> 0 | J20: =N((Calc_1!J$4>=Calc_1!$F18)*ABS(Calc_1!J103)>Tolerance) -> 0 | K20: =N((Calc_1!K$4>=Calc_1!$F18)*ABS(Calc_1!K103)>Tolerance) -> 0 | L20: =N((Calc_1!L$4>=Calc_1!$F18)*ABS(Calc_1!L103)>Tolerance) -> 0 | M20: =N((Calc_1!M$4>=Calc_1!$F18)*ABS(Calc_1!M103)>Tolerance) -> 0 | N20: =N((Calc_1!N$4>=Calc_1!$F18)*ABS(Calc_1!N103)>Tolerance) -> 0 | O20: =N((Calc_1!O$4>=Calc_1!$F18)*ABS(Calc_1!O103)>Tolerance) -> 0 | P20: =N((Calc_1!P$4>=Calc_1!$F18)*ABS(Calc_1!P103)>Tolerance) -> 0 | Q20: =N((Calc_1!Q$4>=Calc_1!$F18)*ABS(Calc_1!Q103)>Tolerance) -> 0 | ... EO20: =N((Calc_1!EO$4>=Calc_1!$F18)*ABS(Calc_1!EO103)>Tolerance) -> 0
C21: Debt repaid by the end of the tenor – Calc_2 | D21: flag | E21: =IF(F21=0,"OK","CHECK") -> OK | F21: =SUM(J21:EO21) -> 0 | J21: =N((Calc_2!J$4>=Calc_2!$F18)*ABS(Calc_2!J103)>Tolerance) -> 0 | K21: =N((Calc_2!K$4>=Calc_2!$F18)*ABS(Calc_2!K103)>Tolerance) -> 0 | L21: =N((Calc_2!L$4>=Calc_2!$F18)*ABS(Calc_2!L103)>Tolerance) -> 0 | M21: =N((Calc_2!M$4>=Calc_2!$F18)*ABS(Calc_2!M103)>Tolerance) -> 0 | N21: =N((Calc_2!N$4>=Calc_2!$F18)*ABS(Calc_2!N103)>Tolerance) -> 0 | O21: =N((Calc_2!O$4>=Calc_2!$F18)*ABS(Calc_2!O103)>Tolerance) -> 0 | P21: =N((Calc_2!P$4>=Calc_2!$F18)*ABS(Calc_2!P103)>Tolerance) -> 0 | Q21: =N((Calc_2!Q$4>=Calc_2!$F18)*ABS(Calc_2!Q103)>Tolerance) -> 0 | ... EO21: =N((Calc_2!EO$4>=Calc_2!$F18)*ABS(Calc_2!EO103)>Tolerance) -> 0
C22: DSCR not below target – Calc_1 | D22: flag | E22: =IF(F22=0,"OK","CHECK") -> OK | F22: =N(Calc_1!$E107<In_DSCR-Tolerance) -> 0
C23: DSCR not below target – Calc_2 | D23: flag | E23: =IF(F23=0,"OK","CHECK") -> OK | F23: =N(Calc_2!$E107<In_DSCR-Tolerance) -> 0
C24: Sources = uses to COD – Calc_1 | D24: flag | E24: =IF(F24=0,"OK","CHECK") -> OK | F24: =N(ABS(Calc_1!$E128+Calc_1!$I135-Calc_1!$E103)>Tolerance) -> 0
C25: Sources = uses to COD – Calc_2 | D25: flag | E25: =IF(F25=0,"OK","CHECK") -> OK | F25: =N(ABS(Calc_2!$E128+Calc_2!$I135-Calc_2!$E103)>Tolerance) -> 0
C26: XIRR returned a number on every route – Calc_1 | D26: flag | E26: =IF(F26=0,"OK","CHECK") -> OK | F26: =N(ISERROR(Calc_1!$E140))+N(ISERROR(Calc_1!$E153))+N(ISERROR(Calc_1!$E151))+N(ISERROR(Calc_1!$E147)) -> 0
C27: XIRR returned a number on every route – Calc_2 | D27: flag | E27: =IF(F27=0,"OK","CHECK") -> OK | F27: =N(ISERROR(Calc_2!$E140))+N(ISERROR(Calc_2!$E153))+N(ISERROR(Calc_2!$E151))+N(ISERROR(Calc_2!$E147)) -> 0
C28: Stored results = live case | D28: flag | E28: =IF(F28=0,"OK","CHECK") -> OK | F28: =--(SUMPRODUCT(ABS(Stored_Results-Live_Results)*(Scenario_Names=Scenario_Name))>Tolerance) -> 0
C30: Checks excluding stored = live | F30: =SUMPRODUCT(ABS(F12:F27)) -> 0
C32: Master check | E32: =IF(F32=0,"OK","CHECK") -> OK | F32: =SUMPRODUCT(ABS(F12:F28)) -> 0
C34: ***END***
