Workbook

Sheet Dashboard
B2: =C3&" – Dashboard" -> Project Bora – Dashboard
C3: Project Bora
C4: Bid strategy – BORA 1 / BORA 2 (2 x 100 MVA, Szombathely)
C5: Version | E5: v2
C6: Model date | E6: 46307
C7: Key-assumption set | E7: =Scenario_Name -> Base
C8: Master check | E8: =IF(Master_Check=0,"OK","CHECK") -> OK
C9: Item | D9: Unit | E9: BORA 1 | F9: BORA 2 | T9: Key assumptions | U9: Unit | V9: Live
A11: x | C11: The bid: commitments, points and impact vs the zero bid (macro) | E11: BORA 1 | F11: BORA 2 | H11: Offerable range | I11: Points B1 | J11: Points B2 | K11: Δ RtB profit €m B1 | L11: Δ RtB profit €m B2 | M11: Δ COD IRR B1 | N11: Δ COD IRR B2 | O11: Δ HTM IRR B1 | P11: Δ HTM IRR B2 | Q11: Δ securities €m B1 | R11: Δ securities €m B2 | T11: Key-assumption set
C12: Municipal one-off (ÖSZ-1) | D12: EUR k/MW | E12: 50 | F12: 50 | H12: 0 or 10–50 | I12: =Calc_1!$F$30 -> 20 | J12: =Calc_2!$F$30 -> 20 | K12: 0 | L12: 0 | M12: -0.011627184 | N12: -0.011627184 | O12: -0.0042666176 | P12: -0.0042666176 | Q12: 0 | R12: 0 | T12: Key-assumption set | U12: text | V12: Base
C13: Community contribution (ÖSZ-2) | D13: EUR/MWh | E13: 3 | F13: 2.01 | H13: 0 or 2–3 | I13: =Calc_1!$F$31 -> 15 | J13: =Calc_2!$F$31 -> 0.75 | K13: 0 | L13: 0 | M13: -0.025663154 | N13: -0.017097995 | O13: -0.0060842806 | P13: -0.0040713948 | Q13: 0 | R13: 0
C14: Overbuild (ÖSZ-3) | D14: % | E14: 0.51 | F14: 0.4 | H14: ≥ 0 % | I14: =Calc_1!$F$32 -> 10 | J14: =Calc_2!$F$32 -> 9 | K14: -0.47201652 | L14: -0.37020904 | M14: -0.011488431 | N14: -0.0090180271 | O14: -0.0024539818 | P14: -0.001931658 | Q14: 1.4182192 | R14: 1.1123288 | T14: Key assumptions (live)
C15: BESS power, share of MVA (ÖSZ-4) | D15: % | E15: 0.51 | F15: 0.4 | H15: ≤ wind MW | I15: =Calc_1!$F$33 -> 15 | J15: =Calc_2!$F$33 -> 13.5 | K15: -0.37074274 | L15: -0.29077862 | M15: -0.06507612 | N15: -0.051092496 | O15: -0.012392661 | P15: -0.0098626548 | Q15: 2.7945205 | R15: 2.1917808 | T15: Chinese turbines (0 EU, 1 CN) | U15: flag | V15: =In_CN_Turbine -> 0
C16: BESS duration | D16: h | E16: 4 | F16: 4 | H16: ≥ 4 h | T16: RtB price | U16: EUR k/MVA | V16: =In_RtB_Premium -> 150
C17: Performance security multiple (ÖSZ-6) | D17: x | E17: 1 | F17: 1 | H17: ≥ 1.0 | I17: =Calc_1!$F$35 -> 0 | J17: =Calc_2!$F$35 -> 0 | K17: 0 | L17: 0 | M17: 0 | N17: 0 | O17: 0 | P17: 0 | Q17: 0 | R17: 0 | T17: COD price, EU | U17: EUR k/MW | V17: =In_COD_Price -> 2450
C18: Partial award accepted (ÖSZ-5) | D18: flag | E18: 1 | F18: 1 | H18: 0 / 1 | I18: =Calc_1!$F$34 -> 5 | J18: =Calc_2!$F$34 -> 5 | K18: 0 | L18: 0 | M18: 0 | N18: 0 | O18: 0 | P18: 0 | Q18: 0 | R18: 0 | T18: Turbine price, EU | U18: EUR k/MW | V18: =In_Turbine -> 600
C19: Brownfield site (ÖSZ-7) | D19: flag | E19: 0 | F19: 0 | H19: 0 / 1 | I19: =Calc_1!$F$36 -> 0 | J19: =Calc_2!$F$36 -> 0 | K19: 0 | L19: 0 | M19: 0 | N19: 0 | O19: 0 | P19: 0 | Q19: 0 | R19: 0 | T19: PPA price at COD | U19: EUR/MWh | V19: =In_PPA_Price -> 90
C20: Shared connection (ÖSZ-8) | D20: flag | E20: 1 | F20: 1 | H20: 0 / 1 | I20: =Calc_1!$F$37 -> 5 | J20: =Calc_2!$F$37 -> 5 | K20: 0 | L20: 0 | M20: 0 | N20: 0 | O20: 0 | P20: 0 | Q20: 0 | R20: 0 | T20: Gearing, EU | U20: % | V20: =In_Gearing -> 0.6
C21: EU turbines ≥ 80 % (ÖSZ-9) | D21: flag | E21: 1 | F21: 1 | H21: 0 / 1 | I21: =Calc_1!$F$38 -> 12 | J21: =Calc_2!$F$38 -> 12 | K21: 0 | L21: 0 | M21: 0 | N21: 0 | O21: 0 | P21: 0 | Q21: 0 | R21: 0 | T21: Debt rate | U21: % | V21: =In_Debt_Rate -> 0.05
C22: EU transformers ≥ 80 % (ÖSZ-9) | D22: flag | E22: 1 | F22: 1 | H22: 0 / 1 | I22: =Calc_1!$F$39 -> 3 | J22: =Calc_2!$F$39 -> 3 | K22: 0 | L22: 0 | M22: 0 | N22: 0 | O22: 0 | P22: 0 | Q22: 0 | R22: 0 | T22: Discount rate | U22: % | V22: =In_Discount_Rate -> 0.08
T23: COD | U23: date | V23: =In_COD -> 48121
A24: x | C24: Returns at a glance | E24: BORA 1 | F24: BORA 2 | H24: Zero bid | I24: Δ B1 | J24: Δ B2 | T24: FX | U24: HUF/EUR | V24: =In_FX -> 365
C25: Points, live turbine route | D25: points | E25: =Calc_1!$E41 -> 85 | F25: =Calc_2!$E41 -> 68.25 | H25: 0 | T25: Interest freeze on | U25: flag | V25: =In_Freeze_On -> 1
C26: FEP profit – RtB route | D26: EUR m | E26: =Calc_1!$I151/Thousand -> 6.5467587 | F26: =Calc_2!$I151/Thousand -> 6.7285303 | H26: 7.389518 | I26: -0.84275926 | J26: -0.66098766 | T26: Overbuild built | U26: flag | V26: =In_Overbuild_Built -> 0
C27: FEP IRR – RtB route | D27: % | E27: =Calc_1!$E152 -> 0.22151076 | F27: =Calc_2!$E152 -> 0.22914856 | H27: 0.25782628 | I27: -0.036315523 | J27: -0.028677728 | T27: BESS built | U27: flag | V27: =In_BESS_Built -> 1
C28: FEP IRR – sale at COD | D28: % | E28: =Calc_1!$E169 -> 0.37845437 | F28: =Calc_2!$E169 -> 0.40458152 | H28: 0.49563542 | I28: -0.11718105 | J28: -0.091053893 | T28: Sanction regime (1 pro rata, 2 full) | U28: flag | V28: =In_Sanction_Regime -> 1
C29: FEP NPV – sale at COD | D29: EUR m | E29: =Calc_1!$E171/Thousand -> 30.754863 | F29: =Calc_2!$E171/Thousand -> 33.641147 | H29: 44.610552 | I29: -13.855689 | J29: -10.969406 | T29: ÖSZ-4 basis (0 MVA, 1 wind) | U29: flag | V29: =In_OSZ4_Basis -> 0
C30: FEP IRR – hold to maturity | D30: % | E30: =Calc_1!$E184 -> 0.094907301 | F30: =Calc_2!$E184 -> 0.099496579 | H30: 0.11865423 | I30: -0.023746933 | J30: -0.019157655
C31: FEP NPV – hold to maturity | D31: EUR m | E31: =Calc_1!$E186/Thousand -> 13.363165 | F31: =Calc_2!$E186/Thousand -> 17.199101 | H31: 31.424829 | I31: -18.061664 | J31: -14.225728
C32: Total commitment | D32: EUR m | E32: =Calc_1!$E177/Thousand -> 171.21379 | F32: =Calc_2!$E177/Thousand -> 167.28901 | H32: 147.79968 | I32: 23.414104 | J32: 19.489327
A34: x | C34: Commitment overview (total in Returns at a glance) | E34: BORA 1 | F34: BORA 2
C35: Securities: cash posted and guarantee outstanding | D35: EUR m | E35: =Calc_1!$E173/Thousand -> 8.2346575 | F35: =Calc_2!$E173/Thousand -> 7.3260274
C36: Devex, land, signing and DD | D36: EUR m | E36: =Calc_1!$E174/Thousand -> 3.5196245 | F36: =Calc_2!$E174/Thousand -> 3.5196245
C37: Construction capex incl. connection fees, municipal, pre-COD lease | D37: EUR m | E37: =Calc_1!$E175/Thousand -> 150.91288 | F37: =Calc_2!$E175/Thousand -> 148.27288
C38: Financing: IDC, debt fees, guarantee fees | D38: EUR m | E38: =Calc_1!$E176/Thousand -> 8.5466259 | F38: =Calc_2!$E176/Thousand -> 8.1704781
C39: Memo, not in the total: PB call if overbuild not built | D39: EUR m | E39: =Calc_1!$E178/Thousand -> 1.4182192 | F39: =Calc_2!$E178/Thousand -> 1.1123288
C40: Memo, not in the total: full PB call | D40: EUR m | E40: =Calc_1!$F178/Thousand -> 6.9935616 | F40: =Calc_2!$F178/Thousand -> 6.0849315
A42: x | C42: Points and validity | E42: BORA 1 | F42: BORA 2
C43: Wind committed | D43: MW | E43: =Calc_1!$E24 -> 151 | F43: =Calc_2!$E24 -> 140
C44: Wind built | D44: MW | E44: =Calc_1!$F24 -> 100 | F44: =Calc_2!$F24 -> 100
...

Sheet Inputs
B2: =Dashboard!$C$3&" – Inputs and scenarios" -> Project Bora – Inputs and scenarios
B4: Scenario selected | D4: Set on the Dashboard | F4: =Scenario_Name -> Base
B5: Scenario number | F5: =MATCH(Scenario_Name,Scenario_Names,0) -> 1
B7: Input | C7: Unit | D7: Source / note | F7: Live | H7: Base | I7: Overbuild built | J7: Full PB call | K7: Freeze off | L7: Low premium | M7: ÖSZ-4 on wind
A10: x | C10: Constants
B11: Thousand | C11: # | D11: Scale | F11: 1000
B12: Million | C12: # | D12: Scale | F12: 1000000
B13: Days In Year | C13: days | D13: Day count for year fractions and XIRR | F13: 365
B14: Months In Year | C14: months | F14: 12
B15: Months Per Period | C15: months | D15: Timeline periodicity (quarterly) | F15: 3
B16: Tolerance | C16: # | D16: Check and solver tolerance | F16: 1e-06
A18: x | C18: Timing
B19: Model start date | C19: date | D19: Timeline start | F19: =IF(INDEX($H19:$O19,1,Scenario_Selected)="",$H19,INDEX($H19:$O19,1,Scenario_Selected)) -> 46204 | H19: 46204
B20: Signing fee and DD paid | C20: date | D20: Old engine Inputs E27 | F20: =IF(INDEX($H20:$O20,1,Scenario_Selected)="",$H20,INDEX($H20:$O20,1,Scenario_Selected)) -> 46234 | H20: 46234
B21: Signing (DSA accrual start) | C21: date | D21: Old engine Inputs E70 | F21: =IF(INDEX($H21:$O21,1,Scenario_Selected)="",$H21,INDEX($H21:$O21,1,Scenario_Selected)) -> 46321 | H21: 46321
B22: Devex contingency paid | C22: date | D22: Old engine Devex_FEP row 38 | F22: =IF(INDEX($H22:$O22,1,Scenario_Selected)="",$H22,INDEX($H22:$O22,1,Scenario_Selected)) -> 47118 | H22: 47118
B23: Notice to proceed | C23: date | D23: Old engine Inputs E154 | F23: =IF(INDEX($H23:$O23,1,Scenario_Selected)="",$H23,INDEX($H23:$O23,1,Scenario_Selected)) -> 47391 | H23: 47391
B24: Commercial operation date | C24: date | D24: Bora!N16 | F24: =IF(INDEX($H24:$O24,1,Scenario_Selected)="",$H24,INDEX($H24:$O24,1,Scenario_Selected)) -> 48121 | H24: 48121
B25: Operating life | C25: years | D25: Old engine Inputs E157 | F25: =IF(INDEX($H25:$O25,1,Scenario_Selected)="",$H25,INDEX($H25:$O25,1,Scenario_Selected)) -> 30 | H25: 30
B26: Interest freeze start | C26: date | D26: Old engine Inputs E64 | F26: =IF(INDEX($H26:$O26,1,Scenario_Selected)="",$H26,INDEX($H26:$O26,1,Scenario_Selected)) -> 47299 | H26: 47299
B27: Interest freeze end (accrual resumes) | C27: date | D27: Old engine Inputs E73 | F27: =IF(INDEX($H27:$O27,1,Scenario_Selected)="",$H27,INDEX($H27:$O27,1,Scenario_Selected)) -> 47484 | H27: 47484
B28: Interest freeze on (1 = yes) | C28: flag | D28: User 09-Oct-26 (Inputs E64) | F28: =IF(INDEX($H28:$O28,1,Scenario_Selected)="",$H28,INDEX($H28:$O28,1,Scenario_Selected)) -> 1 | H28: 1 | K28: 0
B29: Sanction paid after COD | C29: months | D29: Kiírás XIII.17; old Tender E31 | F29: =IF(INDEX($H29:$O29,1,Scenario_Selected)="",$H29,INDEX($H29:$O29,1,Scenario_Selected)) -> 6 | H29: 6
A31: x | C31: Money, tax and JV
B32: FX rate | C32: HUF/EUR | D32: Old engine Inputs E11 | F32: =IF(INDEX($H32:$O32,1,Scenario_Selected)="",$H32,INDEX($H32:$O32,1,Scenario_Selected)) -> 365 | H32: 365
B33: Corporate income tax | C33: % | D33: Old engine Inputs E12 | F33: =IF(INDEX($H33:$O33,1,Scenario_Selected)="",$H33,INDEX($H33:$O33,1,Scenario_Selected)) -> 0.09 | H33: 0.09
B34: Signing fee to current owners | C34: EUR k | D34: Old engine Inputs E24 | F34: =IF(INDEX($H34:$O34,1,Scenario_Selected)="",$H34,INDEX($H34:$O34,1,Scenario_Selected)) -> 250 | H34: 250
B35: Transaction and DD costs | C35: EUR k | D35: Old engine Inputs E25 | F35: =IF(INDEX($H35:$O35,1,Scenario_Selected)="",$H35,INDEX($H35:$O35,1,Scenario_Selected)) -> 150 | H35: 150
B36: Sale costs at exit | C36: EUR k | D36: Old engine Inputs E26 | F36: =IF(INDEX($H36:$O36,1,Scenario_Selected)="",$H36,INDEX($H36:$O36,1,Scenario_Selected)) -> 500 | H36: 500
B37: FEP share of distributable proceeds | C37: % | D37: Old engine Inputs E33 | F37: =IF(INDEX($H37:$O37,1,Scenario_Selected)="",$H37,INDEX($H37:$O37,1,Scenario_Selected)) -> 0.7 | H37: 0.7
B38: Developer success fee (DSA) per year | C38: EUR k/MW | D38: Old engine Inputs E36 | F38: =IF(INDEX($H38:$O38,1,Scenario_Selected)="",$H38,INDEX($H38:$O38,1,Scenario_Selected)) -> 2.5 | H38: 2.5
B39: DSA cap | C39: EUR k/MW | D39: Old engine Inputs E37 | F39: =IF(INDEX($H39:$O39,1,Scenario_Selected)="",$H39,INDEX($H39:$O39,1,Scenario_Selected)) -> 10 | H39: 10
A41: x | C41: Tender
B42: Points rounded to decimals | C42: # | D42: Kiírás X.1 b | F42: 2
B43: Net connection capacity per bid | C43: MVA | D43: Old engine Calc E74 | F43: =IF(INDEX($H43:$O43,1,Scenario_Selected)="",$H43,INDEX($H43:$O43,1,Scenario_Selected)) -> 100 | H43: 100
B44: Cap per group per node | C44: MVA | D44: Kiírás V.2 | F44: =IF(INDEX($H44:$O44,1,Scenario_Selected)="",$H44,INDEX($H44:$O44,1,Scenario_Selected)) -> 100 | H44: 100
B45: Build shortfall tolerated without sanction | C45: % | D45: GYIK 28, 30 | F45: =IF(INDEX($H45:$O45,1,Scenario_Selected)="",$H45,INDEX($H45:$O45,1,Scenario_Selected)) -> 0.1 | H45: 0.1
B46: Minimum BESS duration | C46: h | D46: Kiírás Annex 8; GYIK Q5 | F46: =IF(INDEX($H46:$O46,1,Scenario_Selected)="",$H46,INDEX($H46:$O46,1,Scenario_Selected)) -> 4 | H46: 4
B47: ÖSZ-4 basis (0 = net MVA, 1 = committed wind) | C47: flag | D47: User 12-Oct-26; GYIK Q20 = 1 | F47: =IF(INDEX($H47:$O47,1,Scenario_Selected)="",$H47,INDEX($H47:$O47,1,Scenario_Selected)) -> 0 | H47: 0 | M47: 1
A49: x | C49: Deposits and fees (timeline order)
...

Sheet Curves
B2: =Dashboard!$C$3&" – Time-series inputs" -> Project Bora – Time-series inputs
A5: x | C5: Tender scoring bands | E5: Kiírás Annex 3-4; old engine Tender D93:F161
E6: Weight / min | F6: Max | J6: Bands →
C7: ÖSZ-1 municipal one-off – lower bound | D7: EUR k/MW | E7: 10 | F7: 50 | J7: 10 | K7: 15 | L7: 20 | M7: 25 | N7: 30 | O7: 35 | P7: 40 | Q7: 45 | R7: 50
C8: ÖSZ-1 municipal one-off – lower bound included | D8: flag | J8: 0 | K8: 0 | L8: 0 | M8: 0 | N8: 0 | O8: 0 | P8: 0 | Q8: 0 | R8: 1
C9: ÖSZ-1 municipal one-off – inner points (below, bands) | D9: points | E9: 0.2 | J9: 0 | K9: 10 | L9: 20 | M9: 30 | N9: 40 | O9: 55 | P9: 70 | Q9: 80 | R9: 90 | S9: 100
C10: ÖSZ-2 community contribution – lower bound | D10: EUR/MWh | E10: 2 | F10: 3 | J10: 2 | K10: 2.1 | L10: 2.2 | M10: 2.3 | N10: 2.4 | O10: 2.5 | P10: 2.6 | Q10: 2.7 | R10: 2.8 | S10: 2.9 | T10: 3
C11: ÖSZ-2 community contribution – lower bound included | D11: flag | J11: 0 | K11: 0 | L11: 0 | M11: 0 | N11: 0 | O11: 0 | P11: 0 | Q11: 0 | R11: 0 | S11: 0 | T11: 1
C12: ÖSZ-2 community contribution – inner points (below, bands) | D12: points | E12: 0.15 | J12: 0 | K12: 5 | L12: 10 | M12: 20 | N12: 30 | O12: 40 | P12: 50 | Q12: 60 | R12: 70 | S12: 80 | T12: 90 | U12: 100
C13: ÖSZ-3 overbuild – lower bound | D13: % | J13: 0.02 | K13: 0.05 | L13: 0.1 | M13: 0.15 | N13: 0.2 | O13: 0.25 | P13: 0.3 | Q13: 0.35 | R13: 0.4 | S13: 0.5
C14: ÖSZ-3 overbuild – lower bound included | D14: flag | J14: 0 | K14: 1 | L14: 1 | M14: 1 | N14: 1 | O14: 1 | P14: 1 | Q14: 1 | R14: 1 | S14: 0
C15: ÖSZ-3 overbuild – inner points (below, bands) | D15: points | E15: 0.1 | J15: 0 | K15: 10 | L15: 20 | M15: 30 | N15: 40 | O15: 50 | P15: 60 | Q15: 70 | R15: 80 | S15: 90 | T15: 100
C16: ÖSZ-4 BESS ratio – lower bound | D16: % | E16: 0.05 | J16: 0.02 | K16: 0.05 | L16: 0.1 | M16: 0.15 | N16: 0.2 | O16: 0.25 | P16: 0.3 | Q16: 0.35 | R16: 0.4 | S16: 0.5
C17: ÖSZ-4 BESS ratio – lower bound included | D17: flag | J17: 0 | K17: 1 | L17: 1 | M17: 1 | N17: 1 | O17: 1 | P17: 1 | Q17: 1 | R17: 1 | S17: 0
C18: ÖSZ-4 BESS ratio – inner points (below, bands) | D18: points | E18: 0.15 | J18: 0 | K18: 10 | L18: 20 | M18: 30 | N18: 40 | O18: 50 | P18: 60 | Q18: 70 | R18: 80 | S18: 90 | T18: 100
C19: ÖSZ-6 performance security multiple – lower bound | D19: x | J19: 1 | K19: 1.2 | L19: 1.3 | M19: 1.4 | N19: 1.5 | O19: 1.6 | P19: 1.7 | Q19: 1.8 | R19: 1.9 | S19: 2
C20: ÖSZ-6 performance security multiple – lower bound included | D20: flag | J20: 0 | K20: 1 | L20: 1 | M20: 1 | N20: 1 | O20: 1 | P20: 1 | Q20: 1 | R20: 1 | S20: 1
C21: ÖSZ-6 performance security multiple – inner points (below, bands) | D21: points | E21: 0.05 | J21: 0 | K21: 10 | L21: 20 | M21: 30 | N21: 40 | O21: 50 | P21: 60 | Q21: 70 | R21: 80 | S21: 90 | T21: 100
C22: ÖSZ-5 partial award – inner points | D22: points | E22: 0.05 | J22: 100
C23: ÖSZ-7 brownfield – inner points | D23: points | E23: 0.1 | J23: 100
C24: ÖSZ-8 shared connection – inner points | D24: points | E24: 0.05 | J24: 100
C25: ÖSZ-9 EU turbines – inner points | D25: points | E25: 0.15 | J25: 80
C26: ÖSZ-9 EU transformers – inner points | D26: points | J26: 20
A28: x | C28: Devex schedule | E28: BORA_Devex 25-Sep (meeting file Devex_FEP); excl. Other costs
C29: Line (BORA_Devex row) | E29: HUF m | F29: EUR k | I29: EUR k at FX | J29: Pay date | K29: Land
C30: r14 Capacity allocation process - Awarding – Land reservation fee | E30: 0 | F30: 55.65 | I30: =E30*Thousand/In_FX+F30 -> 55.65 | J30: 46431 | K30: 1
C31: r15 Land purchase price | E31: 45.6 | F31: 0 | I31: =E31*Thousand/In_FX+F31 -> 124.93151 | J31: 46431 | K31: 1
C32: r16 Grid connection plan – Design fee | E32: 59.142857 | F32: 0 | I32: =E32*Thousand/In_FX+F32 -> 162.03523 | J32: 46976 | K32: 0
C33: r17 Administrative fee | E33: 0.750544 | F33: 0 | I33: =E33*Thousand/In_FX+F33 -> 2.0562849 | J33: 46976 | K33: 0
C34: r20 Land contracting (additional land) – Legal fee, agent fee | E34: 34.5 | F34: 84 | I34: =E34*Thousand/In_FX+F34 -> 178.52055 | J34: 46296 | K34: 0
C35: r21 Wind measurement – Met Masts | E35: 0 | F35: 398 | I35: =E35*Thousand/In_FX+F35 -> 398 | J35: 46447 | K35: 0
C36: r22 Design fee | E36: 3.6 | F36: 0 | I36: =E36*Thousand/In_FX+F36 -> 9.8630137 | J36: 46388 | K36: 0
C37: r23 EYA | E37: 0 | F37: 4.5 | I37: =E37*Thousand/In_FX+F37 -> 4.5 | J37: 46932 | K37: 0
C38: r24 Land reclassification – Administrative fee | E38: 0.96 | F38: 0 | I38: =E38*Thousand/In_FX+F38 -> 2.630137 | J38: 46746 | K38: 0
C39: r25 Report fee | E39: 8 | F39: 0 | I39: =E39*Thousand/In_FX+F39 -> 21.917808 | J39: 46596 | K39: 0
C40: r26 Zoning plan modification – Design fee | E40: 50 | F40: 0 | I40: =E40*Thousand/In_FX+F40 -> 136.9863 | J40: 46806 | K40: 0
C41: r27 Municipality donation – Donation | E41: 35 | F41: 0 | I41: =E41*Thousand/In_FX+F41 -> 95.890411 | J41: 46806 | K41: 0
... C61: r48 RtB – Land purchase price | E61: 91.2 | F61: 0 | I61: =E61*Thousand/In_FX+F61 -> 249.86301 | J61: 47201 | K61: 1
I62: =E62*Thousand/In_FX+F62 -> 0
I63: =E63*Thousand/In_FX+F63 -> 0
...

Sheet Calc_1
A1: 1 | C1: Bid number
B2: =Dashboard!$C$3&" – Calculations – "&INDEX(Bid_Labels,1,$A$1) -> Project Bora – Calculations – BORA 1
C3: Period start | D3: date | J3: =I$4+1 -> 46204 | K3: =J$4+1 -> 46296 | L3: =K$4+1 -> 46388 | M3: =L$4+1 -> 46478 | N3: =M$4+1 -> 46569 | O3: =N$4+1 -> 46661 | P3: =O$4+1 -> 46753 | Q3: =P$4+1 -> 46844 | ... ET3: =ES$4+1 -> 58988
C4: Period end | D4: date | I4: =In_Model_Start-1 -> 46203 | J4: =EOMONTH(J$3,Months_Per_Period-1) -> 46295 | K4: =EOMONTH(K$3,Months_Per_Period-1) -> 46387 | L4: =EOMONTH(L$3,Months_Per_Period-1) -> 46477 | M4: =EOMONTH(M$3,Months_Per_Period-1) -> 46568 | N4: =EOMONTH(N$3,Months_Per_Period-1) -> 46660 | O4: =EOMONTH(O$3,Months_Per_Period-1) -> 46752 | P4: =EOMONTH(P$3,Months_Per_Period-1) -> 46843 | Q4: =EOMONTH(Q$3,Months_Per_Period-1) -> 46934 | ... ET4: =EOMONTH(ET$3,Months_Per_Period-1) -> 59079
C5: Days in period | D5: days | J5: =J$4-J$3+1 -> 92 | K5: =K$4-K$3+1 -> 92 | L5: =L$4-L$3+1 -> 90 | M5: =M$4-M$3+1 -> 91 | N5: =N$4-N$3+1 -> 92 | O5: =O$4-O$3+1 -> 92 | P5: =P$4-P$3+1 -> 91 | Q5: =Q$4-Q$3+1 -> 91 | ... ET5: =ET$4-ET$3+1 -> 92
C6: Year fraction | D6: factor | J6: =J$5/Days_In_Year -> 0.25205479 | K6: =K$5/Days_In_Year -> 0.25205479 | L6: =L$5/Days_In_Year -> 0.24657534 | M6: =M$5/Days_In_Year -> 0.24931507 | N6: =N$5/Days_In_Year -> 0.25205479 | O6: =O$5/Days_In_Year -> 0.25205479 | P6: =P$5/Days_In_Year -> 0.24931507 | Q6: =Q$5/Days_In_Year -> 0.24931507 | ... ET6: =ET$5/Days_In_Year -> 0.25205479
C7: Year | D7: year | J7: =YEAR(J$4) -> 2026 | K7: =YEAR(K$4) -> 2026 | L7: =YEAR(L$4) -> 2027 | M7: =YEAR(M$4) -> 2027 | N7: =YEAR(N$4) -> 2027 | O7: =YEAR(O$4) -> 2027 | P7: =YEAR(P$4) -> 2028 | Q7: =YEAR(Q$4) -> 2028 | ... ET7: =YEAR(ET$4) -> 2061
C8: Period counter | D8: # | J8: =I$8+1 -> 1 | K8: =J$8+1 -> 2 | L8: =K$8+1 -> 3 | M8: =L$8+1 -> 4 | N8: =M$8+1 -> 5 | O8: =N$8+1 -> 6 | P8: =O$8+1 -> 7 | Q8: =P$8+1 -> 8 | ... ET8: =ES$8+1 -> 141
A11: x | C11: Timing and flags
C12: RtB exit | D12: flag | E12: =INDEX(Dash_Exit_Date,1,$A$1) -> 47483 | I12: =SUM(J12:ET12) -> 1 | J12: =N(AND(J$3<=$E12,J$4>=$E12)) -> 0 | K12: =N(AND(K$3<=$E12,K$4>=$E12)) -> 0 | L12: =N(AND(L$3<=$E12,L$4>=$E12)) -> 0 | M12: =N(AND(M$3<=$E12,M$4>=$E12)) -> 0 | N12: =N(AND(N$3<=$E12,N$4>=$E12)) -> 0 | O12: =N(AND(O$3<=$E12,O$4>=$E12)) -> 0 | P12: =N(AND(P$3<=$E12,P$4>=$E12)) -> 0 | Q12: =N(AND(Q$3<=$E12,Q$4>=$E12)) -> 0 | ... ET12: =N(AND(ET$3<=$E12,ET$4>=$E12)) -> 0
C13: Construction share (NTP → COD) | D13: factor | E13: =In_NTP+1 -> 47392 | F13: =In_COD -> 48121 | I13: =SUM(J13:ET13) -> 1 | J13: =MAX(0,MIN($F13,J$4)-MAX($E13,J$3)+1)/($F13-$E13+1) -> 0 | K13: =MAX(0,MIN($F13,K$4)-MAX($E13,K$3)+1)/($F13-$E13+1) -> 0 | L13: =MAX(0,MIN($F13,L$4)-MAX($E13,L$3)+1)/($F13-$E13+1) -> 0 | M13: =MAX(0,MIN($F13,M$4)-MAX($E13,M$3)+1)/($F13-$E13+1) -> 0 | N13: =MAX(0,MIN($F13,N$4)-MAX($E13,N$3)+1)/($F13-$E13+1) -> 0 | O13: =MAX(0,MIN($F13,O$4)-MAX($E13,O$3)+1)/($F13-$E13+1) -> 0 | P13: =MAX(0,MIN($F13,P$4)-MAX($E13,P$3)+1)/($F13-$E13+1) -> 0 | Q13: =MAX(0,MIN($F13,Q$4)-MAX($E13,Q$3)+1)/($F13-$E13+1) -> 0 | ... ET13: =MAX(0,MIN($F13,ET$4)-MAX($E13,ET$3)+1)/($F13-$E13+1) -> 0
C14: COD | D14: flag | E14: =In_COD -> 48121 | I14: =SUM(J14:ET14) -> 1 | J14: =N(AND(J$3<=$E14,J$4>=$E14)) -> 0 | K14: =N(AND(K$3<=$E14,K$4>=$E14)) -> 0 | L14: =N(AND(L$3<=$E14,L$4>=$E14)) -> 0 | M14: =N(AND(M$3<=$E14,M$4>=$E14)) -> 0 | N14: =N(AND(N$3<=$E14,N$4>=$E14)) -> 0 | O14: =N(AND(O$3<=$E14,O$4>=$E14)) -> 0 | P14: =N(AND(P$3<=$E14,P$4>=$E14)) -> 0 | Q14: =N(AND(Q$3<=$E14,Q$4>=$E14)) -> 0 | ... ET14: =N(AND(ET$3<=$E14,ET$4>=$E14)) -> 0
C15: Operations | D15: flag | E15: =In_COD+1 -> 48122 | F15: =EDATE(In_COD,In_Life*Months_In_Year) -> 59079 | J15: =MAX(0,(MIN($F15,J$4)-MAX($E15,J$3)+1)/J$5) -> 0 | K15: =MAX(0,(MIN($F15,K$4)-MAX($E15,K$3)+1)/K$5) -> 0 | L15: =MAX(0,(MIN($F15,L$4)-MAX($E15,L$3)+1)/L$5) -> 0 | M15: =MAX(0,(MIN($F15,M$4)-MAX($E15,M$3)+1)/M$5) -> 0 | N15: =MAX(0,(MIN($F15,N$4)-MAX($E15,N$3)+1)/N$5) -> 0 | O15: =MAX(0,(MIN($F15,O$4)-MAX($E15,O$3)+1)/O$5) -> 0 | P15: =MAX(0,(MIN($F15,P$4)-MAX($E15,P$3)+1)/P$5) -> 0 | Q15: =MAX(0,(MIN($F15,Q$4)-MAX($E15,Q$3)+1)/Q$5) -> 0 | ... ET15: =MAX(0,(MIN($F15,ET$4)-MAX($E15,ET$3)+1)/ET$5) -> 1
C16: Land lease period (NTP → end of life) | D16: flag | E16: =In_NTP+1 -> 47392 | F16: =EDATE(In_COD,In_Life*Months_In_Year) -> 59079 | J16: =MAX(0,(MIN($F16,J$4)-MAX($E16,J$3)+1)/J$5) -> 0 | K16: =MAX(0,(MIN($F16,K$4)-MAX($E16,K$3)+1)/K$5) -> 0 | L16: =MAX(0,(MIN($F16,L$4)-MAX($E16,L$3)+1)/L$5) -> 0 | M16: =MAX(0,(MIN($F16,M$4)-MAX($E16,M$3)+1)/M$5) -> 0 | N16: =MAX(0,(MIN($F16,N$4)-MAX($E16,N$3)+1)/N$5) -> 0 | O16: =MAX(0,(MIN($F16,O$4)-MAX($E16,O$3)+1)/O$5) -> 0 | P16: =MAX(0,(MIN($F16,P$4)-MAX($E16,P$3)+1)/P$5) -> 0 | Q16: =MAX(0,(MIN($F16,Q$4)-MAX($E16,Q$3)+1)/Q$5) -> 0 | ... ET16: =MAX(0,(MIN($F16,ET$4)-MAX($E16,ET$3)+1)/ET$5) -> 1
C17: Debt repayment period | D17: flag | E17: =In_COD+1 -> 48122 | F17: =EDATE(In_COD,In_Debt_Tenor*Months_In_Year) -> 51774 | J17: =MAX(0,(MIN($F17,J$4)-MAX($E17,J$3)+1)/J$5) -> 0 | K17: =MAX(0,(MIN($F17,K$4)-MAX($E17,K$3)+1)/K$5) -> 0 | L17: =MAX(0,(MIN($F17,L$4)-MAX($E17,L$3)+1)/L$5) -> 0 | M17: =MAX(0,(MIN($F17,M$4)-MAX($E17,M$3)+1)/M$5) -> 0 | N17: =MAX(0,(MIN($F17,N$4)-MAX($E17,N$3)+1)/N$5) -> 0 | O17: =MAX(0,(MIN($F17,O$4)-MAX($E17,O$3)+1)/O$5) -> 0 | P17: =MAX(0,(MIN($F17,P$4)-MAX($E17,P$3)+1)/P$5) -> 0 | Q17: =MAX(0,(MIN($F17,Q$4)-MAX($E17,Q$3)+1)/Q$5) -> 0 | ... ET17: =MAX(0,(MIN($F17,ET$4)-MAX($E17,ET$3)+1)/ET$5) -> 0
C18: Tax depreciation share | D18: factor | E18: =In_COD+1 -> 48122 | F18: =EDATE(In_COD,In_Dep_Years*Months_In_Year) -> 55426 | I18: =SUM(J18:ET18) -> 1 | J18: =MAX(0,MIN($F18,J$4)-MAX($E18,J$3)+1)/($F18-$E18+1) -> 0 | K18: =MAX(0,MIN($F18,K$4)-MAX($E18,K$3)+1)/($F18-$E18+1) -> 0 | L18: =MAX(0,MIN($F18,L$4)-MAX($E18,L$3)+1)/($F18-$E18+1) -> 0 | M18: =MAX(0,MIN($F18,M$4)-MAX($E18,M$3)+1)/($F18-$E18+1) -> 0 | N18: =MAX(0,MIN($F18,N$4)-MAX($E18,N$3)+1)/($F18-$E18+1) -> 0 | O18: =MAX(0,MIN($F18,O$4)-MAX($E18,O$3)+1)/($F18-$E18+1) -> 0 | P18: =MAX(0,MIN($F18,P$4)-MAX($E18,P$3)+1)/($F18-$E18+1) -> 0 | Q18: =MAX(0,MIN($F18,Q$4)-MAX($E18,Q$3)+1)/($F18-$E18+1) -> 0 | ... ET18: =MAX(0,MIN($F18,ET$4)-MAX($E18,ET$3)+1)/($F18-$E18+1) -> 0
C19: Interest freeze (no accrual) | D19: flag | E19: =In_Freeze_Start+1 -> 47300 | F19: =In_Freeze_Start+In_Freeze_On*(In_Freeze_End-In_Freeze_Start)-1 -> 47483 | J19: =MAX(0,(MIN($F19,J$4)-MAX($E19,J$3)+1)/J$5) -> 0 | K19: =MAX(0,(MIN($F19,K$4)-MAX($E19,K$3)+1)/K$5) -> 0 | L19: =MAX(0,(MIN($F19,L$4)-MAX($E19,L$3)+1)/L$5) -> 0 | M19: =MAX(0,(MIN($F19,M$4)-MAX($E19,M$3)+1)/M$5) -> 0 | N19: =MAX(0,(MIN($F19,N$4)-MAX($E19,N$3)+1)/N$5) -> 0 | O19: =MAX(0,(MIN($F19,O$4)-MAX($E19,O$3)+1)/O$5) -> 0 | P19: =MAX(0,(MIN($F19,P$4)-MAX($E19,P$3)+1)/P$5) -> 0 | Q19: =MAX(0,(MIN($F19,Q$4)-MAX($E19,Q$3)+1)/Q$5) -> 0 | ... ET19: =MAX(0,(MIN($F19,ET$4)-MAX($E19,ET$3)+1)/ET$5) -> 0
C20: 31-Dec capitalisation | D20: flag | J20: =N(MONTH(J$4)=Months_In_Year) -> 0 | K20: =N(MONTH(K$4)=Months_In_Year) -> 1 | L20: =N(MONTH(L$4)=Months_In_Year) -> 0 | M20: =N(MONTH(M$4)=Months_In_Year) -> 0 | N20: =N(MONTH(N$4)=Months_In_Year) -> 0 | O20: =N(MONTH(O$4)=Months_In_Year) -> 1 | P20: =N(MONTH(P$4)=Months_In_Year) -> 0 | Q20: =N(MONTH(Q$4)=Months_In_Year) -> 0 | ... ET20: =N(MONTH(ET$4)=Months_In_Year) -> 0
C21: Buyer discount factor to COD | D21: factor | J21: =1/(1+In_Buyer_Rate)^(MAX(0,J$4-In_COD)/Days_In_Year) -> 1 | K21: =1/(1+In_Buyer_Rate)^(MAX(0,K$4-In_COD)/Days_In_Year) -> 1 | L21: =1/(1+In_Buyer_Rate)^(MAX(0,L$4-In_COD)/Days_In_Year) -> 1 | M21: =1/(1+In_Buyer_Rate)^(MAX(0,M$4-In_COD)/Days_In_Year) -> 1 | N21: =1/(1+In_Buyer_Rate)^(MAX(0,N$4-In_COD)/Days_In_Year) -> 1 | O21: =1/(1+In_Buyer_Rate)^(MAX(0,O$4-In_COD)/Days_In_Year) -> 1 | P21: =1/(1+In_Buyer_Rate)^(MAX(0,P$4-In_COD)/Days_In_Year) -> 1 | Q21: =1/(1+In_Buyer_Rate)^(MAX(0,Q$4-In_COD)/Days_In_Year) -> 1 | ... ET21: =1/(1+In_Buyer_Rate)^(MAX(0,ET$4-In_COD)/Days_In_Year) -> 0.099209842
A23: x | C23: Capacity (E: committed, F: built)
C24: Wind | D24: MW | E24: =In_MVA*(1+INDEX(Dash_Overbuild,1,$A$1)) -> 151 | F24: =In_MVA+($E24-In_MVA)*In_Overbuild_Built -> 100
C25: BESS power | D25: MW | E25: =INDEX(Dash_BESS,1,$A$1)*In_MVA -> 51 | F25: =$E25*In_BESS_Built -> 51
C26: BESS energy | D26: MWh | E26: =$E25*INDEX(Dash_BESS_Hours,1,$A$1) -> 204
C27: Grid-bottleneck loss on built wind | D27: % | E27: =($F24-In_MVA)/$F24*In_Bottleneck_Loss -> 0
A29: x | C29: Tender points (E: commitment, F: weighted points)
C30: ÖSZ-1 municipal one-off | D30: EUR k/MW | E30: =INDEX(Dash_Municipal,1,$A$1) -> 50 | F30: =INDEX(Osz1_Pts,1+SUMPRODUCT((Osz1_LB<$E30)+(Osz1_LB=$E30)*Osz1_Incl))*Osz1_W -> 20
C31: ÖSZ-2 community contribution | D31: EUR/MWh | E31: =INDEX(Dash_Community,1,$A$1) -> 3 | F31: =INDEX(Osz2_Pts,1+SUMPRODUCT((Osz2_LB<$E31)+(Osz2_LB=$E31)*Osz2_Incl))*Osz2_W -> 15
C32: ÖSZ-3 overbuild | D32: % | E32: =INDEX(Dash_Overbuild,1,$A$1) -> 0.51 | F32: =INDEX(Osz3_Pts,1+SUMPRODUCT((Osz3_LB<$E32)+(Osz3_LB=$E32)*Osz3_Incl))*Osz3_W -> 10
C33: ÖSZ-4 BESS ratio | D33: % | E33: =INDEX(Dash_BESS,1,$A$1)/IF(In_OSZ4_Basis=1,$E24/In_MVA,1) -> 0.51 | F33: =INDEX(Osz4_Pts,1+SUMPRODUCT((Osz4_LB<$E33)+(Osz4_LB=$E33)*Osz4_Incl))*Osz4_W*($E33>=Osz4_Min) -> 15
C34: ÖSZ-5 partial award | D34: flag | E34: =INDEX(Dash_Partial,1,$A$1) -> 1 | F34: =$E34*Osz5_Pts*Osz5_W -> 5
C35: ÖSZ-6 performance security multiple | D35: x | E35: =INDEX(Dash_PB_Mult,1,$A$1) -> 1 | F35: =INDEX(Osz6_Pts,1+SUMPRODUCT((Osz6_LB<$E35)+(Osz6_LB=$E35)*Osz6_Incl))*Osz6_W -> 0
C36: ÖSZ-7 brownfield | D36: flag | E36: =INDEX(Dash_Brownfield,1,$A$1) -> 0 | F36: =$E36*Osz7_Pts*Osz7_W -> 0
C37: ÖSZ-8 shared connection | D37: flag | E37: =INDEX(Dash_Shared,1,$A$1) -> 1 | F37: =$E37*Osz8_Pts*Osz8_W -> 5
C38: ÖSZ-9 EU turbines | D38: flag | E38: =INDEX(Dash_EU_Turbine,1,$A$1) -> 1 | F38: =$E38*Osz9a_Pts*Osz9_W -> 12
C39: ÖSZ-9 EU transformers | D39: flag | E39: =INDEX(Dash_EU_Transformer,1,$A$1) -> 1 | F39: =$E39*Osz9b_Pts*Osz9_W -> 3
C40: Points total (E: EU route, F: CN route) | D40: points | E40: =ROUND(SUM($F30:$F39),Points_Decimals) -> 85 | F40: =ROUND(SUM($F30:$F37),Points_Decimals) -> 70
C41: Points, live turbine route | D41: points | E41: =IF(In_CN_Turbine=1,$F40,$E40) -> 85
C42: Failed tests (E: capacity, F: offerable range) | D42: # | E42: =N(In_MVA>In_Group_Cap)+N($E24<In_MVA)+N($E25>$E24)+N($E26<$E25*In_Min_Hours) -> 0 | F42: =($E30<>0)*($E30<Osz1_Min)+($E30>Osz1_Max)+($E31<>0)*($E31<Osz2_Min)+($E31>Osz2_Max) -> 0
A44: x | C44: Securities, fees and development costs (E: amount, F: date)
C45: Security base | D45: mHUF | E45: =$E24*In_Bench_Wind+$E26*In_Bench_BESS -> 102106
...

Sheet Calc_2
A1: 2 | C1: Bid number
B2: =Dashboard!$C$3&" – Calculations – "&INDEX(Bid_Labels,1,$A$1) -> Project Bora – Calculations – BORA 2
C3: Period start | D3: date | J3: =I$4+1 -> 46204 | K3: =J$4+1 -> 46296 | L3: =K$4+1 -> 46388 | M3: =L$4+1 -> 46478 | N3: =M$4+1 -> 46569 | O3: =N$4+1 -> 46661 | P3: =O$4+1 -> 46753 | Q3: =P$4+1 -> 46844 | ... ET3: =ES$4+1 -> 58988
C4: Period end | D4: date | I4: =In_Model_Start-1 -> 46203 | J4: =EOMONTH(J$3,Months_Per_Period-1) -> 46295 | K4: =EOMONTH(K$3,Months_Per_Period-1) -> 46387 | L4: =EOMONTH(L$3,Months_Per_Period-1) -> 46477 | M4: =EOMONTH(M$3,Months_Per_Period-1) -> 46568 | N4: =EOMONTH(N$3,Months_Per_Period-1) -> 46660 | O4: =EOMONTH(O$3,Months_Per_Period-1) -> 46752 | P4: =EOMONTH(P$3,Months_Per_Period-1) -> 46843 | Q4: =EOMONTH(Q$3,Months_Per_Period-1) -> 46934 | ... ET4: =EOMONTH(ET$3,Months_Per_Period-1) -> 59079
C5: Days in period | D5: days | J5: =J$4-J$3+1 -> 92 | K5: =K$4-K$3+1 -> 92 | L5: =L$4-L$3+1 -> 90 | M5: =M$4-M$3+1 -> 91 | N5: =N$4-N$3+1 -> 92 | O5: =O$4-O$3+1 -> 92 | P5: =P$4-P$3+1 -> 91 | Q5: =Q$4-Q$3+1 -> 91 | ... ET5: =ET$4-ET$3+1 -> 92
C6: Year fraction | D6: factor | J6: =J$5/Days_In_Year -> 0.25205479 | K6: =K$5/Days_In_Year -> 0.25205479 | L6: =L$5/Days_In_Year -> 0.24657534 | M6: =M$5/Days_In_Year -> 0.24931507 | N6: =N$5/Days_In_Year -> 0.25205479 | O6: =O$5/Days_In_Year -> 0.25205479 | P6: =P$5/Days_In_Year -> 0.24931507 | Q6: =Q$5/Days_In_Year -> 0.24931507 | ... ET6: =ET$5/Days_In_Year -> 0.25205479
C7: Year | D7: year | J7: =YEAR(J$4) -> 2026 | K7: =YEAR(K$4) -> 2026 | L7: =YEAR(L$4) -> 2027 | M7: =YEAR(M$4) -> 2027 | N7: =YEAR(N$4) -> 2027 | O7: =YEAR(O$4) -> 2027 | P7: =YEAR(P$4) -> 2028 | Q7: =YEAR(Q$4) -> 2028 | ... ET7: =YEAR(ET$4) -> 2061
C8: Period counter | D8: # | J8: =I$8+1 -> 1 | K8: =J$8+1 -> 2 | L8: =K$8+1 -> 3 | M8: =L$8+1 -> 4 | N8: =M$8+1 -> 5 | O8: =N$8+1 -> 6 | P8: =O$8+1 -> 7 | Q8: =P$8+1 -> 8 | ... ET8: =ES$8+1 -> 141
A11: x | C11: Timing and flags
C12: RtB exit | D12: flag | E12: =INDEX(Dash_Exit_Date,1,$A$1) -> 47483 | I12: =SUM(J12:ET12) -> 1 | J12: =N(AND(J$3<=$E12,J$4>=$E12)) -> 0 | K12: =N(AND(K$3<=$E12,K$4>=$E12)) -> 0 | L12: =N(AND(L$3<=$E12,L$4>=$E12)) -> 0 | M12: =N(AND(M$3<=$E12,M$4>=$E12)) -> 0 | N12: =N(AND(N$3<=$E12,N$4>=$E12)) -> 0 | O12: =N(AND(O$3<=$E12,O$4>=$E12)) -> 0 | P12: =N(AND(P$3<=$E12,P$4>=$E12)) -> 0 | Q12: =N(AND(Q$3<=$E12,Q$4>=$E12)) -> 0 | ... ET12: =N(AND(ET$3<=$E12,ET$4>=$E12)) -> 0
C13: Construction share (NTP → COD) | D13: factor | E13: =In_NTP+1 -> 47392 | F13: =In_COD -> 48121 | I13: =SUM(J13:ET13) -> 1 | J13: =MAX(0,MIN($F13,J$4)-MAX($E13,J$3)+1)/($F13-$E13+1) -> 0 | K13: =MAX(0,MIN($F13,K$4)-MAX($E13,K$3)+1)/($F13-$E13+1) -> 0 | L13: =MAX(0,MIN($F13,L$4)-MAX($E13,L$3)+1)/($F13-$E13+1) -> 0 | M13: =MAX(0,MIN($F13,M$4)-MAX($E13,M$3)+1)/($F13-$E13+1) -> 0 | N13: =MAX(0,MIN($F13,N$4)-MAX($E13,N$3)+1)/($F13-$E13+1) -> 0 | O13: =MAX(0,MIN($F13,O$4)-MAX($E13,O$3)+1)/($F13-$E13+1) -> 0 | P13: =MAX(0,MIN($F13,P$4)-MAX($E13,P$3)+1)/($F13-$E13+1) -> 0 | Q13: =MAX(0,MIN($F13,Q$4)-MAX($E13,Q$3)+1)/($F13-$E13+1) -> 0 | ... ET13: =MAX(0,MIN($F13,ET$4)-MAX($E13,ET$3)+1)/($F13-$E13+1) -> 0
C14: COD | D14: flag | E14: =In_COD -> 48121 | I14: =SUM(J14:ET14) -> 1 | J14: =N(AND(J$3<=$E14,J$4>=$E14)) -> 0 | K14: =N(AND(K$3<=$E14,K$4>=$E14)) -> 0 | L14: =N(AND(L$3<=$E14,L$4>=$E14)) -> 0 | M14: =N(AND(M$3<=$E14,M$4>=$E14)) -> 0 | N14: =N(AND(N$3<=$E14,N$4>=$E14)) -> 0 | O14: =N(AND(O$3<=$E14,O$4>=$E14)) -> 0 | P14: =N(AND(P$3<=$E14,P$4>=$E14)) -> 0 | Q14: =N(AND(Q$3<=$E14,Q$4>=$E14)) -> 0 | ... ET14: =N(AND(ET$3<=$E14,ET$4>=$E14)) -> 0
C15: Operations | D15: flag | E15: =In_COD+1 -> 48122 | F15: =EDATE(In_COD,In_Life*Months_In_Year) -> 59079 | J15: =MAX(0,(MIN($F15,J$4)-MAX($E15,J$3)+1)/J$5) -> 0 | K15: =MAX(0,(MIN($F15,K$4)-MAX($E15,K$3)+1)/K$5) -> 0 | L15: =MAX(0,(MIN($F15,L$4)-MAX($E15,L$3)+1)/L$5) -> 0 | M15: =MAX(0,(MIN($F15,M$4)-MAX($E15,M$3)+1)/M$5) -> 0 | N15: =MAX(0,(MIN($F15,N$4)-MAX($E15,N$3)+1)/N$5) -> 0 | O15: =MAX(0,(MIN($F15,O$4)-MAX($E15,O$3)+1)/O$5) -> 0 | P15: =MAX(0,(MIN($F15,P$4)-MAX($E15,P$3)+1)/P$5) -> 0 | Q15: =MAX(0,(MIN($F15,Q$4)-MAX($E15,Q$3)+1)/Q$5) -> 0 | ... ET15: =MAX(0,(MIN($F15,ET$4)-MAX($E15,ET$3)+1)/ET$5) -> 1
C16: Land lease period (NTP → end of life) | D16: flag | E16: =In_NTP+1 -> 47392 | F16: =EDATE(In_COD,In_Life*Months_In_Year) -> 59079 | J16: =MAX(0,(MIN($F16,J$4)-MAX($E16,J$3)+1)/J$5) -> 0 | K16: =MAX(0,(MIN($F16,K$4)-MAX($E16,K$3)+1)/K$5) -> 0 | L16: =MAX(0,(MIN($F16,L$4)-MAX($E16,L$3)+1)/L$5) -> 0 | M16: =MAX(0,(MIN($F16,M$4)-MAX($E16,M$3)+1)/M$5) -> 0 | N16: =MAX(0,(MIN($F16,N$4)-MAX($E16,N$3)+1)/N$5) -> 0 | O16: =MAX(0,(MIN($F16,O$4)-MAX($E16,O$3)+1)/O$5) -> 0 | P16: =MAX(0,(MIN($F16,P$4)-MAX($E16,P$3)+1)/P$5) -> 0 | Q16: =MAX(0,(MIN($F16,Q$4)-MAX($E16,Q$3)+1)/Q$5) -> 0 | ... ET16: =MAX(0,(MIN($F16,ET$4)-MAX($E16,ET$3)+1)/ET$5) -> 1
C17: Debt repayment period | D17: flag | E17: =In_COD+1 -> 48122 | F17: =EDATE(In_COD,In_Debt_Tenor*Months_In_Year) -> 51774 | J17: =MAX(0,(MIN($F17,J$4)-MAX($E17,J$3)+1)/J$5) -> 0 | K17: =MAX(0,(MIN($F17,K$4)-MAX($E17,K$3)+1)/K$5) -> 0 | L17: =MAX(0,(MIN($F17,L$4)-MAX($E17,L$3)+1)/L$5) -> 0 | M17: =MAX(0,(MIN($F17,M$4)-MAX($E17,M$3)+1)/M$5) -> 0 | N17: =MAX(0,(MIN($F17,N$4)-MAX($E17,N$3)+1)/N$5) -> 0 | O17: =MAX(0,(MIN($F17,O$4)-MAX($E17,O$3)+1)/O$5) -> 0 | P17: =MAX(0,(MIN($F17,P$4)-MAX($E17,P$3)+1)/P$5) -> 0 | Q17: =MAX(0,(MIN($F17,Q$4)-MAX($E17,Q$3)+1)/Q$5) -> 0 | ... ET17: =MAX(0,(MIN($F17,ET$4)-MAX($E17,ET$3)+1)/ET$5) -> 0
C18: Tax depreciation share | D18: factor | E18: =In_COD+1 -> 48122 | F18: =EDATE(In_COD,In_Dep_Years*Months_In_Year) -> 55426 | I18: =SUM(J18:ET18) -> 1 | J18: =MAX(0,MIN($F18,J$4)-MAX($E18,J$3)+1)/($F18-$E18+1) -> 0 | K18: =MAX(0,MIN($F18,K$4)-MAX($E18,K$3)+1)/($F18-$E18+1) -> 0 | L18: =MAX(0,MIN($F18,L$4)-MAX($E18,L$3)+1)/($F18-$E18+1) -> 0 | M18: =MAX(0,MIN($F18,M$4)-MAX($E18,M$3)+1)/($F18-$E18+1) -> 0 | N18: =MAX(0,MIN($F18,N$4)-MAX($E18,N$3)+1)/($F18-$E18+1) -> 0 | O18: =MAX(0,MIN($F18,O$4)-MAX($E18,O$3)+1)/($F18-$E18+1) -> 0 | P18: =MAX(0,MIN($F18,P$4)-MAX($E18,P$3)+1)/($F18-$E18+1) -> 0 | Q18: =MAX(0,MIN($F18,Q$4)-MAX($E18,Q$3)+1)/($F18-$E18+1) -> 0 | ... ET18: =MAX(0,MIN($F18,ET$4)-MAX($E18,ET$3)+1)/($F18-$E18+1) -> 0
C19: Interest freeze (no accrual) | D19: flag | E19: =In_Freeze_Start+1 -> 47300 | F19: =In_Freeze_Start+In_Freeze_On*(In_Freeze_End-In_Freeze_Start)-1 -> 47483 | J19: =MAX(0,(MIN($F19,J$4)-MAX($E19,J$3)+1)/J$5) -> 0 | K19: =MAX(0,(MIN($F19,K$4)-MAX($E19,K$3)+1)/K$5) -> 0 | L19: =MAX(0,(MIN($F19,L$4)-MAX($E19,L$3)+1)/L$5) -> 0 | M19: =MAX(0,(MIN($F19,M$4)-MAX($E19,M$3)+1)/M$5) -> 0 | N19: =MAX(0,(MIN($F19,N$4)-MAX($E19,N$3)+1)/N$5) -> 0 | O19: =MAX(0,(MIN($F19,O$4)-MAX($E19,O$3)+1)/O$5) -> 0 | P19: =MAX(0,(MIN($F19,P$4)-MAX($E19,P$3)+1)/P$5) -> 0 | Q19: =MAX(0,(MIN($F19,Q$4)-MAX($E19,Q$3)+1)/Q$5) -> 0 | ... ET19: =MAX(0,(MIN($F19,ET$4)-MAX($E19,ET$3)+1)/ET$5) -> 0
C20: 31-Dec capitalisation | D20: flag | J20: =N(MONTH(J$4)=Months_In_Year) -> 0 | K20: =N(MONTH(K$4)=Months_In_Year) -> 1 | L20: =N(MONTH(L$4)=Months_In_Year) -> 0 | M20: =N(MONTH(M$4)=Months_In_Year) -> 0 | N20: =N(MONTH(N$4)=Months_In_Year) -> 0 | O20: =N(MONTH(O$4)=Months_In_Year) -> 1 | P20: =N(MONTH(P$4)=Months_In_Year) -> 0 | Q20: =N(MONTH(Q$4)=Months_In_Year) -> 0 | ... ET20: =N(MONTH(ET$4)=Months_In_Year) -> 0
C21: Buyer discount factor to COD | D21: factor | J21: =1/(1+In_Buyer_Rate)^(MAX(0,J$4-In_COD)/Days_In_Year) -> 1 | K21: =1/(1+In_Buyer_Rate)^(MAX(0,K$4-In_COD)/Days_In_Year) -> 1 | L21: =1/(1+In_Buyer_Rate)^(MAX(0,L$4-In_COD)/Days_In_Year) -> 1 | M21: =1/(1+In_Buyer_Rate)^(MAX(0,M$4-In_COD)/Days_In_Year) -> 1 | N21: =1/(1+In_Buyer_Rate)^(MAX(0,N$4-In_COD)/Days_In_Year) -> 1 | O21: =1/(1+In_Buyer_Rate)^(MAX(0,O$4-In_COD)/Days_In_Year) -> 1 | P21: =1/(1+In_Buyer_Rate)^(MAX(0,P$4-In_COD)/Days_In_Year) -> 1 | Q21: =1/(1+In_Buyer_Rate)^(MAX(0,Q$4-In_COD)/Days_In_Year) -> 1 | ... ET21: =1/(1+In_Buyer_Rate)^(MAX(0,ET$4-In_COD)/Days_In_Year) -> 0.099209842
A23: x | C23: Capacity (E: committed, F: built)
C24: Wind | D24: MW | E24: =In_MVA*(1+INDEX(Dash_Overbuild,1,$A$1)) -> 140 | F24: =In_MVA+($E24-In_MVA)*In_Overbuild_Built -> 100
C25: BESS power | D25: MW | E25: =INDEX(Dash_BESS,1,$A$1)*In_MVA -> 40 | F25: =$E25*In_BESS_Built -> 40
C26: BESS energy | D26: MWh | E26: =$E25*INDEX(Dash_BESS_Hours,1,$A$1) -> 160
C27: Grid-bottleneck loss on built wind | D27: % | E27: =($F24-In_MVA)/$F24*In_Bottleneck_Loss -> 0
A29: x | C29: Tender points (E: commitment, F: weighted points)
C30: ÖSZ-1 municipal one-off | D30: EUR k/MW | E30: =INDEX(Dash_Municipal,1,$A$1) -> 50 | F30: =INDEX(Osz1_Pts,1+SUMPRODUCT((Osz1_LB<$E30)+(Osz1_LB=$E30)*Osz1_Incl))*Osz1_W -> 20
C31: ÖSZ-2 community contribution | D31: EUR/MWh | E31: =INDEX(Dash_Community,1,$A$1) -> 2.01 | F31: =INDEX(Osz2_Pts,1+SUMPRODUCT((Osz2_LB<$E31)+(Osz2_LB=$E31)*Osz2_Incl))*Osz2_W -> 0.75
C32: ÖSZ-3 overbuild | D32: % | E32: =INDEX(Dash_Overbuild,1,$A$1) -> 0.4 | F32: =INDEX(Osz3_Pts,1+SUMPRODUCT((Osz3_LB<$E32)+(Osz3_LB=$E32)*Osz3_Incl))*Osz3_W -> 9
C33: ÖSZ-4 BESS ratio | D33: % | E33: =INDEX(Dash_BESS,1,$A$1)/IF(In_OSZ4_Basis=1,$E24/In_MVA,1) -> 0.4 | F33: =INDEX(Osz4_Pts,1+SUMPRODUCT((Osz4_LB<$E33)+(Osz4_LB=$E33)*Osz4_Incl))*Osz4_W*($E33>=Osz4_Min) -> 13.5
C34: ÖSZ-5 partial award | D34: flag | E34: =INDEX(Dash_Partial,1,$A$1) -> 1 | F34: =$E34*Osz5_Pts*Osz5_W -> 5
C35: ÖSZ-6 performance security multiple | D35: x | E35: =INDEX(Dash_PB_Mult,1,$A$1) -> 1 | F35: =INDEX(Osz6_Pts,1+SUMPRODUCT((Osz6_LB<$E35)+(Osz6_LB=$E35)*Osz6_Incl))*Osz6_W -> 0
C36: ÖSZ-7 brownfield | D36: flag | E36: =INDEX(Dash_Brownfield,1,$A$1) -> 0 | F36: =$E36*Osz7_Pts*Osz7_W -> 0
C37: ÖSZ-8 shared connection | D37: flag | E37: =INDEX(Dash_Shared,1,$A$1) -> 1 | F37: =$E37*Osz8_Pts*Osz8_W -> 5
C38: ÖSZ-9 EU turbines | D38: flag | E38: =INDEX(Dash_EU_Turbine,1,$A$1) -> 1 | F38: =$E38*Osz9a_Pts*Osz9_W -> 12
C39: ÖSZ-9 EU transformers | D39: flag | E39: =INDEX(Dash_EU_Transformer,1,$A$1) -> 1 | F39: =$E39*Osz9b_Pts*Osz9_W -> 3
C40: Points total (E: EU route, F: CN route) | D40: points | E40: =ROUND(SUM($F30:$F39),Points_Decimals) -> 68.25 | F40: =ROUND(SUM($F30:$F37),Points_Decimals) -> 53.25
C41: Points, live turbine route | D41: points | E41: =IF(In_CN_Turbine=1,$F40,$E40) -> 68.25
C42: Failed tests (E: capacity, F: offerable range) | D42: # | E42: =N(In_MVA>In_Group_Cap)+N($E24<In_MVA)+N($E25>$E24)+N($E26<$E25*In_Min_Hours) -> 0 | F42: =($E30<>0)*($E30<Osz1_Min)+($E30>Osz1_Max)+($E31<>0)*($E31<Osz2_Min)+($E31>Osz2_Max) -> 0
A44: x | C44: Securities, fees and development costs (E: amount, F: date)
C45: Security base | D45: mHUF | E45: =$E24*In_Bench_Wind+$E26*In_Bench_BESS -> 88840
...

Sheet Checks
B2: =Dashboard!$C$3&" – Checks" -> Project Bora – Checks
C4: Period end | J4: =Calc_1!J$4 -> 46295 | K4: =Calc_1!K$4 -> 46387 | L4: =Calc_1!L$4 -> 46477 | M4: =Calc_1!M$4 -> 46568 | N4: =Calc_1!N$4 -> 46660 | O4: =Calc_1!O$4 -> 46752 | P4: =Calc_1!P$4 -> 46843 | Q4: =Calc_1!Q$4 -> 46934 | ... ET4: =Calc_1!ET$4 -> 59079
E9: Status | F9: Fails
A11: x | C11: Checks (0 = OK)
C12: Levers within the tender rules – Calc_1 | D12: flag | E12: =IF(F12=0,"OK","CHECK") -> OK | F12: =N(Calc_1!$E42+Calc_1!$F42>0) -> 0
C13: Levers within the tender rules – Calc_2 | D13: flag | E13: =IF(F13=0,"OK","CHECK") -> OK | F13: =N(Calc_2!$E42+Calc_2!$F42>0) -> 0
C14: Exit and COD fall on a quarter end – Calc_1 | D14: flag | E14: =IF(F14=0,"OK","CHECK") -> OK | F14: =N(COUNTIF(Calc_1!$J$4:$ET$4,Calc_1!$E12)=0)+N(COUNTIF(Calc_1!$J$4:$ET$4,In_COD)=0) -> 0
C15: Exit and COD fall on a quarter end – Calc_2 | D15: flag | E15: =IF(F15=0,"OK","CHECK") -> OK | F15: =N(COUNTIF(Calc_2!$J$4:$ET$4,Calc_2!$E12)=0)+N(COUNTIF(Calc_2!$J$4:$ET$4,In_COD)=0) -> 0
C16: Cash posted to the exit = buyer reimbursement + participation fee – Calc_1 | D16: flag | E16: =IF(F16=0,"OK","CHECK") -> OK | F16: =N(ABS(Calc_1!$E60-Calc_1!$E132-Calc_1!$E47)>Tolerance) -> 0
C17: Cash posted to the exit = buyer reimbursement + participation fee – Calc_2 | D17: flag | E17: =IF(F17=0,"OK","CHECK") -> OK | F17: =N(ABS(Calc_2!$E60-Calc_2!$E132-Calc_2!$E47)>Tolerance) -> 0
C18: RtB waterfall: paid + distributable = cash available – Calc_1 | D18: flag | E18: =IF(F18=0,"OK","CHECK") -> OK | F18: =N(ABS(Calc_1!$F141+Calc_1!$F142+Calc_1!$F133-Calc_1!$F132)>Tolerance) -> 0
C19: RtB waterfall: paid + distributable = cash available – Calc_2 | D19: flag | E19: =IF(F19=0,"OK","CHECK") -> OK | F19: =N(ABS(Calc_2!$F141+Calc_2!$F142+Calc_2!$F133-Calc_2!$F132)>Tolerance) -> 0
C20: FEP RtB build-up adds up to the profit – Calc_1 | D20: flag | E20: =IF(F20=0,"OK","CHECK") -> OK | F20: =N(ABS(Calc_1!$F141+Calc_1!$E147+Calc_1!$E58+Calc_1!$E150-Calc_1!$I151)>Tolerance) -> 0
C21: FEP RtB build-up adds up to the profit – Calc_2 | D21: flag | E21: =IF(F21=0,"OK","CHECK") -> OK | F21: =N(ABS(Calc_2!$F141+Calc_2!$E147+Calc_2!$E58+Calc_2!$E150-Calc_2!$I151)>Tolerance) -> 0
C22: RtB waterfall: no step paid above its amount due – Calc_1 | D22: flag | E22: =IF(F22=0,"OK","CHECK") -> OK | F22: =N(SUMPRODUCT(--(Calc_1!$F133:$F139>Calc_1!$E133:$E139+Tolerance))>0) -> 0
C23: RtB waterfall: no step paid above its amount due – Calc_2 | D23: flag | E23: =IF(F23=0,"OK","CHECK") -> OK | F23: =N(SUMPRODUCT(--(Calc_2!$F133:$F139>Calc_2!$E133:$E139+Tolerance))>0) -> 0
C24: COD waterfall: distributable not negative, paid within cash available – Calc_1 | D24: flag | E24: =IF(F24=0,"OK","CHECK") -> OK | F24: =N(Calc_1!$F166<-Tolerance)+N(SUM(Calc_1!$F162:$F165)>Calc_1!$F161+Tolerance) -> 0
C25: COD waterfall: distributable not negative, paid within cash available – Calc_2 | D25: flag | E25: =IF(F25=0,"OK","CHECK") -> OK | F25: =N(Calc_2!$F166<-Tolerance)+N(SUM(Calc_2!$F162:$F165)>Calc_2!$F161+Tolerance) -> 0
C26: Sources = uses to COD (equity + debt vs all-in cost lines) – Calc_1 | D26: flag | E26: =IF(F26=0,"OK","CHECK") -> OK | F26: =N(ABS(Calc_1!$E179-Calc_1!$F179)>Tolerance) -> 0
C27: Sources = uses to COD (equity + debt vs all-in cost lines) – Calc_2 | D27: flag | E27: =IF(F27=0,"OK","CHECK") -> OK | F27: =N(ABS(Calc_2!$E179-Calc_2!$F179)>Tolerance) -> 0
C28: Debt repaid by the end of the tenor – Calc_1 | D28: flag | E28: =IF(F28=0,"OK","CHECK") -> OK | F28: =SUM(J28:ET28) -> 0 | J28: =N((Calc_1!J$4>=Calc_1!$F17)*ABS(Calc_1!J100)>Tolerance) -> 0 | K28: =N((Calc_1!K$4>=Calc_1!$F17)*ABS(Calc_1!K100)>Tolerance) -> 0 | L28: =N((Calc_1!L$4>=Calc_1!$F17)*ABS(Calc_1!L100)>Tolerance) -> 0 | M28: =N((Calc_1!M$4>=Calc_1!$F17)*ABS(Calc_1!M100)>Tolerance) -> 0 | N28: =N((Calc_1!N$4>=Calc_1!$F17)*ABS(Calc_1!N100)>Tolerance) -> 0 | O28: =N((Calc_1!O$4>=Calc_1!$F17)*ABS(Calc_1!O100)>Tolerance) -> 0 | P28: =N((Calc_1!P$4>=Calc_1!$F17)*ABS(Calc_1!P100)>Tolerance) -> 0 | Q28: =N((Calc_1!Q$4>=Calc_1!$F17)*ABS(Calc_1!Q100)>Tolerance) -> 0 | ... ET28: =N((Calc_1!ET$4>=Calc_1!$F17)*ABS(Calc_1!ET100)>Tolerance) -> 0
C29: Debt repaid by the end of the tenor – Calc_2 | D29: flag | E29: =IF(F29=0,"OK","CHECK") -> OK | F29: =SUM(J29:ET29) -> 0 | J29: =N((Calc_2!J$4>=Calc_2!$F17)*ABS(Calc_2!J100)>Tolerance) -> 0 | K29: =N((Calc_2!K$4>=Calc_2!$F17)*ABS(Calc_2!K100)>Tolerance) -> 0 | L29: =N((Calc_2!L$4>=Calc_2!$F17)*ABS(Calc_2!L100)>Tolerance) -> 0 | M29: =N((Calc_2!M$4>=Calc_2!$F17)*ABS(Calc_2!M100)>Tolerance) -> 0 | N29: =N((Calc_2!N$4>=Calc_2!$F17)*ABS(Calc_2!N100)>Tolerance) -> 0 | O29: =N((Calc_2!O$4>=Calc_2!$F17)*ABS(Calc_2!O100)>Tolerance) -> 0 | P29: =N((Calc_2!P$4>=Calc_2!$F17)*ABS(Calc_2!P100)>Tolerance) -> 0 | Q29: =N((Calc_2!Q$4>=Calc_2!$F17)*ABS(Calc_2!Q100)>Tolerance) -> 0 | ... ET29: =N((Calc_2!ET$4>=Calc_2!$F17)*ABS(Calc_2!ET100)>Tolerance) -> 0
C30: XIRR returned a number on every route – Calc_1 | D30: flag | E30: =IF(F30=0,"OK","CHECK") -> OK | F30: =N(ISTEXT(Calc_1!$E152))+N(ISERROR(Calc_1!$E184))+N(ISERROR(Calc_1!$E169)) -> 0
C31: XIRR returned a number on every route – Calc_2 | D31: flag | E31: =IF(F31=0,"OK","CHECK") -> OK | F31: =N(ISTEXT(Calc_2!$E152))+N(ISERROR(Calc_2!$E184))+N(ISERROR(Calc_2!$E169)) -> 0
C32: Stored zero bid + Δ = live, base set – bid 1 | D32: flag | E32: =IF(F32=0,"OK","CHECK") -> OK | F32: =(Scenario_Selected=1)*(SUMPRODUCT(ABS(ZB_Live_1-ZB_Zero_Stored-ZB_Delta_1_Stored))>Tolerance) -> 0
C33: Stored zero bid + Δ = live, base set – bid 2 | D33: flag | E33: =IF(F33=0,"OK","CHECK") -> OK | F33: =(Scenario_Selected=1)*(SUMPRODUCT(ABS(ZB_Live_2-ZB_Zero_Stored-ZB_Delta_2_Stored))>Tolerance) -> 0
C34: Stored results = live case | D34: flag | E34: =IF(F34=0,"OK","CHECK") -> OK | F34: =--(SUMPRODUCT(ABS(Stored_Results-Live_Results)*(Scenario_Names=Scenario_Name))>Tolerance) -> 0
C36: Master check | E36: =IF(F36=0,"OK","CHECK") -> OK | F36: =SUMPRODUCT(ABS(F12:F34)) -> 0
C38: ***END***
