Workbook

Sheet Cover
B2: Project ARES – BORA onshore wind (Hungary)
B3: Bora IC model v4 – FEP returns: RtB sale, sale at COD, hold to maturity; RtB tender strategies S0–S4 (11-Oct-2026)
B5: Sheet | C5: Purpose | D5: Status
B6: Control Panel | C6: Route and tender-strategy selectors, the five tender strategies S0–S4 with their points, the offerable ranges and point bands (section g), every business input (one source) and the scenario comparison of all routes (Excel data table). | D6: Live – edit here
B7: Dashboard | C7: Results only: headline returns side by side (sell at RTB vs HTM build & operate), Case A/B bridges, FEP-file tie-out, sensitivities, turbine-case comparison (section 11, live). | D7: Live
B8: Inputs | C8: Every static input, per case (10 case columns), fed from the Control Panel; sections per topic. Yellow = estimates. | D8: Live – edit here (yellow = estimates)
B9: Curves | C9: EURIBOR forward curves and the open Aurora Hungary wind capture-price block (amber – paste in, then set Inputs E166 = 1). | D9: EURIBOR live; Aurora awaiting paste
B10: Deposits | C10: Schedule of MEKH tender securities and grid-connection fee: gross, netting, payable, grid month, k€, cash vs guarantee, recovery %, reconciliation to the 280 MW source table. | D10: Live
B11: MOIC | C11: Sell-at-RTB monthly grid (months 0-60), 14 numbered blocks. No inputs. | D11: Live
B12: HTM | C12: Annual hold-to-maturity engine 2026–2061 (30-year life from COD), 15 blocks: development phase (from MOIC/Deposits), capex, generation, revenue, opex, debt, tax, cash flows, results incl. NPV/Equity, sensitivities, buyer returns (block 14) and gearing sensitivity (block 15). | D12: Live – on estimates
B13: Open_Items | C13: Every open assumption, its interim treatment and owner. | D13: Working sheet – hidden for IC (right-click a tab → Unhide)
B14: Change_Log | C14: Full audit trail of every build phase, defect and fix. | D14: Working sheet – hidden for IC (right-click a tab → Unhide)
B15: Tender | C15: Tender strategies S0–S4 for Bora (set on the Control Panel) – GYIK rules; offerable ranges and band points (Control Panel section g); promise price effect on the RtB and COD exit vs the current bid; group caps and community purchase right (sections 8–9); live 5 × 5 returns matrix. | D15: Live – scenarios set on the Control Panel
B18: Conventions
B19: Blue text on cream fill = hard-coded input; black = formula; green = link from another sheet.
B20: Yellow fill = key assumption to confirm with the deal team; amber fill = awaiting data.
B21: Units are stated in column D of every sheet. EUR k unless stated; mHUF = HUF million; FX at Inputs E11.
B22: Sign convention on MOIC cash-flow blocks: positive = inflow to the party, negative = outflow.
B23: Month 0 = investment date (Inputs E23). Column G on MOIC holds row totals or scalar results.
B24: The IC paper of 27-Jul-26 was used for context only; no IC-deck number was typed into the model.
B26: Headline – active case
B27: Case | C27: =Inputs!E7 -> FEP base case
B28: FEP net profit (post-tax), k€ | C28: =MOIC!G182 -> 15173.724
B29: MOIC | C29: =MOIC!G186 -> 1.3121055
B30: IRR (post-tax) | C30: =MOIC!G187 -> 0.20894449
B31: Integrity checks | C31: =MOIC!G270 -> ALL OK
B32: HTM – project IRR (unlevered, post-tax) | C32: =HTM!G135 -> 0.108862
B33: HTM – equity IRR (levered, post-tax) | C33: =HTM!G139 -> 0.11965554
B34: HTM – FEP net cash over life, k€ | C34: =HTM!G144 -> 1303176.7
B35: HTM – LCOE, EUR/MWh | C35: =HTM!G156 -> 102.14704
B36: HTM integrity checks | C36: =HTM!G172 -> ALL OK
B37: FEP NPV / Equity – sell at RTB (HTM: see Dashboard) | C37: =MOIC!G194 -> 0.17787568
B38: Update note
B39: 06-Sep-26: final MEKH tender terms (30-Aug-26) reflected – see Inputs section Q, Open_Items 31–35 (item 31: no 400 kV node offered) and Change_Log entries 57–60 (rows 61–64). Figures from press coverage of the kiírás; verify against the MEKH document before the IC.
B40: 25-Sep-26: review comments reflected – 30-year life, COD-year operating fraction fix, land lease from NTP, devex in tax losses, debt 1.75% fee / 10-yr tenor, NPV/Equity, buyer IRR, gearing sensitivity; v3 archive tabs deleted. See Change_Log #63–#72.
B41: 02-Oct-26: open items #1–#15, #54–#55 closed; control panel moved to its own sheet; FEP exit-waterfall interest aligned to BORA Devex 01-Oct-26 (frozen 30/06/2029); single 8% discount rate; commitment fee and bid-offer inputs added; land lease 3 k€/MW/yr.
B42: IC version: working sheets Open_Items, Change_Log, Devex_FEP, BORA_Devex and Run_Map are hidden (not deleted) – unhide via right-click on any tab. No macro in this file.
B43: 08-Oct-26: 90 €/MWh PPA (10 yrs) applied to all turbine and sale-at-COD cases incl. Chinese; Tender sheet added (MEKH tender score, tender scenarios, promise price effect, returns matrix); sale at COD (cases 7 / 8). Chinese cases: no EU transformer points, substation capex −10%. HTM = hold to maturity.
B44: 10-Oct-26: Bora IC model v2 – one Control Panel (route / tender-scenario selectors, tender scenarios 0 / A / B / C with their points, every business input, scenario comparison of all routes via an Excel data table, buyer IRR at our COD price); no macro.
B45: 11-Oct-26 (v4): strategy S0 zero bid added (every commitment at its minimum, 0 points, valid – GYIK 17); price-effect reference stays S1 (current bid), so S0 shows a positive price effect; offerable ranges and band points on the Control Panel (section g); ÖSZ-9a points only with the EU-turbine commitment.

Sheet Control Panel
C2: Bora – Control Panel (IC model v4: RtB tender strategies S0–S4; RtB sale, sale at COD, hold to maturity)
C3: Blue cells on cream are the inputs – the model's input cells link here (one source). Everything else is a formula; Excel recalculates the whole workbook, including the scenario comparison (Excel data table, section f). No macro.
C4: If recalculation feels slow: File › Options › Formulas › 'Automatic except for data tables'; F9 then refreshes sections d and e. Other model inputs (rates, deposits, curves): blue cells on the Inputs and Tender sheets.
C6: a. Selection
C7: Item | D7: Unit | E7: Selection | F7: Code | G7: Name | O7: Model cell
C8: Active route | D8: route | E8: RtB sale (case 1) | F8: =INDEX($D$14:$D$18,MATCH($E$8,$C$14:$C$18,0)) -> 1 | O8: → Inputs E6 (model case) – while the data-table driver E10 = 0
C9: Active tender strategy (S0 zero bid … S4 maximum score) | D9: scenario | E9: S1 | F9: =MATCH($E$9&"",{"S1","S2","S3","S4","S0"},0)-1 -> 0 | G9: =INDEX(Tender!$E$11:$I$11,1,$F$9+1) -> S1 – Current bid | O9: → Tender E5 (0 … 4, F9) – while E10 = 0
C10: Data-table driver – leave 0 (input cell of the data table, section f) | D10: # | E10: 0 | O10: → Inputs E6 and Tender E5 take the run's case / scenario while Excel fills the table
C11: Model in use: case (Inputs E6) / tender scenario (Tender E5) | D11: check | E11: =Inputs!$E$6 -> 1 | F11: =Tender!$E$5 -> 0 | G11: =IF(AND(Inputs!$E$6=$F$8,Tender!$E$5=$F$9,$E$10=0),"OK","FAIL – set E10 back to 0") -> OK
C13: Route (list for E8) | D13: Case | E13: Exit | G13: Turbine | O13: Note
C14: RtB sale (case 1) | D14: 1 | E14: Sale of the project rights at RtB | G14: Scenario's turbine (row 22) | O14: RtB: no construction; buyer pays the RtB premium (± price effect of the promises)
C15: Sale at COD – European turbine (case 7) | D15: 7 | E15: Sale of 100 % of the SPV at COD | G15: European | O15: Cases 7 / 8: build, sell 100 % of the SPV at COD (price per installed MW)
C16: Sale at COD – Chinese turbine (case 8) | D16: 8 | E16: Sale of 100 % of the SPV at COD | G16: Chinese
C17: Hold to maturity – European turbine (case 2) | D17: 2 | E17: Build, operate, hold | G17: European | O17: Cases 2 / 3: build and operate for the full life (FEP JV share)
C18: Hold to maturity – Chinese turbine (case 3) | D18: 3 | E18: Build, operate, hold | G18: Chinese
C20: b. Tender strategies S0–S4 (ÖSZ commitments) – edit columns E:I; price-effect reference = S1 current bid
C21: Commitment | D21: Unit | E21: S0 – zero bid | F21: S1 – current bid | G21: S2 – free points | H21: S3 – ≈70 points | I21: S4 – max. score | J21: Active (Tender J) | O21: Tender row (columns E:I link here) / rule | P21: Link check
C22: Scenario name | D22: text | E22: S0 – Zero bid | F22: S1 – Current bid | G22: S2 – Free points | H22: S3 – Cost-efficient (≈70 points) | I22: S4 – Maximum score | J22: =Tender!$J$11 -> S1 – Current bid | O22: Tender E11:I11 | P22: =IF(AND((Tender!$E$11&"")=($F$22&""),(Tender!$F$11&"")=($G$22&""),(Tender!$G$11&"")=($H$22&""),(Tender!$H$11&"")=($I$22&""),(Tender!$I$11&"")=($E$22&"")),"OK","FAIL") -> OK
C23: ÖSZ-1 one-off municipal contribution | D23: k€/MW | E23: 0 | F23: 20 | G23: 20 | H23: 50 | I23: 50 | J23: =Tender!$J$12 -> 20 | O23: Tender E12:I12 | P23: =IF(AND(ABS(N(Tender!$E$12)-N($F$23))<=Tender!$E$32,ABS(N(Tender!$F$12)-N($G$23))<=Tender!$E$32,ABS(N(Tender!$G$12)-N($H$23))<=Tender!$E$32,ABS(N(Tender!$H$12)-N($I$23))<=Tender!$E$32,ABS(N(Tender!$I$12)-N($E$23))<=Tender!$E$32),"OK","FAIL") -> OK
C24: ÖSZ-2 annual community contribution on energy fed in | D24: €/MWh | E24: 0 | F24: 2 | G24: 2 | H24: 2 | I24: 3 | J24: =Tender!$J$13 -> 2 | O24: Tender E13:I13 | P24: =IF(AND(ABS(N(Tender!$E$13)-N($F$24))<=Tender!$E$32,ABS(N(Tender!$F$13)-N($G$24))<=Tender!$E$32,ABS(N(Tender!$G$13)-N($H$24))<=Tender!$E$32,ABS(N(Tender!$H$13)-N($I$24))<=Tender!$E$32,ABS(N(Tender!$I$13)-N($E$24))<=Tender!$E$32),"OK","FAIL") -> OK
C25: ÖSZ-3 overbuild – installed wind above the net connection capacity | D25: % | E25: 0 | F25: 0.305 | G25: 0.4 | H25: 0.4 | I25: 0.54 | J25: =Tender!$J$14 -> 0.305 | O25: Tender E14:I14 | P25: =IF(AND(ABS(N(Tender!$E$14)-N($F$25))<=Tender!$E$32,ABS(N(Tender!$F$14)-N($G$25))<=Tender!$E$32,ABS(N(Tender!$G$14)-N($H$25))<=Tender!$E$32,ABS(N(Tender!$H$14)-N($I$25))<=Tender!$E$32,ABS(N(Tender!$I$14)-N($E$25))<=Tender!$E$32),"OK","FAIL") -> OK
C26: ÖSZ-4 BESS power as % of the ratio basis (row below) | D26: % | E26: 0 | F26: 0.34482759 | G26: 0.45 | H26: 0.45 | I26: 0.51 | J26: =Tender!$J$15 -> 0.34482759 | O26: Tender E15:I15 | P26: =IF(AND(ABS(N(Tender!$E$15)-N($F$26))<=Tender!$E$32,ABS(N(Tender!$F$15)-N($G$26))<=Tender!$E$32,ABS(N(Tender!$G$15)-N($H$26))<=Tender!$E$32,ABS(N(Tender!$H$15)-N($I$26))<=Tender!$E$32,ABS(N(Tender!$I$15)-N($E$26))<=Tender!$E$32),"OK","FAIL") -> OK
C27: ÖSZ-4 BESS ratio basis (1 = installed wind, GYIK 20; 0 = net MVA) | D27: 1 / 0 | E27: 1 | F27: 1 | G27: 0 | H27: 0 | I27: 1 | J27: =Tender!$J$25 -> 1 | O27: Tender E25:I25 | P27: =IF(AND(ABS(N(Tender!$E$25)-N($F$27))<=Tender!$E$32,ABS(N(Tender!$F$25)-N($G$27))<=Tender!$E$32,ABS(N(Tender!$G$25)-N($H$27))<=Tender!$E$32,ABS(N(Tender!$H$25)-N($I$27))<=Tender!$E$32,ABS(N(Tender!$I$25)-N($E$27))<=Tender!$E$32),"OK","FAIL") -> OK
C28: ÖSZ-4 BESS duration | D28: h | E28: 4 | F28: 4 | G28: 4 | H28: 4 | I28: 4 | J28: =Tender!$J$16 -> 4 | O28: Tender E16:I16 | P28: =IF(AND(ABS(N(Tender!$E$16)-N($F$28))<=Tender!$E$32,ABS(N(Tender!$F$16)-N($G$28))<=Tender!$E$32,ABS(N(Tender!$G$16)-N($H$28))<=Tender!$E$32,ABS(N(Tender!$H$16)-N($I$28))<=Tender!$E$32,ABS(N(Tender!$I$16)-N($E$28))<=Tender!$E$32),"OK","FAIL") -> OK
C29: ÖSZ-6 performance security (% of the tender minimum) | D29: % | E29: 1 | F29: 1.5 | G29: 1.6 | H29: 2 | I29: 2.1 | J29: =Tender!$J$17 -> 1.5 | O29: Tender E17:I17 | P29: =IF(AND(ABS(N(Tender!$E$17)-N($F$29))<=Tender!$E$32,ABS(N(Tender!$F$17)-N($G$29))<=Tender!$E$32,ABS(N(Tender!$G$17)-N($H$29))<=Tender!$E$32,ABS(N(Tender!$H$17)-N($I$29))<=Tender!$E$32,ABS(N(Tender!$I$17)-N($E$29))<=Tender!$E$32),"OK","FAIL") -> OK
C30: ÖSZ-5 accept partial award (1 = yes) | D30: 1 / 0 | E30: 0 | F30: 0 | G30: 1 | H30: 1 | I30: 1 | J30: =Tender!$J$18 -> 0 | O30: Tender E18:I18 | P30: =IF(AND(ABS(N(Tender!$E$18)-N($F$30))<=Tender!$E$32,ABS(N(Tender!$F$18)-N($G$30))<=Tender!$E$32,ABS(N(Tender!$G$18)-N($H$30))<=Tender!$E$32,ABS(N(Tender!$H$18)-N($I$30))<=Tender!$E$32,ABS(N(Tender!$I$18)-N($E$30))<=Tender!$E$32),"OK","FAIL") -> OK
C31: ÖSZ-7 brownfield site ≥ 70 % (1 = yes) | D31: 1 / 0 | E31: 0 | F31: 0 | G31: 0 | H31: 0 | I31: 0 | J31: =Tender!$J$19 -> 0 | O31: Tender E19:I19 | P31: =IF(AND(ABS(N(Tender!$E$19)-N($F$31))<=Tender!$E$32,ABS(N(Tender!$F$19)-N($G$31))<=Tender!$E$32,ABS(N(Tender!$G$19)-N($H$31))<=Tender!$E$32,ABS(N(Tender!$H$19)-N($I$31))<=Tender!$E$32,ABS(N(Tender!$I$19)-N($E$31))<=Tender!$E$32),"OK","FAIL") -> OK
C32: ÖSZ-8 shared connection point and line (1 = yes) | D32: 1 / 0 | E32: 0 | F32: 0 | G32: 1 | H32: 1 | I32: 1 | J32: =Tender!$J$20 -> 0 | O32: Tender E20:I20 | P32: =IF(AND(ABS(N(Tender!$E$20)-N($F$32))<=Tender!$E$32,ABS(N(Tender!$F$20)-N($G$32))<=Tender!$E$32,ABS(N(Tender!$G$20)-N($H$32))<=Tender!$E$32,ABS(N(Tender!$H$20)-N($I$32))<=Tender!$E$32,ABS(N(Tender!$I$20)-N($E$32))<=Tender!$E$32),"OK","FAIL") -> OK
C33: ÖSZ-9a turbine of the scenario (1 = EU, 0 = CN) – RtB route and headline score | D33: 1 / 0 | E33: 0 | F33: 1 | G33: 1 | H33: 1 | I33: 1 | J33: =Tender!$J$22 -> 1 | O33: Tender E22:I22 | P33: =IF(AND(ABS(N(Tender!$E$22)-N($F$33))<=Tender!$E$32,ABS(N(Tender!$F$22)-N($G$33))<=Tender!$E$32,ABS(N(Tender!$G$22)-N($H$33))<=Tender!$E$32,ABS(N(Tender!$H$22)-N($I$33))<=Tender!$E$32,ABS(N(Tender!$I$22)-N($E$33))<=Tender!$E$32),"OK","FAIL") -> OK
C34: ÖSZ-9b EU-made generator transformer (1 = yes; European-turbine routes only) | D34: 1 / 0 | E34: 0 | F34: 0 | G34: 1 | H34: 1 | I34: 1 | J34: =Tender!$J$21 -> 0 | O34: Tender E21:I21 | P34: =IF(AND(ABS(N(Tender!$E$21)-N($F$34))<=Tender!$E$32,ABS(N(Tender!$F$21)-N($G$34))<=Tender!$E$32,ABS(N(Tender!$G$21)-N($H$34))<=Tender!$E$32,ABS(N(Tender!$H$21)-N($I$34))<=Tender!$E$32,ABS(N(Tender!$I$21)-N($E$34))<=Tender!$E$32),"OK","FAIL") -> OK
C35: Derived per scenario (Tender rows 40–45, live)
C36: Gross installed wind = net MVA × (1 + overbuild) | D36: MW | E36: =Tender!I$40 -> 200 | F36: =Tender!E$40 -> 261 | G36: =Tender!F$40 -> 280 | H36: =Tender!G$40 -> 280 | I36: =Tender!H$40 -> 308 | J36: =Tender!$J$40 -> 261 | O36: Tender E40:I40
C37: BESS power = ratio × basis MW | D37: MW | E37: =Tender!I$41 -> 0 | F37: =Tender!E$41 -> 90 | G37: =Tender!F$41 -> 90 | H37: =Tender!G$41 -> 90 | I37: =Tender!H$41 -> 157.08 | J37: =Tender!$J$41 -> 90 | O37: Tender E41:I41
C38: BESS energy (power × duration) | D38: MWh | E38: =Tender!I$42 -> 0 | F38: =Tender!E$42 -> 360 | G38: =Tender!F$42 -> 360 | H38: =Tender!G$42 -> 360 | I38: =Tender!H$42 -> 628.32 | J38: =Tender!$J$42 -> 360 | O38: Tender E42:I42
C39: BESS ratio of installed wind (ÖSZ-4 x, GYIK 20) | D39: % | E39: =Tender!I$44 -> 0 | F39: =Tender!E$44 -> 0.34482759 | G39: =Tender!F$44 -> 0.32142857 | H39: =Tender!G$44 -> 0.32142857 | I39: =Tender!H$44 -> 0.51 | J39: =Tender!$J$44 -> 0.34482759 | O39: Tender E44:I44
C40: Clipping loss at the connection capacity (L20 estimate) | D40: % | E40: =Tender!I$45 -> 0 | F40: =Tender!E$45 -> 0.0465125 | G40: =Tender!F$45 -> 0.08 | H40: =Tender!G$45 -> 0.08 | I40: =Tender!H$45 -> 0.1458 | J40: =Tender!$J$45 -> 0.0465125 | O40: Tender E45:I45
C41: Points – Annex 3 weight × Annex 4 inner points, GYIK rules (Tender rows 51–88, live)
C42: ÖSZ-1 municipal contribution | D42: pts | E42: =Tender!I$55 -> 0 | F42: =Tender!E$55 -> 4 | G42: =Tender!F$55 -> 4 | H42: =Tender!G$55 -> 20 | I42: =Tender!H$55 -> 20 | O42: Tender E55:I55
C43: ÖSZ-2 community contribution | D43: pts | E43: =Tender!I$60 -> 0 | F43: =Tender!E$60 -> 0 | G43: =Tender!F$60 -> 0 | H43: =Tender!G$60 -> 0 | I43: =Tender!H$60 -> 15 | O43: Tender E60:I60
C44: ÖSZ-3 overbuild | D44: pts | E44: =Tender!I$65 -> 0 | F44: =Tender!E$65 -> 7 | G44: =Tender!F$65 -> 9 | H44: =Tender!G$65 -> 9 | I44: =Tender!H$65 -> 10 | O44: Tender E65:I65
...

Sheet Tender
C2: Tender – MEKH capacity tender 2026 for Bora: tender strategies S0–S4 (columns E:I; E = S1 current bid = price-effect reference, I = S0 zero bid; J = active), points (GYIK rules), price effect of the promises and the returns matrix
C3: Column J = the active strategy (E5, set on the Control Panel) → Inputs G20 / G21 / G90 / G233 / G234 / G297 / M230 / N230, HTM E36 and row 340. Strategy columns E:I link to the Control Panel (one source). Blue = input, green = link, black = formula. Section 5 is live (Control Panel data table); section 7 holds the checks (→ MOIC G271, HTM G173).
C5: Active tender strategy (0 = S1, 1 = S2, 2 = S3, 3 = S4, 4 = S0) – set on the Control Panel (E9; data-table runs: E10) | D5: # | E5: =IF('Control Panel'!$E$10=0,'Control Panel'!$F$9,INDEX('Control Panel'!$D$306:$D$330,'Control Panel'!$E$10)) -> 0 | F5: =$J$11 -> S1 – Current bid
C7: Active case (set on the Control Panel → Inputs E6) | D7: # | E7: =Inputs!$E$6 -> 1 | F7: =Inputs!$E$7 -> FEP base case
C9: 1. Tender strategies – columns E:I = S1 / S2 / S3 / S4 / S0 (links to the Control Panel, section b), column J = active strategy; price-effect reference = S1 (column E)
C10: Item | D10: Unit | E10: S1 – current bid (reference) | F10: S2 – free points | G10: S3 – ≈70 points | H10: S4 – maximum score | I10: S0 – zero bid | J10: Active | K10: Feeds / note
C11: Scenario name | D11: Text | E11: ='Control Panel'!$F$22 -> S1 – Current bid | F11: ='Control Panel'!$G$22 -> S2 – Free points | G11: ='Control Panel'!$H$22 -> S3 – Cost-efficient (≈70 points) | H11: ='Control Panel'!$I$22 -> S4 – Maximum score | I11: ='Control Panel'!$E$22 -> S0 – Zero bid | J11: =INDEX($E11:$I11,1,$E$5+1) -> S1 – Current bid | K11: Selector E5 (Control Panel E9)
C12: ÖSZ-1 One-off municipal contribution | D12: k€/MW | E12: ='Control Panel'!$F$23 -> 20 | F12: ='Control Panel'!$G$23 -> 20 | G12: ='Control Panel'!$H$23 -> 50 | H12: ='Control Panel'!$I$23 -> 50 | I12: ='Control Panel'!$E$23 -> 0 | J12: =INDEX($E12:$I12,1,$E$5+1) -> 20 | K12: → Inputs G233 (paid in the COD year on net MW, HTM row 29)
C13: ÖSZ-2 Annual community contribution on energy fed in | D13: €/MWh | E13: ='Control Panel'!$F$24 -> 2 | F13: ='Control Panel'!$G$24 -> 2 | G13: ='Control Panel'!$H$24 -> 2 | H13: ='Control Panel'!$I$24 -> 3 | I13: ='Control Panel'!$E$24 -> 0 | J13: =INDEX($E13:$I13,1,$E$5+1) -> 2 | K13: → Inputs G234 (every operating year, HTM row 59)
C14: ÖSZ-3 Overbuild – gross wind above net MVA | D14: % | E14: ='Control Panel'!$F$25 -> 0.305 | F14: ='Control Panel'!$G$25 -> 0.4 | G14: ='Control Panel'!$H$25 -> 0.4 | H14: ='Control Panel'!$I$25 -> 0.54 | I14: ='Control Panel'!$E$25 -> 0 | J14: =INDEX($E14:$I14,1,$E$5+1) -> 0.305 | K14: Gross installed wind = net MVA × (1 + overbuild), row 40 per strategy (S1: 30.5 % → 261 MW, Munka1: Bora1 151 + Bora2 110; S2 / S3: 40 % → 280 MW; S4: 54 % → 308 MW; S0: 0 % → 200 MW)
C15: ÖSZ-4 BESS power ratio (basis: row 25 – installed wind or net MVA) | D15: % | E15: ='Control Panel'!$F$26 -> 0.34482759 | F15: ='Control Panel'!$G$26 -> 0.45 | G15: ='Control Panel'!$H$26 -> 0.45 | H15: ='Control Panel'!$I$26 -> 0.51 | I15: ='Control Panel'!$E$26 -> 0 | J15: =INDEX($E15:$I15,1,$E$5+1) -> 0.34482759 | K15: BESS = ratio × basis (row 25), row 41 per strategy. S1: 90 MW = 34.48 % of the 261 MW installed wind (Munka1: Bora 70 + 20 MW); S2 / S3: 45 % of the net MVA = 90 MW; S4: 51 % of installed wind (GYIK 20); S0: no BESS
C16: ÖSZ-4 BESS duration | D16: h | E16: ='Control Panel'!$F$28 -> 4 | F16: ='Control Panel'!$G$28 -> 4 | G16: ='Control Panel'!$H$28 -> 4 | H16: ='Control Panel'!$I$28 -> 4 | I16: ='Control Panel'!$E$28 -> 4 | J16: =INDEX($E16:$I16,1,$E$5+1) -> 4 | K16: → Inputs G21 (≥ 4 h needed for ÖSZ-4 points)
C17: ÖSZ-6 Performance security as % of the tender minimum | D17: % | E17: ='Control Panel'!$F$29 -> 1.5 | F17: ='Control Panel'!$G$29 -> 1.6 | G17: ='Control Panel'!$H$29 -> 2 | H17: ='Control Panel'!$I$29 -> 2.1 | I17: ='Control Panel'!$E$29 -> 1 | J17: =INDEX($E17:$I17,1,$E$5+1) -> 1.5 | K17: → Inputs G90 performance bond uplift (Deposits row 10)
C18: ÖSZ-5 Accept partial award | D18: 1 / 0 | E18: ='Control Panel'!$F$30 -> 0 | F18: ='Control Panel'!$G$30 -> 1 | G18: ='Control Panel'!$H$30 -> 1 | H18: ='Control Panel'!$I$30 -> 1 | I18: ='Control Panel'!$E$30 -> 0 | J18: =INDEX($E18:$I18,1,$E$5+1) -> 0 | K18: Scored; no cost modelled
C19: ÖSZ-7 Brownfield site (≥ 70 %) | D19: 1 / 0 | E19: ='Control Panel'!$F$31 -> 0 | F19: ='Control Panel'!$G$31 -> 0 | G19: ='Control Panel'!$H$31 -> 0 | H19: ='Control Panel'!$I$31 -> 0 | I19: ='Control Panel'!$E$31 -> 0 | J19: =INDEX($E19:$I19,1,$E$5+1) -> 0 | K19: Not available at Bora's node – no points in any scenario
C20: ÖSZ-8 Shared connection point and line | D20: 1 / 0 | E20: ='Control Panel'!$F$32 -> 0 | F20: ='Control Panel'!$G$32 -> 1 | G20: ='Control Panel'!$H$32 -> 1 | H20: ='Control Panel'!$I$32 -> 1 | I20: ='Control Panel'!$E$32 -> 0 | J20: =INDEX($E20:$I20,1,$E$5+1) -> 0 | K20: Scored; no cost modelled
C21: ÖSZ-9b EU-made generator transformer (European-turbine routes only) | D21: 1 / 0 | E21: ='Control Panel'!$F$34 -> 0 | F21: ='Control Panel'!$G$34 -> 1 | G21: ='Control Panel'!$H$34 -> 1 | H21: ='Control Panel'!$I$34 -> 1 | I21: ='Control Panel'!$E$34 -> 0 | J21: =INDEX($E21:$I21,1,$E$5+1) -> 0 | K21: Chinese routes: non-EU transformer, substation capex reduced by Tender E29 (Inputs I167 / N167)
C22: Turbine of the scenario (1 = European, 0 = Chinese) | D22: 1 / 0 | E22: ='Control Panel'!$F$33 -> 1 | F22: ='Control Panel'!$G$33 -> 1 | G22: ='Control Panel'!$H$33 -> 1 | H22: ='Control Panel'!$I$33 -> 1 | I22: ='Control Panel'!$E$33 -> 0 | J22: =INDEX($E22:$I22,1,$E$5+1) -> 1 | K22: Headline score of the scenario and the score of its RtB route; ÖSZ-9a turbine points only for European
C23: Sale at COD price – European turbine, before clipping | D23: k€/gross MW | E23: ='Control Panel'!$E$133 -> 2450 | F23: ='Control Panel'!$E$133 -> 2450 | G23: ='Control Panel'!$E$133 -> 2450 | H23: ='Control Panel'!$E$133 -> 2450 | I23: ='Control Panel'!$E$133 -> 2450 | J23: =INDEX($E23:$I23,1,$E$5+1) -> 2450 | K23: One price for all scenarios (Control Panel section c); × (1 − clip) per scenario (row 46) → Inputs M230 (case 7)
C24: Sale at COD price – Chinese turbine, before clipping | D24: k€/gross MW | E24: ='Control Panel'!$E$134 -> 2100 | F24: ='Control Panel'!$E$134 -> 2100 | G24: ='Control Panel'!$E$134 -> 2100 | H24: ='Control Panel'!$E$134 -> 2100 | I24: ='Control Panel'!$E$134 -> 2100 | J24: =INDEX($E24:$I24,1,$E$5+1) -> 2100 | K24: One price for all scenarios (Control Panel section c); × (1 − clip) per scenario (row 47) → Inputs N230 (case 8)
C25: ÖSZ-4 BESS ratio basis (1 = % of installed gross wind, GYIK 20; 0 = % of net MVA) | D25: 1 / 0 | E25: ='Control Panel'!$F$27 -> 1 | F25: ='Control Panel'!$G$27 -> 0 | G25: ='Control Panel'!$H$27 -> 0 | H25: ='Control Panel'!$I$27 -> 1 | I25: ='Control Panel'!$E$27 -> 1 | J25: =INDEX($E25:$I25,1,$E$5+1) -> 1 | K25: Round 5 (GYIK 20): ÖSZ-4 is scored on BESS MW ÷ installed wind MW (BT1)
C26: 1b. Common inputs (one value for all scenarios) | D26: Unit | E26: Value | F26: Note
C27: Reference overbuild of the L20 clipping estimate | D27: % | E27: 0.2 | F27: clip(x) = L20 × (x ÷ 20 %)² – estimate, replace with an 8,760 h export-cap study
C28: Clipping loss at the reference overbuild (L20) – ESTIMATE, all scenarios incl. 0 | D28: % | E28: ='Control Panel'!$E$113 -> 0.02 | F28: Physical effect of the overbuild (row 43), so it applies in every scenario; set on the Control Panel
C29: Chinese routes: substation and 132 kV bay capex reduction (non-EU transformer) | D29: % | E29: 0.1 | F29: → Inputs I167 / N167 (cases 3 / 8)
C30: Pass-through of the promises' PV into the exit price (RtB and sale at COD) | D30: % | E30: ='Control Panel'!$E$89 -> 1 | F30: 100 % = the buyer deducts the full PV of the promises relative to the S1 current-bid reference (promises below it, e.g. S0, add to the price); set on the Control Panel
C31: Performance security held after COD (buyer's guarantee fee, RtB price effect) | D31: months | E31: 6 | F31: Tender XII.2 – security returned 6 months after COD (as v5)
C32: Check tolerance – absolute | D32: k€ / mHUF | E32: 0.01 | F32: Used by the check rows (section 7, Deposits)
C33: Check tolerance – relative | D33: x | E33: 1e-06 | F33: Live vs data-table tie-out (section 6)
C35: 2. Strategy block – each tender strategy applied to Bora (columns E:I = S1 / S2 / S3 / S4 / S0; column J = active strategy → Inputs / HTM)
C36: Item | D36: Unit | E36: S1 | F36: S2 | G36: S3 | H36: S4 | I36: S0 | J36: Active scenario | K36: Note
C37: Net grid connection capacity (Annex 1) | D37: MVA | E37: ='Control Panel'!$E$74 -> 200 | F37: =$E37 -> 200 | G37: =$E37 -> 200 | H37: =$E37 -> 200 | I37: =$E37 -> 200 | J37: =$E37 -> 200 | K37: Control Panel section c – RtB premium (default basis), grid fees, TSO bond
C38: S1 current bid (column E) – gross installed wind (reference of the price effect = column E row 40) | D38: MW | E38: =$E$40 -> 261 | J38: =$E38 -> 261 | K38: Munka1: Bora1 151 + Bora2 110 = 261 MW
C39: S1 current bid (column E) – BESS power (reference of the price effect = column E row 41) | D39: MW | E39: =$E$41 -> 90 | J39: =$E39 -> 90 | K39: Munka1: Bora 70 + 20 MW
C40: Gross installed wind = net MVA × (1 + overbuild) | D40: MW | E40: =ROUND($E37*(1+E$14),6) -> 261 | F40: =ROUND($E37*(1+F$14),6) -> 280 | G40: =ROUND($E37*(1+G$14),6) -> 280 | H40: =ROUND($E37*(1+H$14),6) -> 308 | I40: =ROUND($E37*(1+I$14),6) -> 200 | J40: =INDEX($E40:$I40,1,$E$5+1) -> 261 | K40: Active (column I) → Inputs G297 (installed wind)
C41: BESS power = ratio × basis MW (row 25) | D41: MW | E41: =ROUND(E$15*CHOOSE(E$25+1,$E37,E40),6) -> 90 | F41: =ROUND(F$15*CHOOSE(F$25+1,$E37,F40),6) -> 90 | G41: =ROUND(G$15*CHOOSE(G$25+1,$E37,G40),6) -> 90 | H41: =ROUND(H$15*CHOOSE(H$25+1,$E37,H40),6) -> 157.08 | I41: =ROUND(I$15*CHOOSE(I$25+1,$E37,I40),6) -> 0 | J41: =INDEX($E41:$I41,1,$E$5+1) -> 90 | K41: Active → Inputs G20 / G282; ratio × installed wind (row 25 = 1) or × net MVA
C42: BESS energy (power × duration) | D42: MWh | E42: =E41*E$16 -> 360 | F42: =F41*F$16 -> 360 | G42: =G41*G$16 -> 360 | H42: =H41*H$16 -> 628.32 | I42: =I41*I$16 -> 0 | J42: =INDEX($E42:$I42,1,$E$5+1) -> 360
C43: Overbuild (gross wind ÷ net MVA − 1) | D43: % | E43: =E40/E37-1 -> 0.305 | F43: =F40/F37-1 -> 0.4 | G43: =G40/G37-1 -> 0.4 | H43: =H40/H37-1 -> 0.54 | I43: =I40/I37-1 -> 0 | J43: =INDEX($E43:$I43,1,$E$5+1) -> 0.305 | K43: ÖSZ-3 commitment
C44: BESS ratio (BESS MW ÷ installed gross wind MW – GYIK 20, BT1) | D44: % | E44: =E41/E40 -> 0.34482759 | F44: =F41/F40 -> 0.32142857 | G44: =G41/G40 -> 0.32142857 | H44: =H41/H40 -> 0.51 | I44: =I41/I40 -> 0 | J44: =INDEX($E44:$I44,1,$E$5+1) -> 0.34482759 | K44: ÖSZ-4 commitment (round 5: was ÷ net MVA)
C45: Clipping loss at the connection capacity (L20 × (overbuild ÷ reference)²) | D45: % | E45: =$E$28*(MAX(0,E43)/$E$27)^2 -> 0.0465125 | F45: =$E$28*(MAX(0,F43)/$E$27)^2 -> 0.08 | G45: =$E$28*(MAX(0,G43)/$E$27)^2 -> 0.08 | H45: =$E$28*(MAX(0,H43)/$E$27)^2 -> 0.1458 | I45: =$E$28*(MAX(0,I43)/$E$27)^2 -> 0 | J45: =INDEX($E45:$I45,1,$E$5+1) -> 0.0465125 | K45: Active → HTM E36 (generation × (1 − clip)), applied once
...

Sheet Dashboard
B1: HUN Onshore Wind – MOIC model v5
C2: Dashboard – results only. All inputs and the route / tender-scenario selectors are on the Control Panel; sections 1 onwards show results.
C3: Live: case / tender scenario (set on the Control Panel) → | E3: =Inputs!$E$7 -> FEP base case | F3: =Tender!$J$11 -> S1 – Current bid
C6: 1. Headline returns – sell at RTB (active case) vs hold-to-maturity with European / Chinese turbine | E6: Sell at RTB | F6: HTM – European turbine | G6: HTM – Chinese turbine
C7: Active case | D7: Name | E7: ="Case "&Inputs!$E$6&" – "&Inputs!E7 -> Case 1 – FEP base case | F7: ="Case 2 – "&Inputs!H7 -> Case 2 – European turbine | G7: ="Case 3 – "&Inputs!I7 -> Case 3 – Chinese turbine
C8: Case description | D8: Text | E8: =FIXED(Inputs!E141,0)&" k€/MW RTB premium × "&FIXED(Inputs!E150,0)&IF(Inputs!E149=1," MW installed wind (FLAG)"," MVA net")&", sale "&Inputs!E28&" months after RTB" -> 150 k€/MW RTB premium × 200 MVA net, sale 9 months after RTB | F8: =FIXED(IF(Inputs!H162="",Inputs!$G162,Inputs!H162),0)&" k€/MW, "&FIXED(IF(Inputs!H217="",Inputs!$G217,Inputs!H217)*100,0)&"% debt, PPA "&FIXED(IF(Inputs!H191="",Inputs!$G191,Inputs!H191),0)&" €/MWh" -> 950 k€/MW, 60% debt, PPA 90 €/MWh | G8: =FIXED(IF(Inputs!I162="",Inputs!$G162,Inputs!I162),0)&" k€/MW, "&FIXED(IF(Inputs!I217="",Inputs!$G217,Inputs!I217)*100,0)&"% debt, PPA "&FIXED(IF(Inputs!I191="",Inputs!$G191,Inputs!I191),0)&" €/MWh" -> 500 k€/MW, 50% debt, PPA 90 €/MWh
C9: Successful capacity – net grid / gross wind | D9: MW | E9: =TEXT(Inputs!E18,"0")&" / "&TEXT(Inputs!E29,"0") -> 200 / 261 | F9: =TEXT(Inputs!$E$18,"0")&" / "&TEXT(Inputs!$E$29,"0") -> 200 / 261 | G9: =TEXT(Inputs!$E$18,"0")&" / "&TEXT(Inputs!$E$29,"0") -> 200 / 261
C10: Exit / price basis | D10: k€/MW | €/MWh | E10: =Inputs!E141 -> 150 | F10: =E218 -> 136.7236 | G10: =F218 -> 136.7236
C11: Gross proceeds / lifetime revenue | D11: k€ | E11: =MOIC!G171 -> 64143.615 | F11: =E219 -> 2358431.6 | G11: =F219 -> 2358431.6
C12: FEP net profit (pre-tax) – MOIC basis (after signing fee, DD, guarantee fees; before cost of capital) | D12: k€ / mHUF | E12: =FIXED(MOIC!$G$172,0)&" / "&FIXED(MOIC!$G$172*Inputs!$E$11/1000,0) -> 15,526 / 5,667 | F12: =FIXED(E223,0)&" / "&FIXED(E223*Inputs!$E$11/1000,0) -> 1,254,061 / 457,732 | G12: =FIXED(F223,0)&" / "&FIXED(F223*Inputs!$E$11/1000,0) -> 1,431,277 / 522,416
C13: FEP net profit (pre-tax) – Case B: with cost of capital | D13: k€ / mHUF | E13: =FIXED($L$40,0)&" / "&FIXED(($L$40)*Inputs!$E$11/1000,0) -> 10,273 / 3,750 | F13: - | G13: -
C14: FEP net profit (post-tax) – MOIC basis (MOIC G182; basis of headline MOIC / IRR) | D14: k€ / mHUF | E14: =FIXED(MOIC!$G$182,0)&" / "&FIXED(MOIC!$G$182*Inputs!$E$11/1000,0) -> 15,174 / 5,538 | F14: =FIXED(E224,0)&" / "&FIXED(E224*Inputs!$E$11/1000,0) -> 1,137,959 / 415,355 | G14: =FIXED(F224,0)&" / "&FIXED(F224*Inputs!$E$11/1000,0) -> 1,299,225 / 474,217
C15: FEP net profit (post-tax) – Case B: with cost of capital | D15: k€ / mHUF | E15: =FIXED($L$42,0)&" / "&FIXED(($L$42)*Inputs!$E$11/1000,0) -> 9,921 / 3,621 | F15: - | G15: -
C16: FEP MOIC | D16: x | E16: =MOIC!G186 -> 1.3121055 | F16: =E228 -> 6.133291 | G16: =F228 -> 7.7915901
C17: FEP IRR (post-tax) | D17: % | E17: =MOIC!G187 -> 0.20894449 | F17: =E225 -> 0.09991356 | G17: =F225 -> 0.13111233
C18: FEP NPV (post-tax) at NPV / Equity rate (Inputs E253) | D18: k€ | E18: =MOIC!G192 -> 7253.3564 | F18: =E226 -> 62081.307 | G18: =F226 -> 139279.29
C19: FEP NPV / Equity (NPV ÷ PV of equity invested) | D19: x | E19: =MOIC!G194 -> 0.17787568 | F19: =E227 -> 0.37667365 | G19: =F227 -> 0.97347376
C20: Project IRR – unlevered, post-tax | D20: % | E20: n/a | F20: =E233 -> 0.091701924 | G20: =F233 -> 0.12109681
C21: FEP peak cumulative exposure | D21: k€ | E21: =MOIC!G188 -> 48525.878 | F21: =E229 -> 221682.18 | G21: =F229 -> 191299.15
C22: FEP peak cumulative exposure | D22: mHUF | E22: =MOIC!G189 -> 17711.945 | F22: =F21*Inputs!$E$11/1000 -> 80913.997 | G22: =G21*Inputs!$E$11/1000 -> 69824.188
C23: Economic profit (RTB) / project NPV (HTM) | D23: k€ | E23: =MOIC!G190 -> 9943.1039 | F23: =E234 -> 47524.011 | G23: =F234 -> 133488.73
C24: Timeline | D24: Text | E24: =CHOOSE(MONTH(Inputs!E27),"Jan","Feb","Mar","Apr","May","Jun","Jul","Aug","Sep","Oct","Nov","Dec")&"-"&RIGHT(YEAR(Inputs!E27),2)&" → RTB "&CHOOSE(MONTH(Inputs!E56),"Jan","Feb","Mar","Apr","May","Jun","Jul","Aug","Sep","Oct","Nov","Dec")&"-"&RIGHT(YEAR(Inputs!E56),2)&" → sale "&CHOOSE(MONTH(Inputs!E58),"Jan","Feb","Mar","Apr","May","Jun","Jul","Aug","Sep","Oct","Nov","Dec")&"-"&RIGHT(YEAR(Inputs!E58),2) -> Jul-26 → RTB Jun-29 → sale Mar-30 | F24: ="COD "&CHOOSE(MONTH(Inputs!$E$155),"Jan","Feb","Mar","Apr","May","Jun","Jul","Aug","Sep","Oct","Nov","Dec")&"-"&RIGHT(YEAR(Inputs!$E$155),2)&" → capex "&FIXED(E212,0)&" k€/MW → payback "&E230 -> COD Sep-31 → capex 2,156 k€/MW → payback 2044 | G24: ="COD "&CHOOSE(MONTH(Inputs!$E$155),"Jan","Feb","Mar","Apr","May","Jun","Jul","Aug","Sep","Oct","Nov","Dec")&"-"&RIGHT(YEAR(Inputs!$E$155),2)&" → capex "&FIXED(F212,0)&" k€/MW → payback "&F230 -> COD Sep-31 → capex 1,533 k€/MW → payback 2041
C25: Integrity checks | D25: Status | E25: =MOIC!G270 -> ALL OK | F25: =E240 -> ALL OK | G25: =F240 -> ALL OK
C26: Sell-at-RTB column follows the active case (Inputs E6). European / Chinese columns (F–G) link to section 11 (live – Control Panel data table, active tender scenario). Tender local-benefit commitments (20 k€/MW one-off at COD, 2 €/MWh on generation) sit in HTM only; a buyer at RTB inherits them, so read the RTB premium as gross of the 20 k€/MW.
C27: 2. FEP sources & uses to exit (cash actually funded by FEP; k€ and mHUF at Inputs FX) | H27: ="FEP profit – two cases (sale "&DAY(Inputs!E58)&"/"&TEXT(MONTH(Inputs!E58),"00")&"/"&YEAR(Inputs!E58)&"; "&LEFT(Inputs!$F$64,FIND(":",Inputs!$F$64)-1)&")" -> FEP profit – two cases (sale 31/03/2030; Interest pause 30/06/2029 – 01/01/2030) | K27: Case A: profit bridge – before deal costs, guarantee fees and cost of capital (not a headline) | L27: Case B: with cost of capital
C28: Uses | E28: k€ | F28: mHUF | H28: Interest on recoverable loan (12 % per line to the RtB sale, interest pause excluded: cash TSO bond, connection fees, participation fee) | J28: k€ | K28: =Deposits!$Y$23+Deposits!$Y$24 -> 4370.0331 | L28: =K28 -> 4370.0331
C29: DD and transaction costs | D29: k€ | E29: =-MOIC!G159 -> 150 | F29: =E29*Inputs!$E$11/1000 -> 54.75 | H29: Interest on at-risk loan (20%) | J29: k€ | K29: =MOIC!G126 -> 0 | L29: =K29 -> 0
C30: Signing fee | D30: k€ | E30: =-MOIC!G158 -> 250 | F30: =E30*Inputs!$E$11/1000 -> 91.25 | H30: Return on at-risk devex and land: MAX(20 % to the RtB sale excl. the pause, 2×) – principal × 1 | J30: k€ | K30: =MOIC!G131 -> 3087.8459 | L30: =K30 -> 3087.8459
C31: Devex (FEP-funded share, incl. land costs reimbursed by buyer at RtB exit) | D31: k€ | E31: =-MOIC!G162 -> 3087.8459 | F31: =E31*Inputs!$E$11/1000 -> 1127.0638 | H31: Interest on bank-guaranteed securities (6%) | J31: k€ | K31: =MOIC!G169 -> 3219.9262 | L31: =K31 -> 3219.9262
C32: Securities and connection fee – cash posted, net of pre-sale refunds (FEP share) | D32: k€ | E32: =-(MOIC!G160+MOIC!G161) -> 41448.238 | F32: =E32*Inputs!$E$11/1000 -> 15128.607 | H32: Total interest earned by FEP | J32: k€ | K32: =SUM(K28:K31) -> 10677.805 | L32: =SUM(L28:L31) -> 10677.805
C33: Bank guarantee fees | D33: k€ | E33: =-MOIC!G163 -> 3681.2145 | F33: =E33*Inputs!$E$11/1000 -> 1343.6433 | H33: FEP 70% share of distributable proceeds | J33: k€ | K33: =MOIC!G170 -> 11608.63 | L33: =K33 -> 11608.63
C34: Total uses | D34: k€ | E34: =SUM(E29:E33) -> 48617.299 | F34: =E34*Inputs!$E$11/1000 -> 17745.314 | H34: Less: devex and participation fee carried by FEP (not repaid; land costs repaid by buyer at RtB exit added back) | J34: k€ | K34: =MOIC!G162+MOIC!G161+MOIC!G167 -> -2678.9045 | L34: =K34 -> -2678.9045
H35: FEP profit before costs of capital and deal costs | J35: k€ | K35: =K32+K33+K34 -> 19607.531 | L35: =L32+L33+L34 -> 19607.531
C36: Sources | E36: k€ | F36: mHUF | H36: Less: signing fee | J36: k€ | K36: 0 | L36: =MOIC!G158 -> -250
C37: FEP equity (signing fee + transaction costs) | D37: k€ | E37: =-(MOIC!G158+MOIC!G159) -> 400 | F37: =E37*Inputs!$E$11/1000 -> 146 | H37: Less: DD and transaction costs | J37: k€ | K37: 0 | L37: =MOIC!G159 -> -150
C38: FEP shareholder loan – recoverable (refunded if the project fails) | D38: k€ | E38: =-MOIC!G160 -> 41431.8 | F38: =E38*Inputs!$E$11/1000 -> 15122.607 | H38: Less: bank guarantee fees (guarantee price on guaranteed securities) | J38: k€ | K38: 0 | L38: =MOIC!G163 -> -3681.2145
C39: FEP shareholder loan – at-risk (devex and land costs; all deposits and grid bonds are refunded on failure) | D39: k€ | E39: =-(MOIC!G161+MOIC!G162) -> 3104.2843 | F39: =E39*Inputs!$E$11/1000 -> 1133.0638 | H39: Less: cost of capital on cash-funded items (Inputs E72) | J39: k€ | K39: 0 | L39: =-MOIC!G200 -> -5253.0928
C40: FEP direct funding of guarantee fees | D40: k€ | E40: =-MOIC!G163 -> 3681.2145 | F40: =E40*Inputs!$E$11/1000 -> 1343.6433 | H40: FEP net profit (pre-tax) | J40: k€ | K40: =SUM(K35:K39) -> 19607.531 | L40: =SUM(L35:L39) -> 10273.223
C41: Total sources | D41: k€ | E41: =SUM(E37:E40) -> 48617.299 | F41: =E41*Inputs!$E$11/1000 -> 17745.314 | H41: Less: corporate income tax – actual tax per MOIC G174 (70% share gain exempt under participation exemption, Inputs E14; interest and top-up taxable) | J41: k€ | K41: =MOIC!$G$174 -> -352.59175 | L41: =MOIC!G174 -> -352.59175
C42: Sources = Uses | D42: Check | E42: =IF(ABS(E34-E41)<0.01,"OK","FAIL") -> OK | H42: FEP net profit (post-tax) | J42: k€ | K42: =K40+K41 -> 19254.939 | L42: =L40+L41 -> 9920.6317
...

Sheet Bora
B1: =Inputs!G279&" – "&TEXT(Inputs!G281,"0")&" MW net grid / "&TEXT(Inputs!G297,"0")&" MW gross onshore wind, grid node "&Inputs!G280 -> Bora – 200 MW net grid / 261 MW gross onshore wind, grid node Szombathely OVIT (SZHO B 132.00)
B2: Project model view – sell at RTB, hold to maturity and sale at COD, each with European / Chinese turbine. Section A: live inputs; section B: all routes of the active tender scenario (live – Control Panel data table).
B4: A. Project inputs (live – Inputs block M)
B5: Input | C5: Unit | D5: Value | G5: Source / note
B6: Grid node (hálózati csomópont) | C6: Name | D6: =Inputs!G280 -> Szombathely OVIT (SZHO B 132.00) | G6: MEKH/MAVIR Kapacitás pályázati kiírás 2026, Annex 1
B7: Net grid connection capacity | C7: MW | D7: =Inputs!G281 -> 200 | G7: Annex 1 (1 MVA = 1 MW) – RTB premium (default basis, Inputs E149), grid fees, TSO bond; the success fee (DSA) is on the installed wind MW (row 18)
B8: BESS connection capacity / storage | C8: MW | D8: =Inputs!G282 -> 90 | G8: 4-hour duration (Inputs E21)
B9: Signing fee to current owners | C9: k€ | D9: =Inputs!G283 -> 250
B10: FEP share of RTB proceeds | C10: % | D10: =IF(Inputs!G284=1,Inputs!G285,1) -> 0.7 | G10: 70/30 JV with developer
B11: Number of tender bids | C11: # | D11: =Inputs!G287 -> 2 | G11: Participation fee per bid
B12: Indirect connection fee | C12: Ft/MVA | D12: =Inputs!G288 -> 73071306 | G12: Annex 1 – fajlagos várható közvetett csatlakozási díj
B13: Direct connection investment | C13: Ft | D13: =Inputs!G289 -> 508345804 | G13: Annex 1 – per connection point (TMÁ)
B14: Indirect / direct connection fee per MW | C14: mHUF/MW | D14: =FIXED(Inputs!G290,3)&" / "&FIXED(Inputs!G291,3) -> 73.071 / 2.542
B15: Devex – total incl. contingency (target) | C15: k€ | D15: =Inputs!G292 -> 3137.8459 | G15: Devex_FEP line items × scaling factor
B16: Devex scaling factor vs BORA Devex | C16: x | D16: =Inputs!G294 -> 1
B17: RTB exit premium | C17: k€/MW | D17: =Inputs!$E$141 -> 150 | G17: RtB premium (Control Panel section c)
B18: Gross installed wind capacity (overbuild) | C18: MW | D18: =Inputs!G297 -> 261 | G18: Munka1 – bid / performance bonds, turbine & BOP capex, generation, opex
B19: B. Returns – all routes of the active tender scenario (live, Control Panel data table): Sell at RTB | Hold-to-maturity European | Hold-to-maturity Chinese | Sale at COD European | Sale at COD Chinese
B20: Metric | C20: Unit | D20: Sell at RTB | E20: HTM – European | F20: HTM – Chinese | G20: Sale at COD – European | H20: Sale at COD – Chinese | I20: Note
B21: FEP headline returns
B22: FEP net profit (pre-tax) | C22: k€ | D22: =INDEX('Control Panel'!$G$306:$G$330,Tender!$E$5*5+1) -> 15526.316 | E22: =INDEX('Control Panel'!$G$306:$G$330,Tender!$E$5*5+4) -> 1254061.3 | F22: =INDEX('Control Panel'!$G$306:$G$330,Tender!$E$5*5+5) -> 1431276.9 | G22: =INDEX('Control Panel'!$G$306:$G$330,Tender!$E$5*5+2) -> 103211.98 | H22: =INDEX('Control Panel'!$G$306:$G$330,Tender!$E$5*5+3) -> 135331.94 | I22: RTB: MOIC basis (G172 / G182) – after deal costs and guarantee fees, before cost of capital
B23: FEP net profit (post-tax) | C23: k€ | D23: =INDEX('Control Panel'!$H$306:$H$330,Tender!$E$5*5+1) -> 15173.724 | E23: =INDEX('Control Panel'!$H$306:$H$330,Tender!$E$5*5+4) -> 1137959.2 | F23: =INDEX('Control Panel'!$H$306:$H$330,Tender!$E$5*5+5) -> 1299225.4 | G23: =INDEX('Control Panel'!$H$306:$H$330,Tender!$E$5*5+2) -> 103211.98 | H23: =INDEX('Control Panel'!$H$306:$H$330,Tender!$E$5*5+3) -> 135331.94
B24: FEP IRR (post-tax) | C24: % | D24: =INDEX('Control Panel'!$I$306:$I$330,Tender!$E$5*5+1) -> 0.20894449 | E24: =INDEX('Control Panel'!$I$306:$I$330,Tender!$E$5*5+4) -> 0.09991356 | F24: =INDEX('Control Panel'!$I$306:$I$330,Tender!$E$5*5+5) -> 0.13111233 | G24: =INDEX('Control Panel'!$I$306:$I$330,Tender!$E$5*5+2) -> 0.31364238 | H24: =INDEX('Control Panel'!$I$306:$I$330,Tender!$E$5*5+3) -> 0.42123413 | I24: RTB: all cash
B25: FEP NPV (post-tax, Inputs E253 rate) | C25: k€ | D25: =INDEX('Control Panel'!$J$306:$J$330,Tender!$E$5*5+1) -> 7253.3564 | E25: =INDEX('Control Panel'!$J$306:$J$330,Tender!$E$5*5+4) -> 62081.307 | F25: =INDEX('Control Panel'!$J$306:$J$330,Tender!$E$5*5+5) -> 139279.29 | G25: =INDEX('Control Panel'!$J$306:$J$330,Tender!$E$5*5+2) -> 57524.989 | H25: =INDEX('Control Panel'!$J$306:$J$330,Tender!$E$5*5+3) -> 80447.169
B26: FEP NPV / Equity | C26: x | D26: =INDEX('Control Panel'!$K$306:$K$330,Tender!$E$5*5+1) -> 0.17787568 | E26: =INDEX('Control Panel'!$K$306:$K$330,Tender!$E$5*5+4) -> 0.37667365 | F26: =INDEX('Control Panel'!$K$306:$K$330,Tender!$E$5*5+5) -> 0.97347376 | G26: =INDEX('Control Panel'!$K$306:$K$330,Tender!$E$5*5+2) -> 0.4009341 | H26: =INDEX('Control Panel'!$K$306:$K$330,Tender!$E$5*5+3) -> 0.6310593
B27: FEP MOIC | C27: x | D27: =INDEX('Control Panel'!$L$306:$L$330,Tender!$E$5*5+1) -> 1.3121055 | E27: =INDEX('Control Panel'!$L$306:$L$330,Tender!$E$5*5+4) -> 6.133291 | F27: =INDEX('Control Panel'!$L$306:$L$330,Tender!$E$5*5+5) -> 7.7915901 | G27: =INDEX('Control Panel'!$L$306:$L$330,Tender!$E$5*5+2) -> 1.5372084 | H27: =INDEX('Control Panel'!$L$306:$L$330,Tender!$E$5*5+3) -> 1.7952252 | I27: RTB: all cash
B28: FEP peak cumulative exposure | C28: k€ | D28: =INDEX('Control Panel'!$M$306:$M$330,Tender!$E$5*5+1) -> 48525.878 | E28: =INDEX('Control Panel'!$M$306:$M$330,Tender!$E$5*5+4) -> 221682.18 | F28: =INDEX('Control Panel'!$M$306:$M$330,Tender!$E$5*5+5) -> 191299.15 | G28: =INDEX('Control Panel'!$M$306:$M$330,Tender!$E$5*5+2) -> 192126.5 | H28: =INDEX('Control Panel'!$M$306:$M$330,Tender!$E$5*5+3) -> 170180.66
B29: Economic profit (RTB) / project NPV (HTM) | C29: k€ | D29: =INDEX('Control Panel'!$N$306:$N$330,Tender!$E$5*5+1) -> 9943.1039 | E29: =INDEX('Control Panel'!$N$306:$N$330,Tender!$E$5*5+4) -> 47524.011 | F29: =INDEX('Control Panel'!$N$306:$N$330,Tender!$E$5*5+5) -> 133488.73 | G29: =INDEX('Control Panel'!$N$306:$N$330,Tender!$E$5*5+2) -> 57524.989 | H29: =INDEX('Control Panel'!$N$306:$N$330,Tender!$E$5*5+3) -> 80447.169
B30: Integrity checks | C30: Status | D30: =INDEX('Control Panel'!$O$306:$O$330,Tender!$E$5*5+1) -> ALL OK | E30: =INDEX('Control Panel'!$O$306:$O$330,Tender!$E$5*5+4) -> ALL OK | F30: =INDEX('Control Panel'!$O$306:$O$330,Tender!$E$5*5+5) -> ALL OK | G30: =INDEX('Control Panel'!$O$306:$O$330,Tender!$E$5*5+2) -> ALL OK / OK | H30: =INDEX('Control Panel'!$O$306:$O$330,Tender!$E$5*5+3) -> ALL OK / OK
B31: Sell at RTB – detail
B32: RTB date → sale date | C32: Date | D32: =INDEX('Control Panel'!$P$306:$P$330,Tender!$E$5*5+1) -> Jun-29 → Mar-30 | E32: =INDEX('Control Panel'!$P$306:$P$330,Tender!$E$5*5+4) -> – | F32: =INDEX('Control Panel'!$P$306:$P$330,Tender!$E$5*5+5) -> – | G32: =INDEX('Control Panel'!$P$306:$P$330,Tender!$E$5*5+2) -> COD Sep-31 → sale at COD | H32: =INDEX('Control Panel'!$P$306:$P$330,Tender!$E$5*5+3) -> COD Sep-31 → sale at COD
B33: Gross RTB proceeds (premium + buyer reimbursement) | C33: k€ | D33: =INDEX('Control Panel'!$Q$306:$Q$330,Tender!$E$5*5+1) -> 64143.615 | E33: =INDEX('Control Panel'!$Q$306:$Q$330,Tender!$E$5*5+4) -> – | F33: =INDEX('Control Panel'!$Q$306:$Q$330,Tender!$E$5*5+5) -> – | G33: =INDEX('Control Panel'!$Q$306:$Q$330,Tender!$E$5*5+2) -> 609707.58 | H33: =INDEX('Control Panel'!$Q$306:$Q$330,Tender!$E$5*5+3) -> 522606.5
B34: FEP net profit pre-tax – Case B (signing fee, DD, guarantee fees, cost of capital) | C34: k€ | D34: =INDEX('Control Panel'!$R$306:$R$330,Tender!$E$5*5+1) -> 10273.223 | E34: =INDEX('Control Panel'!$R$306:$R$330,Tender!$E$5*5+4) -> – | F34: =INDEX('Control Panel'!$R$306:$R$330,Tender!$E$5*5+5) -> – | G34: =INDEX('Control Panel'!$R$306:$R$330,Tender!$E$5*5+2) -> 272537.82 | H34: =INDEX('Control Panel'!$R$306:$R$330,Tender!$E$5*5+3) -> 161496.92
B35: FEP net profit post-tax – Case B | C35: k€ | D35: =INDEX('Control Panel'!$S$306:$S$330,Tender!$E$5*5+1) -> 9920.6317 | E35: =INDEX('Control Panel'!$S$306:$S$330,Tender!$E$5*5+4) -> – | F35: =INDEX('Control Panel'!$S$306:$S$330,Tender!$E$5*5+5) -> – | G35: =INDEX('Control Panel'!$S$306:$S$330,Tender!$E$5*5+2) -> 336669.76 | H35: =INDEX('Control Panel'!$S$306:$S$330,Tender!$E$5*5+3) -> 360609.58
B36: Gearing (senior debt / total capex) | C36: % | D36: =INDEX('Control Panel'!$T$306:$T$330,Tender!$E$5*5+1) -> – | E36: =INDEX('Control Panel'!$T$306:$T$330,Tender!$E$5*5+4) -> – | F36: =INDEX('Control Panel'!$T$306:$T$330,Tender!$E$5*5+5) -> – | G36: =INDEX('Control Panel'!$T$306:$T$330,Tender!$E$5*5+2) -> 0.6 | H36: =INDEX('Control Panel'!$T$306:$T$330,Tender!$E$5*5+3) -> 0.5
B37: Sale at COD price per installed MW (after clipping) | C37: k€/MW | D37: =INDEX('Control Panel'!$U$306:$U$330,Tender!$E$5*5+1) -> – | E37: =INDEX('Control Panel'!$U$306:$U$330,Tender!$E$5*5+4) -> – | F37: =INDEX('Control Panel'!$U$306:$U$330,Tender!$E$5*5+5) -> – | G37: =INDEX('Control Panel'!$U$306:$U$330,Tender!$E$5*5+2) -> 2336.0444 | H37: =INDEX('Control Panel'!$U$306:$U$330,Tender!$E$5*5+3) -> 2002.3238
B38: Grid connection fee – indirect / direct | C38: mHUF | D38: =INDEX('Control Panel'!$V$306:$V$330,Tender!$E$5*5+1) -> 14,614 / 508 | E38: =INDEX('Control Panel'!$V$306:$V$330,Tender!$E$5*5+4) -> – | F38: =INDEX('Control Panel'!$V$306:$V$330,Tender!$E$5*5+5) -> – | G38: =INDEX('Control Panel'!$V$306:$V$330,Tender!$E$5*5+2) -> 14,614 / 508 | H38: =INDEX('Control Panel'!$V$306:$V$330,Tender!$E$5*5+3) -> 14,614 / 508
B39: Total tender securities and grid fees (gross) | C39: mHUF | D39: =INDEX('Control Panel'!$W$306:$W$330,Tender!$E$5*5+1) -> 23592.162 | E39: =INDEX('Control Panel'!$W$306:$W$330,Tender!$E$5*5+4) -> – | F39: =INDEX('Control Panel'!$W$306:$W$330,Tender!$E$5*5+5) -> – | G39: =INDEX('Control Panel'!$W$306:$W$330,Tender!$E$5*5+2) -> 23592.162 | H39: =INDEX('Control Panel'!$W$306:$W$330,Tender!$E$5*5+3) -> 23592.162
B40: Devex – total incl. contingency | C40: k€ | D40: =INDEX('Control Panel'!$X$306:$X$330,Tender!$E$5*5+1) -> 3137.8459 | E40: =INDEX('Control Panel'!$X$306:$X$330,Tender!$E$5*5+4) -> – | F40: =INDEX('Control Panel'!$X$306:$X$330,Tender!$E$5*5+5) -> – | G40: =INDEX('Control Panel'!$X$306:$X$330,Tender!$E$5*5+2) -> 3137.8459 | H40: =INDEX('Control Panel'!$X$306:$X$330,Tender!$E$5*5+3) -> 3137.8459
B41: Hold-to-maturity – detail
...

Sheet Inputs
A1: HUN Onshore Wind – MOIC model v5
A2: Inputs – all static inputs. Column E = active case (picks case column G:P; falls back to case 1 if the selected case cell is blank).
A3: Blue on cream = input. Black = calculated. Green = link from another sheet. Yellow fill = key assumption to confirm. Amber fill = awaiting input.
C5: Input | D5: Unit | E5: Active case | F5: Note | G5: Case 1 | H5: Case 2 | I5: Case 3 | J5: Case 4 | K5: Case 5 | L5: Case 6 | M5: Case 7 | N5: Case 8 | O5: Case 9 | P5: Case 10
C6: Case # | D6: # | E6: =IF('Control Panel'!$E$10=0,'Control Panel'!$F$8,INDEX('Control Panel'!$E$306:$E$330,'Control Panel'!$E$10)) -> 1 | F6: Set on the Control Panel (E8 route; data-table driver E10) | G6: 1 | H6: =G6+1 -> 2 | I6: =H6+1 -> 3 | J6: =I6+1 -> 4 | K6: =J6+1 -> 5 | L6: =K6+1 -> 6 | M6: =L6+1 -> 7 | N6: =M6+1 -> 8 | O6: =N6+1 -> 9 | P6: =O6+1 -> 10
C7: Case name | D7: Name | E7: {=INDEX($G7:$P7,$E$6)} -> FEP base case | G7: FEP base case | H7: European turbine | I7: Chinese turbine | J7: No deposit recovery at exit | K7: IC deck basis (280 MW, 70/30 JV) | L7: All deposits cash-settled | M7: Sale at COD, European turbine | N7: Sale at COD, Chinese turbine | O7: Spare | P7: Spare
C8: Case description | D8: Text | E8: {=INDEX($G8:$P8,$E$6)} -> FEP funds 100%, 70/30 JV on proceeds, 200 MW, aligned to BORA Devex 29/09/2026 | G8: FEP funds 100%, 70/30 JV on proceeds, 200 MW, aligned to BORA Devex 29/09/2026 | H8: Turbine supply 950 k€/MW, 60% gearing, 100% of output under a 90 €/MWh PPA (10 yrs, 1% p.a. indexation), Aurora Central merchant tail | I8: Turbine supply 500 k€/MW, 50% gearing, 100% of output under a 90 €/MWh PPA (10 yrs, 1% p.a. indexation), Aurora Central merchant tail | J8: As case 1 but buyer does not reimburse securities / connection fee | K8: Portfolio 280 MW, JV 70/30 live, success fee live | L8: As case 1 but no bank guarantees | M8: No RTB exit. Build with European turbine (as case 2), 60% gearing, 90 €/MWh PPA; sell 100% of the SPV at the project's COD (Bora: Sep-2031 override) at the Tender price per gross MW net of clipping and of the post-COD promise costs (enterprise value; senior debt repaid from proceeds). | N8: No RTB exit. Build with Chinese turbine (as case 3), 50% gearing, 90 €/MWh PPA; sell 100% of the SPV at the project's COD (Bora: Sep-2031 override) at the Tender price per gross MW net of clipping and of the post-COD promise costs (enterprise value; senior debt repaid from proceeds).
B10: x | C10: A. Macro
C11: EUR / HUF | D11: HUF/EUR | E11: {=IF(INDEX($G11:$P11,$E$6)="",$G11,INDEX($G11:$P11,$E$6))} -> 365 | F11: Single FX for the whole model (also used for mHUF reporting outputs). | G11: 365
C12: Hungary corporate income tax | D12: % | E12: {=IF(INDEX($G12:$P12,$E$6)="",$G12,INDEX($G12:$P12,$E$6))} -> 0.09 | F12: Applied to positive cumulative profit at sale, less any gain exempted by the participation exemption (E14). | G12: 0.09
C13: Cost of capital for economic profit | D13: % | E13: {=IF(INDEX($G13:$P13,$E$6)="",$G13,INDEX($G13:$P13,$E$6))} -> 0.08 | F13: Monthly charge on the negative cumulative equity position. Linked to the single discount rate (Inputs row 253 ← Control Panel section c), per decision 02-Oct-26 (Open_Items #10). Previously 8.9% typed. | G13: =G$253 -> 0.08 | H13: =H$253 | I13: =I$253 | M13: =H13 | N13: =I13
C14: Participation exemption on RtB share sale (1 = gain on shares exempt) | D14: Switch | E14: {=IF(INDEX($G14:$P14,$E$6)="",$G14,INDEX($G14:$P14,$E$6))} -> 1 | F14: 1 = the share of distributable proceeds (gain on the SPV/JV shares) is exempt from CIT under the Hungarian participation exemption (bejelentett részesedés): shareholding notified to NAV within 75 days of acquisition and held ≥ 1 year before sale (investment date E27 to sale ≈ 3 years). Interest, 2× top-up and loan returns stay taxable at E12. 0 = flat E12 on all profit at sale. | G14: 1
B15: x | C15: B. Capacity, acquisition and exit timing
C16: Gross capacity entered in tender | D16: MW | E16: {=IF(INDEX($G16:$P16,$E$6)="",$G16,INDEX($G16:$P16,$E$6))} -> 200 | F16: Bid-stage items (participation fee, bid bond) scale with this. | G16: ='Control Panel'!$E$74 -> 200 | K16: 280
C17: Conversion rate (capacity awarded and taken to RTB) | D17: % | E17: {=IF(INDEX($G17:$P17,$E$6)="",$G17,INDEX($G17:$P17,$E$6))} -> 1 | F17: Post-award items and exit proceeds scale with successful capacity. | G17: 1
C18: Successful capacity | D18: MW | E18: =E16*E17 -> 200
C19: Failed capacity | D19: MW | E19: =E16-E18 -> 0 | F19: Devex on failed capacity is still spent; its bid bond is refunded at award if the switch below is on.
C20: BESS connection capacity (gross) | D20: MW | E20: {=IF(INDEX($G20:$P20,$E$6)="",$G20,INDEX($G20:$P20,$E$6))} -> 90 | F20: BESS power rating entered in the tender. FEP workbook assumes 100 MW (50% of wind). | G20: =Tender!$J$41 -> 90
C21: BESS duration | D21: Hours | E21: {=IF(INDEX($G21:$P21,$E$6)="",$G21,INDEX($G21:$P21,$E$6))} -> 4 | F21: Storage hours at rated power – linked to Tender J16 (active tender strategy; 4 h in every strategy, Munka1 0.25C) | G21: =Tender!$J$16 -> 4
C22: BESS storage capacity (gross) | D22: MWh | E22: =E20*E21 -> 360 | F22: Drives the BESS leg of the security base at the bid stage.
C23: BESS storage capacity (successful) | D23: MWh | E23: =E22*E17 -> 360 | F23: Post-award BESS base; scales with the same conversion rate as wind.
C24: Signing fee to current owners | D24: k€ | E24: {=IF(INDEX($G24:$P24,$E$6)="",$G24,INDEX($G24:$P24,$E$6))} -> 250 | F24: Paid at month 0. | G24: ='Control Panel'!$E$75 -> 250 | K24: 295
C25: Transaction / DD costs to FEP | D25: k€ | E25: {=IF(INDEX($G25:$P25,$E$6)="",$G25,INDEX($G25:$P25,$E$6))} -> 150 | F25: Paid at month 0. | G25: 150
C26: Sale costs at exit | D26: k€ | E26: {=IF(INDEX($G26:$P26,$E$6)="",$G26,INDEX($G26:$P26,$E$6))} -> 500 | F26: Deducted from proceeds in the waterfall. | G26: 500
C27: Investment date (month 0) | D27: Date | E27: {=IF(INDEX($G27:$P27,$E$6)="",$G27,INDEX($G27:$P27,$E$6))} -> 46234 | F27: Start of the monthly grid; every month steps by EOMONTH. | G27: 46234
C28: Lag from RTB to sale | D28: Months | E28: {=IF(INDEX($G28:$P28,$E$6)="",$G28,INDEX($G28:$P28,$E$6))} -> 9 | F28: ="RTB + "&E28&" months = RtB sale (BORA Devex proposal; was 3). RTB "&DAY(E56)&"/"&TEXT(MONTH(E56),"00")&"/"&YEAR(E56)&" → sale "&DAY(E58)&"/"&TEXT(MONTH(E58),"00")&"/"&YEAR(E58) -> RTB + 9 months = RtB sale (BORA Devex proposal; was 3). RTB 30/06/2029 → sale 31/03/2030 | G28: ='Control Panel'!$E$88 -> 9 | H28: =IF('Control Panel'!$F$88="","",'Control Panel'!$F$88) | I28: =IF('Control Panel'!$G$88="","",'Control Panel'!$G$88) | M28: =H28 | N28: =I28
C29: Gross installed wind capacity – successful (overbuild) | D29: MW | E29: =IF(E281=0,E18,E18*E297/E281) -> 261 | F29: Net successful MW (E18) × gross / net ratio of the project (row 297 ÷ row 281). Drives bid / performance bonds, turbine & BOP capex, generation, opex, decommissioning, the COD sale price and the developer success fee (DSA, DSA on installed MW per BORA_Devex – user 09-Oct-26). Grid fees, TSO bond and the RTB premium stay on net MW (E18; premium: switch row 149).
B30: x | C30: C. Ownership and developer economics
C31: JV structure live (1 = 70/30 JV, 0 = FEP 100%) | D31: Switch | E31: {=IF(INDEX($G31:$P31,$E$6)="",$G31,INDEX($G31:$P31,$E$6))} -> 1 | F31: Master switch. Also drives Assumptions!E8 on the HTM side. | G31: ='Control Panel'!$E$76 -> 1 | K31: 1
C32: FEP share of net proceeds if JV | D32: % | E32: {=IF(INDEX($G32:$P32,$E$6)="",$G32,INDEX($G32:$P32,$E$6))} -> 0.7 | G32: ='Control Panel'!$E$77 -> 0.7
C33: FEP effective share of distributable proceeds | D33: % | E33: =IF(E31=1,E32,1) -> 0.7
C34: Developer effective share | D34: % | E34: =1-E33 -> 0.3
C35: Developer funds pro rata (1 = yes) | D35: Switch | E35: {=IF(INDEX($G35:$P35,$E$6)="",$G35,INDEX($G35:$P35,$E$6))} -> 0 | F35: If on, the developer funds its share of both shareholder loans on the same terms. | G35: 0
C36: Developer success fee p.a. | D36: k€/MW | E36: {=IF(INDEX($G36:$P36,$E$6)="",$G36,INDEX($G36:$P36,$E$6))} -> 2.5 | F36: DSA on installed MW per BORA_Devex – user 09-Oct-26: accrues pro rata to the sale on the installed wind MW (E29, BORA_Devex V37 = 2 500 €/MW × V6); settled at exit from proceeds (not funded to RTB). Cap E37 per the same MW. | G36: 2.5
C37: Success fee cap | D37: k€/MW | E37: {=IF(INDEX($G37:$P37,$E$6)="",$G37,INDEX($G37:$P37,$E$6))} -> 10 | G37: 10
C38: Success fee live | D38: Switch | E38: =E31 -> 1 | F38: Fee only exists in the JV case.
B40: x | C40: D. Milestone timing (drives RTB and sale dates). Milestone devex amounts (rows 41–48) are NO LONGER USED – devex comes from the BORA_Devex sheet via Devex_FEP.
C41: Milestone 1 devex | D41: k€/MW | E41: {=IF(INDEX($G41:$P41,$E$6)="",$G41,INDEX($G41:$P41,$E$6))} -> 0 | F41: NOT USED since 29-Sep-2026 – kept for reference only (grouped). Devex = BORA Devex line items with their own payment dates (Devex_FEP / BORA_Devex).
C42: Milestone 2 devex | D42: k€/MW | E42: {=IF(INDEX($G42:$P42,$E$6)="",$G42,INDEX($G42:$P42,$E$6))} -> 0
C43: Milestone 3 devex | D43: k€/MW | E43: {=IF(INDEX($G43:$P43,$E$6)="",$G43,INDEX($G43:$P43,$E$6))} -> 0
...

Sheet Curves
A1: Bora Onshore Wind – MOIC model v5
A2: Curves – time-series inputs: EURIBOR curves (monthly, aligned to the MOIC grid) and the Aurora Hungarian wind capture price placeholder (annual).
B4: x | C4: 1. EURIBOR curves (monthly) – select the curve in use on Inputs!E112
C5: Month index | G5: → | H5: =MOIC!H4 -> 0 | I5: =MOIC!I4 -> 1 | J5: =MOIC!J4 -> 2 | K5: =MOIC!K4 -> 3 | L5: =MOIC!L4 -> 4 | M5: =MOIC!M4 -> 5 | N5: =MOIC!N4 -> 6 | O5: =MOIC!O4 -> 7 | ... BP5: =MOIC!BP4 -> 60
C6: Period end date | D6: Date | H6: =MOIC!H5 -> 46234 | I6: =MOIC!I5 -> 46265 | J6: =MOIC!J5 -> 46295 | K6: =MOIC!K5 -> 46326 | L6: =MOIC!L5 -> 46356 | M6: =MOIC!M5 -> 46387 | N6: =MOIC!N5 -> 46418 | O6: =MOIC!O5 -> 46446 | ... BP6: =MOIC!BP5 -> 48060
C7: Curve in use (selected) | D7: % p.a. | E7: =Inputs!E112 -> 1M EURIBOR Jul-26 | H7: =INDEX(H$9:H$11,MATCH($E$7,$C$9:$C$11,0)) -> 0.02204 | I7: =INDEX(I$9:I$11,MATCH($E$7,$C$9:$C$11,0)) -> 0.0230337 | J7: =INDEX(J$9:J$11,MATCH($E$7,$C$9:$C$11,0)) -> 0.0239429 | K7: =INDEX(K$9:K$11,MATCH($E$7,$C$9:$C$11,0)) -> 0.0248091 | L7: =INDEX(L$9:L$11,MATCH($E$7,$C$9:$C$11,0)) -> 0.0256369 | M7: =INDEX(M$9:M$11,MATCH($E$7,$C$9:$C$11,0)) -> 0.0263515 | N7: =INDEX(N$9:N$11,MATCH($E$7,$C$9:$C$11,0)) -> 0.0270143 | O7: =INDEX(O$9:O$11,MATCH($E$7,$C$9:$C$11,0)) -> 0.0274756 | ... BP7: =INDEX(BP$9:BP$11,MATCH($E$7,$C$9:$C$11,0)) -> 0.0278735
C8: Available curves | D8: Unit | E8: Source | F8: Note
C9: 1M EURIBOR Aug-25 | D9: % p.a. | E9: Source: Chatham financial, 28/8/25 | F9: Monthly 1M EURIBOR forward; held flat after the last quoted month. | H9: 0.019 | I9: 0.0188 | J9: 0.0186 | K9: 0.0184 | L9: 0.0182 | M9: 0.0181 | N9: 0.018 | O9: 0.018 | P9: 0.018 | Q9: 0.018 | R9: 0.018 | S9: 0.0181 | T9: 0.0182 | U9: 0.0183 | V9: 0.0185 | W9: 0.0186 | X9: 0.0188 | Y9: 0.019 | Z9: 0.0192 | AA9: 0.0192 | AB9: 0.0192 | AC9: 0.0192 | AD9: 0.0192 | AE9: 0.0192 | AF9: 0.0192 | AG9: 0.0192 | AH9: 0.0192 | AI9: 0.0192 | AJ9: 0.0192 | AK9: 0.0192 | AL9: 0.0192 | AM9: 0.0192 | AN9: 0.0192 | AO9: 0.0192 | AP9: 0.0192 | AQ9: 0.0192 | AR9: 0.0192 | AS9: 0.0192 | AT9: 0.0192 | AU9: 0.0192 | AV9: 0.0192 | AW9: 0.0192 | AX9: 0.0192 | AY9: 0.0192 | AZ9: 0.0192 | BA9: 0.0192 | BB9: 0.0192 | BC9: 0.0192 | BD9: 0.0192 | BE9: 0.0192 | BF9: 0.0192 | BG9: 0.0192 | BH9: 0.0192 | BI9: 0.0192 | BJ9: 0.0192 | BK9: =BJ9 -> 0.0192 | BL9: =BK9 -> 0.0192 | BM9: =BL9 -> 0.0192 | BN9: =BM9 -> 0.0192 | BO9: =BN9 -> 0.0192 | BP9: =BO9 -> 0.0192
C10: 1M EURIBOR Nov-25 | D10: % p.a. | E10: Source: Chatham financial, 10/11/25 | F10: Monthly 1M EURIBOR forward; held flat after the last quoted month. | H10: 0.01891 | I10: 0.0188532 | J10: 0.0187946 | K10: 0.0187431 | L10: 0.0186996 | M10: 0.0186559 | N10: 0.0186267 | O10: 0.0186046 | P10: 0.0185936 | Q10: 0.0185946 | R10: 0.0186079 | S10: 0.0186343 | T10: 0.018673 | U10: 0.018725 | V10: 0.0187935 | W10: 0.0188776 | X10: 0.0189673 | Y10: 0.0190866 | Z10: 0.0192105 | AA10: 0.0192105 | AB10: 0.0192105 | AC10: 0.0192105 | AD10: 0.0192105 | AE10: 0.0192105 | AF10: 0.0192105 | AG10: 0.0192105 | AH10: 0.0192105 | AI10: 0.0192105 | AJ10: 0.0192105 | AK10: 0.0192105 | AL10: 0.0192105 | AM10: 0.0192105 | AN10: 0.0192105 | AO10: 0.0192105 | AP10: 0.0192105 | AQ10: 0.0192105 | AR10: 0.0192105 | AS10: 0.0192105 | AT10: 0.0192105 | AU10: 0.0192105 | AV10: 0.0192105 | AW10: 0.0192105 | AX10: 0.0192105 | AY10: 0.0192105 | AZ10: 0.0192105 | BA10: 0.0192105 | BB10: 0.0192105 | BC10: 0.0192105 | BD10: 0.0192105 | BE10: 0.0192105 | BF10: 0.0192105 | BG10: 0.0192105 | BH10: 0.0192105 | BI10: 0.0192105 | BJ10: 0.0192105 | BK10: =BJ10 -> 0.0192105 | BL10: =BK10 -> 0.0192105 | BM10: =BL10 -> 0.0192105 | BN10: =BM10 -> 0.0192105 | BO10: =BN10 -> 0.0192105 | BP10: =BO10 -> 0.0192105
