Workbook
Name Balancing: Inputs!$E$64
Name Bench_BESS: Inputs!$E$8
Name Bench_Wind: Inputs!$E$7
Name BESS_Capex: Inputs!$E$51
Name Bid_Sec_Rate: Inputs!$E$9
Name Capex_Civil: Inputs!$E$44
Name Capex_Cont: Inputs!$E$50
Name Capex_Elec: Inputs!$E$45
Name Capex_Fdn: Inputs!$E$43
Name Capex_Install: Inputs!$E$42
Name Capex_Land: Inputs!$E$47
Name Capex_Owner: Inputs!$E$46
Name Case_CN: Dashboard!$H$27
Name Case_EU: Dashboard!$H$26
Name Case_OM: Dashboard!$H$30
Name Case_P50: Dashboard!$H$29
Name Case_PPA: Dashboard!$H$28
Name CIT_Rate: Inputs!$E$39
Name Clipping: Inputs!$E$54
Name Curtailment: Inputs!$E$53
Name Dash_BESS_Share: Dashboard!$E$8:$G$8
Name Dash_Brownfield: Dashboard!$E$15:$G$15
Name Dash_Case: Dashboard!$H$25
Name Dash_Case_CN: Dashboard!$E$27:$G$27
Name Dash_Case_EU: Dashboard!$E$26:$G$26
Name Dash_Case_OM: Dashboard!$E$30:$G$30
Name Dash_Case_P50: Dashboard!$E$29:$G$29
Name Dash_Case_PPA: Dashboard!$E$28:$G$28
Name Dash_Community: Dashboard!$E$12:$G$12
Name Dash_DSA: Dashboard!$E$20:$G$20
Name Dash_FEP_Share: Dashboard!$E$19:$G$19
Name Dash_Hours: Dashboard!$E$9:$G$9
Name Dash_JV: Dashboard!$E$21:$G$21
Name Dash_Municipal: Dashboard!$E$11:$G$11
Name Dash_MVA: Dashboard!$E$6:$G$6
Name Dash_Overbuild: Dashboard!$E$7:$G$7
Name Dash_P50: Dashboard!$E$22:$G$22
Name Dash_Partial: Dashboard!$E$13:$G$13
Name Dash_PB_Mult: Dashboard!$E$14:$G$14
Name Dash_Premium: Dashboard!$E$18:$G$18
Name Dash_Shared: Dashboard!$E$16:$G$16
Name Dash_Shortfall: Dashboard!$E$10:$G$10
Name Dash_Turbine: Dashboard!$E$17:$G$17
Name Days_In_Year: Inputs!$E$75
Name Degradation: Inputs!$E$55
Name Devex_Class: Inputs!$G$80:$G$112
Name Devex_Date: Inputs!$F$80:$F$112
Name Devex_Floor: Inputs!$E$32
Name Devex_HUF: Inputs!$E$80:$E$112
Name Discount_Rate: Inputs!$E$72
Name DSA_Cap: Inputs!$E$38
Name DSA_Rate: Inputs!$E$37
Name First_Year: Inputs!$E$73
Name Freeze_Date: Inputs!$E$33
Name FX: Inputs!$E$6
Name Grid_Charges: Inputs!$E$65
Name HIPA_Rate: Inputs!$E$67
Name Life: Inputs!$E$71
Name Lump_Basis: Inputs!$E$49
Name Master_Check: Dashboard!$H$442

Sheet Dashboard
C2: HU wind projects
C3: Master check (0 = OK; checks at the end of the detail) | D3: flag | H3: =Master_Check -> 0
B5: x | C5: Key inputs: the bids | E5: Bora | F5: Iváncsa | G5: Dunaújváros | H5: Total
C6: Net connection capacity | D6: MVA | E6: 50 | F6: 50 | G6: 50 | H6: =SUM(E6:G6) -> 150
C7: Overbuild (ÖSZ-3) | D7: % | E7: 0.2 | F7: 0.4 | G7: 0.4
C8: BESS power, share of MVA (ÖSZ-4) | D8: % | E8: 0.1 | F8: 0.2 | G8: 0.2
C9: BESS duration | D9: h | E9: 4 | F9: 4 | G9: 4
C10: Wind built below the bid | D10: % | E10: 0.1 | F10: 0.1 | G10: 0.1
C11: Municipal one-off (ÖSZ-1), at COD | D11: EUR k/MVA | E11: 20 | F11: 50 | G11: 50
C12: Community contribution (ÖSZ-2) | D12: EUR/MWh | E12: 0 | F12: 3 | G12: 3
C13: Partial award accepted (ÖSZ-5) | D13: flag | E13: 1 | F13: 1 | G13: 1
C14: Performance security multiple (ÖSZ-6) | D14: x | E14: 1 | F14: 1 | G14: 1
C15: Brownfield site (ÖSZ-7) | D15: flag | E15: 0 | F15: 0 | G15: 0
C16: Shared connection (ÖSZ-8) | D16: flag | E16: 1 | F16: 1 | G16: 1
C17: Turbine route (EU or CN; EU scores ÖSZ-9) | D17: text | E17: CN | F17: CN | G17: CN
C18: RtB premium | D18: EUR k/MVA | E18: 150 | F18: 150 | G18: 150
C19: FEP share of distributable proceeds | D19: % | E19: 0.7 | F19: 1 | G19: 1
C20: Developer success fee (DSA) on | D20: flag | E20: 1 | F20: 0 | G20: 0
C21: JV with a developer (1 = yes; claims and DSA apply) | D21: flag | E21: 1 | F21: 0 | G21: 0
C22: Net P50 hours (project wind study) | D22: h/yr | E22: 2500 | F22: 2500 | G22: 2500
B24: x | C24: Case: turbine price, PPA, yield, O&M | E24: Base | F24: Low | G24: High | H24: Live
C25: Case selected (Base, Low or High) | D25: case | H25: Base
C26: Turbine supply incl. transport, EU route | D26: EUR k/MW | E26: 850 | F26: 950 | G26: 800 | H26: =INDEX(E26:G26,MATCH(Dash_Case,$E$24:$G$24,0)) -> 850 | J26: Bora Dashboard H8 / Inputs G162
C27: Turbine supply incl. transport, CN route | D27: EUR k/MW | E27: 500 | F27: 600 | G27: 480 | H27: =INDEX(E27:G27,MATCH(Dash_Case,$E$24:$G$24,0)) -> 500 | J27: Bora Inputs H162
C28: PPA price in the COD year | D28: EUR/MWh | E28: 90 | F28: 90 | G28: 100 | H28: =INDEX(E28:G28,MATCH(Dash_Case,$E$24:$G$24,0)) -> 90 | J28: Bora Dashboard H9
C29: Net P50 hours (not used: project P50 in row 22) | D29: h/yr | E29: 2400 | F29: 2350 | G29: 2500 | H29: =INDEX(E29:G29,MATCH(Dash_Case,$E$24:$G$24,0)) -> 2400 | J29: Bora Dashboard H10
C30: O&M full-service contract | D30: EUR k/MW/yr | E30: 12 | F30: 12 | G30: 10 | H30: =INDEX(E30:G30,MATCH(Dash_Case,$E$24:$G$24,0)) -> 12 | J30: Bora Dashboard H11
B32: x | C32: Bid points and capacity | E32: Bora | F32: Iváncsa | G32: Dunaújváros | H32: Total
C33: Points – municipal one-off | D33: points | E33: =INDEX(Osz1_Pts,1+SUMPRODUCT((Osz1_LB<E11)+(Osz1_LB=E11)*Osz1_Incl))*Osz1_W -> 4 | F33: =INDEX(Osz1_Pts,1+SUMPRODUCT((Osz1_LB<F11)+(Osz1_LB=F11)*Osz1_Incl))*Osz1_W -> 20 | G33: =INDEX(Osz1_Pts,1+SUMPRODUCT((Osz1_LB<G11)+(Osz1_LB=G11)*Osz1_Incl))*Osz1_W -> 20
C34: Points – community contribution | D34: points | E34: =INDEX(Osz2_Pts,1+SUMPRODUCT((Osz2_LB<E12)+(Osz2_LB=E12)*Osz2_Incl))*Osz2_W -> 0 | F34: =INDEX(Osz2_Pts,1+SUMPRODUCT((Osz2_LB<F12)+(Osz2_LB=F12)*Osz2_Incl))*Osz2_W -> 15 | G34: =INDEX(Osz2_Pts,1+SUMPRODUCT((Osz2_LB<G12)+(Osz2_LB=G12)*Osz2_Incl))*Osz2_W -> 15
C35: Points – overbuild | D35: points | E35: =INDEX(Osz3_Pts,1+SUMPRODUCT((Osz3_LB<E7)+(Osz3_LB=E7)*Osz3_Incl))*Osz3_W -> 5 | F35: =INDEX(Osz3_Pts,1+SUMPRODUCT((Osz3_LB<F7)+(Osz3_LB=F7)*Osz3_Incl))*Osz3_W -> 9 | G35: =INDEX(Osz3_Pts,1+SUMPRODUCT((Osz3_LB<G7)+(Osz3_LB=G7)*Osz3_Incl))*Osz3_W -> 9
C36: Points – BESS | D36: points | E36: {=INDEX(Osz4_Pts,1+SUMPRODUCT((Osz4_LB<E8)+(Osz4_LB=E8)*Osz4_Incl))*Osz4_W} -> 4.5 | F36: {=INDEX(Osz4_Pts,1+SUMPRODUCT((Osz4_LB<F8)+(Osz4_LB=F8)*Osz4_Incl))*Osz4_W} -> 7.5 | G36: {=INDEX(Osz4_Pts,1+SUMPRODUCT((Osz4_LB<G8)+(Osz4_LB=G8)*Osz4_Incl))*Osz4_W} -> 7.5
C37: Points – partial award | D37: points | E37: =E13*Osz5_Pts*Osz5_W -> 5 | F37: =F13*Osz5_Pts*Osz5_W -> 5 | G37: =G13*Osz5_Pts*Osz5_W -> 5
C38: Points – performance security | D38: points | E38: =INDEX(Osz6_Pts,1+SUMPRODUCT((Osz6_LB<E14)+(Osz6_LB=E14)*Osz6_Incl))*Osz6_W -> 0 | F38: =INDEX(Osz6_Pts,1+SUMPRODUCT((Osz6_LB<F14)+(Osz6_LB=F14)*Osz6_Incl))*Osz6_W -> 0 | G38: =INDEX(Osz6_Pts,1+SUMPRODUCT((Osz6_LB<G14)+(Osz6_LB=G14)*Osz6_Incl))*Osz6_W -> 0
C39: Points – brownfield | D39: points | E39: =E15*Osz7_Pts*Osz7_W -> 0 | F39: =F15*Osz7_Pts*Osz7_W -> 0 | G39: =G15*Osz7_Pts*Osz7_W -> 0
C40: Points – shared connection | D40: points | E40: =E16*Osz8_Pts*Osz8_W -> 5 | F40: =F16*Osz8_Pts*Osz8_W -> 5 | G40: =G16*Osz8_Pts*Osz8_W -> 5
C41: Points – EU turbines | D41: points | E41: =N(E17="EU")*Osz9a_Pts*Osz9_W -> 0 | F41: =N(F17="EU")*Osz9a_Pts*Osz9_W -> 0 | G41: =N(G17="EU")*Osz9a_Pts*Osz9_W -> 0
C42: Points – EU transformers | D42: points | E42: =Inputs!E$19*Osz9b_Pts*Osz9_W -> 0 | F42: =Inputs!F$19*Osz9b_Pts*Osz9_W -> 0 | G42: =Inputs!G$19*Osz9b_Pts*Osz9_W -> 0
C43: Points total | D43: points | E43: =SUM(E33:E42) -> 23.5 | F43: =SUM(F33:F42) -> 61.5 | G43: =SUM(G33:G42) -> 61.5
C44: Wind committed in the bid | D44: MW | E44: =E6*(1+E7) -> 60 | F44: =F6*(1+F7) -> 70 | G44: =G6*(1+G7) -> 70 | H44: =SUM(E44:G44) -> 200
...

Sheet Inputs
C2: HU wind bids – other inputs (blue) with sources
B4: x | C4: Inputs | E4: Bora | F4: Iváncsa | G4: Dunaújváros | H4: Source
C5: Tender and grid (all projects; value in column E)
C6: FX rate | D6: HUF/EUR | E6: 365 | H6: Bora Inputs E11; Bid_Cash E45
C7: Security base: benchmark investment, wind | D7: HUF/MW | E7: 406000000 | H7: Bora Inputs E75; Bid_Cash E46
C8: Security base: benchmark investment, BESS | D8: HUF/MWh | E8: 200000000 | H8: Bora Inputs E89; Bid_Cash E47
C9: Bid security, share of base | D9: % | E9: 0.005 | H9: Bora Inputs E76; Bid_Cash E49
C10: Performance security, minimum share of base | D10: % | E10: 0.025 | H10: Bora Inputs E77; Bid_Cash E50
C11: Participation fee per bid | D11: HUF | E11: 3000000 | H11: Bora Inputs E81; Bid_Cash E48
C12: TSO connection-request security | D12: HUF/MVA | E12: 4500000 | H12: Bora Inputs E83; Bid_Cash E51
C13: Per project: fees, devex, dates
C14: Indirect connection fee | D14: HUF/MVA | E14: 73071306 | F14: 19826680 | G14: 19826680 | H14: Bora Inputs G290; Bid_Cash E52
C15: Direct connection fee per connection point | D15: HUF | E15: 508345804 | F15: 460000000 | G15: 460000000 | H15: Bora Inputs G291; Bid_Cash E53
C16: Bids sharing the connection point | D16: count | E16: 2 | F16: 1 | G16: 1 | H16: Bora: 2 bids per point (SPEC §22.2)
C17: Signing fee and DD | D17: EUR k | E17: 100 | F17: 150 | G17: 150 | H17: Bora E24+E25: 400 × 50/200; Bid_Cash E55
C18: Devex scale (bid MVA ÷ 200 MVA of the devex file) | D18: x | E18: 0.25 | F18: 0.25 | G18: 0.25 | H18: SPEC §26.2: 50/200; 1 = the full devex file
C19: EU transformers ≥ 80 % (ÖSZ-9) | D19: flag | E19: 0 | F19: 0 | G19: 0 | H19: Bid_Cash E16; SPEC §23.1
C20: Signing fee and DD paid | D20: date | E20: 46234 | F20: 46234 | G20: 46234 | H20: Bora Inputs E27; Bid_Cash E34
C21: Bid submission: fee paid, bid security posted | D21: date | E21: 46325 | F21: 46325 | G21: 46325 | H21: Bora Inputs E95; Bid_Cash E35
C22: Performance security posted | D22: date | E22: 46402 | F22: 46402 | G22: 46402 | H22: Bora Deposits K10 (E96 + 17 d); Bid_Cash E36
C23: TSO security paid | D23: date | E23: 46402 | F23: 46402 | G23: 46402 | H23: Bora Inputs E97; Bid_Cash E37
C24: Connection agreement (HCSSZ): fees paid | D24: date | E24: 47027 | F24: 47027 | G24: 47027 | H24: Bora Inputs E99; Bid_Cash E39
C25: Notice to proceed | D25: date | E25: 47299 | F25: 47299 | G25: 47299 | H25: Bora Inputs E154; Bid_Cash E40
... C28: DSA accrual start | D28: date | E28: 46325 | F28: 46325 | G28: 46325 | H28: Bora Inputs E70; others: signing (DSA off)
C29: RtB exit terms (all projects; value in column E)
C30: Claim rate, cash lines (incl. cash-posted securities) | D30: % | E30: 0.12 | H30: Devex file V18; SPEC §21.1
C31: Claim rate, devex | D31: % | E31: 0.2 | H31: Devex file V19
C32: Devex minimum return multiple | D32: x | E32: 2 | H32: Devex file V20
C33: Interest freeze date | D33: date | E33: 47299 | H33: Devex file V24
C34: Sale date, Case B (RtB exit after HCSSZ) | D34: date | E34: 47391 | H34: Bora Inputs E58; SPEC §21.1
C35: Sale date, Case A (before HCSSZ) | D35: date | E35: 47026 | H35: SPEC §25.2 (user, 28-Oct-2026)
C36: Sale costs per project | D36: EUR k | E36: 250 | H36: SPEC §21.1
C37: Developer success fee (on committed MW, 30/360) | D37: EUR k/MW/yr | E37: 2.5 | H37: Bora Inputs E36
C38: Developer success fee cap | D38: EUR k/MW | E38: 10 | H38: Bora Inputs E37
C39: Corporate income tax on exit gains | D39: % | E39: 0.15 | H39: SPEC §22.2 (exit gains only)
C40: Share deal, participation exemption on the share gain (1 = on); claims taxed as interest | D40: flag | E40: 1
C41: Capex (per MW of wind built unless stated; turbines: case table on the Dashboard)
C42: Turbine installation and erection | D42: EUR k/MW | E42: 80 | H42: Bora Inputs G163
C43: Foundations | D43: EUR k/MW | E43: 90 | H43: Bora Inputs G164
C44: Balance of plant – civil | D44: EUR k/MW | E44: 70 | H44: Bora Inputs G165
...
