Workbook
Name Scenario_Name: Inputs!$F$4
Name Scenario_Selected: Inputs!$F$5
Name Scenario_Names: Inputs!$H$7:$H$7
Name Thousand: Inputs!$F$11
Name Million: Inputs!$F$12
Name Days_In_Year: Inputs!$F$13
Name Months_In_Year: Inputs!$F$14
Name Months_Per_Period: Inputs!$F$15
Name Tolerance: Inputs!$F$16
Name In_Model_Start: Inputs!$F$19
Name In_COD: Inputs!$F$20
Name In_Life: Inputs!$F$21
Name In_Bids: Inputs!$F$24
Name In_MVA: Inputs!$F$25
Name In_Overbuild: Inputs!$F$26
Name In_BESS: Inputs!$F$27
Name In_BESS_Hours: Inputs!$F$28
Name In_Wind_ND: Inputs!$F$29
Name In_Turbine: Inputs!$F$32
Name In_Installation: Inputs!$F$33
Name In_Foundations: Inputs!$F$34
Name In_BoP: Inputs!$F$35
Name In_Owner: Inputs!$F$36
Name In_Land: Inputs!$F$37
Name In_Contingency: Inputs!$F$38
Name In_BESS_Capex: Inputs!$F$39
Name In_White_Label: Inputs!$F$40
Name In_Municipal: Inputs!$F$43
Name In_Community: Inputs!$F$44
Name In_P50_Hours: Inputs!$F$45
Name In_Curtailment: Inputs!$F$46
Name In_Degradation: Inputs!$F$47
Name In_Rate: Inputs!$F$48
Name In_CIT: Inputs!$F$49
Name In_CIT_On: Inputs!$F$50
Name In_Bench_Wind: Inputs!$F$53
Name In_Bench_BESS: Inputs!$F$54
Name In_PB_Rate: Inputs!$F$55
Name In_FX: Inputs!$F$56
Name In_Tolerance_Cap: Inputs!$F$57
Name In_Bora_PB: Inputs!$F$58
Name In_Sanction_Lag: Inputs!$F$59
Name In_COD_Price: Inputs!$F$62
Name In_BC_Tax_Base: Inputs!$F$63
Name In_ZB_Tax_Base: Inputs!$F$64
Name In_Dep_Years: Inputs!$F$65
Name BC_Date: Curves!$E$7:$E$126
Name BC_Revenue: Curves!$F$7:$F$126
Name BC_Opex: Curves!$I$7:$I$126
Name BC_EBITDA: Curves!$J$7:$J$126
Name ZB_Date: Curves!$E$130:$E$249
Name ZB_Revenue: Curves!$F$130:$F$249
Name ZB_Opex: Curves!$I$130:$I$249
Name ZB_EBITDA: Curves!$J$130:$J$249
Name Out_Overbuild: Summary!$E$14
Name Out_BESS: Summary!$E$15
Name Out_Municipal: Summary!$E$16
Name Out_Community_PV: Summary!$E$17
Name Out_White_Label: Summary!$E$18
Name Out_Savings_Total: Summary!$E$19

Sheet Cover
B2: =C3&" – Cover"
B3: Project | C3: Bora non-delivery case
B4: Purpose | C4: Savings at COD vs the performance security called
B5: Version | C5: v1
B6: Date | C6: 46310
B7: Author | C7: FEP
A9: x | C9: Colour legend
C10: Hard-coded input | E10: Inputs and Curves only, with unit and source
C11: Link from another sheet
C12: Calculation
C13: Macro-written value | E13: Written by vba/*.bas only (PASTE rows, solved inputs, stored scenario results)
C14: Opening seed | E14: Corkscrew opening balance
A16: x | C16: Model status
B17: Master check | C17: =IF(Master_Check=0,"OK","CHECK")
C20: ***END***

Sheet Summary
B2: =Cover!$C$3&" – Summary"
A4: x | C4: Savings at COD if no commitment is delivered
C5: Item | D5: Unit | E5: Both bids | F5: Per bid | G5: EUR k/MW
C6: Overbuild capex not spent (EUR k/MW: per committed MW)
C7: Turbine supply, EU | D7: EUR m | E7: =Calc!$F$26/Thousand | F7: =Calc!$E$26/Thousand | G7: =Calc!$E$26/Calc!$E$12
C8: Installation and erection | D8: EUR m | E8: =Calc!$F$27/Thousand | F8: =Calc!$E$27/Thousand | G8: =Calc!$E$27/Calc!$E$12
C9: Foundations | D9: EUR m | E9: =Calc!$F$28/Thousand | F9: =Calc!$E$28/Thousand | G9: =Calc!$E$28/Calc!$E$12
C10: Balance of plant | D10: EUR m | E10: =Calc!$F$29/Thousand | F10: =Calc!$E$29/Thousand | G10: =Calc!$E$29/Calc!$E$12
C11: Owner's costs | D11: EUR m | E11: =Calc!$F$30/Thousand | F11: =Calc!$E$30/Thousand | G11: =Calc!$E$30/Calc!$E$12
C12: Land and easements | D12: EUR m | E12: =Calc!$F$31/Thousand | F12: =Calc!$E$31/Thousand | G12: =Calc!$E$31/Calc!$E$12
C13: Contingency | D13: EUR m | E13: =Calc!$F$32/Thousand | F13: =Calc!$E$32/Thousand | G13: =Calc!$E$32/Calc!$E$12
C14: Overbuild capex | D14: EUR m | E14: =Calc!$F$33/Thousand | F14: =Calc!$E$33/Thousand | G14: =Calc!$E$33/Calc!$E$12
C15: BESS capex | D15: EUR m | E15: =Calc!$F$34/Thousand | F15: =Calc!$E$34/Thousand | G15: =Calc!$E$34/Calc!$E$12
C16: Municipal one-off | D16: EUR m | E16: =Calc!$F$35/Thousand | F16: =Calc!$E$35/Thousand | G16: =Calc!$E$35/Calc!$E$12
C17: Community contribution (PV at 8 % to COD) | D17: EUR m | E17: =Calc!$F$36/Thousand | F17: =Calc!$E$36/Thousand | G17: =Calc!$E$36/Calc!$E$12
C18: EU to CN turbines and transformers (white labelling) | D18: EUR m | E18: =Calc!$F$37/Thousand | F18: =Calc!$E$37/Thousand | G18: =Calc!$E$37/Calc!$E$12
C19: Total savings at COD | D19: EUR m | E19: =Calc!$F$38/Thousand | F19: =Calc!$E$38/Thousand | G19: =Calc!$E$38/Calc!$E$12
C20: PB called (full call) | D20: EUR m | E20: =Calc!$F$42/Thousand | F20: =Calc!$E$42/Thousand | G20: =Calc!$E$42/Calc!$E$12
C21: Net saving (savings less PB called) | D21: EUR m | E21: =Calc!$F$43/Thousand | F21: =Calc!$E$43/Thousand | G21: =Calc!$E$43/Calc!$E$12
C23: Savings excluding the community PV | D23: EUR m | E23: =Calc!$F$39/Thousand | F23: =Calc!$E$39/Thousand | G23: =Calc!$E$39/Calc!$E$12
C24: Savings ÷ PB called | D24: x | E24: =Calc!$E$44
C25: Memo: PB lost under the pro-rata reading (XII.12) | D25: EUR m | E25: =Calc!$F$46/Thousand | F25: =Calc!$E$46/Thousand | G25: =Calc!$E$46/Calc!$E$12
A27: x | C27: COD buyer's project IRR (unlevered, post-tax; IRR per bid = both bids)
C28: Item | D28: Unit | E28: A: original | F28: B: no delivery | G28: Zero bid
C29: Buyer project IRR | D29: % | E29: =Calc!$E$58 | F29: =Calc!$E$60 | G29: =Calc!$E$61
C30: Buyer NPV at 8 % to COD, both bids | D30: EUR m | E30: =Calc!$F$58*In_Bids/Thousand | F30: =Calc!$F$60*In_Bids/Thousand | G30: =Calc!$F$61*In_Bids/Thousand
C31: Change in buyer IRR, B less A | D31: pp | E31: =Calc!$E$62
C32: Memo: B if the seller bears the PB call | D32: % | F32: =Calc!$E$59
A34: x | C34: Memo
C35: Points lost after the award: none, the award stands
C36: 3-year group exclusion, as the PB is called | D36: text | E36: =Calc!$E$48
C37: Connection right under a full call: kept (GYIK Q72)
C38: Connection capacity lost, pro-rata reading (GYIK 28/30) | D38: MVA | E38: =Calc!$F$47 | F38: =Calc!$E$47
A40: x | C40: Sanction
C41: Points commitments not proven by COD: full PB call, no discretion (Kiírás XIII.17; GYIK Q72).
C42: Capacity shortfall above 10 %: PB and connection right lost pro rata (XII.12; GYIK 28/30/44).
C43: A called PB excludes the whole group from capacity tenders for 3 years (VII.2 n; GYIK Q71).
C44: The exclusion hits the group at the time of the call: the buyer's group after a sale.
A46: x | C46: Checks
C47: Master check | E47: =IF(Master_Check=0,"OK","CHECK")
...

Sheet Inputs
B2: =Cover!$C$3&" – Inputs and scenarios"
B4: Scenario selected | F4: Base
B5: Scenario number | F5: =MATCH(Scenario_Name,Scenario_Names,0)
B7: Input | C7: Unit | D7: Source / note | F7: Live | H7: Base
A10: x | C10: Constants
B11: Thousand | C11: # | D11: Scale | F11: 1000
B12: Million | C12: # | D12: Scale | F12: 1000000
B13: Days In Year | C13: days | D13: Day count for year fractions and XIRR | F13: 365
B14: Months In Year | C14: months | F14: 12
B15: Months Per Period | C15: months | D15: Timeline periodicity (annual) | F15: 12
B16: Tolerance | C16: # | D16: Check and solver tolerance | F16: 1e-06
A18: x | C18: Timing
B19: Model start date | C19: date | D19: Timeline start | F19: =IF(INDEX($H19:$O19,1,Scenario_Selected)="",$H19,INDEX($H19:$O19,1,Scenario_Selected)) | H19: 47849
B20: Commercial operation date (COD) | C20: date | D20: Bora model Inputs (Bora!N16) | F20: =IF(INDEX($H20:$O20,1,Scenario_Selected)="",$H20,INDEX($H20:$O20,1,Scenario_Selected)) | H20: 48121
B21: Community contribution term from COD | C21: years | D21: Bora model Inputs (E157) | F21: =IF(INDEX($H21:$O21,1,Scenario_Selected)="",$H21,INDEX($H21:$O21,1,Scenario_Selected)) | H21: 30
A23: x | C23: Bids and commitments (per bid)
B24: Bids (BORA 1 and BORA 2) | C24: # | D24: SPEC §1 | F24: =IF(INDEX($H24:$O24,1,Scenario_Selected)="",$H24,INDEX($H24:$O24,1,Scenario_Selected)) | H24: 2
B25: Net connection capacity | C25: MVA | D25: Bora model Inputs | F25: =IF(INDEX($H25:$O25,1,Scenario_Selected)="",$H25,INDEX($H25:$O25,1,Scenario_Selected)) | H25: 100
B26: Overbuild committed (ÖSZ-3) | C26: % | D26: Bora model Dashboard | F26: =IF(INDEX($H26:$O26,1,Scenario_Selected)="",$H26,INDEX($H26:$O26,1,Scenario_Selected)) | H26: 0.51
B27: BESS power committed, share of MVA (ÖSZ-4) | C27: % | D27: Bora model Dashboard | F27: =IF(INDEX($H27:$O27,1,Scenario_Selected)="",$H27,INDEX($H27:$O27,1,Scenario_Selected)) | H27: 0.51
B28: BESS duration | C28: h | D28: Bora model Dashboard | F28: =IF(INDEX($H28:$O28,1,Scenario_Selected)="",$H28,INDEX($H28:$O28,1,Scenario_Selected)) | H28: 4
B29: Wind built if not delivered | C29: MW | D29: SPEC §3 (= MVA) | F29: =IF(INDEX($H29:$O29,1,Scenario_Selected)="",$H29,INDEX($H29:$O29,1,Scenario_Selected)) | H29: 100
A31: x | C31: Capex saved
B32: Turbine supply, EU | C32: EUR k/MW | D32: Bora model Inputs (user 12-Oct-26) | F32: =IF(INDEX($H32:$O32,1,Scenario_Selected)="",$H32,INDEX($H32:$O32,1,Scenario_Selected)) | H32: 600
B33: Turbine installation and erection | C33: EUR k/MW | D33: Bora model Inputs (old E163) | F33: =IF(INDEX($H33:$O33,1,Scenario_Selected)="",$H33,INDEX($H33:$O33,1,Scenario_Selected)) | H33: 80
B34: Foundations | C34: EUR k/MW | D34: Bora model Inputs (old E164) | F34: =IF(INDEX($H34:$O34,1,Scenario_Selected)="",$H34,INDEX($H34:$O34,1,Scenario_Selected)) | H34: 90
B35: Balance of plant | C35: EUR k/MW | D35: Bora model Inputs (old E165:E166) | F35: =IF(INDEX($H35:$O35,1,Scenario_Selected)="",$H35,INDEX($H35:$O35,1,Scenario_Selected)) | H35: 130
B36: Owner's costs | C36: EUR k/MW | D36: Bora model Inputs (old E169) | F36: =IF(INDEX($H36:$O36,1,Scenario_Selected)="",$H36,INDEX($H36:$O36,1,Scenario_Selected)) | H36: 40
B37: Land and easements | C37: EUR k/MW | D37: Bora model Inputs (old E170) | F37: =IF(INDEX($H37:$O37,1,Scenario_Selected)="",$H37,INDEX($H37:$O37,1,Scenario_Selected)) | H37: 15
B38: Contingency on overbuild capex | C38: % | D38: Bora model Inputs (old E171) | F38: =IF(INDEX($H38:$O38,1,Scenario_Selected)="",$H38,INDEX($H38:$O38,1,Scenario_Selected)) | H38: 0.05
B39: BESS capex | C39: EUR k/MW | D39: Bora model Inputs (user 12-Oct-26) | F39: =IF(INDEX($H39:$O39,1,Scenario_Selected)="",$H39,INDEX($H39:$O39,1,Scenario_Selected)) | H39: 240
B40: EU to CN turbines and transformers, saving | C40: EUR k/MW | D40: User 15-Oct-26 | F40: =IF(INDEX($H40:$O40,1,Scenario_Selected)="",$H40,INDEX($H40:$O40,1,Scenario_Selected)) | H40: 100
A42: x | C42: Municipal and community commitments
B43: Municipal one-off at COD (ÖSZ-1) | C43: EUR k/MW | D43: Bora model Dashboard | F43: =IF(INDEX($H43:$O43,1,Scenario_Selected)="",$H43,INDEX($H43:$O43,1,Scenario_Selected)) | H43: 50
B44: Community contribution (ÖSZ-2) | C44: EUR/MWh | D44: Bora model Dashboard | F44: =IF(INDEX($H44:$O44,1,Scenario_Selected)="",$H44,INDEX($H44:$O44,1,Scenario_Selected)) | H44: 3
B45: Net P50 hours | C45: h/yr | D45: Bora model Inputs (old E179) | F45: =IF(INDEX($H45:$O45,1,Scenario_Selected)="",$H45,INDEX($H45:$O45,1,Scenario_Selected)) | H45: 2460
B46: Curtailment | C46: % | D46: Bora model Inputs (old E181) | F46: =IF(INDEX($H46:$O46,1,Scenario_Selected)="",$H46,INDEX($H46:$O46,1,Scenario_Selected)) | H46: 0.02
B47: Degradation per year | C47: % | D47: Bora model Inputs (old E182) | F47: =IF(INDEX($H47:$O47,1,Scenario_Selected)="",$H47,INDEX($H47:$O47,1,Scenario_Selected)) | H47: 0.003
B48: Discount rate (PV to COD) | C48: % | D48: Bora model Inputs (old E253) | F48: =IF(INDEX($H48:$O48,1,Scenario_Selected)="",$H48,INDEX($H48:$O48,1,Scenario_Selected)) | H48: 0.08
B49: Corporate income tax | C49: % | D49: Bora model Inputs (old E12) | F49: =IF(INDEX($H49:$O49,1,Scenario_Selected)="",$H49,INDEX($H49:$O49,1,Scenario_Selected)) | H49: 0.09
...

Sheet Curves
B2: =Cover!$C$3&" – Time-series inputs"
A5: x | C5: Original plan (A, base case): operating cash flows after COD, per bid | E5: Bora model, base case, Calc_1 rows 112-119
D6: EUR k | E6: Period end | F6: Revenue | I6: Opex | J6: EBITDA
E7: 48213 | F7: 5468.8833 | I7: -1317.7768 | J7: 4151.1065
E8: 48304 | F8: 5463.5333 | I8: -1329.8235 | J8: 4133.7098
E9: 48395 | F9: 5463.5333 | I9: -1329.8235 | J9: 4133.7098
E10: 48487 | F10: 5523.5721 | I10: -1344.437 | J10: 4179.1351
E11: 48579 | F11: 5507.0014 | I11: -1342.5603 | J11: 4164.4411
E12: 48669 | F12: 5441.1568 | I12: -1340.0626 | J12: 4101.0943
E13: 48760 | F13: 5501.6141 | I13: -1354.9522 | J13: 4146.662
E14: 48852 | F14: 5562.0714 | I14: -1369.8417 | J14: 4192.2297
E15: 48944 | F15: 5545.3852 | I15: -1367.9428 | J15: 4177.4425
E16: 49034 | F16: 5479.0817 | I16: -1365.5155 | J16: 4113.5662
E17: 49125 | F17: 5539.9604 | I17: -1380.6879 | J17: 4159.2725
E18: 49217 | F18: 5600.8391 | I18: -1395.8603 | J18: 4204.9788
... E126: 59079 | F126: 6756.1527 | I126: -2393.7405 | J126: 4362.4122
A128: x | C128: Zero bid: operating cash flows after COD, per bid | E128: Bora model, zero bid, Calc_1 rows 112-119
D129: EUR k | E129: Period end | F129: Revenue | I129: Opex | J129: EBITDA
E130: 48213 | F130: 5468.8833 | I130: -1135.4807 | J130: 4333.4026
E131: 48304 | F131: 5463.5333 | I131: -1149.5089 | J131: 4314.0244
E132: 48395 | F132: 5463.5333 | I132: -1149.5089 | J132: 4314.0244
E133: 48487 | F133: 5523.5721 | I133: -1162.1409 | J133: 4361.4313
E134: 48579 | F134: 5507.0014 | I134: -1160.8111 | J134: 4346.1903
E135: 48669 | F135: 5441.1568 | I135: -1162.2644 | J135: 4278.8924
E136: 48760 | F136: 5501.6141 | I136: -1175.1785 | J136: 4326.4357
E137: 48852 | F137: 5562.0714 | I137: -1188.0925 | J137: 4373.9789
E138: 48944 | F138: 5545.3852 | I138: -1186.7388 | J138: 4358.6464
E139: 49034 | F139: 5479.0817 | I139: -1188.2507 | J139: 4290.831
E140: 49125 | F140: 5539.9604 | I140: -1201.4535 | J140: 4338.5069
E141: 49217 | F141: 5600.8391 | I141: -1214.6563 | J141: 4386.1828
... E249: 59079 | F249: 6756.1527 | I249: -2226.6557 | J249: 4529.497
C251: ***END***

Sheet Calc
B2: =Cover!$C$3&" – Calculations"
C3: Period start | D3: date | J3: =I$4+1 | K3: =J$4+1 | L3: =K$4+1 | M3: =L$4+1 | N3: =M$4+1 | O3: =N$4+1 | P3: =O$4+1 | Q3: =P$4+1 | ... AN3: =AM$4+1
C4: Period end | D4: date | I4: =In_Model_Start-1 | J4: =EOMONTH(J$3,Months_Per_Period-1) | K4: =EOMONTH(K$3,Months_Per_Period-1) | L4: =EOMONTH(L$3,Months_Per_Period-1) | M4: =EOMONTH(M$3,Months_Per_Period-1) | N4: =EOMONTH(N$3,Months_Per_Period-1) | O4: =EOMONTH(O$3,Months_Per_Period-1) | P4: =EOMONTH(P$3,Months_Per_Period-1) | Q4: =EOMONTH(Q$3,Months_Per_Period-1) | ... AN4: =EOMONTH(AN$3,Months_Per_Period-1)
C5: Days in period | D5: days | J5: =J$4-J$3+1 | K5: =K$4-K$3+1 | L5: =L$4-L$3+1 | M5: =M$4-M$3+1 | N5: =N$4-N$3+1 | O5: =O$4-O$3+1 | P5: =P$4-P$3+1 | Q5: =Q$4-Q$3+1 | ... AN5: =AN$4-AN$3+1
C6: Year fraction | D6: factor | J6: =J$5/Days_In_Year | K6: =K$5/Days_In_Year | L6: =L$5/Days_In_Year | M6: =M$5/Days_In_Year | N6: =N$5/Days_In_Year | O6: =O$5/Days_In_Year | P6: =P$5/Days_In_Year | Q6: =Q$5/Days_In_Year | ... AN6: =AN$5/Days_In_Year
C7: Year | D7: year | J7: =YEAR(J$4) | K7: =YEAR(K$4) | L7: =YEAR(L$4) | M7: =YEAR(M$4) | N7: =YEAR(N$4) | O7: =YEAR(O$4) | P7: =YEAR(P$4) | Q7: =YEAR(Q$4) | ... AN7: =YEAR(AN$4)
C8: Period counter | D8: # | J8: =I$8+1 | K8: =J$8+1 | L8: =K$8+1 | M8: =L$8+1 | N8: =M$8+1 | O8: =N$8+1 | P8: =O$8+1 | Q8: =P$8+1 | ... AN8: =AM$8+1
A11: x | C11: Capacity per bid
C12: Committed wind (built if delivered) | D12: MW | E12: =In_MVA*(1+In_Overbuild)
C13: Wind not built | D13: MW | E13: =$E12-In_Wind_ND
C14: BESS committed (E: MW, F: MWh) | D14: MW | E14: =In_BESS*In_MVA | F14: =$E14*In_BESS_Hours
C15: Security base (E: wind, F: BESS) | D15: mHUF | E15: =$E12*In_Bench_Wind | F15: =$F14*In_Bench_BESS
A17: x | C17: Community contribution not paid (committed wind, per bid)
C18: Operating period (COD to end of term) | D18: flag | E18: =In_COD+1 | F18: =EDATE(In_COD,In_Life*Months_In_Year) | J18: =MAX(0,(MIN($F18,J$4)-MAX($E18,J$3)+1)/J$5) | K18: =MAX(0,(MIN($F18,K$4)-MAX($E18,K$3)+1)/K$5) | L18: =MAX(0,(MIN($F18,L$4)-MAX($E18,L$3)+1)/L$5) | M18: =MAX(0,(MIN($F18,M$4)-MAX($E18,M$3)+1)/M$5) | N18: =MAX(0,(MIN($F18,N$4)-MAX($E18,N$3)+1)/N$5) | O18: =MAX(0,(MIN($F18,O$4)-MAX($E18,O$3)+1)/O$5) | P18: =MAX(0,(MIN($F18,P$4)-MAX($E18,P$3)+1)/P$5) | Q18: =MAX(0,(MIN($F18,Q$4)-MAX($E18,Q$3)+1)/Q$5) | ... AN18: =MAX(0,(MIN($F18,AN$4)-MAX($E18,AN$3)+1)/AN$5)
C19: Degradation factor | D19: factor | J19: =(1-In_Degradation)^(J$7-YEAR(In_COD)) | K19: =(1-In_Degradation)^(K$7-YEAR(In_COD)) | L19: =(1-In_Degradation)^(L$7-YEAR(In_COD)) | M19: =(1-In_Degradation)^(M$7-YEAR(In_COD)) | N19: =(1-In_Degradation)^(N$7-YEAR(In_COD)) | O19: =(1-In_Degradation)^(O$7-YEAR(In_COD)) | P19: =(1-In_Degradation)^(P$7-YEAR(In_COD)) | Q19: =(1-In_Degradation)^(Q$7-YEAR(In_COD)) | ... AN19: =(1-In_Degradation)^(AN$7-YEAR(In_COD))
C20: Net generation | D20: MWh | I20: =SUM(J20:AN20) | J20: =$E12*In_P50_Hours*(1-In_Curtailment)*J19*J18*J$6 | K20: =$E12*In_P50_Hours*(1-In_Curtailment)*K19*K18*K$6 | L20: =$E12*In_P50_Hours*(1-In_Curtailment)*L19*L18*L$6 | M20: =$E12*In_P50_Hours*(1-In_Curtailment)*M19*M18*M$6 | N20: =$E12*In_P50_Hours*(1-In_Curtailment)*N19*N18*N$6 | O20: =$E12*In_P50_Hours*(1-In_Curtailment)*O19*O18*O$6 | P20: =$E12*In_P50_Hours*(1-In_Curtailment)*P19*P18*P$6 | Q20: =$E12*In_P50_Hours*(1-In_Curtailment)*Q19*Q18*Q$6 | ... AN20: =$E12*In_P50_Hours*(1-In_Curtailment)*AN19*AN18*AN$6
C21: Discount factor to COD | D21: factor | J21: =1/(1+In_Rate)^((J$4-In_COD)/Days_In_Year) | K21: =1/(1+In_Rate)^((K$4-In_COD)/Days_In_Year) | L21: =1/(1+In_Rate)^((L$4-In_COD)/Days_In_Year) | M21: =1/(1+In_Rate)^((M$4-In_COD)/Days_In_Year) | N21: =1/(1+In_Rate)^((N$4-In_COD)/Days_In_Year) | O21: =1/(1+In_Rate)^((O$4-In_COD)/Days_In_Year) | P21: =1/(1+In_Rate)^((P$4-In_COD)/Days_In_Year) | Q21: =1/(1+In_Rate)^((Q$4-In_COD)/Days_In_Year) | ... AN21: =1/(1+In_Rate)^((AN$4-In_COD)/Days_In_Year)
C22: Community contribution not paid (E: PV by XNPV) | D22: EUR k | E22: =XNPV(In_Rate,$J22:$AN22,$J$4:$AN$4)*INDEX($J21:$AN21,1) | I22: =SUM(J22:AN22) | J22: =In_Community*J20*(1-In_CIT*In_CIT_On)/Thousand | K22: =In_Community*K20*(1-In_CIT*In_CIT_On)/Thousand | L22: =In_Community*L20*(1-In_CIT*In_CIT_On)/Thousand | M22: =In_Community*M20*(1-In_CIT*In_CIT_On)/Thousand | N22: =In_Community*N20*(1-In_CIT*In_CIT_On)/Thousand | O22: =In_Community*O20*(1-In_CIT*In_CIT_On)/Thousand | P22: =In_Community*P20*(1-In_CIT*In_CIT_On)/Thousand | Q22: =In_Community*Q20*(1-In_CIT*In_CIT_On)/Thousand | ... AN22: =In_Community*AN20*(1-In_CIT*In_CIT_On)/Thousand
A24: x | C24: Savings at COD (E: per bid, F: both bids)
C25: Overbuild capex not spent
C26: Turbine supply, EU | D26: EUR k | E26: =In_Turbine*$E13 | F26: =$E26*In_Bids
C27: Installation and erection | D27: EUR k | E27: =In_Installation*$E13 | F27: =$E27*In_Bids
C28: Foundations | D28: EUR k | E28: =In_Foundations*$E13 | F28: =$E28*In_Bids
C29: Balance of plant | D29: EUR k | E29: =In_BoP*$E13 | F29: =$E29*In_Bids
C30: Owner's costs | D30: EUR k | E30: =In_Owner*$E13 | F30: =$E30*In_Bids
C31: Land and easements | D31: EUR k | E31: =In_Land*$E13 | F31: =$E31*In_Bids
C32: Contingency | D32: EUR k | E32: =In_Contingency*SUM($E26:$E31) | F32: =$E32*In_Bids
C33: Overbuild capex | D33: EUR k | E33: =(In_Turbine+In_Installation+In_Foundations+In_BoP+In_Owner+In_Land)*$E13*(1+In_Contingency) | F33: =$E33*In_Bids
C34: BESS capex | D34: EUR k | E34: =In_BESS_Capex*$E14 | F34: =$E34*In_Bids
C35: Municipal one-off | D35: EUR k | E35: =In_Municipal*In_MVA | F35: =$E35*In_Bids
C36: Community contribution (PV to COD) | D36: EUR k | E36: =SUMPRODUCT($J22:$AN22,$J21:$AN21) | F36: =$E36*In_Bids
C37: EU to CN turbines and transformers (white labelling) | D37: EUR k | E37: =In_White_Label*In_Wind_ND | F37: =$E37*In_Bids
C38: Total savings at COD | D38: EUR k | E38: =SUM($E33:$E37) | F38: =$E38*In_Bids
C39: Savings excluding the community PV | D39: EUR k | E39: =$E38-$E36 | F39: =$E39*In_Bids
A41: x | C41: Performance security (E: per bid, F: both bids)
C42: PB called (full call) | D42: EUR k | E42: =-In_PB_Rate*($E15+$F15)*Thousand/In_FX | F42: =$E42*In_Bids
C43: Net saving (savings less PB called) | D43: EUR k | E43: =$E38+$E42 | F43: =$E43*In_Bids
C44: Savings ÷ PB called | D44: x | E44: =$E38/-$E42
C45: Wind shortfall share | D45: % | E45: =$E13/$E12
C46: PB lost, pro-rata reading (BESS in full, wind pro rata) | D46: EUR k | E46: =-In_PB_Rate*($E45*($E45>In_Tolerance_Cap)*$E15+$F15)*Thousand/In_FX | F46: =$E46*In_Bids
...

Sheet Checks
B2: =Cover!$C$3&" – Checks"
C4: Period end | J4: =Calc!J$4 | K4: =Calc!K$4 | L4: =Calc!L$4 | M4: =Calc!M$4 | N4: =Calc!N$4 | O4: =Calc!O$4 | P4: =Calc!P$4 | Q4: =Calc!Q$4 | ... AN4: =Calc!AN$4
E9: Status | F9: Fails
A11: x | C11: Checks (0 = OK)
C12: Overbuild capex: elements = total | D12: flag | E12: =IF(F12=0,"OK","CHECK") | F12: =--(ABS(SUM(Calc!$E$26:$E$32)-Calc!$E33)>Tolerance)
C13: PB per bid = Bora model PB (EUR 6,993.6 k) | D13: flag | E13: =IF(F13=0,"OK","CHECK") | F13: =--(ABS(-Calc!$E42-In_Bora_PB)>Tolerance)
C14: Community PV: XNPV = SUMPRODUCT | D14: flag | E14: =IF(F14=0,"OK","CHECK") | F14: =--(ABS(Calc!$E22-Calc!$E36)>Tolerance)
C15: Base-case data: revenue + opex = EBITDA | D15: flag | E15: =IF(F15=0,"OK","CHECK") | F15: =--(ABS(SUM(BC_Revenue)+SUM(BC_Opex)-SUM(BC_EBITDA))>Tolerance)
C16: Base-case EBITDA all on the timeline | D16: flag | E16: =IF(F16=0,"OK","CHECK") | F16: =--(ABS(SUM(BC_EBITDA)-Calc!$I54)>Tolerance)
C17: Zero-bid data: revenue + opex = EBITDA | D17: flag | E17: =IF(F17=0,"OK","CHECK") | F17: =--(ABS(SUM(ZB_Revenue)+SUM(ZB_Opex)-SUM(ZB_EBITDA))>Tolerance)
C18: Zero-bid EBITDA all on the timeline | D18: flag | E18: =IF(F18=0,"OK","CHECK") | F18: =--(ABS(SUM(ZB_EBITDA)-Calc!$I55)>Tolerance)
C20: Master check | E20: =IF(F20=0,"OK","CHECK") | F20: =SUMPRODUCT(ABS(F12:F18))
C22: ***END***
