Workbook

Sheet Dashboard
C2: HU wind projects
C3: Master check (0 = OK; checks at the end of the detail) | D3: flag | H3: =Master_Check -> 0
B5: x | C5: Key inputs: the bids | E5: Bora | F5: Iváncsa | G5: Dunaújváros | H5: Total
C6: Net connection capacity | D6: MVA | E6: 50 | F6: 50 | G6: 50 | H6: =SUM(E6:G6) -> 150
C7: Overbuild (ÖSZ-3) | D7: % | E7: 0 | F7: 0.4 | G7: 0.4
C8: BESS power, share of MVA (ÖSZ-4) | D8: % | E8: 0 | F8: 0.2 | G8: 0.2
C9: BESS duration | D9: h | E9: 4 | F9: 4 | G9: 4
C10: Wind built below the bid | D10: % | E10: 0 | F10: 0 | G10: 0
C11: Municipal one-off (ÖSZ-1), at COD | D11: EUR k/MVA | E11: 20 | F11: 50 | G11: 50
C12: Community contribution (ÖSZ-2) | D12: EUR/MWh | E12: 0 | F12: 3 | G12: 3
C13: Partial award accepted (ÖSZ-5) | D13: flag | E13: 1 | F13: 1 | G13: 1
C14: Performance security multiple (ÖSZ-6) | D14: x | E14: 1 | F14: 1 | G14: 1
C15: Brownfield site (ÖSZ-7) | D15: flag | E15: 0 | F15: 0 | G15: 0
C16: Shared connection (ÖSZ-8) | D16: flag | E16: 1 | F16: 1 | G16: 1
C17: Turbine route (EU or CN; EU scores ÖSZ-9) | D17: text | E17: CN | F17: CN | G17: CN
C18: RtB premium | D18: EUR k/MVA | E18: 150 | F18: 150 | G18: 150
C19: FEP share of distributable proceeds | D19: % | E19: 0.7 | F19: 1 | G19: 1
C20: Developer success fee (DSA) on | D20: flag | E20: 1 | F20: 0 | G20: 0
C21: JV with a developer (1 = yes; claims and DSA apply) | D21: flag | E21: 1 | F21: 0 | G21: 0
C22: Net P50 hours (project wind study) | D22: h/yr | E22: 2500 | F22: 2500 | G22: 2500
B24: x | C24: Case: turbine price, PPA, yield, O&M | E24: Base | F24: Low | G24: High | H24: Live
C25: Case selected (Base, Low or High) | D25: case | H25: Base
C26: Turbine supply incl. transport, EU route | D26: EUR k/MW | E26: 850 | F26: 950 | G26: 800 | H26: =INDEX(E26:G26,MATCH(Dash_Case,$E$24:$G$24,0)) -> 850 | J26: Bora Dashboard H8 / Inputs G162
C27: Turbine supply incl. transport, CN route | D27: EUR k/MW | E27: 500 | F27: 600 | G27: 480 | H27: =INDEX(E27:G27,MATCH(Dash_Case,$E$24:$G$24,0)) -> 500 | J27: Bora Inputs H162
C28: PPA price in the COD year | D28: EUR/MWh | E28: 90 | F28: 90 | G28: 100 | H28: =INDEX(E28:G28,MATCH(Dash_Case,$E$24:$G$24,0)) -> 90 | J28: Bora Dashboard H9
C29: Net P50 hours (not used: project P50 in row 21) | D29: h/yr | E29: 2500 | F29: 2460 | G29: 2600 | H29: =INDEX(E29:G29,MATCH(Dash_Case,$E$24:$G$24,0)) -> 2500 | J29: Bora Dashboard H10
C30: O&M full-service contract | D30: EUR k/MW/yr | E30: 12 | F30: 12 | G30: 10 | H30: =INDEX(E30:G30,MATCH(Dash_Case,$E$24:$G$24,0)) -> 12 | J30: Bora Dashboard H11
B32: x | C32: Bid points and capacity | E32: Bora | F32: Iváncsa | G32: Dunaújváros | H32: Total
C33: Points – municipal one-off | D33: points | E33: =INDEX(Osz1_Pts,1+SUMPRODUCT((Osz1_LB<E11)+(Osz1_LB=E11)*Osz1_Incl))*Osz1_W -> 4 | F33: =INDEX(Osz1_Pts,1+SUMPRODUCT((Osz1_LB<F11)+(Osz1_LB=F11)*Osz1_Incl))*Osz1_W -> 20 | G33: =INDEX(Osz1_Pts,1+SUMPRODUCT((Osz1_LB<G11)+(Osz1_LB=G11)*Osz1_Incl))*Osz1_W -> 20
C34: Points – community contribution | D34: points | E34: =INDEX(Osz2_Pts,1+SUMPRODUCT((Osz2_LB<E12)+(Osz2_LB=E12)*Osz2_Incl))*Osz2_W -> 0 | F34: =INDEX(Osz2_Pts,1+SUMPRODUCT((Osz2_LB<F12)+(Osz2_LB=F12)*Osz2_Incl))*Osz2_W -> 15 | G34: =INDEX(Osz2_Pts,1+SUMPRODUCT((Osz2_LB<G12)+(Osz2_LB=G12)*Osz2_Incl))*Osz2_W -> 15
C35: Points – overbuild | D35: points | E35: =INDEX(Osz3_Pts,1+SUMPRODUCT((Osz3_LB<E7)+(Osz3_LB=E7)*Osz3_Incl))*Osz3_W -> 0 | F35: =INDEX(Osz3_Pts,1+SUMPRODUCT((Osz3_LB<F7)+(Osz3_LB=F7)*Osz3_Incl))*Osz3_W -> 9 | G35: =INDEX(Osz3_Pts,1+SUMPRODUCT((Osz3_LB<G7)+(Osz3_LB=G7)*Osz3_Incl))*Osz3_W -> 9
C36: Points – BESS | D36: points | E36: =INDEX(Osz3_Pts,1+SUMPRODUCT((Osz3_LB<E8)+(Osz3_LB=E8)*Osz3_Incl))*Osz4_W -> 0 | F36: =INDEX(Osz3_Pts,1+SUMPRODUCT((Osz3_LB<F8)+(Osz3_LB=F8)*Osz3_Incl))*Osz4_W -> 7.5 | G36: =INDEX(Osz3_Pts,1+SUMPRODUCT((Osz3_LB<G8)+(Osz3_LB=G8)*Osz3_Incl))*Osz4_W -> 7.5
C37: Points – partial award | D37: points | E37: =E13*Osz5_Pts*Osz5_W -> 5 | F37: =F13*Osz5_Pts*Osz5_W -> 5 | G37: =G13*Osz5_Pts*Osz5_W -> 5
C38: Points – performance security | D38: points | E38: =INDEX(Osz6_Pts,1+SUMPRODUCT((Osz6_LB<E14)+(Osz6_LB=E14)*Osz6_Incl))*Osz6_W -> 0 | F38: =INDEX(Osz6_Pts,1+SUMPRODUCT((Osz6_LB<F14)+(Osz6_LB=F14)*Osz6_Incl))*Osz6_W -> 0 | G38: =INDEX(Osz6_Pts,1+SUMPRODUCT((Osz6_LB<G14)+(Osz6_LB=G14)*Osz6_Incl))*Osz6_W -> 0
C39: Points – brownfield | D39: points | E39: =E15*Osz7_Pts*Osz7_W -> 0 | F39: =F15*Osz7_Pts*Osz7_W -> 0 | G39: =G15*Osz7_Pts*Osz7_W -> 0
C40: Points – shared connection | D40: points | E40: =E16*Osz8_Pts*Osz8_W -> 5 | F40: =F16*Osz8_Pts*Osz8_W -> 5 | G40: =G16*Osz8_Pts*Osz8_W -> 5
C41: Points – EU turbines | D41: points | E41: =N(E17="EU")*Osz9a_Pts*Osz9_W -> 0 | F41: =N(F17="EU")*Osz9a_Pts*Osz9_W -> 0 | G41: =N(G17="EU")*Osz9a_Pts*Osz9_W -> 0
C42: Points – EU transformers | D42: points | E42: =Inputs!E$25*Osz9b_Pts*Osz9_W -> 0 | F42: =Inputs!F$25*Osz9b_Pts*Osz9_W -> 0 | G42: =Inputs!G$25*Osz9b_Pts*Osz9_W -> 0
C43: Points total | D43: points | E43: =SUM(E33:E42) -> 14 | F43: =SUM(F33:F42) -> 61.5 | G43: =SUM(G33:G42) -> 61.5
C44: Wind committed in the bid | D44: MW | E44: =E6*(1+E7) -> 50 | F44: =F6*(1+F7) -> 70 | G44: =G6*(1+G7) -> 70 | H44: =SUM(E44:G44) -> 190
...

Sheet Inputs
C2: HU wind bids – other inputs (blue) with sources
B4: x | C4: Inputs | E4: Bora | F4: Iváncsa | G4: Dunaújváros | H4: Source
C5: Tender and grid (all projects; value in column E)
C6: FX rate | D6: HUF/EUR | E6: 365 | H6: Bora Inputs E11; Bid_Cash E45
C7: Security base: benchmark investment, wind | D7: HUF/MW | E7: 406000000 | H7: Bora Inputs E75; Bid_Cash E46
C8: Security base: benchmark investment, BESS | D8: HUF/MWh | E8: 200000000 | H8: Bora Inputs E89; Bid_Cash E47
C9: Bid security, share of base | D9: % | E9: 0.005 | H9: Bora Inputs E76; Bid_Cash E49
C10: Performance security, minimum share of base | D10: % | E10: 0.025 | H10: Bora Inputs E77; Bid_Cash E50
C11: Participation fee per bid | D11: HUF | E11: 3000000 | H11: Bora Inputs E81; Bid_Cash E48
C12: TSO connection-request security | D12: HUF/MVA | E12: 4500000 | H12: Bora Inputs E83; Bid_Cash E51
C13: Per project: fees, devex, dates
C14: Indirect connection fee | D14: HUF/MVA | E14: 73071306 | F14: 19826680 | G14: 19826680 | H14: Bora Inputs G290; Bid_Cash E52
C15: Direct connection fee per connection point | D15: HUF | E15: 508345804 | F15: 460000000 | G15: 460000000 | H15: Bora Inputs G291; Bid_Cash E53
C16: Bids sharing the connection point | D16: count | E16: 2 | F16: 1 | G16: 1 | H16: Bora: 2 bids per point (SPEC §22.2)
C17: Signing fee and DD | D17: EUR k | E17: 100 | F17: 150 | G17: 150 | H17: Bora E24+E25: 400 × 50/200; Bid_Cash E55
C18: Devex: grid connection plan and agreement | D18: EUR k | E18: 40.47 | F18: =$E18/SUM($E$18:$E$23)*F$24 -> 51.588971 | G18: =$E18/SUM($E$18:$E$23)*G$24 -> 51.588971 | H18: Bora share × F25/G25 (Iváncsa, Dunaújváros); Bora: Devex_FEP × 50/100 MVA
C19: Devex: land (reservation, purchase, contracting) | D19: EUR k | E19: 150.66 | F19: =$E19/SUM($E$18:$E$23)*F$24 -> 192.05323 | G19: =$E19/SUM($E$18:$E$23)*G$24 -> 192.05323 | H19: Bora share × F25/G25 (Iváncsa, Dunaújváros); Bora: Devex_FEP × 50/100 MVA
C20: Devex: permits, zoning, cable rights | D20: EUR k | E20: 333.93 | F20: =$E20/SUM($E$18:$E$23)*F$24 -> 425.67593 | G20: =$E20/SUM($E$18:$E$23)*G$24 -> 425.67593 | H20: Bora share × F25/G25 (Iváncsa, Dunaújváros); Bora: Devex_FEP × 50/100 MVA
C21: Devex: studies (wind, environment, ground) | D21: EUR k | E21: 151.36 | F21: =$E21/SUM($E$18:$E$23)*F$24 -> 192.94556 | G21: =$E21/SUM($E$18:$E$23)*G$24 -> 192.94556 | H21: Bora share × F25/G25 (Iváncsa, Dunaújváros); Bora: Devex_FEP × 50/100 MVA
C22: Devex: legal, financial and other | D22: EUR k | E22: 37.5 | F22: =$E22/SUM($E$18:$E$23)*F$24 -> 47.802975 | G22: =$E22/SUM($E$18:$E$23)*G$24 -> 47.802975 | H22: Bora share × F25/G25 (Iváncsa, Dunaújváros); Bora: Devex_FEP × 50/100 MVA
C23: Devex: contingency | D23: EUR k | E23: 70.55 | F23: =$E23/SUM($E$18:$E$23)*F$24 -> 89.933331 | G23: =$E23/SUM($E$18:$E$23)*G$24 -> 89.933331 | H23: Bora share × F25/G25 (Iváncsa, Dunaújváros); Bora: Devex_FEP × 50/100 MVA
C24: Devex total, Iváncsa and Dunaújváros (allocated pro rata to Bora's categories) | D24: EUR k | F24: 1000 | G24: 1000 | H24: User, 27-Oct-26: EUR 1m per project, split as Bora
C25: EU transformers ≥ 80 % (ÖSZ-9) | D25: flag | E25: 0 | F25: 0 | G25: 0 | H25: Bid_Cash E16; SPEC §23.1
C26: Signing fee and DD paid | D26: date | E26: 46234 | F26: 46234 | G26: 46234 | H26: Bora Inputs E27; Bid_Cash E34
C27: Bid submission: fee paid, bid security posted | D27: date | E27: 46325 | F27: 46325 | G27: 46325 | H27: Bora Inputs E95; Bid_Cash E35
C28: Performance security posted | D28: date | E28: 46402 | F28: 46402 | G28: 46402 | H28: Bora Deposits K10 (E96 + 17 d); Bid_Cash E36
C29: TSO security paid | D29: date | E29: 46402 | F29: 46402 | G29: 46402 | H29: Bora Inputs E97; Bid_Cash E37
C30: Connection agreement (HCSSZ): fees paid | D30: date | E30: 47027 | F30: 47027 | G30: 47027 | H30: Bora Inputs E99; Bid_Cash E39
C31: Devex average payment date | D31: date | E31: 46752 | F31: 46752 | G31: 46752 | H31: Bora Devex_FEP, amount-weighted; Bid_Cash 'continuous'
C32: Notice to proceed | D32: date | E32: 47299 | F32: 47299 | G32: 47299 | H32: Bora Inputs E154; Bid_Cash E40
C33: COD | D33: date | E33: 48029 | F33: 48029 | G33: 48029 | H33: Bora Inputs E155; Bid_Cash E41
C34: Performance security released | D34: date | E34: 48669 | F34: 48669 | G34: 48669 | H34: Bid_Cash E42 (Kiírás XII.13, estimate)
C35: DSA accrual start | D35: date | E35: 46325 | F35: 46325 | G35: 46325 | H35: Bora Inputs E70; others: signing (DSA off)
C36: RtB exit terms (all projects; value in column E)
C37: Claim rate, cash lines (incl. cash-posted securities) | D37: % | E37: 0.12 | H37: Devex file V18; SPEC §21.1
C38: Claim rate, devex | D38: % | E38: 0.2 | H38: Devex file V19
C39: Devex minimum return multiple | D39: x | E39: 2 | H39: Devex file V20
C40: Interest freeze date | D40: date | E40: 47299 | H40: Devex file V24
C41: Sale date, Case B (RtB exit after HCSSZ) | D41: date | E41: 47391 | H41: Bora Inputs E58; SPEC §21.1
C42: Sale date, Case A (before HCSSZ) | D42: date | E42: 47026 | H42: SPEC §25.2 (user, 28-Oct-2026)
...
