Workbook

Sheet Stat_Inp
B2: Outputs
B3: Project IRR | C3: % | F3: =Model!D37 -> 0.093844097
B4: Buyer Unlevered IRR | C4: % | F4: =Model!D44 -> 0.079572534
B6: Buyer IRR Sensitivities
B8: Purchase price vs CAPEX | J8: Purchase price vs Capture price | S8: Purchase price vs Yield
D9: Buyer purchase price, €k/MW | M9: Buyer purchase price, €k/MW | U9: Buyer purchase price, €k/MW
C10: =F4 -> 0.079572534 | D10: =E10-10 -> 60 | E10: =F10-10 -> 70 | F10: 80 | G10: =F10+10 -> 90 | H10: =G10+10 -> 100 | L10: =$F$4 -> 0.079572534 | M10: =N10-10 -> 60 | N10: =O10-10 -> 70 | O10: 80 | P10: =O10+10 -> 90 | Q10: =P10+10 -> 100 | T10: =$F$4 -> 0.079572534 | U10: =V10-10 -> 60 | V10: =W10-10 -> 70 | W10: 80 | X10: =W10+10 -> 90 | Y10: =X10+10 -> 100
B11: CAPEX, €k/MW | C11: =C12+10 -> 535 | J11: Capture price, €/MWh | L11: =L12 + 5 -> 55 | T11: =T12+25 -> 1300
C12: =C13+10 -> 525 | L12: =L13 + 5 -> 50 | T12: =T13+25 -> 1275
C13: 515 | L13: 45 | T13: 1250
C14: =C13 - 10 -> 505 | L14: =L13-5 -> 40 | T14: =T13-25 -> 1225
C15: =C14 - 10 -> 495 | L15: =L14-5 -> 35 | T15: =T14-25 -> 1200
C16: =C15 - 10 -> 485 | L16: =L15-5 -> 30 | T16: =T15-25 -> 1175
B18: Scenarios
B19: 1
B21: Inputs | C21: Unit | F21: Live | H21: 1 | I21: =H21+1 -> 2 | J21: =I21+1 -> 3 | K21: =J21+1 -> 4 | L21: =K21+1 -> 5 | M21: =L21+1 -> 6 | N21: =M21+1 -> 7
B22: Macro | H22: PV (N-S) | I22: PV (N-S) + BESS | J22: PV (E-W) | K22: PV (E-W) + BESS | L22: PV (E-W) | M22: PV (E-W) | N22: PV (E-W)
B23: Inflation profile | C23: Selection
B24: Quarter of inflation step-up | C24: Quarter | F24: {=IF(ISBLANK(INDEX(H24:O24, B$19)), H24, INDEX(H24:O24, B$19))} -> 1 | H24: 1
B25: Acquisition date | C25: Date | F25: {=IF(ISBLANK(INDEX(H25:O25, B$19)), H25, INDEX(H25:O25, B$19))} -> 46173 | H25: =H29 -> 46173
B26: Equity premium | C26: €k/MW | F26: {=IF(ISBLANK(INDEX(H26:O26, B$19)), H26, INDEX(H26:O26, B$19))} -> 90 | H26: 90
B28: Construction
B29: Construction start | C29: Date | F29: {=IF(ISBLANK(INDEX(H29:O29, B$19)), H29, INDEX(H29:O29, B$19))} -> 46173 | H29: 46173
B30: Construction timeline | C30: Months | F30: {=IF(ISBLANK(INDEX(H30:O30, B$19)), H30, INDEX(H30:O30, B$19))} -> 18 | H30: 18
B31: Construction End | C31: Date | F31: =EOMONTH(F29,F30) -> 46721
B33: PV
B34: CAPEX | C34: €k/MW | F34: {=IF(ISBLANK(INDEX(H34:O34, B$19)), H34, INDEX(H34:O34, B$19))} -> 515 | H34: 515
B35: PV useful life | C35: Years | F35: {=IF(ISBLANK(INDEX(H35:O35, B$19)), H35, INDEX(H35:O35, B$19))} -> 35 | H35: 35
B37: BESS
B38: BESS CAPEX | C38: €k/MW | F38: {=IF(ISBLANK(INDEX(H38:O38, B$19)), H38, INDEX(H38:O38, B$19))} -> 220 | H38: 220
B39: BESS CAPEX - refresh | C39: €k/MW | F39: {=IF(ISBLANK(INDEX(H39:O39, B$19)), H39, INDEX(H39:O39, B$19))} -> 110 | H39: 110
B40: BESS useful life | C40: Years | F40: {=IF(ISBLANK(INDEX(H40:O40, B$19)), H40, INDEX(H40:O40, B$19))} -> 17 | H40: 17
B42: Operations start | C42: Date | F42: =F31+1 -> 46722
B43: Asset hold period | C43: Years | F43: =F35 -> 35
B44: Operations end | C44: Date | F44: =EOMONTH(F42, (F43*12)) -> 59536
B45: BESS useful life | C45: Years | F45: =F40 -> 17
B46: BESS refresh period | C46: Date | F46: =EOMONTH(F42, (F45*12)) -> 52962
B48: Generation
B49: PV
B50: Capacity | C50: MW | F50: {=IF(ISBLANK(INDEX(H50:O50, B$19)), H50, INDEX(H50:O50, B$19))} -> 61 | H50: 61
...

Sheet Dyn_Inp
B2: Dynamic Inputs
B4: Month of construction | E4: 1 | F4: =E4+1 -> 2 | G4: =F4+1 -> 3 | H4: =G4+1 -> 4 | I4: =H4+1 -> 5 | J4: =I4+1 -> 6 | K4: =J4+1 -> 7 | L4: =K4+1 -> 8 | M4: =L4+1 -> 9 | ... AB4: =AA4+1 -> 24
B5: CAPEX timetable | C5: Source: Finland model | E5: 0.1 | F5: 0.0625 | G5: 0.0625 | H5: 0.0625 | I5: 0.0625 | J5: 0.0625 | K5: 0.0625 | L5: 0.0625 | M5: 0.0625 | N5: 0.066666667 | O5: 0.066666667 | P5: 0.066666667 | Q5: 0.03 | R5: 0.03 | S5: 0.03 | T5: 0.03 | U5: 0.03 | V5: 0.05 | W5: 0 | X5: 0 | Y5: 0 | Z5: 0 | AA5: 0 | AB5: 0
B7: Year | E7: 2025 | F7: =E7+1 -> 2026 | G7: =F7+1 -> 2027 | H7: =G7+1 -> 2028 | I7: =H7+1 -> 2029 | J7: =I7+1 -> 2030 | K7: =J7+1 -> 2031 | L7: =K7+1 -> 2032 | M7: =L7+1 -> 2033 | ... AS7: =AR7+1 -> 2065
B8: Inflation | C8: Source: IMF | E8: 0.049 | F8: 0.036 | G8: 0.032 | H8: 0.03 | I8: 0.03 | J8: 0.025 | K8: 0.025 | L8: 0.025 | M8: 0.025 | N8: 0.025 | O8: 0.025 | P8: 0.025 | Q8: 0.025 | R8: 0.025 | S8: 0.025 | T8: 0.025 | U8: 0.025 | V8: 0.025 | W8: 0.025 | X8: 0.025 | Y8: 0.025 | Z8: 0.025 | AA8: 0.025 | AB8: 0.025 | AC8: 0.025 | AD8: 0.025 | AE8: 0.025 | AF8: 0.025 | AG8: 0.025 | AH8: 0.025 | AI8: 0.025 | AJ8: 0.025 | AK8: 0.025 | AL8: 0.025 | AM8: 0.025 | AN8: 0.025 | AO8: 0.025 | AP8: 0.025 | AQ8: 0.025 | AR8: 0.025 | AS8: 0.025

Sheet Model
B2: Timing | H2: Sum
B3: Period start | I3: 45931 | J3: =I4+1 -> 46023 | K3: =J4+1 -> 46113 | L3: =K4+1 -> 46204 | M3: =L4+1 -> 46296 | N3: =M4+1 -> 46388 | O3: =N4+1 -> 46478 | P3: =O4+1 -> 46569 | Q3: =P4+1 -> 46661 | ... FM3: =FL4+1 -> 60541
B4: Period end | I4: =EOMONTH(I3,2) -> 46022 | J4: =EOMONTH(J3,2) -> 46112 | K4: =EOMONTH(K3,2) -> 46203 | L4: =EOMONTH(L3,2) -> 46295 | M4: =EOMONTH(M3,2) -> 46387 | N4: =EOMONTH(N3,2) -> 46477 | O4: =EOMONTH(O3,2) -> 46568 | P4: =EOMONTH(P3,2) -> 46660 | ... FM4: =EOMONTH(FM3,2) -> 60632
B5: Days in period | I5: =I4 - I3 + 1 -> 92 | J5: =J4 - J3 + 1 -> 90 | K5: =K4 - K3 + 1 -> 91 | L5: =L4 - L3 + 1 -> 92 | M5: =M4 - M3 + 1 -> 92 | N5: =N4 - N3 + 1 -> 90 | O5: =O4 - O3 + 1 -> 91 | P5: =P4 - P3 + 1 -> 92 | ... FM5: =FM4 - FM3 + 1 -> 92
B6: Days in year | I6: =DATE(I9, 12, 31) - DATE(I9, 1, 1) +1 -> 365 | J6: =DATE(J9, 12, 31) - DATE(J9, 1, 1) +1 -> 365 | K6: =DATE(K9, 12, 31) - DATE(K9, 1, 1) +1 -> 365 | L6: =DATE(L9, 12, 31) - DATE(L9, 1, 1) +1 -> 365 | M6: =DATE(M9, 12, 31) - DATE(M9, 1, 1) +1 -> 365 | N6: =DATE(N9, 12, 31) - DATE(N9, 1, 1) +1 -> 365 | O6: =DATE(O9, 12, 31) - DATE(O9, 1, 1) +1 -> 365 | P6: =DATE(P9, 12, 31) - DATE(P9, 1, 1) +1 -> 365 | ... FM6: =DATE(FM9, 12, 31) - DATE(FM9, 1, 1) +1 -> 365
B7: Fraction of year | I7: =I5/I6 -> 0.25205479 | J7: =J5/J6 -> 0.24657534 | K7: =K5/K6 -> 0.24931507 | L7: =L5/L6 -> 0.25205479 | M7: =M5/M6 -> 0.25205479 | N7: =N5/N6 -> 0.24657534 | O7: =O5/O6 -> 0.24931507 | P7: =P5/P6 -> 0.25205479 | ... FM7: =FM5/FM6 -> 0.25205479
B8: Quarter | I8: =MONTH(I4) / 3 -> 4 | J8: =MONTH(J4) / 3 -> 1 | K8: =MONTH(K4) / 3 -> 2 | L8: =MONTH(L4) / 3 -> 3 | M8: =MONTH(M4) / 3 -> 4 | N8: =MONTH(N4) / 3 -> 1 | O8: =MONTH(O4) / 3 -> 2 | P8: =MONTH(P4) / 3 -> 3 | ... FM8: =MONTH(FM4) / 3 -> 4
B9: Year | I9: =YEAR(I4) -> 2025 | J9: =YEAR(J4) -> 2026 | K9: =YEAR(K4) -> 2026 | L9: =YEAR(L4) -> 2026 | M9: =YEAR(M4) -> 2026 | N9: =YEAR(N4) -> 2027 | O9: =YEAR(O4) -> 2027 | P9: =YEAR(P4) -> 2027 | ... FM9: =YEAR(FM4) -> 2065
B11: Flags
B12: Construction | C12: % | D12: =Stat_Inp!F29 -> 46173 | E12: =Stat_Inp!F31 -> 46721 | I12: =MAX(0,(MIN($E12,I$4)-MAX($D12,I$3)+1)/I$5)+((($D12-$E12+1)/I$5)*($D12>I$3)*($E12<I$4)) -> 0 | J12: =MAX(0,(MIN($E12,J$4)-MAX($D12,J$3)+1)/J$5)+((($D12-$E12+1)/J$5)*($D12>J$3)*($E12<J$4)) -> 0 | K12: =MAX(0,(MIN($E12,K$4)-MAX($D12,K$3)+1)/K$5)+((($D12-$E12+1)/K$5)*($D12>K$3)*($E12<K$4)) -> 0.34065934 | L12: =MAX(0,(MIN($E12,L$4)-MAX($D12,L$3)+1)/L$5)+((($D12-$E12+1)/L$5)*($D12>L$3)*($E12<L$4)) -> 1 | M12: =MAX(0,(MIN($E12,M$4)-MAX($D12,M$3)+1)/M$5)+((($D12-$E12+1)/M$5)*($D12>M$3)*($E12<M$4)) -> 1 | N12: =MAX(0,(MIN($E12,N$4)-MAX($D12,N$3)+1)/N$5)+((($D12-$E12+1)/N$5)*($D12>N$3)*($E12<N$4)) -> 1 | O12: =MAX(0,(MIN($E12,O$4)-MAX($D12,O$3)+1)/O$5)+((($D12-$E12+1)/O$5)*($D12>O$3)*($E12<O$4)) -> 1 | P12: =MAX(0,(MIN($E12,P$4)-MAX($D12,P$3)+1)/P$5)+((($D12-$E12+1)/P$5)*($D12>P$3)*($E12<P$4)) -> 1 | ... FM12: =MAX(0,(MIN($E12,FM$4)-MAX($D12,FM$3)+1)/FM$5)+((($D12-$E12+1)/FM$5)*($D12>FM$3)*($E12<FM$4)) -> 0
B13: Construction month | C13: Month | H13: 0 | I13: =IF(I12, H13 + ROUND( I12 * (MONTH(I4) - MONTH(I3) +1), 0), 0) -> 0 | J13: =IF(J12, I13 + ROUND( J12 * (MONTH(J4) - MONTH(J3) +1), 0), 0) -> 0 | K13: =IF(K12, J13 + ROUND( K12 * (MONTH(K4) - MONTH(K3) +1), 0), 0) -> 1 | L13: =IF(L12, K13 + ROUND( L12 * (MONTH(L4) - MONTH(L3) +1), 0), 0) -> 4 | M13: =IF(M12, L13 + ROUND( M12 * (MONTH(M4) - MONTH(M3) +1), 0), 0) -> 7 | N13: =IF(N12, M13 + ROUND( N12 * (MONTH(N4) - MONTH(N3) +1), 0), 0) -> 10 | O13: =IF(O12, N13 + ROUND( O12 * (MONTH(O4) - MONTH(O3) +1), 0), 0) -> 13 | P13: =IF(P12, O13 + ROUND( P12 * (MONTH(P4) - MONTH(P3) +1), 0), 0) -> 16 | ... FM13: =IF(FM12, FL13 + ROUND( FM12 * (MONTH(FM4) - MONTH(FM3) +1), 0), 0) -> 0
B14: Operations | C14: % | D14: =Stat_Inp!F42 -> 46722 | E14: =Stat_Inp!F44 -> 59536 | H14: 0 | I14: =MAX(0,(MIN($E14,I$4)-MAX($D14,I$3)+1)/I$5)+((($D14-$E14+1)/I$5)*($D14>I$3)*($E14<I$4)) -> 0 | J14: =MAX(0,(MIN($E14,J$4)-MAX($D14,J$3)+1)/J$5)+((($D14-$E14+1)/J$5)*($D14>J$3)*($E14<J$4)) -> 0 | K14: =MAX(0,(MIN($E14,K$4)-MAX($D14,K$3)+1)/K$5)+((($D14-$E14+1)/K$5)*($D14>K$3)*($E14<K$4)) -> 0 | L14: =MAX(0,(MIN($E14,L$4)-MAX($D14,L$3)+1)/L$5)+((($D14-$E14+1)/L$5)*($D14>L$3)*($E14<L$4)) -> 0 | M14: =MAX(0,(MIN($E14,M$4)-MAX($D14,M$3)+1)/M$5)+((($D14-$E14+1)/M$5)*($D14>M$3)*($E14<M$4)) -> 0 | N14: =MAX(0,(MIN($E14,N$4)-MAX($D14,N$3)+1)/N$5)+((($D14-$E14+1)/N$5)*($D14>N$3)*($E14<N$4)) -> 0 | O14: =MAX(0,(MIN($E14,O$4)-MAX($D14,O$3)+1)/O$5)+((($D14-$E14+1)/O$5)*($D14>O$3)*($E14<O$4)) -> 0 | P14: =MAX(0,(MIN($E14,P$4)-MAX($D14,P$3)+1)/P$5)+((($D14-$E14+1)/P$5)*($D14>P$3)*($E14<P$4)) -> 0 | ... FM14: =MAX(0,(MIN($E14,FM$4)-MAX($D14,FM$3)+1)/FM$5)+((($D14-$E14+1)/FM$5)*($D14>FM$3)*($E14<FM$4)) -> 0
B15: First operating period | C15: Flag | I15: =N(AND(H14=0,I14>0)) -> 0 | J15: =N(AND(I14=0,J14>0)) -> 0 | K15: =N(AND(J14=0,K14>0)) -> 0 | L15: =N(AND(K14=0,L14>0)) -> 0 | M15: =N(AND(L14=0,M14>0)) -> 0 | N15: =N(AND(M14=0,N14>0)) -> 0 | O15: =N(AND(N14=0,O14>0)) -> 0 | P15: =N(AND(O14=0,P14>0)) -> 0 | ... FM15: =N(AND(FL14=0,FM14>0)) -> 0
B16: Last operating period | C16: Flag | I16: =N(AND(I14>0,J14=0)) -> 0 | J16: =N(AND(J14>0,K14=0)) -> 0 | K16: =N(AND(K14>0,L14=0)) -> 0 | L16: =N(AND(L14>0,M14=0)) -> 0 | M16: =N(AND(M14>0,N14=0)) -> 0 | N16: =N(AND(N14>0,O14=0)) -> 0 | O16: =N(AND(O14>0,P14=0)) -> 0 | P16: =N(AND(P14>0,Q14=0)) -> 0 | ... FM16: =N(AND(FM14>0,FN14=0)) -> 0
B17: Operations year | C17: Count | I17: =IF(I14, I9 - YEAR($D14) +1, 0) -> 0 | J17: =IF(J14, J9 - YEAR($D14) +1, 0) -> 0 | K17: =IF(K14, K9 - YEAR($D14) +1, 0) -> 0 | L17: =IF(L14, L9 - YEAR($D14) +1, 0) -> 0 | M17: =IF(M14, M9 - YEAR($D14) +1, 0) -> 0 | N17: =IF(N14, N9 - YEAR($D14) +1, 0) -> 0 | O17: =IF(O14, O9 - YEAR($D14) +1, 0) -> 0 | P17: =IF(P14, P9 - YEAR($D14) +1, 0) -> 0 | ... FM17: =IF(FM14, FM9 - YEAR($D14) +1, 0) -> 0
B19: Inflation
B20: Annual inflation | C20: % | I20: =SUMIFS(Dyn_Inp!$E$8:$AS$8, Dyn_Inp!$E$7:$AS$7, I$9) -> 0.049 | J20: =SUMIFS(Dyn_Inp!$E$8:$AS$8, Dyn_Inp!$E$7:$AS$7, J$9) -> 0.036 | K20: =SUMIFS(Dyn_Inp!$E$8:$AS$8, Dyn_Inp!$E$7:$AS$7, K$9) -> 0.036 | L20: =SUMIFS(Dyn_Inp!$E$8:$AS$8, Dyn_Inp!$E$7:$AS$7, L$9) -> 0.036 | M20: =SUMIFS(Dyn_Inp!$E$8:$AS$8, Dyn_Inp!$E$7:$AS$7, M$9) -> 0.036 | N20: =SUMIFS(Dyn_Inp!$E$8:$AS$8, Dyn_Inp!$E$7:$AS$7, N$9) -> 0.032 | O20: =SUMIFS(Dyn_Inp!$E$8:$AS$8, Dyn_Inp!$E$7:$AS$7, O$9) -> 0.032 | P20: =SUMIFS(Dyn_Inp!$E$8:$AS$8, Dyn_Inp!$E$7:$AS$7, P$9) -> 0.032 | ... FM20: =SUMIFS(Dyn_Inp!$E$8:$AS$8, Dyn_Inp!$E$7:$AS$7, FM$9) -> 0.025
B21: Step-up flag | C21: Flag | D21: =Stat_Inp!F24 -> 1 | I21: =N($D21 = I8) -> 0 | J21: =N($D21 = J8) -> 1 | K21: =N($D21 = K8) -> 0 | L21: =N($D21 = L8) -> 0 | M21: =N($D21 = M8) -> 0 | N21: =N($D21 = N8) -> 1 | O21: =N($D21 = O8) -> 0 | P21: =N($D21 = P8) -> 0 | ... FM21: =N($D21 = FM8) -> 0
B22: Inflation in period | C22: % | I22: =I20 * I21 -> 0 | J22: =J20 * J21 -> 0.036 | K22: =K20 * K21 -> 0 | L22: =L20 * L21 -> 0 | M22: =M20 * M21 -> 0 | N22: =N20 * N21 -> 0.032 | O22: =O20 * O21 -> 0 | P22: =P20 * P21 -> 0 | ... FM22: =FM20 * FM21 -> 0
B23: Inflation index (all items) | C23: Index | H23: 1 | I23: =H23 * (1 + I22) -> 1 | J23: =I23 * (1 + J22) -> 1.036 | K23: =J23 * (1 + K22) -> 1.036 | L23: =K23 * (1 + L22) -> 1.036 | M23: =L23 * (1 + M22) -> 1.036 | N23: =M23 * (1 + N22) -> 1.069152 | O23: =N23 * (1 + O22) -> 1.069152 | P23: =O23 * (1 + P22) -> 1.069152 | ... FM23: =FL23 * (1 + FM22) -> 2.7591357
B25: Valuation
B27: Construction flag | C27: Flag | H27: =SUM(I27:FM27) -> 1 | I27: =N(AND(I$3<=$D12,I$4>=$D12)) -> 0 | J27: =N(AND(J3<=$D12,J4>=$D12)) -> 0 | K27: =N(AND(K3<=$D12,K4>=$D12)) -> 1 | L27: =N(AND(L3<=$D12,L4>=$D12)) -> 0 | M27: =N(AND(M3<=$D12,M4>=$D12)) -> 0 | N27: =N(AND(N3<=$D12,N4>=$D12)) -> 0 | O27: =N(AND(O3<=$D12,O4>=$D12)) -> 0 | P27: =N(AND(P3<=$D12,P4>=$D12)) -> 0 | Q27: =N(AND(Q3<=$D12,Q4>=$D12)) -> 0 | ... FM27: =N(AND(FM3<=$D12,FM4>=$D12)) -> 0
B28: Acquisition flag | C28: Flag | D28: =Stat_Inp!F25 -> 46173 | H28: =SUM(I28:FM28) -> 1 | I28: =N(AND(I$3<=$D28,I$4>=$D28)) -> 0 | J28: =N(AND(J$3<=$D28,J$4>=$D28)) -> 0 | K28: =N(AND(K$3<=$D28,K$4>=$D28)) -> 1 | L28: =N(AND(L$3<=$D28,L$4>=$D28)) -> 0 | M28: =N(AND(M$3<=$D28,M$4>=$D28)) -> 0 | N28: =N(AND(N$3<=$D28,N$4>=$D28)) -> 0 | O28: =N(AND(O$3<=$D28,O$4>=$D28)) -> 0 | P28: =N(AND(P$3<=$D28,P$4>=$D28)) -> 0 | ... FM28: =N(AND(FM$3<=$D28,FM$4>=$D28)) -> 0
B29: Ownership flag | C29: Flag | H29: =SUM(I29:FM29) -> 159 | I29: =SUM($I28:I28) -> 0 | J29: =SUM($I28:J28) -> 0 | K29: =SUM($I28:K28) -> 1 | L29: =SUM($I28:L28) -> 1 | M29: =SUM($I28:M28) -> 1 | N29: =SUM($I28:N28) -> 1 | O29: =SUM($I28:O28) -> 1 | P29: =SUM($I28:P28) -> 1 | ... FM29: =SUM($I28:FM28) -> 1
B31: EBITDA | C31: €k | H31: =SUM(I31:FM31) -> 128735.67 | I31: =I50 -> 0 | J31: =J50 -> 0 | K31: =K50 -> -8.4469479 | L31: =L50 -> -25.068362 | M31: =M50 -> -25.068362 | N31: =N50 -> -25.308146 | O31: =O50 -> -25.589348 | P31: =P50 -> -25.870549 | ... FM31: =FM50 -> 0
B32: Cash taxes | C32: €k | H32: =SUM(I32:FM32) -> 8758.8599 | I32: =I118 -> 0 | J32: =J118 -> 0 | K32: =K118 -> 0 | L32: =L118 -> 0 | M32: =M118 -> 0 | N32: =N118 -> 0 | O32: =O118 -> 0 | P32: =P118 -> 0 | ... FM32: =FM118 -> 0
B33: ∆ NWC | C33: €k | H33: =SUM(I33:FM33) -> 0 | I33: =I99 -> 0 | J33: =J99 -> 0 | K33: =K99 -> 2.7847081 | L33: =L99 -> 5.3897576 | M33: =M99 -> 0 | N33: =N99 -> 0.2615829 | O33: =O99 -> 0 | P33: =P99 -> 0 | ... FM33: =FM99 -> 0
B34: CAPEX | C34: €k | H34: =SUM(I34:FM34) -> -31415 | I34: =-1 * I71 -> 0 | J34: =-1 * J71 -> 0 | K34: =-1 * K71 -> -3141.5 | L34: =-1 * L71 -> -5890.3125 | M34: =-1 * M71 -> -5890.3125 | N34: =-1 * N71 -> -6021.2083 | O34: =-1 * O71 -> -5131.1167 | P34: =-1 * P71 -> -2827.35 | ... FM34: =-1 * FM71 -> 0
B35: Free cash flow to the firm | C35: €k | H35: =SUM(I35:FM35) -> 106079.53 | I35: =SUM(I31:I34) -> 0 | J35: =SUM(J31:J34) -> 0 | K35: =SUM(K31:K34) -> -3147.1622 | L35: =SUM(L31:L34) -> -5909.9911 | M35: =SUM(M31:M34) -> -5915.3809 | N35: =SUM(N31:N34) -> -6046.2549 | O35: =SUM(O31:O34) -> -5156.706 | P35: =SUM(P31:P34) -> -2853.2205 | ... FM35: =SUM(FM31:FM34) -> 0
B37: Project IRR | C37: % | D37: =SUM(I37:FM37) -> 0.093844097 | I37: =IFERROR(I$27 * XIRR(I35:$FM35, I$4:$FM$4,0), 0) -> 0 | J37: =IFERROR(J$27 * XIRR(J35:$FM35, J$4:$FM$4,0), 0) -> 0 | K37: =IFERROR(K$27 * XIRR(K35:$FM35, K$4:$FM$4,0), 0) -> 0.093844097 | L37: =IFERROR(L$27 * XIRR(L35:$FM35, L$4:$FM$4,0), 0) -> 0 | M37: =IFERROR(M$27 * XIRR(M35:$FM35, M$4:$FM$4,0), 0) -> 0 | N37: =IFERROR(N$27 * XIRR(N35:$FM35, N$4:$FM$4,0), 0) -> 0 | O37: =IFERROR(O$27 * XIRR(O35:$FM35, O$4:$FM$4,0), 0) -> 0 | P37: =IFERROR(P$27 * XIRR(P35:$FM35, P$4:$FM$4,0), 0) -> 0 | ... FM37: =IFERROR(FM$27 * XIRR(FM35:$FM35, FM$4:$FM$4,0), 0) -> 0
B39: Buyer return
B40: Purchase price | C40: €k | D40: =Stat_Inp!F26 -> 90 | H40: =SUM(I40:FM40) -> -5490 | I40: =-1 * $D40 * $D61 * I28 -> 0 | J40: =-1 * $D40 * $D61 * J28 -> 0 | K40: =-1 * $D40 * $D61 * K28 -> -5490 | L40: =-1 * $D40 * $D61 * L28 -> 0 | M40: =-1 * $D40 * $D61 * M28 -> 0 | N40: =-1 * $D40 * $D61 * N28 -> 0 | O40: =-1 * $D40 * $D61 * O28 -> 0 | P40: =-1 * $D40 * $D61 * P28 -> 0 | ... FM40: =-1 * $D40 * $D61 * FM28 -> 0
B41: Post-purchase cash flows | C41: €k | H41: =SUM(I41:FM41) -> 106079.53 | I41: =I29 * I35 -> 0 | J41: =J29 * J35 -> 0 | K41: =K29 * K35 -> -3147.1622 | L41: =L29 * L35 -> -5909.9911 | M41: =M29 * M35 -> -5915.3809 | N41: =N29 * N35 -> -6046.2549 | O41: =O29 * O35 -> -5156.706 | P41: =P29 * P35 -> -2853.2205 | ... FM41: =FM29 * FM35 -> 0
B42: Net cash flows | C42: €k | H42: =SUM(I42:FM42) -> 100589.53 | I42: =SUM(I40:I41) -> 0 | J42: =SUM(J40:J41) -> 0 | K42: =SUM(K40:K41) -> -8637.1622 | L42: =SUM(L40:L41) -> -5909.9911 | M42: =SUM(M40:M41) -> -5915.3809 | N42: =SUM(N40:N41) -> -6046.2549 | O42: =SUM(O40:O41) -> -5156.706 | P42: =SUM(P40:P41) -> -2853.2205 | ... FM42: =SUM(FM40:FM41) -> 0
B44: Buyer IRR | C44: % | D44: =SUM(I44:FM44) -> 0.079572534 | I44: =IFERROR(I$27 * XIRR(I42:$FM42, I$4:$FM$4,0), 0) -> 0 | J44: =IFERROR(J$27 * XIRR(J42:$FM42, J$4:$FM$4,0), 0) -> 0 | K44: =IFERROR(K$27 * XIRR(K42:$FM42, K$4:$FM$4,0), 0) -> 0.079572534 | L44: =IFERROR(L$27 * XIRR(L42:$FM42, L$4:$FM$4,0), 0) -> 0 | M44: =IFERROR(M$27 * XIRR(M42:$FM42, M$4:$FM$4,0), 0) -> 0 | N44: =IFERROR(N$27 * XIRR(N42:$FM42, N$4:$FM$4,0), 0) -> 0 | O44: =IFERROR(O$27 * XIRR(O42:$FM42, O$4:$FM$4,0), 0) -> 0 | P44: =IFERROR(P$27 * XIRR(P42:$FM42, P$4:$FM$4,0), 0) -> 0 | ... FM44: =IFERROR(FM$27 * XIRR(FM42:$FM42, FM$4:$FM$4,0), 0) -> 0
B47: Income statement
B48: Revenue | C48: €k | H48: =SUM(I48:FM48) -> 202885.33 | I48: =I87 -> 0 | J48: =J87 -> 0 | K48: =K87 -> 0 | L48: =L87 -> 0 | M48: =M87 -> 0 | N48: =N87 -> 0 | O48: =O87 -> 0 | P48: =P87 -> 0 | ... FM48: =FM87 -> 0
B49: Operating costs | C49: €k | H49: =SUM(I49:FM49) -> -74149.668 | I49: =-1 * I93 -> 0 | J49: =-1 * J93 -> 0 | K49: =-1 * K93 -> -8.4469479 | L49: =-1 * L93 -> -25.068362 | M49: =-1 * M93 -> -25.068362 | N49: =-1 * N93 -> -25.308146 | O49: =-1 * O93 -> -25.589348 | P49: =-1 * P93 -> -25.870549 | ... FM49: =-1 * FM93 -> 0
B50: EBITDA | C50: €k | H50: =SUM(I50:FM50) -> 128735.67 | I50: =SUM(I48:I49) -> 0 | J50: =SUM(J48:J49) -> 0 | K50: =SUM(K48:K49) -> -8.4469479 | L50: =SUM(L48:L49) -> -25.068362 | M50: =SUM(M48:M49) -> -25.068362 | N50: =SUM(N48:N49) -> -25.308146 | O50: =SUM(O48:O49) -> -25.589348 | P50: =SUM(P48:P49) -> -25.870549 | ... FM50: =SUM(FM48:FM49) -> 0
B51: EBITDA margin | C51: % | I51: =IFERROR(I50 / I48, 0) -> 0 | J51: =IFERROR(J50 / J48, 0) -> 0 | K51: =IFERROR(K50 / K48, 0) -> 0 | L51: =IFERROR(L50 / L48, 0) -> 0 | M51: =IFERROR(M50 / M48, 0) -> 0 | N51: =IFERROR(N50 / N48, 0) -> 0 | O51: =IFERROR(O50 / O48, 0) -> 0 | P51: =IFERROR(P50 / P48, 0) -> 0 | ... FM51: =IFERROR(FM50 / FM48, 0) -> 0
...
