Workbook

Sheet Dashboard
B2: =C3&" – Dashboard" -> Project Zalahaláp – Dashboard
C3: Project Zalahaláp
C4: 63 MWp PV + 50 MW / 200 MWh BESS – sale at RtB, sale at COD or hold
C5: Version | E5: v1
C6: Model date | E6: 46317
C7: Key-assumption set | E7: =Scenario_Name -> Base
C8: Master check | E8: =IF(Master_Check=0,"OK","CHECK") -> OK
C9: Item | D9: Unit | E9: A Original | F9: B Aurora | G9: C Offer | AB9: Key assumptions | AC9: Unit | AD9: Live
A11: x | C11: Levers (case per sheet; other inputs on Inputs, by set) | E11: A Original | F11: B Aurora | G11: C Offer | AB11: Key-assumption set
C12: Revenue case (A, B or C) | D12: text | E12: A | F12: B | G12: C | AB12: Key-assumption set | AC12: text | AD12: Base
C13: Case name | D13: text | E13: =INDEX(Case_Labels,1,Calc_1!$F12) -> v3 reconstruction | F13: =INDEX(Case_Labels,1,Calc_2!$F12) -> Aurora merchant | G13: =INDEX(Case_Labels,1,Calc_3!$F12) -> Offer + merchant tail
C14: PV price curve, direct export | D14: text | E14: =Calc_1!$E42 -> v3 capture | F14: =Calc_2!$E42 -> DC 4h direct | G14: =Calc_3!$E42 -> DC 4h direct | AB14: Key assumptions (live)
C15: PV price curve, energy sent to the BESS | D15: text | E15: =Calc_1!$E43 -> v3 capture | F15: =Calc_2!$E43 -> DC 4h transfer | G15: =Calc_3!$E43 -> DC 4h transfer | AB15: RtB price (0 = implied) | AC15: EUR k/MWp | AD15: =In_RtB_Price -> 90
C16: BESS revenue curve (Aurora block) | D16: text | E16: =Calc_1!$E47 -> DC 4h | F16: =Calc_2!$E47 -> DC 4h | G16: =Calc_3!$E47 -> DC 4h | AB16: COD price (0 = implied) | AC16: EUR k/MWp | AD16: =In_COD_Price -> 0
C17: Offers in case C: PV / BESS | D17: text | E17: =IF(Calc_1!$E57=1,In_Offer_PV&" / "&In_Offer_BESS,"–") -> – | F17: =IF(Calc_2!$E57=1,In_Offer_PV&" / "&In_Offer_BESS,"–") -> – | G17: =IF(Calc_3!$E57=1,In_Offer_PV&" / "&In_Offer_BESS,"–") -> C2a / C2c | AB17: Buyer target IRR, RtB | AC17: % | AD17: =In_Buyer_IRR_RtB -> 0.08
C18: BESS offer duration ≠ built (1 = yes) | D18: flag | E18: =Calc_1!$E65 -> 0 | F18: =Calc_2!$E65 -> 0 | G18: =Calc_3!$E65 -> 1 | AB18: Buyer target IRR, COD | AC18: % | AD18: =In_Buyer_IRR_COD -> 0.08
C19: BESS built | D19: MW | E19: =Calc_1!$E18 -> 50 | F19: =Calc_2!$E18 -> 50 | G19: =Calc_3!$E18 -> 50 | AB19: Asset deal (1 = FEP gain taxed) | AC19: flag | AD19: =In_Sale_Form -> 0
C20: BESS energy | D20: MWh | E20: =Calc_1!$F18 -> 200 | F20: =Calc_2!$F18 -> 200 | G20: =Calc_3!$F18 -> 200 | AB20: PV merchant price change | AC20: % | AD20: =In_PV_Price_Adj -> 0
C21: Grid import allowed for charging | D21: MW | E21: =In_Grid_Import_MW -> 0 | F21: =In_Grid_Import_MW -> 0 | G21: =In_Grid_Import_MW -> 0 | AB21: Yield, cases B and C | AC21: MWh/MWp | AD21: =In_Yield -> 1265
C22: Stack kept without grid charging, year 1 | D22: % | E22: =AVERAGEIF(Calc_1!$J$7:$FH$7,YEAR(Calc_1!$F16)+1,Calc_1!$J50:$FH50) -> 0.87953311 | F22: =AVERAGEIF(Calc_2!$J$7:$FH$7,YEAR(Calc_2!$F16)+1,Calc_2!$J50:$FH50) -> 0.87953311 | G22: =AVERAGEIF(Calc_3!$J$7:$FH$7,YEAR(Calc_3!$F16)+1,Calc_3!$J50:$FH50) -> 0.87953311 | AB22: BESS power | AC22: MW | AD22: =In_BESS_MW -> 50
C23: Buyer target IRR (unlevered, after tax) | D23: % | E23: =In_Buyer_IRR_RtB -> 0.08 | F23: =In_Buyer_IRR_RtB -> 0.08 | G23: =In_Buyer_IRR_RtB -> 0.08 | AB23: BESS duration | AC23: h | AD23: =In_BESS_Hours -> 4
C24: Futureal share at the RtB exit | D24: % | E24: =Calc_1!$E227 -> 0.6 | F24: =Calc_2!$E227 -> 0.6 | G24: =Calc_3!$E227 -> 0.6 | AB24: BESS built | AC24: flag | AD24: =In_BESS_On -> 1
C25: Futureal share at a COD sale | D25: % | E25: =Calc_1!$E255 -> 0.6 | F25: =Calc_2!$E255 -> 0.6 | G25: =Calc_3!$E255 -> 0.6 | AB25: BESS repowered | AC25: flag | AD25: =In_Repower -> 1
AB26: BESS capex | AC26: EUR k/MWh | AD26: =In_BESS_Capex -> 110
A27: x | C27: Returns at a glance | E27: A Original | F27: B Aurora | G27: C Offer | AB27: BESS haircut | AC27: % | AD27: =In_BESS_Haircut -> 0
C28: Sale at RtB | E28: A Original | F28: B Aurora | G28: C Offer | AB28: Grid import for charging | AC28: MW | AD28: =In_Grid_Import_MW -> 0
C29: Development costs (100 %) | D29: EUR m | E29: =Calc_1!$E185/Thousand -> 5.631 | F29: =Calc_2!$E185/Thousand -> 5.661 | G29: =Calc_3!$E185/Thousand -> 5.661 | AB29: PV offer (case C) | AC29: text | AD29: =In_Offer_PV -> C2a
C30: Construction capex (paid by the buyer) | D30: EUR m | E30: =Calc_1!$E180/Thousand -> 56.385 | F30: =Calc_2!$E180/Thousand -> 57.085 | G30: =Calc_3!$E180/Thousand -> 57.085 | AB30: BESS offer (case C) | AC30: text | AD30: =In_Offer_BESS -> C2c
C31: RtB price used | D31: EUR k/MWp | E31: =Calc_1!$E194 -> 90 | F31: =Calc_2!$E194 -> 90 | G31: =Calc_3!$E194 -> 90 | AB31: Gearing cap | AC31: % | AD31: =In_Gearing -> 0.55
C32: Implied RtB price at the buyer target IRR | D32: EUR k/MWp | E32: =Calc_1!$E192 -> 270.4537 | F32: =Calc_2!$E192 -> 34.005711 | G32: =Calc_3!$E192 -> 0 | AB32: Debt rate | AC32: % | AD32: =In_Debt_Rate -> 0.05
C33: Implied price below zero (floored, 1 = yes) | D33: flag | E33: =N(Calc_1!$F192<0) -> 0 | F33: =N(Calc_2!$F192<0) -> 0 | G33: =N(Calc_3!$F192<0) -> 1 | AB33: DSCR merchant | AC33: x | AD33: =In_DSCR_Merchant -> 1.35
C34: All-in implied price incl. reimbursements | D34: EUR k/MWp | E34: =Calc_1!$F193 -> 344.7078 | F34: =Calc_2!$F193 -> 105.90254 | G34: =Calc_3!$F193 -> 71.896825 | AB34: CIT | AC34: % | AD34: =In_CIT -> 0.09
C35: Buyer all-in price at our price | D35: EUR k/MWp | E35: =Calc_1!$E194+Calc_1!$E193 -> 164.2541 | F35: =Calc_2!$E194+Calc_2!$E193 -> 161.89683 | G35: =Calc_3!$E194+Calc_3!$E193 -> 161.89683 | AB35: Discount rate | AC35: % | AD35: =In_Discount_Rate -> 0.08
C36: Buyer IRR at our price, unlevered, after tax | D36: % | E36: =Calc_1!$E196 -> 0.09758288 | F36: =Calc_2!$E196 -> 0.073727777 | G36: =Calc_3!$E196 -> 0.057439932 | AB36: FX | AC36: HUF/EUR | AD36: =In_FX -> 400
C37: Buyer IRR at our price, before tax | D37: % | E37: =Calc_1!$E198 -> 0.10481234 | F37: =Calc_2!$E198 -> 0.079772257 | G37: =Calc_3!$E198 -> 0.061743371 | AB37: COD, cases B and C | AC37: date | AD37: =In_COD -> 46843
C38: Buyer IRR at our price, levered | D38: % | E38: =Calc_1!$E200 -> 0.11506981 | F38: =Calc_2!$E200 -> 0.081662433 | G38: =Calc_3!$E200 -> 0.057608148 | AB38: RtB exit, cases B and C | AC38: date | AD38: =In_RtB_Exit -> 46477
C39: Buyer equity (price, reimbursements, to COD) | D39: EUR m | E39: =Calc_1!$E199/Thousand -> 37.096749 | F39: =Calc_2!$E199/Thousand -> 37.564449 | G39: =Calc_3!$E199/Thousand -> 53.102847 | AB39: Share rule (1 step, 0 v3) | AC39: flag | AD39: =In_Share_Rule -> 1
C40: FEP equity contributed | D40: EUR m | E40: =(-Calc_1!$I241)/Thousand -> 7.434864 | F40: =(-Calc_2!$I241)/Thousand -> 7.4720874 | G40: =(-Calc_3!$I241)/Thousand -> 7.4720874 | AB40: Early works lines in development | AC40: # | AD40: =In_Milestones_Scope -> 4
C41: FEP proceeds | D41: EUR m | E41: =Calc_1!$I242/Thousand -> 9.7280213 | F41: =Calc_2!$I242/Thousand -> 9.8725721 | G41: =Calc_3!$I242/Thousand -> 9.8725721
C42: FEP profit | D42: EUR m | E42: =Calc_1!$I245/Thousand -> 2.2719959 | F42: =Calc_2!$I245/Thousand -> 2.3744495 | G42: =Calc_3!$I245/Thousand -> 2.3744495 | AB42: Not re-optimised in Excel
...

Sheet Inputs
B2: =Dashboard!$C$3&" – Inputs and scenarios" -> Project Zalahaláp – Inputs and scenarios
B4: Scenario selected | D4: Set on the Dashboard | F4: =Scenario_Name -> Base
B5: Scenario number | F5: =MATCH(Scenario_Name,Scenario_Names,0) -> 1
B7: Input | C7: Unit | D7: Source / note | F7: Live | H7: Base | I7: Reconciliation (v3 rules) | J7: PV price −10% | K7: PV yield −10% | L7: BESS revenue −20% | M7: Capex +10% | N7: Buyer IRR +1 pp | O7: RtB and COD price −10% | P7: RtB price = implied | Q7: Gearing −10 pp | R7: COD +12 months | S7: BESS 2 h | T7: No BESS | U7: BESS capex 200 k€/MWh | V7: No BESS repower | W7: PV and BESS prices −20% | X7: C: E.ON PPA + option B | Y7: C: MVM 45 + MET floor
A10: x | C10: Constants
B11: Thousand | C11: # | D11: Scale | F11: 1000
B12: Million | C12: # | D12: Scale | F12: 1000000
B13: Days In Year | C13: days | D13: Day count for year fractions and XIRR | F13: 365
B14: Months In Year | C14: months | D14: Calendar | F14: 12
B15: Months Per Period | C15: months | D15: Timeline periodicity (quarterly) | F15: 3
B16: Tolerance | C16: # | D16: Check and solver tolerance | F16: 1e-06
A18: x | C18: Timing
B19: Model start date | C19: date | D19: Timeline start | F19: =IF(INDEX($H19:$Y19,1,Scenario_Selected)="",$H19,INDEX($H19:$Y19,1,Scenario_Selected)) -> 45931 | H19: 45931
B20: Sensitivity step (price, yield, capex, opex sets) | C20: % | D20: SPEC §10 | F20: 0.1
B21: Large sensitivity step (BESS revenue, downside sets) | C21: % | D21: SPEC §10 | F21: 0.2
B22: Rate step (buyer IRR, debt rate sets) | C22: % | D22: SPEC §10 | F22: 0.01
B23: Hours in a day | C23: h | D23: Grid export limit | F23: 24
B24: Key-assumption set of the reconciliation | C24: # | D24: SPEC §10 set 2 | F24: 2
B25: Acquisition, JV start, deposits paid | C25: date | D25: ZHLP v3 Stat_inp E39 | F25: =IF(INDEX($H25:$Y25,1,Scenario_Selected)="",$H25,INDEX($H25:$Y25,1,Scenario_Selected)) -> 45991 | H25: 45991
B26: Ready to build (cases B, C) | C26: date | D26: Teaser p6; placeholder – pending user (SPEC §16 Q5) | F26: =IF(INDEX($H26:$Y26,1,Scenario_Selected)="",$H26,INDEX($H26:$Y26,1,Scenario_Selected)) -> 46387 | H26: 46387
B27: RtB sale closing (exit), cases B, C | C27: date | D27: placeholder – pending user (SPEC §16 Q5) | F27: =IF(INDEX($H27:$Y27,1,Scenario_Selected)="",$H27,INDEX($H27:$Y27,1,Scenario_Selected)) -> 46477 | H27: 46477
B28: Notice to proceed (cases B, C) | C28: date | D28: placeholder – pending user (SPEC §16 Q5) | F28: =IF(INDEX($H28:$Y28,1,Scenario_Selected)="",$H28,INDEX($H28:$Y28,1,Scenario_Selected)) -> 46568 | H28: 46568
B29: Commercial operation, PV and BESS (cases B, C) | C29: date | D29: Teaser p6; placeholder – pending user (SPEC §16 Q5) | F29: =IF(INDEX($H29:$Y29,1,Scenario_Selected)="",$H29,INDEX($H29:$Y29,1,Scenario_Selected)) -> 46843 | H29: 46843
B30: COD delay (construction longer) | C30: months | D30: SPEC §10 | F30: =IF(INDEX($H30:$Y30,1,Scenario_Selected)="",$H30,INDEX($H30:$Y30,1,Scenario_Selected)) -> 0 | H30: 0 | R30: 12
B31: Operating life | C31: years | D31: ZHLP v3 Control D30 | F31: =IF(INDEX($H31:$Y31,1,Scenario_Selected)="",$H31,INDEX($H31:$Y31,1,Scenario_Selected)) -> 35 | H31: 35
B32: Pre-RtB development costs: first month | C32: date | D32: ZHLP v3 Control D116 | F32: =IF(INDEX($H32:$Y32,1,Scenario_Selected)="",$H32,INDEX($H32:$Y32,1,Scenario_Selected)) -> 46326 | H32: 46326
B33: Pre-RtB development costs: last month | C33: date | D33: ZHLP v3 Control D117 | F33: =IF(INDEX($H33:$Y33,1,Scenario_Selected)="",$H33,INDEX($H33:$Y33,1,Scenario_Selected)) -> 46477 | H33: 46477
A35: x | C35: PV and grid (cases B, C; case A on Curves)
B36: PV capacity | C36: MWp | D36: Teaser p1 | F36: =IF(INDEX($H36:$Y36,1,Scenario_Selected)="",$H36,INDEX($H36:$Y36,1,Scenario_Selected)) -> 63 | H36: 63
B37: Grid export capacity | C37: MVA | D37: Teaser p1 | F37: =IF(INDEX($H37:$Y37,1,Scenario_Selected)="",$H37,INDEX($H37:$Y37,1,Scenario_Selected)) -> 49.9 | H37: 49.9
B38: Specific yield | C38: MWh/MWp | D38: Teaser p1 (v3: 1,250) | F38: =IF(INDEX($H38:$Y38,1,Scenario_Selected)="",$H38,INDEX($H38:$Y38,1,Scenario_Selected)) -> 1265 | H38: 1265
B39: Yield change (P90 proxy) | C39: % | D39: SPEC §10 | F39: =IF(INDEX($H39:$Y39,1,Scenario_Selected)="",$H39,INDEX($H39:$Y39,1,Scenario_Selected)) -> 0 | H39: 0 | K39: =-Sens_Step -> -0.1
B40: PV availability | C40: % | D40: ZHLP v3 Control D56 | F40: =IF(INDEX($H40:$Y40,1,Scenario_Selected)="",$H40,INDEX($H40:$Y40,1,Scenario_Selected)) -> 0.995 | H40: 0.995
B41: PV degradation per year | C41: % | D41: ZHLP v3 Control D57 | F41: =IF(INDEX($H41:$Y41,1,Scenario_Selected)="",$H41,INDEX($H41:$Y41,1,Scenario_Selected)) -> 0.003 | H41: 0.003
B42: Clipping, case A (v3 + fix 5), share of DC energy | C42: % | D42: placeholder – pending user (SPEC §16 Q13) | F42: =IF(INDEX($H42:$Y42,1,Scenario_Selected)="",$H42,INDEX($H42:$Y42,1,Scenario_Selected)) -> 0.02 | H42: 0.02
B43: Clipping, cases B, C (DC-coupled BESS) | C43: % | D43: Aurora s+29 = 0; placeholder – pending user (SPEC §16 Q13) | F43: =IF(INDEX($H43:$Y43,1,Scenario_Selected)="",$H43,INDEX($H43:$Y43,1,Scenario_Selected)) -> 0 | H43: 0
B44: Grid import allowed for BESS charging | C44: MW | D44: confirmed by user, 22-Oct-2026 (no grid charging) | F44: =IF(INDEX($H44:$Y44,1,Scenario_Selected)="",$H44,INDEX($H44:$Y44,1,Scenario_Selected)) -> 0 | H44: 0
B45: aFRR-down/FCR capacity deliverable from PV charge | C45: % | D45: placeholder – aFRR-down/FCR share deliverable from PV SoC | F45: =IF(INDEX($H45:$Y45,1,Scenario_Selected)="",$H45,INDEX($H45:$Y45,1,Scenario_Selected)) -> 0 | H45: 0
A47: x | C47: BESS
B48: BESS built (1 = yes) | C48: flag | D48: Teaser p1; SPEC §10 | F48: =IF(INDEX($H48:$Y48,1,Scenario_Selected)="",$H48,INDEX($H48:$Y48,1,Scenario_Selected)) -> 1 | H48: 1 | T48: 0
...

Sheet Curves
B2: =Dashboard!$C$3&" – Time-series inputs" -> Project Zalahaláp – Time-series inputs
A5: x | C5: Notes
C6: Aurora battery revenue blocks (Degraded batteries) are fixed dispatch outputs of Aurora's model: they do NOT re-optimise when inputs change.
C7: BESS MW scales them linearly; hours and cycles switch blocks. RTE, degradation, grid cap, PV:BESS ratio and charging rules act only through the haircut, PV-only factor and augmentation inputs. Aurora's 98 % availability is inside the blocks.
C8: No grid charging (user, 22-Oct-2026): the stack keeps DA/ID discharge at the share PV can charge, the PV transfer cost and aFRR-up capacity (PV-only factor); aFRR energy and aFRR-down/FCR capacity are lost (the deliverable share of the latter is In_AFRR_Down_Share).
C9: Network charges apply to grid-drawn energy only (Hungarian RHD); none with no import.
C10: The hourly export and charging limits live inside Aurora's dispatch (1 MW PV : 1 MW storage : 1 MW grid); Excel only checks the annual energy balance.
C11: Aurora data: data/aurora_extract.py → data/aurora_curves.csv (source rows cited per curve). Case A curves: data/old_engine/old_curves.csv (ZHLP v3 Aurora_Curve).
A13: x | C13: Revenue-case table (one column per case; Calc picks the case on the Dashboard) | E13: SPEC §6.4
C14: Item | J14: A | K14: B | L14: C
C15: Case | D15: text | J15: A | K15: B | L15: C
C16: Case name | D16: text | J16: v3 reconstruction | K16: Aurora merchant | L16: Offer + merchant tail
C17: PV price curve, direct export | D17: text | E17: ZHLP v3 Control D15:D29 | J17: v3 capture | K17: =In_PV_Curve -> DC 4h direct | L17: =In_PV_Curve -> DC 4h direct
C18: PV price curve, energy sent to the BESS | D18: text | E18: ZHLP v3 Control D15:D29 | J18: v3 capture | K18: =In_PV_Transfer_Curve -> DC 4h transfer | L18: =In_PV_Transfer_Curve -> DC 4h transfer
C19: Clipping, share of DC energy | D19: % | E19: ZHLP v3 Control D15:D29 | J19: =In_Clip_Loss*In_Fix_Clip -> 0.02 | K19: =In_Clip_Loss_DC -> 0 | L19: =In_Clip_Loss_DC -> 0
C20: BESS revenue curve | D20: text | E20: ZHLP v3 Control D15:D29 | J20: =IF(In_Fix_BESS=1,In_BESS_Block,"v3 BESS") -> DC 4h | K20: =In_BESS_Block -> DC 4h | L20: =In_BESS_Block -> DC 4h
C21: Offtake offer applies (1 = yes) | D21: flag | J21: 0 | K21: 0 | L21: 1
C22: PV capacity (MWp) | D22: MWp | E22: ZHLP v3 Control D15:D29 | J22: 61 | K22: =In_MWp -> 63 | L22: =In_MWp -> 63
C23: Grid export capacity (MVA) | D23: MVA | E23: ZHLP v3 Control D15:D29 | J23: 50 | K23: =In_Grid_MVA -> 49.9 | L23: =In_Grid_MVA -> 49.9
C24: Specific yield (MWh/MWp) | D24: MWh/MWp | E24: ZHLP v3 Control D15:D29 | J24: 1250 | K24: =In_Yield -> 1265 | L24: =In_Yield -> 1265
C25: Ready to build | D25: date | E25: ZHLP v3 Control D15:D29 | J25: 46234 | K25: =In_RtB -> 46387 | L25: =In_RtB -> 46387
C26: RtB sale closing (exit) | D26: date | E26: ZHLP v3 Control D15:D29 | J26: 46326 | K26: =In_RtB_Exit -> 46477 | L26: =In_RtB_Exit -> 46477
C27: NTP (construction start − 1 day) | D27: date | E27: ZHLP v3 Control D15:D29 | J27: 46477 | K27: =In_NTP -> 46568 | L27: =In_NTP -> 46568
C28: COD (operations from the next day) | D28: date | E28: ZHLP v3 Control D15:D29 | J28: 46843 | K28: =In_COD -> 46843 | L28: =In_COD -> 46843
A30: x | C30: PV prices, real 2025: <block> direct = (s+34+s+35)/s+31, transfer = s+36/s+32; v3 Low/High = ∓ 15 % | E30: v3 Aurora_Curve L; Aurora s+34:s+37 over s+31, s+32 (aurora_curves.csv)
C31: Year | J31: 2025 | K31: 2026 | L31: 2027 | M31: 2028 | N31: 2029 | O31: 2030 | P31: 2031 | Q31: 2032 | R31: 2033 | S31: 2034 | T31: 2035 | U31: 2036 | V31: 2037 | W31: 2038 | X31: 2039 | Y31: 2040 | Z31: 2041 | AA31: 2042 | AB31: 2043 | AC31: 2044 | AD31: 2045 | AE31: 2046 | AF31: 2047 | AG31: 2048 | AH31: 2049 | AI31: 2050 | AJ31: 2051 | AK31: 2052 | AL31: 2053 | AM31: 2054 | AN31: 2055 | AO31: 2056 | AP31: 2057 | AQ31: 2058 | AR31: 2059 | AS31: 2060 | AT31: 2061 | AU31: 2062 | AV31: 2063 | AW31: 2064
C32: v3 capture | D32: EUR/MWh | J32: 0 | K32: 78.3445 | L32: 77.571 | M32: 71.5 | N32: 67.002 | O32: 61.6785 | P32: 64.0315 | Q32: 62.465 | R32: 62.868 | S32: 60.5345 | T32: 60.4305 | U32: 60.476 | V32: 62.8095 | W32: 62.244 | X32: 61.919 | Y32: 61.061 | Z32: 60.3135 | AA32: 60.853 | AB32: 61.0545 | AC32: 60.554 | AD32: 61.7435 | AE32: 61.9905 | AF32: 61.8735 | AG32: 60.645 | AH32: 60.7815 | AI32: 60.047 | AJ32: 59.4425 | AK32: 58.305 | AL32: 58.9615 | AM32: 58.7405 | AN32: 58.552 | AO32: 57.8305 | AP32: 58.4285 | AQ32: 59.8845 | AR32: 60.9245 | AS32: 60.2615 | AT32: 60.2615 | AU32: 60.2615 | AV32: 60.2615 | AW32: 60.2615
C33: v3 capture Low | D33: EUR/MWh | J33: 0 | K33: 66.592825 | L33: 65.93535 | M33: 60.775 | N33: 56.9517 | O33: 52.426725 | P33: 54.426775 | Q33: 53.09525 | R33: 53.4378 | S33: 51.454325 | T33: 51.365925 | U33: 51.4046 | V33: 53.388075 | W33: 52.9074 | X33: 52.63115 | Y33: 51.90185 | Z33: 51.266475 | AA33: 51.72505 | AB33: 51.896325 | AC33: 51.4709 | AD33: 52.481975 | AE33: 52.691925 | AF33: 52.592475 | AG33: 51.54825 | AH33: 51.664275 | AI33: 51.03995 | AJ33: 50.526125 | AK33: 49.55925 | AL33: 50.117275 | AM33: 49.929425 | AN33: 49.7692 | AO33: 49.155925 | AP33: 49.664225 | AQ33: 50.901825 | AR33: 51.785825 | AS33: 51.222275 | AT33: 51.222275 | AU33: 51.222275 | AV33: 51.222275 | AW33: 51.222275
C34: v3 capture High | D34: EUR/MWh | J34: 0 | K34: 90.096175 | L34: 89.20665 | M34: 82.225 | N34: 77.0523 | O34: 70.930275 | P34: 73.636225 | Q34: 71.83475 | R34: 72.2982 | S34: 69.614675 | T34: 69.495075 | U34: 69.5474 | V34: 72.230925 | W34: 71.5806 | X34: 71.20685 | Y34: 70.22015 | Z34: 69.360525 | AA34: 69.98095 | AB34: 70.212675 | AC34: 69.6371 | AD34: 71.005025 | AE34: 71.289075 | AF34: 71.154525 | AG34: 69.74175 | AH34: 69.898725 | AI34: 69.05405 | AJ34: 68.358875 | AK34: 67.05075 | AL34: 67.805725 | AM34: 67.551575 | AN34: 67.3348 | AO34: 66.505075 | AP34: 67.192775 | AQ34: 68.867175 | AR34: 70.063175 | AS34: 69.300725 | AT34: 69.300725 | AU34: 69.300725 | AV34: 69.300725 | AW34: 69.300725
C35: DC 4h direct | D35: EUR/MWh | J35: 0 | K35: 0 | L35: 107.45398 | M35: 97.385579 | N35: 90.576086 | O35: 82.517914 | P35: 82.820586 | Q35: 77.089947 | R35: 76.043866 | S35: 71.106742 | T35: 69.435847 | U35: 68.220039 | V35: 70.386891 | W35: 69.78564 | X35: 68.102419 | Y35: 65.251077 | Z35: 62.520992 | AA35: 62.657367 | AB35: 62.263383 | AC35: 61.00633 | AD35: 62.575628 | AE35: 62.378225 | AF35: 62.020215 | AG35: 59.242295 | AH35: 70.826934 | AI35: 68.089247 | AJ35: 66.577524 | AK35: 64.569189 | AL35: 63.525124 | AM35: 62.203209 | AN35: 61.14484 | AO35: 59.041048 | AP35: 58.877107 | AQ35: 57.914745 | AR35: 57.8271 | AS35: 56.585236 | AT35: 56.585236 | AU35: 56.585236 | AV35: 56.585236 | AW35: 56.585236
C36: DC 2h direct | D36: EUR/MWh | J36: 0 | K36: 0 | L36: 83.416853 | M36: 74.7685 | N36: 70.386499 | O36: 62.214056 | P36: 63.421937 | Q36: 58.828288 | R36: 59.096765 | S36: 54.400285 | T36: 53.286899 | U36: 53.253133 | V36: 56.079909 | W36: 56.213238 | X36: 54.97995 | Y36: 52.88098 | Z36: 50.684825 | AA36: 50.938819 | AB36: 50.58768 | AC36: 49.753263 | AD36: 51.490997 | AE36: 51.887551 | AF36: 51.818932 | AG36: 52.680134 | AH36: 51.949949 | AI36: 50.701172 | AJ36: 50.225707 | AK36: 48.931741 | AL36: 48.634119 | AM36: 47.837442 | AN36: 47.325811 | AO36: 46.079868 | AP36: 46.140978 | AQ36: 45.754272 | AR36: 46.240982 | AS36: 45.587123 | AT36: 45.587123 | AU36: 45.587123 | AV36: 45.587123 | AW36: 45.587123
C37: DC 2h 1.5cy direct | D37: EUR/MWh | J37: 0 | K37: 0 | L37: 82.694231 | M37: 73.787131 | N37: 69.853057 | O37: 61.389308 | P37: 62.25282 | Q37: 57.135993 | R37: 56.975302 | S37: 51.818739 | T37: 50.294247 | U37: 49.478048 | V37: 52.956021 | W37: 52.817266 | X37: 51.658425 | Y37: 49.200642 | Z37: 47.132255 | AA37: 47.57186 | AB37: 46.977152 | AC37: 46.199864 | AD37: 48.687544 | AE37: 48.828746 | AF37: 49.555441 | AG37: 48.006782 | AH37: 47.7335 | AI37: 46.960386 | AJ37: 46.834548 | AK37: 46.048238 | AL37: 45.338632 | AM37: 44.787254 | AN37: 44.384792 | AO37: 43.547221 | AP37: 43.422912 | AQ37: 42.66133 | AR37: 42.863504 | AS37: 42.429673 | AT37: 42.429673 | AU37: 42.429673 | AV37: 42.429673 | AW37: 42.429673
C38: DC 4h 2030 direct | D38: EUR/MWh | J38: 0 | K38: 0 | L38: 0 | M38: 0 | N38: 0 | O38: 85.849206 | P38: 86.031328 | Q38: 79.676919 | R38: 78.411918 | S38: 73.225545 | T38: 71.350014 | U38: 69.795642 | V38: 71.870425 | W38: 71.398089 | X38: 69.789439 | Y38: 66.836711 | Z38: 63.824837 | AA38: 64.113335 | AB38: 63.587594 | AC38: 62.296139 | AD38: 63.883592 | AE38: 63.582671 | AF38: 63.204832 | AG38: 60.458234 | AH38: 59.579516 | AI38: 58.004895 | AJ38: 57.171326 | AK38: 67.724636 | AL38: 66.181738 | AM38: 64.516444 | AN38: 62.969981 | AO38: 60.862872 | AP38: 60.407526 | AQ38: 59.433835 | AR38: 59.066951 | AS38: 57.981814 | AT38: 57.981814 | AU38: 57.981814 | AV38: 57.981814 | AW38: 57.981814
C39: DC 2h 1.5cy 2030 direct | D39: EUR/MWh | J39: 0 | K39: 0 | L39: 0 | M39: 0 | N39: 0 | O39: 62.693931 | P39: 63.279601 | Q39: 57.920576 | R39: 57.487356 | S39: 52.198963 | T39: 50.688957 | U39: 49.649229 | V39: 53.274742 | W39: 52.839031 | X39: 51.730359 | Y39: 49.502394 | Z39: 47.256307 | AA39: 47.868696 | AB39: 47.3048 | AC39: 46.677679 | AD39: 48.555079 | AE39: 48.661643 | AF39: 49.449238 | AG39: 48.399821 | AH39: 47.878595 | AI39: 46.972557 | AJ39: 46.860056 | AK39: 46.262424 | AL39: 45.597747 | AM39: 45.039769 | AN39: 44.52662 | AO39: 43.769958 | AP39: 43.626343 | AQ39: 42.875757 | AR39: 42.868088 | AS39: 42.366441 | AT39: 42.366441 | AU39: 42.366441 | AV39: 42.366441 | AW39: 42.366441
C40: DC 4h transfer | D40: EUR/MWh | J40: 0 | K40: 0 | L40: 36.551423 | M40: 36.097357 | N40: 35.996376 | O40: 29.77703 | P40: 31.636148 | Q40: 27.42858 | R40: 30.352489 | S40: 26.813027 | T40: 26.596533 | U40: 26.460903 | V40: 28.163462 | W40: 29.492749 | X40: 28.037109 | Y40: 27.233291 | Z40: 25.066688 | AA40: 24.191368 | AB40: 24.216529 | AC40: 22.625349 | AD40: 23.382458 | AE40: 24.462475 | AF40: 22.629013 | AG40: 18.91539 | AH40: 22.466774 | AI40: 20.973221 | AJ40: 20.34225 | AK40: 18.850295 | AL40: 19.550285 | AM40: 19.055435 | AN40: 18.401118 | AO40: 17.800007 | AP40: 18.265574 | AQ40: 19.412634 | AR40: 20.635924 | AS40: 20.340431 | AT40: 20.340431 | AU40: 20.340431 | AV40: 20.340431 | AW40: 20.340431
C41: DC 2h transfer | D41: EUR/MWh | J41: 0 | K41: 0 | L41: 33.023974 | M41: 33.141213 | N41: 33.466048 | O41: 31.04554 | P41: 33.172509 | Q41: 28.591635 | R41: 31.553597 | S41: 28.861867 | T41: 29.065848 | U41: 27.355375 | V41: 29.102814 | W41: 29.159744 | X41: 28.653022 | Y41: 26.564583 | Z41: 24.28655 | AA41: 22.537967 | AB41: 23.462371 | AC41: 21.41509 | AD41: 22.214485 | AE41: 22.970048 | AF41: 21.394321 | AG41: 18.472763 | AH41: 19.249735 | AI41: 17.754987 | AJ41: 16.631675 | AK41: 15.769368 | AL41: 16.723233 | AM41: 16.19841 | AN41: 15.440636 | AO41: 15.045102 | AP41: 16.026328 | AQ41: 17.181861 | AR41: 19.048647 | AS41: 19.173193 | AT41: 19.173193 | AU41: 19.173193 | AV41: 19.173193 | AW41: 19.173193
C42: DC 2h 1.5cy transfer | D42: EUR/MWh | J42: 0 | K42: 0 | L42: 44.617385 | M42: 43.899406 | N42: 41.982546 | O42: 37.05035 | P42: 40.470618 | Q42: 37.242679 | R42: 41.092166 | S42: 38.587058 | T42: 39.572829 | U42: 40.743539 | V42: 41.396338 | W42: 42.326672 | X42: 41.683712 | Y42: 40.920411 | Z42: 38.679266 | AA42: 37.627564 | AB42: 38.906648 | AC42: 40.758918 | AD42: 40.874471 | AE42: 41.966451 | AF42: 39.175537 | AG42: 33.634636 | AH42: 33.639209 | AI42: 32.205861 | AJ42: 30.708781 | AK42: 28.685588 | AL42: 30.501997 | AM42: 29.298482 | AN42: 28.744962 | AO42: 27.011886 | AP42: 28.057637 | AQ42: 30.731584 | AR42: 33.203539 | AS42: 32.244968 | AT42: 32.244968 | AU42: 32.244968 | AV42: 32.244968 | AW42: 32.244968
C43: DC 4h 2030 transfer | D43: EUR/MWh | J43: 0 | K43: 0 | L43: 0 | M43: 0 | N43: 0 | O43: 30.315776 | P43: 31.849777 | Q43: 27.7096 | R43: 30.282906 | S43: 26.735758 | T43: 26.618476 | U43: 27.086578 | V43: 28.814559 | W43: 29.775652 | X43: 28.066023 | Y43: 27.107955 | Z43: 25.243238 | AA43: 24.12802 | AB43: 24.229836 | AC43: 22.697181 | AD43: 23.539019 | AE43: 24.718921 | AF43: 23.026195 | AG43: 18.778533 | AH43: 19.542868 | AI43: 18.779579 | AJ43: 18.675949 | AK43: 19.933274 | AL43: 20.072103 | AM43: 19.599791 | AN43: 18.859533 | AO43: 17.956064 | AP43: 18.978811 | AQ43: 19.640276 | AR43: 21.161142 | AS43: 20.772434 | AT43: 20.772434 | AU43: 20.772434 | AV43: 20.772434 | AW43: 20.772434
... C45: Baseload (info) | D45: EUR/MWh | J45: 0 | K45: 120.53 | L45: 119.34 | M45: 110 | N45: 103.08 | O45: 94.89 | P45: 98.51 | Q45: 96.1 | R45: 96.72 | S45: 93.13 | T45: 92.97 | U45: 93.04 | V45: 96.63 | W45: 95.76 | X45: 95.26 | Y45: 93.94 | Z45: 92.79 | AA45: 93.62 | AB45: 93.93 | AC45: 93.16 | AD45: 94.99 | AE45: 95.37 | AF45: 95.19 | AG45: 93.3 | AH45: 93.51 | AI45: 92.38 | AJ45: 91.45 | AK45: 89.7 | AL45: 90.71 | AM45: 90.37 | AN45: 90.08 | AO45: 88.97 | AP45: 89.89 | AQ45: 92.13 | AR45: 93.73 | AS45: 92.71 | AT45: 92.71 | AU45: 92.71 | AV45: 92.71 | AW45: 92.71
D46: EUR/MWh
...

Sheet Calc_1
A1: 1 | C1: Bid number
B2: =Dashboard!$C$3&" – Calculations – "&INDEX(Bid_Labels,1,$A$1) -> Project Zalahaláp – Calculations – A Original
C3: Period start | D3: date | J3: =I$4+1 -> 45931 | K3: =J$4+1 -> 46023 | L3: =K$4+1 -> 46113 | M3: =L$4+1 -> 46204 | N3: =M$4+1 -> 46296 | O3: =N$4+1 -> 46388 | P3: =O$4+1 -> 46478 | Q3: =P$4+1 -> 46569 | ... FH3: =FG$4+1 -> 59993
C4: Period end | D4: date | I4: =In_Model_Start-1 -> 45930 | J4: =EOMONTH(J$3,Months_Per_Period-1) -> 46022 | K4: =EOMONTH(K$3,Months_Per_Period-1) -> 46112 | L4: =EOMONTH(L$3,Months_Per_Period-1) -> 46203 | M4: =EOMONTH(M$3,Months_Per_Period-1) -> 46295 | N4: =EOMONTH(N$3,Months_Per_Period-1) -> 46387 | O4: =EOMONTH(O$3,Months_Per_Period-1) -> 46477 | P4: =EOMONTH(P$3,Months_Per_Period-1) -> 46568 | Q4: =EOMONTH(Q$3,Months_Per_Period-1) -> 46660 | ... FH4: =EOMONTH(FH$3,Months_Per_Period-1) -> 60083
C5: Days in period | D5: days | J5: =J$4-J$3+1 -> 92 | K5: =K$4-K$3+1 -> 90 | L5: =L$4-L$3+1 -> 91 | M5: =M$4-M$3+1 -> 92 | N5: =N$4-N$3+1 -> 92 | O5: =O$4-O$3+1 -> 90 | P5: =P$4-P$3+1 -> 91 | Q5: =Q$4-Q$3+1 -> 92 | ... FH5: =FH$4-FH$3+1 -> 91
C6: Year fraction | D6: factor | J6: =J$5/Days_In_Year -> 0.25205479 | K6: =K$5/Days_In_Year -> 0.24657534 | L6: =L$5/Days_In_Year -> 0.24931507 | M6: =M$5/Days_In_Year -> 0.25205479 | N6: =N$5/Days_In_Year -> 0.25205479 | O6: =O$5/Days_In_Year -> 0.24657534 | P6: =P$5/Days_In_Year -> 0.24931507 | Q6: =Q$5/Days_In_Year -> 0.25205479 | ... FH6: =FH$5/Days_In_Year -> 0.24931507
C7: Year | D7: year | J7: =YEAR(J$4) -> 2025 | K7: =YEAR(K$4) -> 2026 | L7: =YEAR(L$4) -> 2026 | M7: =YEAR(M$4) -> 2026 | N7: =YEAR(N$4) -> 2026 | O7: =YEAR(O$4) -> 2027 | P7: =YEAR(P$4) -> 2027 | Q7: =YEAR(Q$4) -> 2027 | ... FH7: =YEAR(FH$4) -> 2064
C8: Period counter | D8: # | J8: =I$8+1 -> 1 | K8: =J$8+1 -> 2 | L8: =K$8+1 -> 3 | M8: =L$8+1 -> 4 | N8: =M$8+1 -> 5 | O8: =N$8+1 -> 6 | P8: =O$8+1 -> 7 | Q8: =P$8+1 -> 8 | ... FH8: =FG$8+1 -> 155
A11: x | C11: Case and timing
C12: Revenue case (E: lever, F: column of the case table) | D12: text | E12: =INDEX(Dash_Case,1,$A$1) -> A | F12: =MATCH($E12,Case_Names,0) -> 1
C13: PV capacity (E: MWp) and grid export (F: MVA) | D13: MW | E13: =INDEX(Case_MWp,1,$F12) -> 61 | F13: =INDEX(Case_MVA,1,$F12) -> 50
C14: Specific yield (E: case, F: after the yield set) | D14: MWh/MWp | E14: =INDEX(Case_Yield,1,$F12) -> 1250 | F14: =$E14*(1+In_Yield_Adj) -> 1250
C15: RtB (E) and RtB exit (F) | D15: date | E15: =INDEX(Case_RtB,1,$F12) -> 46234 | F15: =INDEX(Case_Exit,1,$F12) -> 46326
C16: NTP (E) and COD (F) | D16: date | E16: =INDEX(Case_NTP,1,$F12) -> 46477 | F16: =EOMONTH(INDEX(Case_COD,1,$F12),In_COD_Delay) -> 46843
C17: Clipping, share of DC energy (case table) | D17: % | E17: =INDEX(Case_Clip,1,$F12) -> 0.02
C18: BESS built (E: MW, F: MWh) | D18: MW | E18: =In_BESS_MW*In_BESS_On -> 50 | F18: =$E18*In_BESS_Hours -> 200
C19: Acquisition and JV start | D19: flag | E19: =In_Acq -> 45991 | I19: =SUM(J19:FH19) -> 1 | J19: =N(AND(J$3<=$E19,J$4>=$E19)) -> 1 | K19: =N(AND(K$3<=$E19,K$4>=$E19)) -> 0 | L19: =N(AND(L$3<=$E19,L$4>=$E19)) -> 0 | M19: =N(AND(M$3<=$E19,M$4>=$E19)) -> 0 | N19: =N(AND(N$3<=$E19,N$4>=$E19)) -> 0 | O19: =N(AND(O$3<=$E19,O$4>=$E19)) -> 0 | P19: =N(AND(P$3<=$E19,P$4>=$E19)) -> 0 | Q19: =N(AND(Q$3<=$E19,Q$4>=$E19)) -> 0 | ... FH19: =N(AND(FH$3<=$E19,FH$4>=$E19)) -> 0
C20: RtB exit (sale closing) | D20: flag | E20: =$F15 -> 46326 | I20: =SUM(J20:FH20) -> 1 | J20: =N(AND(J$3<=$E20,J$4>=$E20)) -> 0 | K20: =N(AND(K$3<=$E20,K$4>=$E20)) -> 0 | L20: =N(AND(L$3<=$E20,L$4>=$E20)) -> 0 | M20: =N(AND(M$3<=$E20,M$4>=$E20)) -> 0 | N20: =N(AND(N$3<=$E20,N$4>=$E20)) -> 1 | O20: =N(AND(O$3<=$E20,O$4>=$E20)) -> 0 | P20: =N(AND(P$3<=$E20,P$4>=$E20)) -> 0 | Q20: =N(AND(Q$3<=$E20,Q$4>=$E20)) -> 0 | ... FH20: =N(AND(FH$3<=$E20,FH$4>=$E20)) -> 0
C21: NTP | D21: flag | E21: =$E16 -> 46477 | I21: =SUM(J21:FH21) -> 1 | J21: =N(AND(J$3<=$E21,J$4>=$E21)) -> 0 | K21: =N(AND(K$3<=$E21,K$4>=$E21)) -> 0 | L21: =N(AND(L$3<=$E21,L$4>=$E21)) -> 0 | M21: =N(AND(M$3<=$E21,M$4>=$E21)) -> 0 | N21: =N(AND(N$3<=$E21,N$4>=$E21)) -> 0 | O21: =N(AND(O$3<=$E21,O$4>=$E21)) -> 1 | P21: =N(AND(P$3<=$E21,P$4>=$E21)) -> 0 | Q21: =N(AND(Q$3<=$E21,Q$4>=$E21)) -> 0 | ... FH21: =N(AND(FH$3<=$E21,FH$4>=$E21)) -> 0
C22: COD | D22: flag | E22: =$F16 -> 46843 | I22: =SUM(J22:FH22) -> 1 | J22: =N(AND(J$3<=$E22,J$4>=$E22)) -> 0 | K22: =N(AND(K$3<=$E22,K$4>=$E22)) -> 0 | L22: =N(AND(L$3<=$E22,L$4>=$E22)) -> 0 | M22: =N(AND(M$3<=$E22,M$4>=$E22)) -> 0 | N22: =N(AND(N$3<=$E22,N$4>=$E22)) -> 0 | O22: =N(AND(O$3<=$E22,O$4>=$E22)) -> 0 | P22: =N(AND(P$3<=$E22,P$4>=$E22)) -> 0 | Q22: =N(AND(Q$3<=$E22,Q$4>=$E22)) -> 0 | ... FH22: =N(AND(FH$3<=$E22,FH$4>=$E22)) -> 0
C23: Exit column on the timeline (buyer view at RtB) | D23: # | E23: =MATCH($E20-1,$J$4:$FH$4,1)+1 -> 5
C24: COD column on the timeline (buyer view at COD) | D24: # | E24: =MATCH($E22,$J$4:$FH$4,0) -> 10
C25: After the exit period | D25: flag | J25: =N(J$3>$E20) -> 0 | K25: =N(K$3>$E20) -> 0 | L25: =N(L$3>$E20) -> 0 | M25: =N(M$3>$E20) -> 0 | N25: =N(N$3>$E20) -> 0 | O25: =N(O$3>$E20) -> 1 | P25: =N(P$3>$E20) -> 1 | Q25: =N(Q$3>$E20) -> 1 | ... FH25: =N(FH$3>$E20) -> 1
C26: After COD | D26: flag | J26: =N(J$4>$E22) -> 0 | K26: =N(K$4>$E22) -> 0 | L26: =N(L$4>$E22) -> 0 | M26: =N(M$4>$E22) -> 0 | N26: =N(N$4>$E22) -> 0 | O26: =N(O$4>$E22) -> 0 | P26: =N(P$4>$E22) -> 0 | Q26: =N(Q$4>$E22) -> 0 | ... FH26: =N(FH$4>$E22) -> 1
C27: Construction spread (NTP → COD) | D27: factor | E27: =$E16+1 -> 46478 | F27: =$F16 -> 46843 | I27: =SUM(J27:FH27) -> 1 | J27: =MAX(0,MIN($F27,J$4)-MAX($E27,J$3)+1)/($F27-$E27+1) -> 0 | K27: =MAX(0,MIN($F27,K$4)-MAX($E27,K$3)+1)/($F27-$E27+1) -> 0 | L27: =MAX(0,MIN($F27,L$4)-MAX($E27,L$3)+1)/($F27-$E27+1) -> 0 | M27: =MAX(0,MIN($F27,M$4)-MAX($E27,M$3)+1)/($F27-$E27+1) -> 0 | N27: =MAX(0,MIN($F27,N$4)-MAX($E27,N$3)+1)/($F27-$E27+1) -> 0 | O27: =MAX(0,MIN($F27,O$4)-MAX($E27,O$3)+1)/($F27-$E27+1) -> 0 | P27: =MAX(0,MIN($F27,P$4)-MAX($E27,P$3)+1)/($F27-$E27+1) -> 0.24863388 | Q27: =MAX(0,MIN($F27,Q$4)-MAX($E27,Q$3)+1)/($F27-$E27+1) -> 0.25136612 | ... FH27: =MAX(0,MIN($F27,FH$4)-MAX($E27,FH$3)+1)/($F27-$E27+1) -> 0
C28: Operations (COD → end of life) | D28: flag | E28: =$F16+1 -> 46844 | F28: =EDATE($F16,In_Life*Months_In_Year) -> 59626 | J28: =MAX(0,(MIN($F28,J$4)-MAX($E28,J$3)+1)/J$5) -> 0 | K28: =MAX(0,(MIN($F28,K$4)-MAX($E28,K$3)+1)/K$5) -> 0 | L28: =MAX(0,(MIN($F28,L$4)-MAX($E28,L$3)+1)/L$5) -> 0 | M28: =MAX(0,(MIN($F28,M$4)-MAX($E28,M$3)+1)/M$5) -> 0 | N28: =MAX(0,(MIN($F28,N$4)-MAX($E28,N$3)+1)/N$5) -> 0 | O28: =MAX(0,(MIN($F28,O$4)-MAX($E28,O$3)+1)/O$5) -> 0 | P28: =MAX(0,(MIN($F28,P$4)-MAX($E28,P$3)+1)/P$5) -> 0 | Q28: =MAX(0,(MIN($F28,Q$4)-MAX($E28,Q$3)+1)/Q$5) -> 0 | ... FH28: =MAX(0,(MIN($F28,FH$4)-MAX($E28,FH$3)+1)/FH$5) -> 0
C29: Operating years elapsed at the period start | D29: years | J29: =MAX(0,J$3-1-$F16)/Days_In_Year -> 0 | K29: =MAX(0,K$3-1-$F16)/Days_In_Year -> 0 | L29: =MAX(0,L$3-1-$F16)/Days_In_Year -> 0 | M29: =MAX(0,M$3-1-$F16)/Days_In_Year -> 0 | N29: =MAX(0,N$3-1-$F16)/Days_In_Year -> 0 | O29: =MAX(0,O$3-1-$F16)/Days_In_Year -> 0 | P29: =MAX(0,P$3-1-$F16)/Days_In_Year -> 0 | Q29: =MAX(0,Q$3-1-$F16)/Days_In_Year -> 0 | ... FH29: =MAX(0,FH$3-1-$F16)/Days_In_Year -> 36.024658
C30: DSA loan spread (acquisition → RtB) | D30: factor | E30: =In_Acq+1 -> 45992 | F30: =$E15 -> 46234 | I30: =SUM(J30:FH30) -> 1 | J30: =MAX(0,MIN($F30,J$4)-MAX($E30,J$3)+1)/($F30-$E30+1) -> 0.12757202 | K30: =MAX(0,MIN($F30,K$4)-MAX($E30,K$3)+1)/($F30-$E30+1) -> 0.37037037 | L30: =MAX(0,MIN($F30,L$4)-MAX($E30,L$3)+1)/($F30-$E30+1) -> 0.3744856 | M30: =MAX(0,MIN($F30,M$4)-MAX($E30,M$3)+1)/($F30-$E30+1) -> 0.12757202 | N30: =MAX(0,MIN($F30,N$4)-MAX($E30,N$3)+1)/($F30-$E30+1) -> 0 | O30: =MAX(0,MIN($F30,O$4)-MAX($E30,O$3)+1)/($F30-$E30+1) -> 0 | P30: =MAX(0,MIN($F30,P$4)-MAX($E30,P$3)+1)/($F30-$E30+1) -> 0 | Q30: =MAX(0,MIN($F30,Q$4)-MAX($E30,Q$3)+1)/($F30-$E30+1) -> 0 | ... FH30: =MAX(0,MIN($F30,FH$4)-MAX($E30,FH$3)+1)/($F30-$E30+1) -> 0
C31: Pre-RtB development cost spread | D31: factor | E31: =EOMONTH(In_PreRtB_First,-1)+1 -> 46296 | F31: =In_PreRtB_Last -> 46477 | I31: =SUM(J31:FH31) -> 1 | J31: =MAX(0,MIN($F31,J$4)-MAX($E31,J$3)+1)/($F31-$E31+1) -> 0 | K31: =MAX(0,MIN($F31,K$4)-MAX($E31,K$3)+1)/($F31-$E31+1) -> 0 | L31: =MAX(0,MIN($F31,L$4)-MAX($E31,L$3)+1)/($F31-$E31+1) -> 0 | M31: =MAX(0,MIN($F31,M$4)-MAX($E31,M$3)+1)/($F31-$E31+1) -> 0 | N31: =MAX(0,MIN($F31,N$4)-MAX($E31,N$3)+1)/($F31-$E31+1) -> 0.50549451 | O31: =MAX(0,MIN($F31,O$4)-MAX($E31,O$3)+1)/($F31-$E31+1) -> 0.49450549 | P31: =MAX(0,MIN($F31,P$4)-MAX($E31,P$3)+1)/($F31-$E31+1) -> 0 | Q31: =MAX(0,MIN($F31,Q$4)-MAX($E31,Q$3)+1)/($F31-$E31+1) -> 0 | ... FH31: =MAX(0,MIN($F31,FH$4)-MAX($E31,FH$3)+1)/($F31-$E31+1) -> 0
C32: Debt repayment period | D32: flag | E32: =$F16+1 -> 46844 | F32: =EDATE($F16,In_Debt_Tenor*Months_In_Year) -> 52321 | J32: =MAX(0,(MIN($F32,J$4)-MAX($E32,J$3)+1)/J$5) -> 0 | K32: =MAX(0,(MIN($F32,K$4)-MAX($E32,K$3)+1)/K$5) -> 0 | L32: =MAX(0,(MIN($F32,L$4)-MAX($E32,L$3)+1)/L$5) -> 0 | M32: =MAX(0,(MIN($F32,M$4)-MAX($E32,M$3)+1)/M$5) -> 0 | N32: =MAX(0,(MIN($F32,N$4)-MAX($E32,N$3)+1)/N$5) -> 0 | O32: =MAX(0,(MIN($F32,O$4)-MAX($E32,O$3)+1)/O$5) -> 0 | P32: =MAX(0,(MIN($F32,P$4)-MAX($E32,P$3)+1)/P$5) -> 0 | Q32: =MAX(0,(MIN($F32,Q$4)-MAX($E32,Q$3)+1)/Q$5) -> 0 | ... FH32: =MAX(0,(MIN($F32,FH$4)-MAX($E32,FH$3)+1)/FH$5) -> 0
C33: Last debt repayment | D33: flag | E33: =EDATE($F16,In_Debt_Tenor*Months_In_Year) -> 52321 | I33: =SUM(J33:FH33) -> 1 | J33: =N(AND(J$3<=$E33,J$4>=$E33)) -> 0 | K33: =N(AND(K$3<=$E33,K$4>=$E33)) -> 0 | L33: =N(AND(L$3<=$E33,L$4>=$E33)) -> 0 | M33: =N(AND(M$3<=$E33,M$4>=$E33)) -> 0 | N33: =N(AND(N$3<=$E33,N$4>=$E33)) -> 0 | O33: =N(AND(O$3<=$E33,O$4>=$E33)) -> 0 | P33: =N(AND(P$3<=$E33,P$4>=$E33)) -> 0 | Q33: =N(AND(Q$3<=$E33,Q$4>=$E33)) -> 0 | ... FH33: =N(AND(FH$3<=$E33,FH$4>=$E33)) -> 0
C34: Tax depreciation spread: PV, grid, development | D34: factor | E34: =$F16+1 -> 46844 | F34: =EDATE($F16,In_Dep_Years*Months_In_Year) -> 57800 | I34: =SUM(J34:FH34) -> 1 | J34: =MAX(0,MIN($F34,J$4)-MAX($E34,J$3)+1)/($F34-$E34+1) -> 0 | K34: =MAX(0,MIN($F34,K$4)-MAX($E34,K$3)+1)/($F34-$E34+1) -> 0 | L34: =MAX(0,MIN($F34,L$4)-MAX($E34,L$3)+1)/($F34-$E34+1) -> 0 | M34: =MAX(0,MIN($F34,M$4)-MAX($E34,M$3)+1)/($F34-$E34+1) -> 0 | N34: =MAX(0,MIN($F34,N$4)-MAX($E34,N$3)+1)/($F34-$E34+1) -> 0 | O34: =MAX(0,MIN($F34,O$4)-MAX($E34,O$3)+1)/($F34-$E34+1) -> 0 | P34: =MAX(0,MIN($F34,P$4)-MAX($E34,P$3)+1)/($F34-$E34+1) -> 0 | Q34: =MAX(0,MIN($F34,Q$4)-MAX($E34,Q$3)+1)/($F34-$E34+1) -> 0 | ... FH34: =MAX(0,MIN($F34,FH$4)-MAX($E34,FH$3)+1)/($F34-$E34+1) -> 0
C35: Tax depreciation spread: BESS | D35: factor | E35: =$F16+1 -> 46844 | F35: =EDATE($F16,In_Dep_BESS_Years*Months_In_Year) -> 50495 | I35: =SUM(J35:FH35) -> 1 | J35: =MAX(0,MIN($F35,J$4)-MAX($E35,J$3)+1)/($F35-$E35+1) -> 0 | K35: =MAX(0,MIN($F35,K$4)-MAX($E35,K$3)+1)/($F35-$E35+1) -> 0 | L35: =MAX(0,MIN($F35,L$4)-MAX($E35,L$3)+1)/($F35-$E35+1) -> 0 | M35: =MAX(0,MIN($F35,M$4)-MAX($E35,M$3)+1)/($F35-$E35+1) -> 0 | N35: =MAX(0,MIN($F35,N$4)-MAX($E35,N$3)+1)/($F35-$E35+1) -> 0 | O35: =MAX(0,MIN($F35,O$4)-MAX($E35,O$3)+1)/($F35-$E35+1) -> 0 | P35: =MAX(0,MIN($F35,P$4)-MAX($E35,P$3)+1)/($F35-$E35+1) -> 0 | Q35: =MAX(0,MIN($F35,Q$4)-MAX($E35,Q$3)+1)/($F35-$E35+1) -> 0 | ... FH35: =MAX(0,MIN($F35,FH$4)-MAX($E35,FH$3)+1)/($F35-$E35+1) -> 0
C36: Debt compounding index (E: at COD, F: rate per period) | D36: factor | E36: =SUMIF($J$4:$FH$4,$F16,$J36:$FH36) -> 1.1322708 | F36: =In_Debt_Rate*Months_Per_Period/Months_In_Year -> 0.0125 | J36: =(1+$F36)^J$8 -> 1.0125 | K36: =(1+$F36)^K$8 -> 1.0251562 | L36: =(1+$F36)^L$8 -> 1.0379707 | M36: =(1+$F36)^M$8 -> 1.0509453 | N36: =(1+$F36)^N$8 -> 1.0640822 | O36: =(1+$F36)^O$8 -> 1.0773832 | P36: =(1+$F36)^P$8 -> 1.0908505 | Q36: =(1+$F36)^Q$8 -> 1.1044861 | ... FH36: =(1+$F36)^FH$8 -> 6.8585126
C37: 31-Dec capitalisation | D37: flag | J37: =N(MONTH(J$4)=Months_In_Year) -> 1 | K37: =N(MONTH(K$4)=Months_In_Year) -> 0 | L37: =N(MONTH(L$4)=Months_In_Year) -> 0 | M37: =N(MONTH(M$4)=Months_In_Year) -> 0 | N37: =N(MONTH(N$4)=Months_In_Year) -> 1 | O37: =N(MONTH(O$4)=Months_In_Year) -> 0 | P37: =N(MONTH(P$4)=Months_In_Year) -> 0 | Q37: =N(MONTH(Q$4)=Months_In_Year) -> 0 | ... FH37: =N(MONTH(FH$4)=Months_In_Year) -> 0
C38: First quarter of the year | D38: flag | J38: =N(MONTH(J$4)<=Months_Per_Period) -> 0 | K38: =N(MONTH(K$4)<=Months_Per_Period) -> 1 | L38: =N(MONTH(L$4)<=Months_Per_Period) -> 0 | M38: =N(MONTH(M$4)<=Months_Per_Period) -> 0 | N38: =N(MONTH(N$4)<=Months_Per_Period) -> 0 | O38: =N(MONTH(O$4)<=Months_Per_Period) -> 1 | P38: =N(MONTH(P$4)<=Months_Per_Period) -> 0 | Q38: =N(MONTH(Q$4)<=Months_Per_Period) -> 0 | ... FH38: =N(MONTH(FH$4)<=Months_Per_Period) -> 0
A40: x | C40: Prices (real 2025 curves × Aurora euro index)
C41: Aurora euro index | D41: factor | J41: =INDEX(Euro_Index,MATCH(J$7,Price_Years,0)) -> 1 | K41: =INDEX(Euro_Index,MATCH(K$7,Price_Years,0)) -> 1.01897 | L41: =INDEX(Euro_Index,MATCH(L$7,Price_Years,0)) -> 1.01897 | M41: =INDEX(Euro_Index,MATCH(M$7,Price_Years,0)) -> 1.01897 | N41: =INDEX(Euro_Index,MATCH(N$7,Price_Years,0)) -> 1.01897 | O41: =INDEX(Euro_Index,MATCH(O$7,Price_Years,0)) -> 1.040399 | P41: =INDEX(Euro_Index,MATCH(P$7,Price_Years,0)) -> 1.040399 | Q41: =INDEX(Euro_Index,MATCH(Q$7,Price_Years,0)) -> 1.040399 | ... FH41: =INDEX(Euro_Index,MATCH(FH$7,Price_Years,0)) -> 2.1668863
C42: PV price, direct export, real 2025 (E: curve) | D42: EUR/MWh | E42: =INDEX(Case_PV_Curve,1,$F12) -> v3 capture | J42: =INDEX(Price_Data,MATCH($E42,Price_Labels,0),MATCH(J$7,Price_Years,0)) -> 0 | K42: =INDEX(Price_Data,MATCH($E42,Price_Labels,0),MATCH(K$7,Price_Years,0)) -> 78.3445 | L42: =INDEX(Price_Data,MATCH($E42,Price_Labels,0),MATCH(L$7,Price_Years,0)) -> 78.3445 | M42: =INDEX(Price_Data,MATCH($E42,Price_Labels,0),MATCH(M$7,Price_Years,0)) -> 78.3445 | N42: =INDEX(Price_Data,MATCH($E42,Price_Labels,0),MATCH(N$7,Price_Years,0)) -> 78.3445 | O42: =INDEX(Price_Data,MATCH($E42,Price_Labels,0),MATCH(O$7,Price_Years,0)) -> 77.571 | P42: =INDEX(Price_Data,MATCH($E42,Price_Labels,0),MATCH(P$7,Price_Years,0)) -> 77.571 | Q42: =INDEX(Price_Data,MATCH($E42,Price_Labels,0),MATCH(Q$7,Price_Years,0)) -> 77.571 | ... FH42: =INDEX(Price_Data,MATCH($E42,Price_Labels,0),MATCH(FH$7,Price_Years,0)) -> 60.2615
C43: PV price, energy sent to the BESS, real 2025 (E: curve) | D43: EUR/MWh | E43: =INDEX(Case_PV_Transfer,1,$F12) -> v3 capture | J43: =INDEX(Price_Data,MATCH($E43,Price_Labels,0),MATCH(J$7,Price_Years,0)) -> 0 | K43: =INDEX(Price_Data,MATCH($E43,Price_Labels,0),MATCH(K$7,Price_Years,0)) -> 78.3445 | L43: =INDEX(Price_Data,MATCH($E43,Price_Labels,0),MATCH(L$7,Price_Years,0)) -> 78.3445 | M43: =INDEX(Price_Data,MATCH($E43,Price_Labels,0),MATCH(M$7,Price_Years,0)) -> 78.3445 | N43: =INDEX(Price_Data,MATCH($E43,Price_Labels,0),MATCH(N$7,Price_Years,0)) -> 78.3445 | O43: =INDEX(Price_Data,MATCH($E43,Price_Labels,0),MATCH(O$7,Price_Years,0)) -> 77.571 | P43: =INDEX(Price_Data,MATCH($E43,Price_Labels,0),MATCH(P$7,Price_Years,0)) -> 77.571 | Q43: =INDEX(Price_Data,MATCH($E43,Price_Labels,0),MATCH(Q$7,Price_Years,0)) -> 77.571 | ... FH43: =INDEX(Price_Data,MATCH($E43,Price_Labels,0),MATCH(FH$7,Price_Years,0)) -> 60.2615
...

Sheet Calc_2
A1: 2 | C1: Bid number
B2: =Dashboard!$C$3&" – Calculations – "&INDEX(Bid_Labels,1,$A$1) -> Project Zalahaláp – Calculations – B Aurora
C3: Period start | D3: date | J3: =I$4+1 -> 45931 | K3: =J$4+1 -> 46023 | L3: =K$4+1 -> 46113 | M3: =L$4+1 -> 46204 | N3: =M$4+1 -> 46296 | O3: =N$4+1 -> 46388 | P3: =O$4+1 -> 46478 | Q3: =P$4+1 -> 46569 | ... FH3: =FG$4+1 -> 59993
C4: Period end | D4: date | I4: =In_Model_Start-1 -> 45930 | J4: =EOMONTH(J$3,Months_Per_Period-1) -> 46022 | K4: =EOMONTH(K$3,Months_Per_Period-1) -> 46112 | L4: =EOMONTH(L$3,Months_Per_Period-1) -> 46203 | M4: =EOMONTH(M$3,Months_Per_Period-1) -> 46295 | N4: =EOMONTH(N$3,Months_Per_Period-1) -> 46387 | O4: =EOMONTH(O$3,Months_Per_Period-1) -> 46477 | P4: =EOMONTH(P$3,Months_Per_Period-1) -> 46568 | Q4: =EOMONTH(Q$3,Months_Per_Period-1) -> 46660 | ... FH4: =EOMONTH(FH$3,Months_Per_Period-1) -> 60083
C5: Days in period | D5: days | J5: =J$4-J$3+1 -> 92 | K5: =K$4-K$3+1 -> 90 | L5: =L$4-L$3+1 -> 91 | M5: =M$4-M$3+1 -> 92 | N5: =N$4-N$3+1 -> 92 | O5: =O$4-O$3+1 -> 90 | P5: =P$4-P$3+1 -> 91 | Q5: =Q$4-Q$3+1 -> 92 | ... FH5: =FH$4-FH$3+1 -> 91
C6: Year fraction | D6: factor | J6: =J$5/Days_In_Year -> 0.25205479 | K6: =K$5/Days_In_Year -> 0.24657534 | L6: =L$5/Days_In_Year -> 0.24931507 | M6: =M$5/Days_In_Year -> 0.25205479 | N6: =N$5/Days_In_Year -> 0.25205479 | O6: =O$5/Days_In_Year -> 0.24657534 | P6: =P$5/Days_In_Year -> 0.24931507 | Q6: =Q$5/Days_In_Year -> 0.25205479 | ... FH6: =FH$5/Days_In_Year -> 0.24931507
C7: Year | D7: year | J7: =YEAR(J$4) -> 2025 | K7: =YEAR(K$4) -> 2026 | L7: =YEAR(L$4) -> 2026 | M7: =YEAR(M$4) -> 2026 | N7: =YEAR(N$4) -> 2026 | O7: =YEAR(O$4) -> 2027 | P7: =YEAR(P$4) -> 2027 | Q7: =YEAR(Q$4) -> 2027 | ... FH7: =YEAR(FH$4) -> 2064
C8: Period counter | D8: # | J8: =I$8+1 -> 1 | K8: =J$8+1 -> 2 | L8: =K$8+1 -> 3 | M8: =L$8+1 -> 4 | N8: =M$8+1 -> 5 | O8: =N$8+1 -> 6 | P8: =O$8+1 -> 7 | Q8: =P$8+1 -> 8 | ... FH8: =FG$8+1 -> 155
A11: x | C11: Case and timing
C12: Revenue case (E: lever, F: column of the case table) | D12: text | E12: =INDEX(Dash_Case,1,$A$1) -> B | F12: =MATCH($E12,Case_Names,0) -> 2
C13: PV capacity (E: MWp) and grid export (F: MVA) | D13: MW | E13: =INDEX(Case_MWp,1,$F12) -> 63 | F13: =INDEX(Case_MVA,1,$F12) -> 49.9
C14: Specific yield (E: case, F: after the yield set) | D14: MWh/MWp | E14: =INDEX(Case_Yield,1,$F12) -> 1265 | F14: =$E14*(1+In_Yield_Adj) -> 1265
C15: RtB (E) and RtB exit (F) | D15: date | E15: =INDEX(Case_RtB,1,$F12) -> 46387 | F15: =INDEX(Case_Exit,1,$F12) -> 46477
C16: NTP (E) and COD (F) | D16: date | E16: =INDEX(Case_NTP,1,$F12) -> 46568 | F16: =EOMONTH(INDEX(Case_COD,1,$F12),In_COD_Delay) -> 46843
C17: Clipping, share of DC energy (case table) | D17: % | E17: =INDEX(Case_Clip,1,$F12) -> 0
C18: BESS built (E: MW, F: MWh) | D18: MW | E18: =In_BESS_MW*In_BESS_On -> 50 | F18: =$E18*In_BESS_Hours -> 200
C19: Acquisition and JV start | D19: flag | E19: =In_Acq -> 45991 | I19: =SUM(J19:FH19) -> 1 | J19: =N(AND(J$3<=$E19,J$4>=$E19)) -> 1 | K19: =N(AND(K$3<=$E19,K$4>=$E19)) -> 0 | L19: =N(AND(L$3<=$E19,L$4>=$E19)) -> 0 | M19: =N(AND(M$3<=$E19,M$4>=$E19)) -> 0 | N19: =N(AND(N$3<=$E19,N$4>=$E19)) -> 0 | O19: =N(AND(O$3<=$E19,O$4>=$E19)) -> 0 | P19: =N(AND(P$3<=$E19,P$4>=$E19)) -> 0 | Q19: =N(AND(Q$3<=$E19,Q$4>=$E19)) -> 0 | ... FH19: =N(AND(FH$3<=$E19,FH$4>=$E19)) -> 0
C20: RtB exit (sale closing) | D20: flag | E20: =$F15 -> 46477 | I20: =SUM(J20:FH20) -> 1 | J20: =N(AND(J$3<=$E20,J$4>=$E20)) -> 0 | K20: =N(AND(K$3<=$E20,K$4>=$E20)) -> 0 | L20: =N(AND(L$3<=$E20,L$4>=$E20)) -> 0 | M20: =N(AND(M$3<=$E20,M$4>=$E20)) -> 0 | N20: =N(AND(N$3<=$E20,N$4>=$E20)) -> 0 | O20: =N(AND(O$3<=$E20,O$4>=$E20)) -> 1 | P20: =N(AND(P$3<=$E20,P$4>=$E20)) -> 0 | Q20: =N(AND(Q$3<=$E20,Q$4>=$E20)) -> 0 | ... FH20: =N(AND(FH$3<=$E20,FH$4>=$E20)) -> 0
C21: NTP | D21: flag | E21: =$E16 -> 46568 | I21: =SUM(J21:FH21) -> 1 | J21: =N(AND(J$3<=$E21,J$4>=$E21)) -> 0 | K21: =N(AND(K$3<=$E21,K$4>=$E21)) -> 0 | L21: =N(AND(L$3<=$E21,L$4>=$E21)) -> 0 | M21: =N(AND(M$3<=$E21,M$4>=$E21)) -> 0 | N21: =N(AND(N$3<=$E21,N$4>=$E21)) -> 0 | O21: =N(AND(O$3<=$E21,O$4>=$E21)) -> 0 | P21: =N(AND(P$3<=$E21,P$4>=$E21)) -> 1 | Q21: =N(AND(Q$3<=$E21,Q$4>=$E21)) -> 0 | ... FH21: =N(AND(FH$3<=$E21,FH$4>=$E21)) -> 0
C22: COD | D22: flag | E22: =$F16 -> 46843 | I22: =SUM(J22:FH22) -> 1 | J22: =N(AND(J$3<=$E22,J$4>=$E22)) -> 0 | K22: =N(AND(K$3<=$E22,K$4>=$E22)) -> 0 | L22: =N(AND(L$3<=$E22,L$4>=$E22)) -> 0 | M22: =N(AND(M$3<=$E22,M$4>=$E22)) -> 0 | N22: =N(AND(N$3<=$E22,N$4>=$E22)) -> 0 | O22: =N(AND(O$3<=$E22,O$4>=$E22)) -> 0 | P22: =N(AND(P$3<=$E22,P$4>=$E22)) -> 0 | Q22: =N(AND(Q$3<=$E22,Q$4>=$E22)) -> 0 | ... FH22: =N(AND(FH$3<=$E22,FH$4>=$E22)) -> 0
C23: Exit column on the timeline (buyer view at RtB) | D23: # | E23: =MATCH($E20-1,$J$4:$FH$4,1)+1 -> 6
C24: COD column on the timeline (buyer view at COD) | D24: # | E24: =MATCH($E22,$J$4:$FH$4,0) -> 10
C25: After the exit period | D25: flag | J25: =N(J$3>$E20) -> 0 | K25: =N(K$3>$E20) -> 0 | L25: =N(L$3>$E20) -> 0 | M25: =N(M$3>$E20) -> 0 | N25: =N(N$3>$E20) -> 0 | O25: =N(O$3>$E20) -> 0 | P25: =N(P$3>$E20) -> 1 | Q25: =N(Q$3>$E20) -> 1 | ... FH25: =N(FH$3>$E20) -> 1
C26: After COD | D26: flag | J26: =N(J$4>$E22) -> 0 | K26: =N(K$4>$E22) -> 0 | L26: =N(L$4>$E22) -> 0 | M26: =N(M$4>$E22) -> 0 | N26: =N(N$4>$E22) -> 0 | O26: =N(O$4>$E22) -> 0 | P26: =N(P$4>$E22) -> 0 | Q26: =N(Q$4>$E22) -> 0 | ... FH26: =N(FH$4>$E22) -> 1
C27: Construction spread (NTP → COD) | D27: factor | E27: =$E16+1 -> 46569 | F27: =$F16 -> 46843 | I27: =SUM(J27:FH27) -> 1 | J27: =MAX(0,MIN($F27,J$4)-MAX($E27,J$3)+1)/($F27-$E27+1) -> 0 | K27: =MAX(0,MIN($F27,K$4)-MAX($E27,K$3)+1)/($F27-$E27+1) -> 0 | L27: =MAX(0,MIN($F27,L$4)-MAX($E27,L$3)+1)/($F27-$E27+1) -> 0 | M27: =MAX(0,MIN($F27,M$4)-MAX($E27,M$3)+1)/($F27-$E27+1) -> 0 | N27: =MAX(0,MIN($F27,N$4)-MAX($E27,N$3)+1)/($F27-$E27+1) -> 0 | O27: =MAX(0,MIN($F27,O$4)-MAX($E27,O$3)+1)/($F27-$E27+1) -> 0 | P27: =MAX(0,MIN($F27,P$4)-MAX($E27,P$3)+1)/($F27-$E27+1) -> 0 | Q27: =MAX(0,MIN($F27,Q$4)-MAX($E27,Q$3)+1)/($F27-$E27+1) -> 0.33454545 | ... FH27: =MAX(0,MIN($F27,FH$4)-MAX($E27,FH$3)+1)/($F27-$E27+1) -> 0
C28: Operations (COD → end of life) | D28: flag | E28: =$F16+1 -> 46844 | F28: =EDATE($F16,In_Life*Months_In_Year) -> 59626 | J28: =MAX(0,(MIN($F28,J$4)-MAX($E28,J$3)+1)/J$5) -> 0 | K28: =MAX(0,(MIN($F28,K$4)-MAX($E28,K$3)+1)/K$5) -> 0 | L28: =MAX(0,(MIN($F28,L$4)-MAX($E28,L$3)+1)/L$5) -> 0 | M28: =MAX(0,(MIN($F28,M$4)-MAX($E28,M$3)+1)/M$5) -> 0 | N28: =MAX(0,(MIN($F28,N$4)-MAX($E28,N$3)+1)/N$5) -> 0 | O28: =MAX(0,(MIN($F28,O$4)-MAX($E28,O$3)+1)/O$5) -> 0 | P28: =MAX(0,(MIN($F28,P$4)-MAX($E28,P$3)+1)/P$5) -> 0 | Q28: =MAX(0,(MIN($F28,Q$4)-MAX($E28,Q$3)+1)/Q$5) -> 0 | ... FH28: =MAX(0,(MIN($F28,FH$4)-MAX($E28,FH$3)+1)/FH$5) -> 0
C29: Operating years elapsed at the period start | D29: years | J29: =MAX(0,J$3-1-$F16)/Days_In_Year -> 0 | K29: =MAX(0,K$3-1-$F16)/Days_In_Year -> 0 | L29: =MAX(0,L$3-1-$F16)/Days_In_Year -> 0 | M29: =MAX(0,M$3-1-$F16)/Days_In_Year -> 0 | N29: =MAX(0,N$3-1-$F16)/Days_In_Year -> 0 | O29: =MAX(0,O$3-1-$F16)/Days_In_Year -> 0 | P29: =MAX(0,P$3-1-$F16)/Days_In_Year -> 0 | Q29: =MAX(0,Q$3-1-$F16)/Days_In_Year -> 0 | ... FH29: =MAX(0,FH$3-1-$F16)/Days_In_Year -> 36.024658
C30: DSA loan spread (acquisition → RtB) | D30: factor | E30: =In_Acq+1 -> 45992 | F30: =$E15 -> 46387 | I30: =SUM(J30:FH30) -> 1 | J30: =MAX(0,MIN($F30,J$4)-MAX($E30,J$3)+1)/($F30-$E30+1) -> 0.078282828 | K30: =MAX(0,MIN($F30,K$4)-MAX($E30,K$3)+1)/($F30-$E30+1) -> 0.22727273 | L30: =MAX(0,MIN($F30,L$4)-MAX($E30,L$3)+1)/($F30-$E30+1) -> 0.22979798 | M30: =MAX(0,MIN($F30,M$4)-MAX($E30,M$3)+1)/($F30-$E30+1) -> 0.23232323 | N30: =MAX(0,MIN($F30,N$4)-MAX($E30,N$3)+1)/($F30-$E30+1) -> 0.23232323 | O30: =MAX(0,MIN($F30,O$4)-MAX($E30,O$3)+1)/($F30-$E30+1) -> 0 | P30: =MAX(0,MIN($F30,P$4)-MAX($E30,P$3)+1)/($F30-$E30+1) -> 0 | Q30: =MAX(0,MIN($F30,Q$4)-MAX($E30,Q$3)+1)/($F30-$E30+1) -> 0 | ... FH30: =MAX(0,MIN($F30,FH$4)-MAX($E30,FH$3)+1)/($F30-$E30+1) -> 0
C31: Pre-RtB development cost spread | D31: factor | E31: =EOMONTH(In_PreRtB_First,-1)+1 -> 46296 | F31: =In_PreRtB_Last -> 46477 | I31: =SUM(J31:FH31) -> 1 | J31: =MAX(0,MIN($F31,J$4)-MAX($E31,J$3)+1)/($F31-$E31+1) -> 0 | K31: =MAX(0,MIN($F31,K$4)-MAX($E31,K$3)+1)/($F31-$E31+1) -> 0 | L31: =MAX(0,MIN($F31,L$4)-MAX($E31,L$3)+1)/($F31-$E31+1) -> 0 | M31: =MAX(0,MIN($F31,M$4)-MAX($E31,M$3)+1)/($F31-$E31+1) -> 0 | N31: =MAX(0,MIN($F31,N$4)-MAX($E31,N$3)+1)/($F31-$E31+1) -> 0.50549451 | O31: =MAX(0,MIN($F31,O$4)-MAX($E31,O$3)+1)/($F31-$E31+1) -> 0.49450549 | P31: =MAX(0,MIN($F31,P$4)-MAX($E31,P$3)+1)/($F31-$E31+1) -> 0 | Q31: =MAX(0,MIN($F31,Q$4)-MAX($E31,Q$3)+1)/($F31-$E31+1) -> 0 | ... FH31: =MAX(0,MIN($F31,FH$4)-MAX($E31,FH$3)+1)/($F31-$E31+1) -> 0
C32: Debt repayment period | D32: flag | E32: =$F16+1 -> 46844 | F32: =EDATE($F16,In_Debt_Tenor*Months_In_Year) -> 52321 | J32: =MAX(0,(MIN($F32,J$4)-MAX($E32,J$3)+1)/J$5) -> 0 | K32: =MAX(0,(MIN($F32,K$4)-MAX($E32,K$3)+1)/K$5) -> 0 | L32: =MAX(0,(MIN($F32,L$4)-MAX($E32,L$3)+1)/L$5) -> 0 | M32: =MAX(0,(MIN($F32,M$4)-MAX($E32,M$3)+1)/M$5) -> 0 | N32: =MAX(0,(MIN($F32,N$4)-MAX($E32,N$3)+1)/N$5) -> 0 | O32: =MAX(0,(MIN($F32,O$4)-MAX($E32,O$3)+1)/O$5) -> 0 | P32: =MAX(0,(MIN($F32,P$4)-MAX($E32,P$3)+1)/P$5) -> 0 | Q32: =MAX(0,(MIN($F32,Q$4)-MAX($E32,Q$3)+1)/Q$5) -> 0 | ... FH32: =MAX(0,(MIN($F32,FH$4)-MAX($E32,FH$3)+1)/FH$5) -> 0
C33: Last debt repayment | D33: flag | E33: =EDATE($F16,In_Debt_Tenor*Months_In_Year) -> 52321 | I33: =SUM(J33:FH33) -> 1 | J33: =N(AND(J$3<=$E33,J$4>=$E33)) -> 0 | K33: =N(AND(K$3<=$E33,K$4>=$E33)) -> 0 | L33: =N(AND(L$3<=$E33,L$4>=$E33)) -> 0 | M33: =N(AND(M$3<=$E33,M$4>=$E33)) -> 0 | N33: =N(AND(N$3<=$E33,N$4>=$E33)) -> 0 | O33: =N(AND(O$3<=$E33,O$4>=$E33)) -> 0 | P33: =N(AND(P$3<=$E33,P$4>=$E33)) -> 0 | Q33: =N(AND(Q$3<=$E33,Q$4>=$E33)) -> 0 | ... FH33: =N(AND(FH$3<=$E33,FH$4>=$E33)) -> 0
C34: Tax depreciation spread: PV, grid, development | D34: factor | E34: =$F16+1 -> 46844 | F34: =EDATE($F16,In_Dep_Years*Months_In_Year) -> 57800 | I34: =SUM(J34:FH34) -> 1 | J34: =MAX(0,MIN($F34,J$4)-MAX($E34,J$3)+1)/($F34-$E34+1) -> 0 | K34: =MAX(0,MIN($F34,K$4)-MAX($E34,K$3)+1)/($F34-$E34+1) -> 0 | L34: =MAX(0,MIN($F34,L$4)-MAX($E34,L$3)+1)/($F34-$E34+1) -> 0 | M34: =MAX(0,MIN($F34,M$4)-MAX($E34,M$3)+1)/($F34-$E34+1) -> 0 | N34: =MAX(0,MIN($F34,N$4)-MAX($E34,N$3)+1)/($F34-$E34+1) -> 0 | O34: =MAX(0,MIN($F34,O$4)-MAX($E34,O$3)+1)/($F34-$E34+1) -> 0 | P34: =MAX(0,MIN($F34,P$4)-MAX($E34,P$3)+1)/($F34-$E34+1) -> 0 | Q34: =MAX(0,MIN($F34,Q$4)-MAX($E34,Q$3)+1)/($F34-$E34+1) -> 0 | ... FH34: =MAX(0,MIN($F34,FH$4)-MAX($E34,FH$3)+1)/($F34-$E34+1) -> 0
C35: Tax depreciation spread: BESS | D35: factor | E35: =$F16+1 -> 46844 | F35: =EDATE($F16,In_Dep_BESS_Years*Months_In_Year) -> 50495 | I35: =SUM(J35:FH35) -> 1 | J35: =MAX(0,MIN($F35,J$4)-MAX($E35,J$3)+1)/($F35-$E35+1) -> 0 | K35: =MAX(0,MIN($F35,K$4)-MAX($E35,K$3)+1)/($F35-$E35+1) -> 0 | L35: =MAX(0,MIN($F35,L$4)-MAX($E35,L$3)+1)/($F35-$E35+1) -> 0 | M35: =MAX(0,MIN($F35,M$4)-MAX($E35,M$3)+1)/($F35-$E35+1) -> 0 | N35: =MAX(0,MIN($F35,N$4)-MAX($E35,N$3)+1)/($F35-$E35+1) -> 0 | O35: =MAX(0,MIN($F35,O$4)-MAX($E35,O$3)+1)/($F35-$E35+1) -> 0 | P35: =MAX(0,MIN($F35,P$4)-MAX($E35,P$3)+1)/($F35-$E35+1) -> 0 | Q35: =MAX(0,MIN($F35,Q$4)-MAX($E35,Q$3)+1)/($F35-$E35+1) -> 0 | ... FH35: =MAX(0,MIN($F35,FH$4)-MAX($E35,FH$3)+1)/($F35-$E35+1) -> 0
C36: Debt compounding index (E: at COD, F: rate per period) | D36: factor | E36: =SUMIF($J$4:$FH$4,$F16,$J36:$FH36) -> 1.1322708 | F36: =In_Debt_Rate*Months_Per_Period/Months_In_Year -> 0.0125 | J36: =(1+$F36)^J$8 -> 1.0125 | K36: =(1+$F36)^K$8 -> 1.0251562 | L36: =(1+$F36)^L$8 -> 1.0379707 | M36: =(1+$F36)^M$8 -> 1.0509453 | N36: =(1+$F36)^N$8 -> 1.0640822 | O36: =(1+$F36)^O$8 -> 1.0773832 | P36: =(1+$F36)^P$8 -> 1.0908505 | Q36: =(1+$F36)^Q$8 -> 1.1044861 | ... FH36: =(1+$F36)^FH$8 -> 6.8585126
C37: 31-Dec capitalisation | D37: flag | J37: =N(MONTH(J$4)=Months_In_Year) -> 1 | K37: =N(MONTH(K$4)=Months_In_Year) -> 0 | L37: =N(MONTH(L$4)=Months_In_Year) -> 0 | M37: =N(MONTH(M$4)=Months_In_Year) -> 0 | N37: =N(MONTH(N$4)=Months_In_Year) -> 1 | O37: =N(MONTH(O$4)=Months_In_Year) -> 0 | P37: =N(MONTH(P$4)=Months_In_Year) -> 0 | Q37: =N(MONTH(Q$4)=Months_In_Year) -> 0 | ... FH37: =N(MONTH(FH$4)=Months_In_Year) -> 0
C38: First quarter of the year | D38: flag | J38: =N(MONTH(J$4)<=Months_Per_Period) -> 0 | K38: =N(MONTH(K$4)<=Months_Per_Period) -> 1 | L38: =N(MONTH(L$4)<=Months_Per_Period) -> 0 | M38: =N(MONTH(M$4)<=Months_Per_Period) -> 0 | N38: =N(MONTH(N$4)<=Months_Per_Period) -> 0 | O38: =N(MONTH(O$4)<=Months_Per_Period) -> 1 | P38: =N(MONTH(P$4)<=Months_Per_Period) -> 0 | Q38: =N(MONTH(Q$4)<=Months_Per_Period) -> 0 | ... FH38: =N(MONTH(FH$4)<=Months_Per_Period) -> 0
A40: x | C40: Prices (real 2025 curves × Aurora euro index)
C41: Aurora euro index | D41: factor | J41: =INDEX(Euro_Index,MATCH(J$7,Price_Years,0)) -> 1 | K41: =INDEX(Euro_Index,MATCH(K$7,Price_Years,0)) -> 1.01897 | L41: =INDEX(Euro_Index,MATCH(L$7,Price_Years,0)) -> 1.01897 | M41: =INDEX(Euro_Index,MATCH(M$7,Price_Years,0)) -> 1.01897 | N41: =INDEX(Euro_Index,MATCH(N$7,Price_Years,0)) -> 1.01897 | O41: =INDEX(Euro_Index,MATCH(O$7,Price_Years,0)) -> 1.040399 | P41: =INDEX(Euro_Index,MATCH(P$7,Price_Years,0)) -> 1.040399 | Q41: =INDEX(Euro_Index,MATCH(Q$7,Price_Years,0)) -> 1.040399 | ... FH41: =INDEX(Euro_Index,MATCH(FH$7,Price_Years,0)) -> 2.1668863
C42: PV price, direct export, real 2025 (E: curve) | D42: EUR/MWh | E42: =INDEX(Case_PV_Curve,1,$F12) -> DC 4h direct | J42: =INDEX(Price_Data,MATCH($E42,Price_Labels,0),MATCH(J$7,Price_Years,0)) -> 0 | K42: =INDEX(Price_Data,MATCH($E42,Price_Labels,0),MATCH(K$7,Price_Years,0)) -> 0 | L42: =INDEX(Price_Data,MATCH($E42,Price_Labels,0),MATCH(L$7,Price_Years,0)) -> 0 | M42: =INDEX(Price_Data,MATCH($E42,Price_Labels,0),MATCH(M$7,Price_Years,0)) -> 0 | N42: =INDEX(Price_Data,MATCH($E42,Price_Labels,0),MATCH(N$7,Price_Years,0)) -> 0 | O42: =INDEX(Price_Data,MATCH($E42,Price_Labels,0),MATCH(O$7,Price_Years,0)) -> 107.45398 | P42: =INDEX(Price_Data,MATCH($E42,Price_Labels,0),MATCH(P$7,Price_Years,0)) -> 107.45398 | Q42: =INDEX(Price_Data,MATCH($E42,Price_Labels,0),MATCH(Q$7,Price_Years,0)) -> 107.45398 | ... FH42: =INDEX(Price_Data,MATCH($E42,Price_Labels,0),MATCH(FH$7,Price_Years,0)) -> 56.585236
C43: PV price, energy sent to the BESS, real 2025 (E: curve) | D43: EUR/MWh | E43: =INDEX(Case_PV_Transfer,1,$F12) -> DC 4h transfer | J43: =INDEX(Price_Data,MATCH($E43,Price_Labels,0),MATCH(J$7,Price_Years,0)) -> 0 | K43: =INDEX(Price_Data,MATCH($E43,Price_Labels,0),MATCH(K$7,Price_Years,0)) -> 0 | L43: =INDEX(Price_Data,MATCH($E43,Price_Labels,0),MATCH(L$7,Price_Years,0)) -> 0 | M43: =INDEX(Price_Data,MATCH($E43,Price_Labels,0),MATCH(M$7,Price_Years,0)) -> 0 | N43: =INDEX(Price_Data,MATCH($E43,Price_Labels,0),MATCH(N$7,Price_Years,0)) -> 0 | O43: =INDEX(Price_Data,MATCH($E43,Price_Labels,0),MATCH(O$7,Price_Years,0)) -> 36.551423 | P43: =INDEX(Price_Data,MATCH($E43,Price_Labels,0),MATCH(P$7,Price_Years,0)) -> 36.551423 | Q43: =INDEX(Price_Data,MATCH($E43,Price_Labels,0),MATCH(Q$7,Price_Years,0)) -> 36.551423 | ... FH43: =INDEX(Price_Data,MATCH($E43,Price_Labels,0),MATCH(FH$7,Price_Years,0)) -> 20.340431
...

Sheet Calc_3
A1: 3 | C1: Bid number
B2: =Dashboard!$C$3&" – Calculations – "&INDEX(Bid_Labels,1,$A$1) -> Project Zalahaláp – Calculations – C Offer
C3: Period start | D3: date | J3: =I$4+1 -> 45931 | K3: =J$4+1 -> 46023 | L3: =K$4+1 -> 46113 | M3: =L$4+1 -> 46204 | N3: =M$4+1 -> 46296 | O3: =N$4+1 -> 46388 | P3: =O$4+1 -> 46478 | Q3: =P$4+1 -> 46569 | ... FH3: =FG$4+1 -> 59993
C4: Period end | D4: date | I4: =In_Model_Start-1 -> 45930 | J4: =EOMONTH(J$3,Months_Per_Period-1) -> 46022 | K4: =EOMONTH(K$3,Months_Per_Period-1) -> 46112 | L4: =EOMONTH(L$3,Months_Per_Period-1) -> 46203 | M4: =EOMONTH(M$3,Months_Per_Period-1) -> 46295 | N4: =EOMONTH(N$3,Months_Per_Period-1) -> 46387 | O4: =EOMONTH(O$3,Months_Per_Period-1) -> 46477 | P4: =EOMONTH(P$3,Months_Per_Period-1) -> 46568 | Q4: =EOMONTH(Q$3,Months_Per_Period-1) -> 46660 | ... FH4: =EOMONTH(FH$3,Months_Per_Period-1) -> 60083
C5: Days in period | D5: days | J5: =J$4-J$3+1 -> 92 | K5: =K$4-K$3+1 -> 90 | L5: =L$4-L$3+1 -> 91 | M5: =M$4-M$3+1 -> 92 | N5: =N$4-N$3+1 -> 92 | O5: =O$4-O$3+1 -> 90 | P5: =P$4-P$3+1 -> 91 | Q5: =Q$4-Q$3+1 -> 92 | ... FH5: =FH$4-FH$3+1 -> 91
C6: Year fraction | D6: factor | J6: =J$5/Days_In_Year -> 0.25205479 | K6: =K$5/Days_In_Year -> 0.24657534 | L6: =L$5/Days_In_Year -> 0.24931507 | M6: =M$5/Days_In_Year -> 0.25205479 | N6: =N$5/Days_In_Year -> 0.25205479 | O6: =O$5/Days_In_Year -> 0.24657534 | P6: =P$5/Days_In_Year -> 0.24931507 | Q6: =Q$5/Days_In_Year -> 0.25205479 | ... FH6: =FH$5/Days_In_Year -> 0.24931507
C7: Year | D7: year | J7: =YEAR(J$4) -> 2025 | K7: =YEAR(K$4) -> 2026 | L7: =YEAR(L$4) -> 2026 | M7: =YEAR(M$4) -> 2026 | N7: =YEAR(N$4) -> 2026 | O7: =YEAR(O$4) -> 2027 | P7: =YEAR(P$4) -> 2027 | Q7: =YEAR(Q$4) -> 2027 | ... FH7: =YEAR(FH$4) -> 2064
C8: Period counter | D8: # | J8: =I$8+1 -> 1 | K8: =J$8+1 -> 2 | L8: =K$8+1 -> 3 | M8: =L$8+1 -> 4 | N8: =M$8+1 -> 5 | O8: =N$8+1 -> 6 | P8: =O$8+1 -> 7 | Q8: =P$8+1 -> 8 | ... FH8: =FG$8+1 -> 155
A11: x | C11: Case and timing
C12: Revenue case (E: lever, F: column of the case table) | D12: text | E12: =INDEX(Dash_Case,1,$A$1) -> C | F12: =MATCH($E12,Case_Names,0) -> 3
C13: PV capacity (E: MWp) and grid export (F: MVA) | D13: MW | E13: =INDEX(Case_MWp,1,$F12) -> 63 | F13: =INDEX(Case_MVA,1,$F12) -> 49.9
C14: Specific yield (E: case, F: after the yield set) | D14: MWh/MWp | E14: =INDEX(Case_Yield,1,$F12) -> 1265 | F14: =$E14*(1+In_Yield_Adj) -> 1265
C15: RtB (E) and RtB exit (F) | D15: date | E15: =INDEX(Case_RtB,1,$F12) -> 46387 | F15: =INDEX(Case_Exit,1,$F12) -> 46477
C16: NTP (E) and COD (F) | D16: date | E16: =INDEX(Case_NTP,1,$F12) -> 46568 | F16: =EOMONTH(INDEX(Case_COD,1,$F12),In_COD_Delay) -> 46843
C17: Clipping, share of DC energy (case table) | D17: % | E17: =INDEX(Case_Clip,1,$F12) -> 0
C18: BESS built (E: MW, F: MWh) | D18: MW | E18: =In_BESS_MW*In_BESS_On -> 50 | F18: =$E18*In_BESS_Hours -> 200
C19: Acquisition and JV start | D19: flag | E19: =In_Acq -> 45991 | I19: =SUM(J19:FH19) -> 1 | J19: =N(AND(J$3<=$E19,J$4>=$E19)) -> 1 | K19: =N(AND(K$3<=$E19,K$4>=$E19)) -> 0 | L19: =N(AND(L$3<=$E19,L$4>=$E19)) -> 0 | M19: =N(AND(M$3<=$E19,M$4>=$E19)) -> 0 | N19: =N(AND(N$3<=$E19,N$4>=$E19)) -> 0 | O19: =N(AND(O$3<=$E19,O$4>=$E19)) -> 0 | P19: =N(AND(P$3<=$E19,P$4>=$E19)) -> 0 | Q19: =N(AND(Q$3<=$E19,Q$4>=$E19)) -> 0 | ... FH19: =N(AND(FH$3<=$E19,FH$4>=$E19)) -> 0
